Workbook

Sheet Start Here
B1: SPARKS Toolbox
B2: Ten money calculators in one workbook. Each tab is one question with a number for an answer.
B4: HOW IT WORKS
B5: Type only in the yellow boxes | C5: Blue numbers on yellow are yours to change. Everything in black is worked out from them and should be left alone.
B6: The answer is at the top of each tab | C6: A sentence in plain words, then the figures behind it. Change a yellow box and the sentence changes.
B7: Empty means not known | C7: A yellow box marked optional can be left blank. Do not type 0 unless the true figure is zero.
B8: Every tab opens with example numbers | C8: They are nobody's real numbers. Type over them with yours.
B9: Percentages are typed as percentages | C9: Type 7 in a rate box and it reads 7.00%. Money is typed in dollars.
B10: Estimates, not advice | C10: Taxes use the 2026 federal tables on the Tax Tables tab, marked unverified. No state schedules, no credits. A tool that says a bill is coming is a reason to check, not a return.
B12: LEGEND
B13: 12345 | C13: A number you type. Blue, on yellow.
B14: 12345 | C14: A number the sheet works out. Black. Leave it.
B15: 12345 | C15: The figure that answers the question. Bold, shaded.
B17: THE TEN TOOLS
B18: Paycheck Check | C18: Is the withholding on this paystub right? Refund or bill in April, and the change per check.
B19: Refinance | C19: Is a new loan worth its closing costs? Three paths to the last payment.
B20: Move the Debt | C20: A balance transfer or a consolidation loan against staying put.
B21: Pay Cash or Finance | C21: 0% for 24 months, or a discount for cash: which leaves you richer?
B22: Lump Sum or Payments | C22: A pension buyout or severance: the return the payments promise, the age the lump runs out.
B23: Cash Ladder | C23: CDs or Treasury bills in rungs against one savings account.
B24: Three Paychecks | C24: Which months hold a third check, and the budget that never counts on it.
B25: Borrow From Yourself | C25: What a 401(k) loan really costs, and the bill if you leave the job.
B26: Sinking Funds | C26: The yearly bills, spread into a monthly set-aside.
B27: Stay or Move | C27: The rent went up: stay, or move, and the counter-offer.
B29: Tax Tables | C29: The 2026 federal brackets, standard deductions, payroll tax rates and 401(k) loan limits the tools read. Change a figure here and every tool follows.
B31: Built from the SPARKS Toolbox (toolbox/), 2026-09-26. The same maths as the web tools; the web tools are the reference.

Sheet 01 Paycheck
B1: Paycheck Check
B2: One paystub, read as a year. Is the withholding on track, or is April a refund or a bill? Type the lines off one check; every check is assumed to look like it.
B4: ONE PAYSTUB
B5: Gross pay, this check | C5: 3000 | D5: Before anything comes out.
B6: Paid | C6: Every two weeks | D6: Pick from the list.
B7: Federal income tax withheld, this check | C7: 280 | D7: The federal line on the stub.
B8: 401(k) or other pre-tax, this check | C8: 180 | D8: 0 if none. Comes off before federal tax, not before payroll tax.
B9: Health, HSA, FSA premiums, this check | C9: 120 | D9: 0 if none. Comes off before federal and payroll tax.
B10: Social Security + Medicare withheld (optional) | D10: Type it to check it. Leave blank to skip.
B11: YOU
B12: Filing status | C12: Single | D12: Pick from the list.
B13: State income tax rate, flat (optional) | C13: 0.05 | D13: A single rate is a rough stand-in for a state schedule. 0 in a state with no income tax.
B14: State tax withheld, this check (optional) | C14: 100
B15: Checks already received this year | C15: 18 | D15: 0 in January.
B16: Other income this year with no withholding | C16: 0 | D16: Interest, a side gig.
B18: THE ANSWER
B19: =IF(ABS($C$32)<200,"On track. April comes within "&TEXT(ABS($C$32),"$#,##0")&" either way. Leave the W-4 alone.",IF($C$32<0,"A refund of about "&TEXT(-$C$32,"$#,##0")&" in April. You are lending the government "&TEXT(-$C$33,"$#,##0")&" a check, interest free.","A bill of about "&TEXT($C$32,"$#,##0")&" in April. Add about "&TEXT($C$33,"$#,##0")&" of extra withholding to each of the "&$C$23&" checks left.")) -> A refund of about $666 in April. You are lending the government $83 a check, interest free.
B21: THE YEAR, READ FROM THIS CHECK
B22: Checks a year | C22: =INDEX('Tax Tables'!$C$59:$C$62,MATCH($C$6,'Tax Tables'!$B$59:$B$62,0)) -> 26
B23: Checks left this year | C23: =MAX(0,$C$22-$C$15) -> 8
B24: Gross for the year | C24: =$C$5*$C$22 -> 78000
B25: Wages for federal tax | C25: =($C$5-$C$8-$C$9)*$C$22+$C$16 -> 70200 | D25: After both kinds of deduction, plus other income.
B26: Wages for payroll tax | C26: =($C$5-$C$9)*$C$22 -> 74880 | D26: Only the premiums come off.
B27: Standard deduction | C27: =INDEX('Tax Tables'!$C$37:$C$40,MATCH($C$12,'Tax Tables'!$B$37:$B$40,0)) -> 16100 | D27: From Tax Tables.
B28: Federal taxable income | C28: =MAX(0,$C$25-$C$27) -> 54100
B29: Federal tax for the year | C29: =SUMPRODUCT(('Tax Tables'!$B$6:$B$33=$C$12)*($C$28>'Tax Tables'!$C$6:$C$33)*($C$28-'Tax Tables'!$C$6:$C$33)*'Tax Tables'!$E$6:$E$33) -> 6614 | D29: The bracket ladder on Tax Tables. No credits.
B30: Rate on the next dollar | C30: =SUMPRODUCT(('Tax Tables'!$B$6:$B$33=$C$12)*($C$28>'Tax Tables'!$C$6:$C$33)*'Tax Tables'!$E$6:$E$33) -> 0.22
B31: Withheld for the year, at this check's rate | C31: =$C$7*$C$22 -> 7280
B32: April: tax less withholding | C32: =$C$29-$C$31 -> -666 | D32: Positive: you will owe. Negative: a refund.
B33: Change per remaining check to land at zero | C33: =IF($C$23>0,$C$32/$C$23,"no checks left") -> -83.25 | D33: Add this to line 4(c) of the W-4 (or reduce withholding by it if negative).
B35: PAYROLL TAX, CHECKED
B36: Social Security + Medicare for the year | C36: =MIN($C$26,'Tax Tables'!$C$44)*'Tax Tables'!$C$43+$C$26*'Tax Tables'!$C$45+MAX(0,$C$26-INDEX('Tax Tables'!$D$37:$D$40,MATCH($C$12,'Tax Tables'!$B$37:$B$40,0)))*'Tax Tables'!$C$46 -> 5728.32
B37: Per check, expected | C37: =$C$36/$C$22 -> 220.32
B38: Yours against expected | C38: =IF($C$10="","type the line to check it",IF(ABS($C$10-$C$37)<5,"matches",IF($C$10>$C$37,"yours is "&TEXT($C$10-$C$37,"$#,##0.00")&" more","yours is "&TEXT($C$37-$C$10,"$#,##0.00")&" less; ask payroll"))) -> type the line to check it | D38: Past the Social Security wage base late in the year, less is normal.
B39: Take-home per check | C39: =$C$5-$C$8-$C$9-$C$7-$C$14-IF($C$10="",$C$37,$C$10) -> 2099.68
B41: STATE, ROUGHLY
B42: State tax for the year at the flat rate | C42: =$C$28*$C$13 -> 2705 | D42: Federal taxable income times the flat rate. A stand-in, not a schedule.
B43: State withheld for the year | C43: =$C$14*$C$22 -> 2600
B44: State, in April | C44: =$C$42-$C$43 -> 105 | D44: Positive: owe. Negative: refund.
B46: Every check is assumed to look like this one. The year's federal tax is the 2026 bracket ladder on the wages after the pre-tax deductions and the standard deduction; no credits, no itemising. Payroll tax is Social Security up to the wage base plus Medicare. An estimate, not a return; the W-4 is where the change is made. Under-withholding by more than 10% of the tax can carry a penalty: the safe harbours are 90% of this year's tax or 100% of last year's.

Sheet 02 Refinance
B1: Refinance
B2: Is the new loan worth its closing costs? Any loan: a mortgage, a car, a student loan. Three paths costed to the last payment, and the month the saving has paid the costs back.
B4: THE LOAN YOU HAVE
B5: Balance left | C5: 300000
B6: Rate now | C6: 0.07
B7: Months left | C7: 300 | D7: Or leave it and type the payment below.
B8: Payment now (optional) | D8: If typed, it is used instead of the months left.
B9: THE LOAN ON OFFER
B10: New rate | C10: 0.055
B11: New term, months | C11: 360
B12: Closing costs | C12: 6000
B13: Roll the closing costs into the new balance? | C13: No | D13: Yes or No.
B15: THE ANSWER
B16: =IF($C$38="Keep the loan you have","Keep the loan you have. Refinancing costs "&TEXT($C$31,"$#,##0")&" more over its life.",IF($C$38="Take the new loan","Take the new loan: "&TEXT(-$C$31,"$#,##0")&" less over its life. The payment falls by "&TEXT($C$29,"$#,##0")&" a month and the closing costs are paid back in "&IF(ISNUMBER($C$30),TEXT($C$30,"0")&" months.","no time."),"Take the new loan but keep paying the old amount: "&TEXT(-$C$36,"$#,##0")&" less over its life, gone in "&TEXT($C$34,"0")&" months. Take the lower rate, ignore the lower payment.")) -> Take the new loan but keep paying the old amount: $145,329 less over its life, gone in 229 months. Take the lower rate, ignore the lower payment.
B18: KEEP THE LOAN YOU HAVE
B19: Payment now | C19: =IF($C$8>0,$C$8,PMT($C$6/12,$C$7,-$C$5)) -> 2120.3376 | D19: The level payment for the rate and months, unless you typed one.
B20: Months to the last payment | C20: =IF($C$8>0,IF($C$8<=$C$5*$C$6/12,"never: the payment does not cover the interest",NPER($C$6/12,-$C$8,$C$5)),$C$7) -> 300
B21: Paid in all | C21: =IFERROR($C$19*$C$20,"never") -> 636101.28
B22: Of which interest | C22: =IFERROR($C$21-$C$5,"never") -> 336101.28
B24: TAKE THE NEW LOAN
B25: New balance | C25: =$C$5+IF($C$13="Yes",$C$12,0) -> 300000
B26: New payment | C26: =PMT($C$10/12,$C$11,-$C$25) -> 1703.367
B27: Paid in all, closing costs included | C27: =$C$26*$C$11+IF($C$13="Yes",0,$C$12) -> 619212.12
B28: Of which interest and costs | C28: =$C$27-$C$5 -> 319212.12
B29: Monthly saving | C29: =$C$19-$C$26 -> 416.97059 | D29: Negative: the new payment is higher.
B30: Break-even | C30: =IF($C$29<=0,"never: the payment does not fall",IF($C$12=0,0,$C$12/$C$29)) -> 14.389504 | D30: Months for the saving to pay back the closing costs.
B31: Lifetime difference against keeping the loan | C31: =IFERROR($C$27-$C$21,"n/a") -> -16889.156 | D31: Negative: the new loan costs less over its life.
B33: NEW LOAN, KEEP PAYING THE OLD AMOUNT
B34: Months to the last payment | C34: =IF($C$19>$C$26,NPER($C$10/12,-$C$19,$C$25),"n/a: the old payment is not higher") -> 228.62999 | D34: The lower rate with the same payment clears it sooner.
B35: Paid in all, closing costs included | C35: =IFERROR($C$19*$C$34+IF($C$13="Yes",0,$C$12),"n/a") -> 490772.75
B36: Lifetime difference against keeping the loan | C36: =IFERROR($C$35-$C$21,"n/a") -> -145328.52
B38: Cheapest path | C38: =IFERROR(IF(MIN($C$21,$C$27,IF(ISNUMBER($C$35),$C$35,$C$21))=$C$21,"Keep the loan you have",IF(ISNUMBER($C$35),IF($C$35<=$C$27,"New loan, keep paying the old amount","Take the new loan"),"Take the new loan")),"Take the new loan") -> New loan, keep paying the old amount
B40: The payment on each loan is the level payment for its rate and term. Closing costs count in the new loan's cost whether paid up front or rolled in. A lower payment on a longer term is the trap this tab exists to show: the payment falls and the lifetime cost rises. Taxes, escrow, insurance and points are not modelled.
B42: BALANCE LEFT, YEAR BY YEAR
B43: Years from now | C43: Keep the loan | D43: Take the new loan
B44: 0 | C44: =IFERROR(IF(0*12>=$C$20,0,MAX(0,-FV($C$6/12,0*12,-$C$19,$C$5))),0) -> 300000 | D44: =IF(0*12>=$C$11,0,MAX(0,-FV($C$10/12,0*12,-$C$26,$C$25))) -> 300000
B45: 1 | C45: =IFERROR(IF(1*12>=$C$20,0,MAX(0,-FV($C$6/12,1*12,-$C$19,$C$5))),0) -> 295410.56 | D45: =IF(1*12>=$C$11,0,MAX(0,-FV($C$10/12,1*12,-$C$26,$C$25))) -> 295958.73
B46: 2 | C46: =IFERROR(IF(2*12>=$C$20,0,MAX(0,-FV($C$6/12,2*12,-$C$19,$C$5))),0) -> 290489.35 | D46: =IF(2*12>=$C$11,0,MAX(0,-FV($C$10/12,2*12,-$C$26,$C$25))) -> 291689.5
B47: 3 | C47: =IFERROR(IF(3*12>=$C$20,0,MAX(0,-FV($C$6/12,3*12,-$C$19,$C$5))),0) -> 285212.38 | D47: =IF(3*12>=$C$11,0,MAX(0,-FV($C$10/12,3*12,-$C$26,$C$25))) -> 287179.46
B48: 4 | C48: =IFERROR(IF(4*12>=$C$20,0,MAX(0,-FV($C$6/12,4*12,-$C$19,$C$5))),0) -> 279553.94 | D48: =IF(4*12>=$C$11,0,MAX(0,-FV($C$10/12,4*12,-$C$26,$C$25))) -> 282415.01
...

Sheet 03 Move the Debt
B1: Move the Debt
B2: A balance transfer or a consolidation loan against leaving it where it is. Three paths, each run to the last payment. The cost of a path is everything paid minus the balance itself: interest plus fees.
B4: THE DEBT
B5: Balance | C5: 8000
B6: APR now | C6: 0.24
B7: What you can pay a month | C7: 400
B8: A BALANCE TRANSFER CARD (leave blank if none)
B9: Transfer fee | C9: 0.03 | D9: Goes onto the balance.
B10: Promo, months at 0% | C10: 18
B11: APR after the promo | C11: 0.27
B12: A CONSOLIDATION LOAN (leave blank if none)
B13: Loan APR | C13: 0.11
B14: Term, months | C14: 24
B15: Origination fee | C15: 0.02 | D15: Added to the loan.
B17: THE ANSWER
B18: =IF($C$37="none clears it","None of these clears the balance at "&TEXT($C$7,"$#,##0")&" a month.",IF($C$37="Stay where it is","Stay where it is. The offers cost more than they save. It clears in "&TEXT($C$21,"0")&" months at "&TEXT($C$22,"$#,##0")&" of interest.",$C$37&": "&TEXT($C$38,"$#,##0")&" less than staying put."&IF($C$37="Balance transfer",IF($C$27=0," Your payment clears it inside the promo."," But "&TEXT($C$27,"$#,##0")&" is left when the promo ends; "&TEXT($C$26,"$#,##0")&" a month would clear it in time."),""))) -> Balance transfer: $2,035 less than staying put. But $1,040 is left when the promo ends; $458 a month would clear it in time.
B20: STAY WHERE IT IS
B21: Months to clear | C21: =IF($C$7<=$C$5*$C$6/12,"never: the payment does not cover the interest",NPER($C$6/12,-$C$7,$C$5)) -> 25.795851
B22: Cost: interest | C22: =IFERROR($C$7*$C$21-$C$5,"never") -> 2318.3404
B24: BALANCE TRANSFER
B25: Balance after the fee | C25: =IF($C$10>0,$C$5*(1+$C$9),"no offer") -> 8240
B26: Payment that clears it inside the promo | C26: =IFERROR($C$25/$C$10,"no offer") -> 457.77778 | D26: The number that matters.
B27: Left when the promo ends, at your payment | C27: =IFERROR(MAX(0,$C$25-$C$7*$C$10),"no offer") -> 1040
B28: Months to clear | C28: =IFERROR(IF($C$27=0,$C$25/$C$7,IF($C$7<=$C$27*$C$11/12,"never",$C$10+NPER($C$11/12,-$C$7,$C$27))),"no offer") -> 20.709181
B29: Cost: interest and fee | C29: =IFERROR($C$7*$C$28-$C$5,"n/a") -> 283.67247
B31: CONSOLIDATION LOAN
B32: Loan amount with the fee | C32: =IF($C$14>0,$C$5*(1+$C$15),"no offer") -> 8160
B33: Its payment | C33: =IFERROR(PMT($C$13/12,$C$14,-$C$32),"no offer") -> 380.31996
B34: Against what you can pay | C34: =IFERROR(IF($C$33>$C$7,TEXT($C$33-$C$7,"$#,##0")&" a month more than you said","fits"),"no offer") -> fits
B35: Cost: interest and fee | C35: =IFERROR($C$33*$C$14-$C$5,"n/a") -> 1127.679
B37: Cheapest path | C37: =IF(MIN(IF(ISNUMBER($C$22),$C$22,9E+099),IF(ISNUMBER($C$29),$C$29,9E+099),IF(ISNUMBER($C$35),$C$35,9E+099))=9E+099,"none clears it",IF(MIN(IF(ISNUMBER($C$22),$C$22,9E+099),IF(ISNUMBER($C$29),$C$29,9E+099),IF(ISNUMBER($C$35),$C$35,9E+099))=IF(ISNUMBER($C$22),$C$22,9E+099),"Stay where it is",IF(MIN(IF(ISNUMBER($C$29),$C$29,9E+099),IF(ISNUMBER($C$35),$C$35,9E+099))=IF(ISNUMBER($C$29),$C$29,9E+099),"Balance transfer","Consolidation loan"))) -> Balance transfer
B38: Saves against staying | C38: =IFERROR($C$22-MIN(IF(ISNUMBER($C$29),$C$29,9E+099),IF(ISNUMBER($C$35),$C$35,9E+099)),"n/a") -> 2034.6679
B40: The transfer fee goes onto the balance; the promo is taken at 0% and the after-rate applies to whatever is left. The trap is not in the arithmetic: a card moved to 0% is an empty card, and if it fills again you have two balances. Close it, freeze it, or cut it up. Minimum payments, late fees and credit score effects are not modelled.

Sheet 04 Cash or Finance
B1: Pay Cash or Finance
B2: The shop offers 0% for two years, or a little off for cash. Which leaves you with more after the last payment? You are assumed to hold the price in cash.
B4: THE THING, AND THE TWO WAYS TO PAY
B5: Price | C5: 2400
B6: Discount for paying cash | C6: 0.05 | D6: 0 if none.
B7: Financing APR | C7: 0 | D7: 0 for a 0% offer.
B8: Months of payments | C8: 24
B9: Any fee to finance | C9: 0
B10: What your cash earns where it sits | C10: 0.04 | D10: The savings account rate, usually.
B11: Is it a "no interest if paid in full by" plan? | C11: Yes | D11: Deferred interest. Yes or No.
B12: The rate on the fine print | C12: 0.2999 | D12: Only used if the answer above is Yes.
B14: THE ANSWER
B15: =IF(ABS($C$24)<1,"A wash: the two end within a dollar of each other.",IF($C$24>0,"Take the payments. You end "&TEXT($C$24,"$#,##0")&" ahead: your cash earns "&TEXT($C$23,"$#,##0")&" while the payments run.","Pay cash. You end "&TEXT(-$C$24,"$#,##0")&" ahead."))&IF($C$11="Yes"," Deferred interest: miss one payment and about "&TEXT(PMT($C$12/12,$C$8,-$C$5)*$C$8-$C$5,"$#,##0")&" of back interest lands.","") -> Pay cash. You end $25 ahead. Deferred interest: miss one payment and about $820 of back interest lands.
B17: THE TWO PATHS
B18: Cash price after the discount | C18: =$C$5*(1-$C$6) -> 2280
B19: Monthly payment | C19: =IF($C$7=0,$C$5/$C$8,PMT($C$7/12,$C$8,-$C$5)) -> 100
B20: Interest and fees on the financing | C20: =$C$19*$C$8-$C$5+$C$9 -> 0
B21: Pay cash: left in the account after the last month | C21: =($C$5-$C$18)*(1+$C$10/12)^$C$8 -> 129.97716 | D21: The discount, kept and growing.
B22: Finance: left in the account after the last payment | C22: =FV($C$10/12,$C$8,$C$19,-($C$5-$C$9)) -> 105.25433 | D22: The cash keeps earning while a payment leaves each month (a positive pmt in FV is money coming out).
B23: Earned by your cash while the payments run | C23: =$C$22-($C$5-$C$9-$C$19*$C$8) -> 105.25433
B24: Financing leaves you ahead by | C24: =$C$22-$C$21 -> -24.722828 | D24: Negative: paying cash leaves you ahead.
B25: Back interest if a deferred payment slips | C25: =IF($C$11="Yes",PMT($C$12/12,$C$8,-$C$5)*$C$8-$C$5,"n/a") -> 820.28197 | D25: Charged from day one at the fine-print rate if a single payment is late or any balance remains at the end.
B27: Paying cash: the discount stays in the account and earns the parked rate. Financing: the account keeps earning while a payment leaves it each month and any fee leaves at once. Whichever leaves more in the account after the last payment won. With a deferred-interest plan, set the payments to autopay and finish a month early.

Sheet 05 Lump or Payments
B1: Lump Sum or Payments
B2: One amount now, or so much a month for life. What return are the payments quietly promising, and how long would the lump sum last if you took it? Nothing here knows how long you will live; the age you plan to is the whole of that assumption.
B4: THE TWO OFFERS
B5: The lump sum, today | C5: 200000
B6: Or, a month | C6: 1200
B7: Payments rise each year by | C7: 0 | D7: 0 if fixed.
B8: Payments start at age (optional) | D8: Blank: they start now.
B9: YOU
B10: Your age | C10: 62
B11: Plan to age | C11: 90
B12: Return you would earn on the lump | C12: 0.05
B14: THE ANSWER
B15: =IF(ISNUMBER($C$22),"The payments, if you expect to live past "&$C$22&". At "&TEXT($C$12,"0.0%")&" the lump sum runs out at that age. The payments are quietly promising "&IF(ISNUMBER($C$21),TEXT($C$21,"0.0%"),"less than nothing")&" a year.","The lump sum, if you can earn "&TEXT($C$12,"0.0%")&". Drawn at "&TEXT($C$6,"$#,##0")&" a month it still holds "&TEXT($C$23,"$#,##0")&" at "&$C$11&". The payments promise only "&IF(ISNUMBER($C$21),TEXT($C$21,"0.0%"),"less than nothing")&" a year.") -> The payments, if you expect to live past 87. At 5.0% the lump sum runs out at that age. The payments are quietly promising 5.7% a year.
B17: THE TWO READINGS
B18: Payments start at | C18: =IF($C$8>0,$C$8,$C$10) -> 62
B19: Payments received by the planning age | C19: =SUM(D50:D111) -> 403200 | D19: From the year table below.
B20: Years of payments to equal the lump | C20: =$C$5/($C$6*12) -> 13.888889 | D20: Ignoring returns.
B21: Implied return of the payments | C21: =IFERROR(IRR(E50:E111),"below zero") -> 0.056581121 | D21: The yearly return the lump would have to earn to fund exactly these payments to the planning age.
B22: Lump sum runs out around age | C22: =IF(ISNUMBER(MATCH(0,F51:F111,0)),$C$10+MATCH(0,F51:F111,0),"not before "&$C$11) -> 87 | D22: Invested at your rate, drawn at the monthly amount from the start age.
B23: Left at the planning age if you take the lump | C23: =INDEX(F50:F111,$C$11-$C$10+1) -> 0
B25: Payments for life are insurance against living long; a lump sum is a bet that you will not, or that you can earn more than the implied return. Someone in good health with long-lived parents should lean to the payments; someone who needs the money flexible, or has heirs, to the lump. Also ask who stands behind the payments. Tax is not modelled: a lump rolled to an IRA is not taxed on arrival; a payment is taxed as it comes.
B48: YEAR BY YEAR
B49: Year | C49: Age | D49: Payments that year | E49: Cash flow for the return | F49: Lump sum left, at your rate
B50: 0 | C50: =$C$10+0 -> 62 | D50: 0 | E50: =-$C$5 -> -200000 | F50: =$C$5 -> 200000
B51: 1 | C51: =$C$10+1 -> 63 | D51: =IF(AND(C50>=$C$18,C50<$C$11),12*$C$6*(1+$C$7)^(C50-$C$18),0) -> 14400 | E51: =D51 -> 14400 | F51: =MAX(0,F50*(1+$C$12)-D51) -> 195600
B52: 2 | C52: =$C$10+2 -> 64 | D52: =IF(AND(C51>=$C$18,C51<$C$11),12*$C$6*(1+$C$7)^(C51-$C$18),0) -> 14400 | E52: =D52 -> 14400 | F52: =MAX(0,F51*(1+$C$12)-D52) -> 190980
B53: 3 | C53: =$C$10+3 -> 65 | D53: =IF(AND(C52>=$C$18,C52<$C$11),12*$C$6*(1+$C$7)^(C52-$C$18),0) -> 14400 | E53: =D53 -> 14400 | F53: =MAX(0,F52*(1+$C$12)-D53) -> 186129
B54: 4 | C54: =$C$10+4 -> 66 | D54: =IF(AND(C53>=$C$18,C53<$C$11),12*$C$6*(1+$C$7)^(C53-$C$18),0) -> 14400 | E54: =D54 -> 14400 | F54: =MAX(0,F53*(1+$C$12)-D54) -> 181035.45
B55: 5 | C55: =$C$10+5 -> 67 | D55: =IF(AND(C54>=$C$18,C54<$C$11),12*$C$6*(1+$C$7)^(C54-$C$18),0) -> 14400 | E55: =D55 -> 14400 | F55: =MAX(0,F54*(1+$C$12)-D55) -> 175687.22
B56: 6 | C56: =$C$10+6 -> 68 | D56: =IF(AND(C55>=$C$18,C55<$C$11),12*$C$6*(1+$C$7)^(C55-$C$18),0) -> 14400 | E56: =D56 -> 14400 | F56: =MAX(0,F55*(1+$C$12)-D56) -> 170071.58
B57: 7 | C57: =$C$10+7 -> 69 | D57: =IF(AND(C56>=$C$18,C56<$C$11),12*$C$6*(1+$C$7)^(C56-$C$18),0) -> 14400 | E57: =D57 -> 14400 | F57: =MAX(0,F56*(1+$C$12)-D57) -> 164175.16
B58: 8 | C58: =$C$10+8 -> 70 | D58: =IF(AND(C57>=$C$18,C57<$C$11),12*$C$6*(1+$C$7)^(C57-$C$18),0) -> 14400 | E58: =D58 -> 14400 | F58: =MAX(0,F57*(1+$C$12)-D58) -> 157983.92
B59: 9 | C59: =$C$10+9 -> 71 | D59: =IF(AND(C58>=$C$18,C58<$C$11),12*$C$6*(1+$C$7)^(C58-$C$18),0) -> 14400 | E59: =D59 -> 14400 | F59: =MAX(0,F58*(1+$C$12)-D59) -> 151483.12
B60: 10 | C60: =$C$10+10 -> 72 | D60: =IF(AND(C59>=$C$18,C59<$C$11),12*$C$6*(1+$C$7)^(C59-$C$18),0) -> 14400 | E60: =D60 -> 14400 | F60: =MAX(0,F59*(1+$C$12)-D60) -> 144657.27
B61: 11 | C61: =$C$10+11 -> 73 | D61: =IF(AND(C60>=$C$18,C60<$C$11),12*$C$6*(1+$C$7)^(C60-$C$18),0) -> 14400 | E61: =D61 -> 14400 | F61: =MAX(0,F60*(1+$C$12)-D61) -> 137490.14
B62: 12 | C62: =$C$10+12 -> 74 | D62: =IF(AND(C61>=$C$18,C61<$C$11),12*$C$6*(1+$C$7)^(C61-$C$18),0) -> 14400 | E62: =D62 -> 14400 | F62: =MAX(0,F61*(1+$C$12)-D62) -> 129964.64
B63: 13 | C63: =$C$10+13 -> 75 | D63: =IF(AND(C62>=$C$18,C62<$C$11),12*$C$6*(1+$C$7)^(C62-$C$18),0) -> 14400 | E63: =D63 -> 14400 | F63: =MAX(0,F62*(1+$C$12)-D63) -> 122062.88
B64: 14 | C64: =$C$10+14 -> 76 | D64: =IF(AND(C63>=$C$18,C63<$C$11),12*$C$6*(1+$C$7)^(C63-$C$18),0) -> 14400 | E64: =D64 -> 14400 | F64: =MAX(0,F63*(1+$C$12)-D64) -> 113766.02
B65: 15 | C65: =$C$10+15 -> 77 | D65: =IF(AND(C64>=$C$18,C64<$C$11),12*$C$6*(1+$C$7)^(C64-$C$18),0) -> 14400 | E65: =D65 -> 14400 | F65: =MAX(0,F64*(1+$C$12)-D65) -> 105054.32
B66: 16 | C66: =$C$10+16 -> 78 | D66: =IF(AND(C65>=$C$18,C65<$C$11),12*$C$6*(1+$C$7)^(C65-$C$18),0) -> 14400 | E66: =D66 -> 14400 | F66: =MAX(0,F65*(1+$C$12)-D66) -> 95907.036
...

Sheet 06 Cash Ladder
B1: Cash Ladder
B2: Cash you will not need this month, split across CDs or Treasury bills that mature at different times, against leaving it all in the savings account.
B4: THE CASH, AND WHERE IT SITS NOW
B5: Cash to place | C5: 20000
B6: Savings account rate | C6: 0.041
B7: Treasury bills? (no state income tax) | C7: Yes | D7: Yes or No.
B8: Your state income tax rate | C8: 0.05 | D8: Used only for Treasuries.
B9: Start date | C9: 46291
B11: THE ANSWER
B12: =IF(ABS($C$28)<1,"A wash: the ladder and the account earn within a dollar a year of each other.",IF($C$28>0,"The ladder earns "&TEXT($C$28,"$#,##0")&" a year more than the account. Blended it pays "&TEXT($C$22,"0.00%")&IF($C$7="Yes",", worth "&TEXT($C$23,"0.00%")&" once state tax is counted","")&"; the first rung unlocks "&TEXT($C$25,"mmm d, yyyy")&".","The account wins by "&TEXT(-$C$28,"$#,##0")&" a year. Leave it where it is.")) -> The ladder earns $196 a year more than the account. Blended it pays 4.83%, worth 5.08% once state tax is counted; the first rung unlocks Dec 26, 2026.
B14: THE RUNGS (type a term and a rate; leave a row blank to skip it)
B15: Rung | C15: Months | D15: Rate | E15: Share (optional) | F15: Amount | G15: Matures on | H15: Interest to maturity | I15: Tax-equivalent rate
B16: Rung 1 | C16: 3 | D16: 0.05 | F16: =IF(C16>0,$C$5*IF(SUM($E$16:$E$19)>0,E16/SUM($E$16:$E$19),1/COUNTIF($C$16:$C$19,">0")),0) -> 5000 | G16: =IF(C16>0,EDATE($C$9,C16),"") -> 46382 | H16: =F16*D16*C16/12 -> 62.5 | I16: =IF(C16>0,IF($C$7="Yes",D16/(1-$C$8),D16),"") -> 0.052631579
B17: Rung 2 | C17: 6 | D17: 0.049 | F17: =IF(C17>0,$C$5*IF(SUM($E$16:$E$19)>0,E17/SUM($E$16:$E$19),1/COUNTIF($C$16:$C$19,">0")),0) -> 5000 | G17: =IF(C17>0,EDATE($C$9,C17),"") -> 46472 | H17: =F17*D17*C17/12 -> 122.5 | I17: =IF(C17>0,IF($C$7="Yes",D17/(1-$C$8),D17),"") -> 0.051578947
B18: Rung 3 | C18: 9 | D18: 0.048 | F18: =IF(C18>0,$C$5*IF(SUM($E$16:$E$19)>0,E18/SUM($E$16:$E$19),1/COUNTIF($C$16:$C$19,">0")),0) -> 5000 | G18: =IF(C18>0,EDATE($C$9,C18),"") -> 46564 | H18: =F18*D18*C18/12 -> 180 | I18: =IF(C18>0,IF($C$7="Yes",D18/(1-$C$8),D18),"") -> 0.050526316
B19: Rung 4 | C19: 12 | D19: 0.046 | F19: =IF(C19>0,$C$5*IF(SUM($E$16:$E$19)>0,E19/SUM($E$16:$E$19),1/COUNTIF($C$16:$C$19,">0")),0) -> 5000 | G19: =IF(C19>0,EDATE($C$9,C19),"") -> 46656 | H19: =F19*D19*C19/12 -> 230 | I19: =IF(C19>0,IF($C$7="Yes",D19/(1-$C$8),D19),"") -> 0.048421053
B21: THE WHOLE
B22: Blended rate | C22: =SUMPRODUCT(F16:F19,D16:D19)/$C$5 -> 0.04825
B23: Blended tax-equivalent rate | C23: =IF($C$7="Yes",$C$22/(1-$C$8),$C$22) -> 0.050789474 | D23: What a taxable account would have to pay to match a Treasury, given state tax.
B24: Average months locked | C24: =SUMPRODUCT(F16:F19,C16:C19)/$C$5 -> 7.5
B25: First rung unlocks | C25: =MIN(G16:G19) -> 46382
B26: Interest by the last maturity, ladder | C26: =SUM(H16:H19) -> 595
B27: Same money in the account, same dates | C27: =SUMPRODUCT(F16:F19,C16:C19)*$C$6/12 -> 512.5
B28: A year of the ladder against the account | C28: =$C$5*($C$23-$C$6) -> 195.78947 | D28: Positive: the ladder earns more.
B30: Each rung earns simple interest to its maturity. A Treasury's interest is exempt from state income tax and a savings account's is not, so the comparison uses the tax-equivalent rate when the rungs are Treasuries. A ladder is a promise not to touch the money: keep what you might need before the first rung matures in the account. When a rung matures, roll it to the longest term and the ladder keeps unlocking. Early withdrawal penalties, reinvestment and federal tax are not modelled.

Sheet 07 Three Paychecks
B1: Three Paychecks
B2: Paid every two weeks, two months a year hold a third check; paid weekly, four months hold a fifth. Here are the months, the amount, and the budget that never counts on it.
B4: HOW YOU ARE PAID | H4: Payday list (helper)
B5: How often | C5: Every two weeks | D5: Pick from the list. | H5: =IF($C$13>0,$C$6+$C$13*(0-4),0) -> 46241
B6: Next payday | C6: 46297 | H6: =IF($C$13>0,$C$6+$C$13*(1-4),0) -> 46255
B7: Net pay per check | C7: 1800 | H7: =IF($C$13>0,$C$6+$C$13*(2-4),0) -> 46269
H8: =IF($C$13>0,$C$6+$C$13*(3-4),0) -> 46283
B9: THE ANSWER | H9: =IF($C$13>0,$C$6+$C$13*(4-4),0) -> 46297
B10: =IF($C$13=0,"Paid "&LOWER($C$5)&", every month has the same number of checks. There is no extra one.",$C$36&" of the next twelve months hold an extra check: "&TEXT($C$18,"$#,##0")&" a year the budget does not need. Build the month on "&TEXT($C$17,"$#,##0")&" ("&$C$15&" checks).") -> 2 of the next twelve months hold an extra check: $3,600 a year the budget does not need. Build the month on $3,600 (2 checks). | H10: =IF($C$13>0,$C$6+$C$13*(5-4),0) -> 46311
H11: =IF($C$13>0,$C$6+$C$13*(6-4),0) -> 46325
B12: THE NUMBERS | H12: =IF($C$13>0,$C$6+$C$13*(7-4),0) -> 46339
B13: Days between paydays | C13: =IF($C$5="Every week",7,IF($C$5="Every two weeks",14,0)) -> 14 | D13: 0 means there is no extra month. | H13: =IF($C$13>0,$C$6+$C$13*(8-4),0) -> 46353
B14: Checks a year | C14: =INDEX('Tax Tables'!$C$59:$C$62,MATCH($C$5,'Tax Tables'!$B$59:$B$62,0)) -> 26 | H14: =IF($C$13>0,$C$6+$C$13*(9-4),0) -> 46367
B15: Checks in a normal month | C15: =INDEX('Tax Tables'!$D$59:$D$62,MATCH($C$5,'Tax Tables'!$B$59:$B$62,0)) -> 2 | H15: =IF($C$13>0,$C$6+$C$13*(10-4),0) -> 46381
B16: Extra checks a year | C16: =$C$14-12*$C$15 -> 2 | H16: =IF($C$13>0,$C$6+$C$13*(11-4),0) -> 46395
B17: Build the month on | C17: =$C$15*$C$7 -> 3600 | D17: The normal count of checks. | H17: =IF($C$13>0,$C$6+$C$13*(12-4),0) -> 46409
B18: The extra checks are worth | C18: =$C$16*$C$7 -> 3600 | D18: A year, free to go somewhere on purpose. | H18: =IF($C$13>0,$C$6+$C$13*(13-4),0) -> 46423
B19: Spread over the year, a month | C19: =$C$18/12 -> 300 | H19: =IF($C$13>0,$C$6+$C$13*(14-4),0) -> 46437
B20: Take-home for the year | C20: =$C$14*$C$7 -> 46800 | H20: =IF($C$13>0,$C$6+$C$13*(15-4),0) -> 46451
H21: =IF($C$13>0,$C$6+$C$13*(16-4),0) -> 46465
B22: THE NEXT TWELVE MONTHS | H22: =IF($C$13>0,$C$6+$C$13*(17-4),0) -> 46479
B23: Month | C23: Paydays | D23: Extra checks | E23: Extra pay | H23: =IF($C$13>0,$C$6+$C$13*(18-4),0) -> 46493
B24: =DATE(YEAR($C$6),MONTH($C$6)+0,1) -> 46296 | C24: =IF($C$13>0,SUMPRODUCT(($H$5:$H$64>=B24)*($H$5:$H$64<=EOMONTH(B24,0))),$C$15) -> 3 | D24: =MAX(0,C24-$C$15) -> 1 | E24: =D24*$C$7 -> 1800 | H24: =IF($C$13>0,$C$6+$C$13*(19-4),0) -> 46507
B25: =DATE(YEAR($C$6),MONTH($C$6)+1,1) -> 46327 | C25: =IF($C$13>0,SUMPRODUCT(($H$5:$H$64>=B25)*($H$5:$H$64<=EOMONTH(B25,0))),$C$15) -> 2 | D25: =MAX(0,C25-$C$15) -> 0 | E25: =D25*$C$7 -> 0 | H25: =IF($C$13>0,$C$6+$C$13*(20-4),0) -> 46521
B26: =DATE(YEAR($C$6),MONTH($C$6)+2,1) -> 46357 | C26: =IF($C$13>0,SUMPRODUCT(($H$5:$H$64>=B26)*($H$5:$H$64<=EOMONTH(B26,0))),$C$15) -> 2 | D26: =MAX(0,C26-$C$15) -> 0 | E26: =D26*$C$7 -> 0 | H26: =IF($C$13>0,$C$6+$C$13*(21-4),0) -> 46535
B27: =DATE(YEAR($C$6),MONTH($C$6)+3,1) -> 46388 | C27: =IF($C$13>0,SUMPRODUCT(($H$5:$H$64>=B27)*($H$5:$H$64<=EOMONTH(B27,0))),$C$15) -> 2 | D27: =MAX(0,C27-$C$15) -> 0 | E27: =D27*$C$7 -> 0 | H27: =IF($C$13>0,$C$6+$C$13*(22-4),0) -> 46549
B28: =DATE(YEAR($C$6),MONTH($C$6)+4,1) -> 46419 | C28: =IF($C$13>0,SUMPRODUCT(($H$5:$H$64>=B28)*($H$5:$H$64<=EOMONTH(B28,0))),$C$15) -> 2 | D28: =MAX(0,C28-$C$15) -> 0 | E28: =D28*$C$7 -> 0 | H28: =IF($C$13>0,$C$6+$C$13*(23-4),0) -> 46563
B29: =DATE(YEAR($C$6),MONTH($C$6)+5,1) -> 46447 | C29: =IF($C$13>0,SUMPRODUCT(($H$5:$H$64>=B29)*($H$5:$H$64<=EOMONTH(B29,0))),$C$15) -> 2 | D29: =MAX(0,C29-$C$15) -> 0 | E29: =D29*$C$7 -> 0 | H29: =IF($C$13>0,$C$6+$C$13*(24-4),0) -> 46577
B30: =DATE(YEAR($C$6),MONTH($C$6)+6,1) -> 46478 | C30: =IF($C$13>0,SUMPRODUCT(($H$5:$H$64>=B30)*($H$5:$H$64<=EOMONTH(B30,0))),$C$15) -> 3 | D30: =MAX(0,C30-$C$15) -> 1 | E30: =D30*$C$7 -> 1800 | H30: =IF($C$13>0,$C$6+$C$13*(25-4),0) -> 46591
B31: =DATE(YEAR($C$6),MONTH($C$6)+7,1) -> 46508 | C31: =IF($C$13>0,SUMPRODUCT(($H$5:$H$64>=B31)*($H$5:$H$64<=EOMONTH(B31,0))),$C$15) -> 2 | D31: =MAX(0,C31-$C$15) -> 0 | E31: =D31*$C$7 -> 0 | H31: =IF($C$13>0,$C$6+$C$13*(26-4),0) -> 46605
B32: =DATE(YEAR($C$6),MONTH($C$6)+8,1) -> 46539 | C32: =IF($C$13>0,SUMPRODUCT(($H$5:$H$64>=B32)*($H$5:$H$64<=EOMONTH(B32,0))),$C$15) -> 2 | D32: =MAX(0,C32-$C$15) -> 0 | E32: =D32*$C$7 -> 0 | H32: =IF($C$13>0,$C$6+$C$13*(27-4),0) -> 46619
B33: =DATE(YEAR($C$6),MONTH($C$6)+9,1) -> 46569 | C33: =IF($C$13>0,SUMPRODUCT(($H$5:$H$64>=B33)*($H$5:$H$64<=EOMONTH(B33,0))),$C$15) -> 2 | D33: =MAX(0,C33-$C$15) -> 0 | E33: =D33*$C$7 -> 0 | H33: =IF($C$13>0,$C$6+$C$13*(28-4),0) -> 46633
B34: =DATE(YEAR($C$6),MONTH($C$6)+10,1) -> 46600 | C34: =IF($C$13>0,SUMPRODUCT(($H$5:$H$64>=B34)*($H$5:$H$64<=EOMONTH(B34,0))),$C$15) -> 2 | D34: =MAX(0,C34-$C$15) -> 0 | E34: =D34*$C$7 -> 0 | H34: =IF($C$13>0,$C$6+$C$13*(29-4),0) -> 46647
B35: =DATE(YEAR($C$6),MONTH($C$6)+11,1) -> 46631 | C35: =IF($C$13>0,SUMPRODUCT(($H$5:$H$64>=B35)*($H$5:$H$64<=EOMONTH(B35,0))),$C$15) -> 2 | D35: =MAX(0,C35-$C$15) -> 0 | E35: =D35*$C$7 -> 0 | H35: =IF($C$13>0,$C$6+$C$13*(30-4),0) -> 46661
B36: Months with an extra check | C36: =COUNTIF(D24:D35,">0") -> 2 | H36: =IF($C$13>0,$C$6+$C$13*(31-4),0) -> 46675
H37: =IF($C$13>0,$C$6+$C$13*(32-4),0) -> 46689
B38: The months are counted from your next payday forward, in the helper list to the right. A payday that falls on a weekend or holiday and is paid early may shift a month by one check. Decide now where the extra goes: the whole check to the highest-rate debt, to the cushion, or to the sinking funds. A standing rule beats a good intention. | H38: =IF($C$13>0,$C$6+$C$13*(33-4),0) -> 46703
H39: =IF($C$13>0,$C$6+$C$13*(34-4),0) -> 46717
H40: =IF($C$13>0,$C$6+$C$13*(35-4),0) -> 46731
H41: =IF($C$13>0,$C$6+$C$13*(36-4),0) -> 46745
...

Sheet 08 401k Loan
B1: Borrow From Yourself
B2: A 401(k) loan pays its interest back to you, which makes it look free. It is not: its cost is what the money did not earn while it was out. Here is that number, and what it costs if you leave the job.
B4: THE LOAN
B5: Borrow | C5: 20000
B6: Vested balance in the plan | C6: 80000
B7: Loan rate | C7: 0.085 | D7: Usually prime plus one or two.
B8: Repay over, months | C8: 60 | D8: Up to 60 by law, except a first home.
B9: Return the plan would earn | C9: 0.07
B10: Contributions you would pause, a month | C10: 500 | D10: 0 if none.
B11: THE TWO RISKS
B12: Your age | C12: 40
B13: Your marginal tax rate | C13: 0.22
B14: If you left the job after, months | C14: 24 | D14: Blank to skip.
B15: THE ALTERNATIVE
B16: A personal loan at | C16: 0.12 | D16: Blank to skip.
B18: THE ANSWER
B19: =IF($C$30>0,"Borrowing from yourself costs about "&TEXT($C$30,"$#,##0")&" over "&$C$8&" months","At a loan rate above the plan return, the loan costs nothing on the arithmetic")&IF(ISNUMBER($C$36),". Leave the job after "&$C$14&" months and "&TEXT($C$33,"$#,##0")&" is still owed: a bill of about "&TEXT($C$36,"$#,##0")&" if it is not repaid.",".")&IF(ISNUMBER($C$40)," "&$C$41&" is cheaper.","") -> Borrowing from yourself costs about $34,772 over 60 months. Leave the job after 24 months and $12,998 is still owed: a bill of about $4,160 if it is not repaid. The personal loan is cheaper.
B21: WHAT IT COSTS
B22: Most the plan can lend | C22: =MIN('Tax Tables'!$C$50,MAX($C$6*'Tax Tables'!$C$51,MIN('Tax Tables'!$C$52,$C$6))) -> 40000 | D22: The lesser of $50,000 and half the vested balance (Tax Tables).
B23: Inside the limits? | C23: =IF($C$5>$C$22,"No: over the amount the plan can lend",IF($C$8>'Tax Tables'!$C$53,"No: over "&'Tax Tables'!$C$53&" months","Yes")) -> Yes
B24: Monthly payment | C24: =PMT($C$7/12,$C$8,-$C$5) -> 410.33063
B25: Interest, paid to yourself | C25: =$C$24*$C$8-$C$5 -> 4619.8376
B26: Left in the plan, the loan would have grown to | C26: =$C$5*(1+$C$9/12)^$C$8 -> 28352.505
B27: Paid back a month at a time, it grows to | C27: =FV($C$9/12,$C$8,-$C$24,0) -> 29376.76 | D27: Each payment lands and grows from then.
B28: Growth the borrowed money misses | C28: =$C$26-$C$27 -> -1024.255 | D28: Can be negative when the loan rate beats the plan return.
B29: Paused contributions, at what they would be worth | C29: =FV($C$9/12,$C$8,-$C$10,0) -> 35796.451
B30: Cost of the plan loan | C30: =MAX(0,$C$28+$C$29) -> 34772.196
B32: IF YOU LEAVE THE JOB
B33: Still owed at that point | C33: =IF($C$14>0,MAX(0,-FV($C$7/12,$C$14,-$C$24,$C$5)),"n/a") -> 12998.5
B34: Income tax on it | C34: =IFERROR($C$33*$C$13,"n/a") -> 2859.6699 | D34: If not repaid by the tax deadline it becomes a withdrawal.
B35: Penalty | C35: =IFERROR(IF($C$12+$C$14/12<'Tax Tables'!$C$55,$C$33*'Tax Tables'!$C$54,0),"n/a") -> 1299.85 | D35: Before 59 and a half.
B36: The bill | C36: =IFERROR($C$34+$C$35,"n/a") -> 4159.5199 | D36: On money that is also gone from the plan.
B38: THE ALTERNATIVE
B39: Personal loan payment | C39: =IF($C$16>0,PMT($C$16/12,$C$8,-$C$5),"n/a") -> 444.88895
B40: Its interest, paid to a lender | C40: =IFERROR($C$39*$C$8-$C$5,"n/a") -> 6693.3372
B41: Cheaper | C41: =IFERROR(IF($C$40<$C$30,"The personal loan","The plan loan"),"n/a") -> The personal loan
B43: A lost employer match is not counted and would make it worse. On leaving a job the unpaid balance is due; a plan may allow rolling the offset amount to an IRA by the tax deadline. The limits are on the Tax Tables tab; a plan may set tighter ones and the plan document wins.

Sheet 09 Sinking Funds
B1: Sinking Funds
B2: The bills that come once or twice a year and always feel like a surprise. Spread into a monthly amount, with what the fund should already hold today and what lands in each of the next twelve months.
B4: TODAY
B5: Today | C5: =TODAY() -> 46291 | D5: Left as a formula, this is always today. Type a date to fix it.
B7: THE ANSWER
B8: =IF($F$27=0,"Add a bill to see the set-aside.","Set aside "&TEXT($F$27,"$#,##0")&" a month. The fund should hold "&TEXT($G$27,"$#,##0")&" today."&IF($C$44<0," Starting there it runs "&TEXT(-$C$44,"$#,##0")&" short in the year ahead: start with "&TEXT($C$45,"$#,##0")&" instead.","")) -> Set aside $568 a month. The fund should hold $3,755 today.
B10: THE BILLS (type up to fifteen; leave a row blank to skip it)
B11: Bill | C11: Amount | D11: Every (months) | E11: Next due | F11: A month | G11: Hold now | H11: A year | I11: Every, or 1 (helper)
B12: Car insurance | C12: 900 | D12: 6 | E12: 46371 | F12: =IF(AND(C12>0,D12>0),C12/D12,0) -> 150 | G12: =IF(AND(C12>0,D12>0,E12>0),C12*MAX(0,MIN(1,1-MAX(0,(E12-$C$5)/30.4375)/D12)),0) -> 505.74949 | H12: =IF(AND(C12>0,D12>0),C12*12/D12,0) -> 1800 | I12: =IF(D12>0,D12,1) -> 6
B13: Holidays and gifts | C13: 1200 | D13: 12 | E13: 46357 | F13: =IF(AND(C13>0,D13>0),C13/D13,0) -> 100 | G13: =IF(AND(C13>0,D13>0,E13>0),C13*MAX(0,MIN(1,1-MAX(0,(E13-$C$5)/30.4375)/D13)),0) -> 983.16222 | H13: =IF(AND(C13>0,D13>0),C13*12/D13,0) -> 1200 | I13: =IF(D13>0,D13,1) -> 12
B14: Property tax | C14: 3200 | D14: 12 | E14: 46487 | F14: =IF(AND(C14>0,D14>0),C14/D14,0) -> 266.66667 | G14: =IF(AND(C14>0,D14>0,E14>0),C14*MAX(0,MIN(1,1-MAX(0,(E14-$C$5)/30.4375)/D14)),0) -> 1482.82 | H14: =IF(AND(C14>0,D14>0),C14*12/D14,0) -> 3200 | I14: =IF(D14>0,D14,1) -> 12
B15: Tyres | C15: 800 | D15: 36 | E15: 46600 | F15: =IF(AND(C15>0,D15>0),C15/D15,0) -> 22.222222 | G15: =IF(AND(C15>0,D15>0,E15>0),C15*MAX(0,MIN(1,1-MAX(0,(E15-$C$5)/30.4375)/D15)),0) -> 574.4011 | H15: =IF(AND(C15>0,D15>0),C15*12/D15,0) -> 266.66667 | I15: =IF(D15>0,D15,1) -> 36
B16: Vet, the yearly visit | C16: 350 | D16: 12 | E16: 46438 | F16: =IF(AND(C16>0,D16>0),C16/D16,0) -> 29.166667 | G16: =IF(AND(C16>0,D16>0,E16>0),C16*MAX(0,MIN(1,1-MAX(0,(E16-$C$5)/30.4375)/D16)),0) -> 209.13758 | H16: =IF(AND(C16>0,D16>0),C16*12/D16,0) -> 350 | I16: =IF(D16>0,D16,1) -> 12
F17: =IF(AND(C17>0,D17>0),C17/D17,0) -> 0 | G17: =IF(AND(C17>0,D17>0,E17>0),C17*MAX(0,MIN(1,1-MAX(0,(E17-$C$5)/30.4375)/D17)),0) -> 0 | H17: =IF(AND(C17>0,D17>0),C17*12/D17,0) -> 0 | I17: =IF(D17>0,D17,1) -> 1
F18: =IF(AND(C18>0,D18>0),C18/D18,0) -> 0 | G18: =IF(AND(C18>0,D18>0,E18>0),C18*MAX(0,MIN(1,1-MAX(0,(E18-$C$5)/30.4375)/D18)),0) -> 0 | H18: =IF(AND(C18>0,D18>0),C18*12/D18,0) -> 0 | I18: =IF(D18>0,D18,1) -> 1
F19: =IF(AND(C19>0,D19>0),C19/D19,0) -> 0 | G19: =IF(AND(C19>0,D19>0,E19>0),C19*MAX(0,MIN(1,1-MAX(0,(E19-$C$5)/30.4375)/D19)),0) -> 0 | H19: =IF(AND(C19>0,D19>0),C19*12/D19,0) -> 0 | I19: =IF(D19>0,D19,1) -> 1
F20: =IF(AND(C20>0,D20>0),C20/D20,0) -> 0 | G20: =IF(AND(C20>0,D20>0,E20>0),C20*MAX(0,MIN(1,1-MAX(0,(E20-$C$5)/30.4375)/D20)),0) -> 0 | H20: =IF(AND(C20>0,D20>0),C20*12/D20,0) -> 0 | I20: =IF(D20>0,D20,1) -> 1
F21: =IF(AND(C21>0,D21>0),C21/D21,0) -> 0 | G21: =IF(AND(C21>0,D21>0,E21>0),C21*MAX(0,MIN(1,1-MAX(0,(E21-$C$5)/30.4375)/D21)),0) -> 0 | H21: =IF(AND(C21>0,D21>0),C21*12/D21,0) -> 0 | I21: =IF(D21>0,D21,1) -> 1
F22: =IF(AND(C22>0,D22>0),C22/D22,0) -> 0 | G22: =IF(AND(C22>0,D22>0,E22>0),C22*MAX(0,MIN(1,1-MAX(0,(E22-$C$5)/30.4375)/D22)),0) -> 0 | H22: =IF(AND(C22>0,D22>0),C22*12/D22,0) -> 0 | I22: =IF(D22>0,D22,1) -> 1
F23: =IF(AND(C23>0,D23>0),C23/D23,0) -> 0 | G23: =IF(AND(C23>0,D23>0,E23>0),C23*MAX(0,MIN(1,1-MAX(0,(E23-$C$5)/30.4375)/D23)),0) -> 0 | H23: =IF(AND(C23>0,D23>0),C23*12/D23,0) -> 0 | I23: =IF(D23>0,D23,1) -> 1
F24: =IF(AND(C24>0,D24>0),C24/D24,0) -> 0 | G24: =IF(AND(C24>0,D24>0,E24>0),C24*MAX(0,MIN(1,1-MAX(0,(E24-$C$5)/30.4375)/D24)),0) -> 0 | H24: =IF(AND(C24>0,D24>0),C24*12/D24,0) -> 0 | I24: =IF(D24>0,D24,1) -> 1
F25: =IF(AND(C25>0,D25>0),C25/D25,0) -> 0 | G25: =IF(AND(C25>0,D25>0,E25>0),C25*MAX(0,MIN(1,1-MAX(0,(E25-$C$5)/30.4375)/D25)),0) -> 0 | H25: =IF(AND(C25>0,D25>0),C25*12/D25,0) -> 0 | I25: =IF(D25>0,D25,1) -> 1
F26: =IF(AND(C26>0,D26>0),C26/D26,0) -> 0 | G26: =IF(AND(C26>0,D26>0,E26>0),C26*MAX(0,MIN(1,1-MAX(0,(E26-$C$5)/30.4375)/D26)),0) -> 0 | H26: =IF(AND(C26>0,D26>0),C26*12/D26,0) -> 0 | I26: =IF(D26>0,D26,1) -> 1
B27: All bills | F27: =SUM(F12:F26) -> 568.05556 | G27: =SUM(G12:G26) -> 3755.2704 | H27: =SUM(H12:H26) -> 6816.6667
B29: THE NEXT TWELVE MONTHS
B30: Month | C30: Lands | D30: Fund after | E30: Set aside
B31: Today | D31: =$G$27 -> 3755.2704
B32: =DATE(YEAR($C$5),MONTH($C$5)+0,1) -> 46266 | C32: =SUMPRODUCT(($C$12:$C$26>0)*($D$12:$D$26>0)*($E$12:$E$26>0)*$C$12:$C$26*(((YEAR(B32)-YEAR($E$12:$E$26))*12+MONTH(B32)-MONTH($E$12:$E$26))>=0)*(MOD(((YEAR(B32)-YEAR($E$12:$E$26))*12+MONTH(B32)-MONTH($E$12:$E$26)),$I$12:$I$26)=0)) -> 0 | D32: =D31+$F$27-C32 -> 4323.3259 | E32: =$F$27 -> 568.05556
B33: =DATE(YEAR($C$5),MONTH($C$5)+1,1) -> 46296 | C33: =SUMPRODUCT(($C$12:$C$26>0)*($D$12:$D$26>0)*($E$12:$E$26>0)*$C$12:$C$26*(((YEAR(B33)-YEAR($E$12:$E$26))*12+MONTH(B33)-MONTH($E$12:$E$26))>=0)*(MOD(((YEAR(B33)-YEAR($E$12:$E$26))*12+MONTH(B33)-MONTH($E$12:$E$26)),$I$12:$I$26)=0)) -> 0 | D33: =D32+$F$27-C33 -> 4891.3815 | E33: =$F$27 -> 568.05556
B34: =DATE(YEAR($C$5),MONTH($C$5)+2,1) -> 46327 | C34: =SUMPRODUCT(($C$12:$C$26>0)*($D$12:$D$26>0)*($E$12:$E$26>0)*$C$12:$C$26*(((YEAR(B34)-YEAR($E$12:$E$26))*12+MONTH(B34)-MONTH($E$12:$E$26))>=0)*(MOD(((YEAR(B34)-YEAR($E$12:$E$26))*12+MONTH(B34)-MONTH($E$12:$E$26)),$I$12:$I$26)=0)) -> 0 | D34: =D33+$F$27-C34 -> 5459.437 | E34: =$F$27 -> 568.05556
B35: =DATE(YEAR($C$5),MONTH($C$5)+3,1) -> 46357 | C35: =SUMPRODUCT(($C$12:$C$26>0)*($D$12:$D$26>0)*($E$12:$E$26>0)*$C$12:$C$26*(((YEAR(B35)-YEAR($E$12:$E$26))*12+MONTH(B35)-MONTH($E$12:$E$26))>=0)*(MOD(((YEAR(B35)-YEAR($E$12:$E$26))*12+MONTH(B35)-MONTH($E$12:$E$26)),$I$12:$I$26)=0)) -> 2100 | D35: =D34+$F$27-C35 -> 3927.4926 | E35: =$F$27 -> 568.05556
B36: =DATE(YEAR($C$5),MONTH($C$5)+4,1) -> 46388 | C36: =SUMPRODUCT(($C$12:$C$26>0)*($D$12:$D$26>0)*($E$12:$E$26>0)*$C$12:$C$26*(((YEAR(B36)-YEAR($E$12:$E$26))*12+MONTH(B36)-MONTH($E$12:$E$26))>=0)*(MOD(((YEAR(B36)-YEAR($E$12:$E$26))*12+MONTH(B36)-MONTH($E$12:$E$26)),$I$12:$I$26)=0)) -> 0 | D36: =D35+$F$27-C36 -> 4495.5481 | E36: =$F$27 -> 568.05556
B37: =DATE(YEAR($C$5),MONTH($C$5)+5,1) -> 46419 | C37: =SUMPRODUCT(($C$12:$C$26>0)*($D$12:$D$26>0)*($E$12:$E$26>0)*$C$12:$C$26*(((YEAR(B37)-YEAR($E$12:$E$26))*12+MONTH(B37)-MONTH($E$12:$E$26))>=0)*(MOD(((YEAR(B37)-YEAR($E$12:$E$26))*12+MONTH(B37)-MONTH($E$12:$E$26)),$I$12:$I$26)=0)) -> 350 | D37: =D36+$F$27-C37 -> 4713.6037 | E37: =$F$27 -> 568.05556
B38: =DATE(YEAR($C$5),MONTH($C$5)+6,1) -> 46447 | C38: =SUMPRODUCT(($C$12:$C$26>0)*($D$12:$D$26>0)*($E$12:$E$26>0)*$C$12:$C$26*(((YEAR(B38)-YEAR($E$12:$E$26))*12+MONTH(B38)-MONTH($E$12:$E$26))>=0)*(MOD(((YEAR(B38)-YEAR($E$12:$E$26))*12+MONTH(B38)-MONTH($E$12:$E$26)),$I$12:$I$26)=0)) -> 0 | D38: =D37+$F$27-C38 -> 5281.6593 | E38: =$F$27 -> 568.05556
B39: =DATE(YEAR($C$5),MONTH($C$5)+7,1) -> 46478 | C39: =SUMPRODUCT(($C$12:$C$26>0)*($D$12:$D$26>0)*($E$12:$E$26>0)*$C$12:$C$26*(((YEAR(B39)-YEAR($E$12:$E$26))*12+MONTH(B39)-MONTH($E$12:$E$26))>=0)*(MOD(((YEAR(B39)-YEAR($E$12:$E$26))*12+MONTH(B39)-MONTH($E$12:$E$26)),$I$12:$I$26)=0)) -> 3200 | D39: =D38+$F$27-C39 -> 2649.7148 | E39: =$F$27 -> 568.05556
B40: =DATE(YEAR($C$5),MONTH($C$5)+8,1) -> 46508 | C40: =SUMPRODUCT(($C$12:$C$26>0)*($D$12:$D$26>0)*($E$12:$E$26>0)*$C$12:$C$26*(((YEAR(B40)-YEAR($E$12:$E$26))*12+MONTH(B40)-MONTH($E$12:$E$26))>=0)*(MOD(((YEAR(B40)-YEAR($E$12:$E$26))*12+MONTH(B40)-MONTH($E$12:$E$26)),$I$12:$I$26)=0)) -> 0 | D40: =D39+$F$27-C40 -> 3217.7704 | E40: =$F$27 -> 568.05556
B41: =DATE(YEAR($C$5),MONTH($C$5)+9,1) -> 46539 | C41: =SUMPRODUCT(($C$12:$C$26>0)*($D$12:$D$26>0)*($E$12:$E$26>0)*$C$12:$C$26*(((YEAR(B41)-YEAR($E$12:$E$26))*12+MONTH(B41)-MONTH($E$12:$E$26))>=0)*(MOD(((YEAR(B41)-YEAR($E$12:$E$26))*12+MONTH(B41)-MONTH($E$12:$E$26)),$I$12:$I$26)=0)) -> 900 | D41: =D40+$F$27-C41 -> 2885.8259 | E41: =$F$27 -> 568.05556
B42: =DATE(YEAR($C$5),MONTH($C$5)+10,1) -> 46569 | C42: =SUMPRODUCT(($C$12:$C$26>0)*($D$12:$D$26>0)*($E$12:$E$26>0)*$C$12:$C$26*(((YEAR(B42)-YEAR($E$12:$E$26))*12+MONTH(B42)-MONTH($E$12:$E$26))>=0)*(MOD(((YEAR(B42)-YEAR($E$12:$E$26))*12+MONTH(B42)-MONTH($E$12:$E$26)),$I$12:$I$26)=0)) -> 0 | D42: =D41+$F$27-C42 -> 3453.8815 | E42: =$F$27 -> 568.05556
B43: =DATE(YEAR($C$5),MONTH($C$5)+11,1) -> 46600 | C43: =SUMPRODUCT(($C$12:$C$26>0)*($D$12:$D$26>0)*($E$12:$E$26>0)*$C$12:$C$26*(((YEAR(B43)-YEAR($E$12:$E$26))*12+MONTH(B43)-MONTH($E$12:$E$26))>=0)*(MOD(((YEAR(B43)-YEAR($E$12:$E$26))*12+MONTH(B43)-MONTH($E$12:$E$26)),$I$12:$I$26)=0)) -> 800 | D43: =D42+$F$27-C43 -> 3221.937 | E43: =$F$27 -> 568.05556
B44: Lowest the fund gets | C44: =MIN(D31:D43) -> 2649.7148
...

Sheet 10 Stay or Move
B1: Stay or Move
B2: The renewal letter came. Over the lease you would sign, does moving pay for itself? And the one number to take back to the landlord.
B4: THE RENTS
B5: Rent now | C5: 1800
B6: Rent if you stay | C6: 1950 | D6: The renewal letter.
B7: Rent at the new place | C7: 1700
B8: WHAT MOVING COSTS, ONCE
B9: Movers, truck, boxes | C9: 1200
B10: Fees and deposit you will not see again | C10: 500 | D10: A returned deposit is not a cost.
B11: Overlap rent, time off, the rest | C11: 800
B12: WHAT CHANGES EVERY MONTH
B13: Commute, more (+) or less (-) a month | C13: 50
B14: Utilities, parking, the rest, + or - | C14: 0
B15: Lease you would sign, months | C15: 12
B17: THE ANSWER
B18: =IF(ABS($C$28)<50,"A wash over "&$C$15&" months: the two come within "&TEXT(ABS($C$28),"$#,##0")&". Stay, unless you want to move.",IF($C$28>0,"Move. Over "&$C$15&" months it is "&TEXT($C$28,"$#,##0")&" cheaper, moving costs included; they are paid back in "&TEXT($C$25,"0")&" months.","Stay. Over "&$C$15&" months moving would cost "&TEXT(-$C$28,"$#,##0")&" more."))&" The counter-offer is "&TEXT($C$29,"$#,##0")&"." -> Stay. Over 12 months moving would cost $100 more. The counter-offer is $1,958.
B20: THE NUMBERS
B21: The rise | C21: =IF($C$5>0,($C$6-$C$5)/$C$5,"n/a") -> 0.083333333
B22: Moving, once | C22: =$C$9+$C$10+$C$11 -> 2500
B23: The new place, a month, all in | C23: =$C$7+$C$13+$C$14 -> 1750
B24: Moving saves, a month | C24: =$C$6-$C$23 -> 200 | D24: Negative: the new place costs more once everything is counted.
B25: Break-even | C25: =IF($C$24>0,$C$22/$C$24,"never") -> 12.5 | D25: Months for the saving to pay back the moving costs.
B26: Stay: cost over the lease | C26: =$C$6*$C$15 -> 23400
B27: Move: cost over the lease, moving included | C27: =$C$23*$C$15+$C$22 -> 23500
B28: Moving saves over the lease | C28: =$C$26-$C$27 -> -100 | D28: Negative: staying is cheaper.
B29: The counter-offer | C29: =$C$27/$C$15 -> 1958.3333 | D29: The rent at which staying costs exactly what moving does. Anything under it and you are ahead staying.
B31: Both paths are summed over the lease term. Staying costs the new rent each month; moving costs the new place's rent plus the monthly changes, plus the one-off costs on day one. An empty month costs the landlord a month of rent, which is why the counter-offer is worth making. The hassle of moving is real and has no box.
B33: MONTH BY MONTH
B34: Month | C34: Stay, so far | D34: Move, so far
B35: 0 | C35: =$C$6*0 -> 0 | D35: =$C$22+$C$23*0 -> 2500
B36: 1 | C36: =$C$6*1 -> 1950 | D36: =$C$22+$C$23*1 -> 4250
B37: 2 | C37: =$C$6*2 -> 3900 | D37: =$C$22+$C$23*2 -> 6000
B38: 3 | C38: =$C$6*3 -> 5850 | D38: =$C$22+$C$23*3 -> 7750
B39: 4 | C39: =$C$6*4 -> 7800 | D39: =$C$22+$C$23*4 -> 9500
B40: 5 | C40: =$C$6*5 -> 9750 | D40: =$C$22+$C$23*5 -> 11250
B41: 6 | C41: =$C$6*6 -> 11700 | D41: =$C$22+$C$23*6 -> 13000
B42: 7 | C42: =$C$6*7 -> 13650 | D42: =$C$22+$C$23*7 -> 14750
B43: 8 | C43: =$C$6*8 -> 15600 | D43: =$C$22+$C$23*8 -> 16500
B44: 9 | C44: =$C$6*9 -> 17550 | D44: =$C$22+$C$23*9 -> 18250
B45: 10 | C45: =$C$6*10 -> 19500 | D45: =$C$22+$C$23*10 -> 20000
...

Sheet Tax Tables
B1: Tax Tables, 2026
B2: Every figure the tools read, in one place. Change a number here and every tool follows. Source and confidence are stated beside each block.
B4: FEDERAL BRACKETS (ordinary income)
B5: Filing status | C5: Taxable income from | D5: Rate | E5: Rate step | F5: Note
B6: Single | C6: 0 | D6: 0.1 | E6: =D6-0 -> 0.1 | F6: Source: Federal ordinary-income brackets and standard deductions for tax year 2026 as announced by the IRS in its annual inflation adjustments (Rev. Proc. 2025-32). Transcribed from memory of the announcement; not yet re-derived against the published text.
B7: Single | C7: 12400 | D7: 0.12 | E7: =D7-D6 -> 0.02
B8: Single | C8: 50400 | D8: 0.22 | E8: =D8-D7 -> 0.1
B9: Single | C9: 105700 | D9: 0.24 | E9: =D9-D8 -> 0.02
B10: Single | C10: 201775 | D10: 0.32 | E10: =D10-D9 -> 0.08
B11: Single | C11: 256225 | D11: 0.35 | E11: =D11-D10 -> 0.03
B12: Single | C12: 640600 | D12: 0.37 | E12: =D12-D11 -> 0.02 | F12: Confidence: unverified. Thresholds have NOT been checked against the IRS revenue procedure line by line. Every room that shows a bracket from this file labels it 'federal only, estimate' until that pass is done (BRIEF §2.4). Marginal bracket only: no credits, no phase-outs, no state.
B13: Married, joint | C13: 0 | D13: 0.1 | E13: =D13-0 -> 0.1
B14: Married, joint | C14: 24800 | D14: 0.12 | E14: =D14-D13 -> 0.02
B15: Married, joint | C15: 100800 | D15: 0.22 | E15: =D15-D14 -> 0.1
B16: Married, joint | C16: 211400 | D16: 0.24 | E16: =D16-D15 -> 0.02
B17: Married, joint | C17: 403550 | D17: 0.32 | E17: =D17-D16 -> 0.08
B18: Married, joint | C18: 512450 | D18: 0.35 | E18: =D18-D17 -> 0.03
B19: Married, joint | C19: 768700 | D19: 0.37 | E19: =D19-D18 -> 0.02 | F19: Tax on a taxable income is the sum over rows of (income above the row's "from", if any) times the rate step. That is the bracket ladder in one formula, and it is what 01 Paycheck uses.
B20: Married, separate | C20: 0 | D20: 0.1 | E20: =D20-0 -> 0.1
B21: Married, separate | C21: 12400 | D21: 0.12 | E21: =D21-D20 -> 0.02
B22: Married, separate | C22: 50400 | D22: 0.22 | E22: =D22-D21 -> 0.1
B23: Married, separate | C23: 105700 | D23: 0.24 | E23: =D23-D22 -> 0.02
B24: Married, separate | C24: 201775 | D24: 0.32 | E24: =D24-D23 -> 0.08
B25: Married, separate | C25: 256225 | D25: 0.35 | E25: =D25-D24 -> 0.03
B26: Married, separate | C26: 384350 | D26: 0.37 | E26: =D26-D25 -> 0.02
B27: Head of household | C27: 0 | D27: 0.1 | E27: =D27-0 -> 0.1
B28: Head of household | C28: 17700 | D28: 0.12 | E28: =D28-D27 -> 0.02
B29: Head of household | C29: 67450 | D29: 0.22 | E29: =D29-D28 -> 0.1
B30: Head of household | C30: 105700 | D30: 0.24 | E30: =D30-D29 -> 0.02
B31: Head of household | C31: 201775 | D31: 0.32 | E31: =D31-D30 -> 0.08
B32: Head of household | C32: 256200 | D32: 0.35 | E32: =D32-D31 -> 0.03
B33: Head of household | C33: 640600 | D33: 0.37 | E33: =D33-D32 -> 0.02
B35: STANDARD DEDUCTION AND ADDITIONAL MEDICARE THRESHOLD
B36: Filing status | C36: Standard deduction | D36: Add. Medicare from
B37: Single | C37: 16100 | D37: 200000 | F37: Standard deduction: same source as the brackets. Additional Medicare threshold: Not deductible, and applies to the earnings above the threshold only.
B38: Married, joint | C38: 32200 | D38: 250000
B39: Married, separate | C39: 16100 | D39: 125000
B40: Head of household | C40: 24150 | D40: 200000
B42: PAYROLL TAX (what an employee pays)
B43: Social Security rate, employee | C43: 0.062 | F43: Half of the 12.4% combined rate; the employer pays the other half.
...
