Workbook

Sheet Start here
B1: The Binders
B2: A workbook that walks you through twelve business playbooks in four systems, one band at a time.
B4: What it is | C4: The playbook binder that shipped with the $100M Money Models launch holds twelve playbooks in four systems: Leads (Marketing Machine, Hooks, Lead Nurture), Sales (Closing Handbook, Proof Checklist, GOATed Ads), Delivery (Retention, Lifetime Value, Branding) and Profit (Price Raise, Promo Cash, Implementation SOPs). This workbook is a companion in its own words, built from the published $100M books and public material. No book or playbook text is reproduced, and it is not affiliated with Acquisition.com.
B5: How to use it | C5: 1. Open a playbook tab (they run left to right in the order of the four systems). 2. Work down band 1, then band 2, and so on. Type into the yellow cells only. 3. Tick a checklist item by choosing Y. When every yellow cell in a band is filled and every item is Y, the band reads done. 4. Come back to Dashboard to see all twelve at once, and to Readings for every figure the binder earns. 5. Do band 1 on every playbook before going deeper. A ring lights on the Dashboard when all twelve clear a band.
B6: The six bands | C6: Band 1, Read: The one idea, and where you stand on it today (payoff: reveal). Band 2, Facts: The few numbers this playbook runs on (payoff: reveal). Band 3, Exercises: The pen and paper work the playbook asks for (payoff: reveal). Band 4, Build: Assemble the thing you will use, and tick it off (payoff: power). Band 5, Run: Use it for a stretch and log what happened (payoff: certainty). Band 6, Sharpen: The moves only visible once the numbers are real (payoff: power).
B7: The four systems | C7: Leads: How do strangers find out you exist? Sales: How does a stranger become a customer? Delivery: How does a customer stay and bring more? Profit: How does each customer pay for the next?
B8: Colours | C8: Yellow cell with blue text: yours to type. Black text: a formula, leave it. Green text: a value read from another tab, typed once and only there (price, gross margin, cost to acquire, the booking rate). Grey italic: an example answer for a made-up money coach who sells an eight-week programme; every example number is invented.
B9: Money and percentages | C9: Type money in whole dollars. Type percentages as percentages (80%). A blank cell means not known yet; it is not zero. Type 0 only when the true answer is zero.
B10: Lists | C10: Where a cell asks for one item a line, press Alt+Enter (Option+Return on a Mac) to start a new line inside the cell. Where a step asks for a small table, fill the rows under its grey header; add more rows on the sheet if eight is not enough.
B11: Rules of thumb | C11: Three to one (lifetime gross profit to cost of a customer), five minutes (first reply to a lead), nine touches (the follow-up sequence), thirty days (cash back from a new customer) are rules of thumb, not findings. Your numbers decide.
B12: Privacy | C12: This file lives wherever you save it. Nothing in it goes anywhere unless you send it.
B13: Version | C13: Built from the Binders app in the Personalfinance repository, data version 1.0, 2026-09-26.
B15: Legend
B16: Yours to type | C16: =IF(B16="","","This is what a filled cell looks like: type over the yellow.") -> This is what a filled cell looks like: type over the yellow.
B17: =1+1 -> 2 | C17: A formula in black. Leave it.
B18: ='Lifetime Value'!D1 -> Delivery system | C18: A value read from another tab, in green.
B19: an example | C19: An example answer, grey and italic. Every example number is made up.

Sheet Dashboard
B1: The Binders
B2: Twelve playbooks in four systems, six bands deep. A band means the same depth on every playbook: read the idea, type the facts, do the exercises, build the thing, run it, sharpen it.
B4: Where you stand
B5: System | C5: Playbook | D5: Levels done | E5: Working on | F5: Answered | G5: Of | H5: Ticked | I5: Of | J5: Share done | L5: Band 1 | M5: Band 2 | N5: Band 3 | O5: Band 4 | P5: Band 5 | Q5: Band 6
B6: Leads | C6: Marketing Machine | D6: ='Marketing Machine'!$D$13 -> 0 | E6: ='Marketing Machine'!$D$14 -> 1 | F6: =SUM('Marketing Machine'!$D$7:$D$12) -> 0 | G6: =SUM('Marketing Machine'!$E$7:$E$12) -> 21 | H6: =SUM('Marketing Machine'!$F$7:$F$12) -> 0 | I6: =SUM('Marketing Machine'!$G$7:$G$12) -> 14 | J6: ='Marketing Machine'!$D$15 -> 0 | L6: ='Marketing Machine'!$H$7 -> not yet | M6: ='Marketing Machine'!$H$8 -> not yet | N6: ='Marketing Machine'!$H$9 -> not yet | O6: ='Marketing Machine'!$H$10 -> not yet | P6: ='Marketing Machine'!$H$11 -> not yet | Q6: ='Marketing Machine'!$H$12 -> not yet
B7: Leads | C7: Hooks | D7: =Hooks!$D$13 -> 0 | E7: =Hooks!$D$14 -> 1 | F7: =SUM(Hooks!$D$7:$D$12) -> 0 | G7: =SUM(Hooks!$E$7:$E$12) -> 15 | H7: =SUM(Hooks!$F$7:$F$12) -> 0 | I7: =SUM(Hooks!$G$7:$G$12) -> 14 | J7: =Hooks!$D$15 -> 0 | L7: =Hooks!$H$7 -> not yet | M7: =Hooks!$H$8 -> not yet | N7: =Hooks!$H$9 -> not yet | O7: =Hooks!$H$10 -> not yet | P7: =Hooks!$H$11 -> not yet | Q7: =Hooks!$H$12 -> not yet
B8: Leads | C8: Lead Nurture | D8: ='Lead Nurture'!$D$13 -> 0 | E8: ='Lead Nurture'!$D$14 -> 1 | F8: =SUM('Lead Nurture'!$D$7:$D$12) -> 0 | G8: =SUM('Lead Nurture'!$E$7:$E$12) -> 17 | H8: =SUM('Lead Nurture'!$F$7:$F$12) -> 0 | I8: =SUM('Lead Nurture'!$G$7:$G$12) -> 15 | J8: ='Lead Nurture'!$D$15 -> 0 | L8: ='Lead Nurture'!$H$7 -> not yet | M8: ='Lead Nurture'!$H$8 -> not yet | N8: ='Lead Nurture'!$H$9 -> not yet | O8: ='Lead Nurture'!$H$10 -> not yet | P8: ='Lead Nurture'!$H$11 -> not yet | Q8: ='Lead Nurture'!$H$12 -> not yet
B9: Sales | C9: Closing Handbook | D9: ='Closing Handbook'!$D$13 -> 0 | E9: ='Closing Handbook'!$D$14 -> 1 | F9: =SUM('Closing Handbook'!$D$7:$D$12) -> 0 | G9: =SUM('Closing Handbook'!$E$7:$E$12) -> 19 | H9: =SUM('Closing Handbook'!$F$7:$F$12) -> 0 | I9: =SUM('Closing Handbook'!$G$7:$G$12) -> 17 | J9: ='Closing Handbook'!$D$15 -> 0 | L9: ='Closing Handbook'!$H$7 -> not yet | M9: ='Closing Handbook'!$H$8 -> not yet | N9: ='Closing Handbook'!$H$9 -> not yet | O9: ='Closing Handbook'!$H$10 -> not yet | P9: ='Closing Handbook'!$H$11 -> not yet | Q9: ='Closing Handbook'!$H$12 -> not yet
B10: Sales | C10: Proof Checklist | D10: ='Proof Checklist'!$D$13 -> 0 | E10: ='Proof Checklist'!$D$14 -> 1 | F10: =SUM('Proof Checklist'!$D$7:$D$12) -> 0 | G10: =SUM('Proof Checklist'!$E$7:$E$12) -> 18 | H10: =SUM('Proof Checklist'!$F$7:$F$12) -> 0 | I10: =SUM('Proof Checklist'!$G$7:$G$12) -> 15 | J10: ='Proof Checklist'!$D$15 -> 0 | L10: ='Proof Checklist'!$H$7 -> not yet | M10: ='Proof Checklist'!$H$8 -> not yet | N10: ='Proof Checklist'!$H$9 -> not yet | O10: ='Proof Checklist'!$H$10 -> not yet | P10: ='Proof Checklist'!$H$11 -> not yet | Q10: ='Proof Checklist'!$H$12 -> not yet
B11: Sales | C11: GOATed Ads | D11: ='GOATed Ads'!$D$13 -> 0 | E11: ='GOATed Ads'!$D$14 -> 1 | F11: =SUM('GOATed Ads'!$D$7:$D$12) -> 0 | G11: =SUM('GOATed Ads'!$E$7:$E$12) -> 21 | H11: =SUM('GOATed Ads'!$F$7:$F$12) -> 0 | I11: =SUM('GOATed Ads'!$G$7:$G$12) -> 15 | J11: ='GOATed Ads'!$D$15 -> 0 | L11: ='GOATed Ads'!$H$7 -> not yet | M11: ='GOATed Ads'!$H$8 -> not yet | N11: ='GOATed Ads'!$H$9 -> not yet | O11: ='GOATed Ads'!$H$10 -> not yet | P11: ='GOATed Ads'!$H$11 -> not yet | Q11: ='GOATed Ads'!$H$12 -> not yet
B12: Delivery | C12: Retention | D12: =Retention!$D$13 -> 0 | E12: =Retention!$D$14 -> 1 | F12: =SUM(Retention!$D$7:$D$12) -> 0 | G12: =SUM(Retention!$E$7:$E$12) -> 15 | H12: =SUM(Retention!$F$7:$F$12) -> 0 | I12: =SUM(Retention!$G$7:$G$12) -> 14 | J12: =Retention!$D$15 -> 0 | L12: =Retention!$H$7 -> not yet | M12: =Retention!$H$8 -> not yet | N12: =Retention!$H$9 -> not yet | O12: =Retention!$H$10 -> not yet | P12: =Retention!$H$11 -> not yet | Q12: =Retention!$H$12 -> not yet
B13: Delivery | C13: Lifetime Value | D13: ='Lifetime Value'!$D$13 -> 0 | E13: ='Lifetime Value'!$D$14 -> 1 | F13: =SUM('Lifetime Value'!$D$7:$D$12) -> 0 | G13: =SUM('Lifetime Value'!$E$7:$E$12) -> 17 | H13: =SUM('Lifetime Value'!$F$7:$F$12) -> 0 | I13: =SUM('Lifetime Value'!$G$7:$G$12) -> 11 | J13: ='Lifetime Value'!$D$15 -> 0 | L13: ='Lifetime Value'!$H$7 -> not yet | M13: ='Lifetime Value'!$H$8 -> not yet | N13: ='Lifetime Value'!$H$9 -> not yet | O13: ='Lifetime Value'!$H$10 -> not yet | P13: ='Lifetime Value'!$H$11 -> not yet | Q13: ='Lifetime Value'!$H$12 -> not yet
B14: Delivery | C14: Branding | D14: =Branding!$D$13 -> 0 | E14: =Branding!$D$14 -> 1 | F14: =SUM(Branding!$D$7:$D$12) -> 0 | G14: =SUM(Branding!$E$7:$E$12) -> 15 | H14: =SUM(Branding!$F$7:$F$12) -> 0 | I14: =SUM(Branding!$G$7:$G$12) -> 13 | J14: =Branding!$D$15 -> 0 | L14: =Branding!$H$7 -> not yet | M14: =Branding!$H$8 -> not yet | N14: =Branding!$H$9 -> not yet | O14: =Branding!$H$10 -> not yet | P14: =Branding!$H$11 -> not yet | Q14: =Branding!$H$12 -> not yet
B15: Profit | C15: Price Raise | D15: ='Price Raise'!$D$13 -> 0 | E15: ='Price Raise'!$D$14 -> 1 | F15: =SUM('Price Raise'!$D$7:$D$12) -> 0 | G15: =SUM('Price Raise'!$E$7:$E$12) -> 15 | H15: =SUM('Price Raise'!$F$7:$F$12) -> 0 | I15: =SUM('Price Raise'!$G$7:$G$12) -> 12 | J15: ='Price Raise'!$D$15 -> 0 | L15: ='Price Raise'!$H$7 -> not yet | M15: ='Price Raise'!$H$8 -> not yet | N15: ='Price Raise'!$H$9 -> not yet | O15: ='Price Raise'!$H$10 -> not yet | P15: ='Price Raise'!$H$11 -> not yet | Q15: ='Price Raise'!$H$12 -> not yet
B16: Profit | C16: Promo Cash | D16: ='Promo Cash'!$D$13 -> 0 | E16: ='Promo Cash'!$D$14 -> 1 | F16: =SUM('Promo Cash'!$D$7:$D$12) -> 0 | G16: =SUM('Promo Cash'!$E$7:$E$12) -> 17 | H16: =SUM('Promo Cash'!$F$7:$F$12) -> 0 | I16: =SUM('Promo Cash'!$G$7:$G$12) -> 12 | J16: ='Promo Cash'!$D$15 -> 0 | L16: ='Promo Cash'!$H$7 -> not yet | M16: ='Promo Cash'!$H$8 -> not yet | N16: ='Promo Cash'!$H$9 -> not yet | O16: ='Promo Cash'!$H$10 -> not yet | P16: ='Promo Cash'!$H$11 -> not yet | Q16: ='Promo Cash'!$H$12 -> not yet
B17: Profit | C17: Implementation SOPs | D17: ='Implementation SOPs'!$D$13 -> 0 | E17: ='Implementation SOPs'!$D$14 -> 1 | F17: =SUM('Implementation SOPs'!$D$7:$D$12) -> 0 | G17: =SUM('Implementation SOPs'!$E$7:$E$12) -> 13 | H17: =SUM('Implementation SOPs'!$F$7:$F$12) -> 0 | I17: =SUM('Implementation SOPs'!$G$7:$G$12) -> 13 | J17: ='Implementation SOPs'!$D$15 -> 0 | L17: ='Implementation SOPs'!$H$7 -> not yet | M17: ='Implementation SOPs'!$H$8 -> not yet | N17: ='Implementation SOPs'!$H$9 -> not yet | O17: ='Implementation SOPs'!$H$10 -> not yet | P17: ='Implementation SOPs'!$H$11 -> not yet | Q17: ='Implementation SOPs'!$H$12 -> not yet
C18: All twelve | D18: =SUM(D6:D17) -> 0 | F18: =SUM(F6:F17) -> 0 | G18: =SUM(G6:G17) -> 203 | H18: =SUM(H6:H17) -> 0 | I18: =SUM(I6:I17) -> 165 | J18: =IF(SUM(G6:G17,I6:I17)=0,0,SUM(F6:F17,H6:H17)/SUM(G6:G17,I6:I17)) -> 0 | L18: =IF(COUNTIF(L6:L17,"done")=12,"ring lit",COUNTIF(L6:L17,"done")&" of 12") -> 0 of 12 | M18: =IF(COUNTIF(M6:M17,"done")=12,"ring lit",COUNTIF(M6:M17,"done")&" of 12") -> 0 of 12 | N18: =IF(COUNTIF(N6:N17,"done")=12,"ring lit",COUNTIF(N6:N17,"done")&" of 12") -> 0 of 12 | O18: =IF(COUNTIF(O6:O17,"done")=12,"ring lit",COUNTIF(O6:O17,"done")&" of 12") -> 0 of 12 | P18: =IF(COUNTIF(P6:P17,"done")=12,"ring lit",COUNTIF(P6:P17,"done")&" of 12") -> 0 of 12 | Q18: =IF(COUNTIF(Q6:Q17,"done")=12,"ring lit",COUNTIF(Q6:Q17,"done")&" of 12") -> 0 of 12
B20: Levels done | D20: =D18&" of 72" -> 0 of 72 | F20: A band is done when every yellow cell in it holds an answer and every checklist item is Y. A ring lights when all twelve playbooks have finished a band. Start with band 1 on every playbook before going deeper: the same rule as the SPARKS planets.
B21: Rings lit | D21: =COUNTIF(L18:Q18,"ring lit")&" of 6" -> 0 of 6
B22: Answers | D22: =F18&" of "&G18 -> 0 of 203
B24: Headline readings
B25: Reading | D25: Value | E25: Playbook | F25: Rule of thumb
B26: Leads needed per month | D26: =Readings!$C$62 -> not yet | E26: Marketing Machine | F26: Customers wanted over the close and booking rates
B27: Show rate (showed / booked) | D27: =Readings!$C$5 -> not yet | E27: Closing Handbook | F27: Seven of ten
B28: Close rate, before (bought / showed) | D28: =Readings!$C$6 -> not yet | E28: Closing Handbook
B29: Lifetime gross profit per customer | D29: =Readings!$C$98 -> not yet | E29: Lifetime Value
B30: Lifetime gross profit to cost of a customer | D30: =Readings!$C$100 -> not yet | E30: Lifetime Value | F30: Three to one
B31: Monthly churn, before | D31: =Readings!$C$111 -> not yet | E31: Retention
B32: Customers you can lose and break even | D32: =Readings!$C$150 -> not yet | E32: Price Raise | F32: Raise over margin plus raise
B33: Thirty-day ratio | D33: =Readings!$C$170 -> not yet | E33: Promo Cash | F33: Above one, growth pays for itself
B34: Cost per customer, before | D34: =Readings!$C$52 -> not yet | E34: GOATed Ads | F34: Against the lifetime gross profit
B35: Procedures someone else runs | D35: =Readings!$C$178 -> not yet | E35: Implementation SOPs

Sheet Lists
A1: machine_channel_now | B1: first_channel | C1: next_move | D1: hook_format | E1: hook_next | F1: magnet_type | G1: nurture_next | H1: closing_next | I1: proof_next | J1: ad_place | K1: ads_next | L1: ret_next | M1: ltv_lever_pick | N1: ltv_next | O1: brand_next | P1: grandfather | Q1: price_next | R1: attraction_type | S1: promo_next | T1: sops_next | U1: yesno
A2: Warm outreach: people who know me | B2: Warm outreach | C2: More: double the volume on the same channel | D2: A post | E2: The frame | F2: Reveal a problem they did not know they had: an audit, a score, a checklist | G2: Faster: cut the reply time in half | H2: Show rate: fix the reminders before the call | I2: Numbers: turn stories into results with figures | J2: Short video | K2: Hook: the click rate is low | L2: Onboarding: the first week | M2: More customers | N2: Raise the price (see Price Raise) | O2: Narrower: cut who it is for | P2: The old price for a set term | Q2: Raise again in a quarter | R2: Win your money back: a result earns a refund or a credit | S2: Raise the attraction offer's string | T2: Hand off one more procedure | U2: Y
A3: Content: posting for people who do not know me yet | B3: Content | C3: Better: fix the message, same volume | D3: An email subject line | E3: The who | F3: A sample or trial of the real thing | G3: More: add three touches | H3: Close rate: tighten the label and the overview | I3: Faces: get three on video | J3: Image and text | K3: Page: clicks do not become leads | L3: Cadence: the check-ins | M3: More per purchase | N3: Add the upsell (see Promo Cash) | O3: Louder: more touches | P3: The old price for as long as they stay | Q3: Hold: the loss was near breakeven | R3: Free with a string: free now, paid after, or a deposit | S3: Raise the upsell take rate | T3: Cut a number nobody uses | U3: N
A4: Cold outreach: contacting strangers | B4: Cold outreach | C4: New: add the next channel, keep this one running | D4: An ad | E4: The claim | F4: One step of a multi-step result: the first week, the first tool | G4: Better: change the magnet | H4: Cash rate: change the payment ask | I4: Reach: get third-party marks | J4: Long video | K4: Sales: leads do not become buyers (see Closing Handbook) | L4: Fit: stop selling to the ones who leave | M4: More purchases | N4: Cut churn (see Retention) | O4: Tighter: fix the off-brand touches | P4: Nothing: everyone moves on the same day | Q4: Add a higher tier above it | R4: Commit for a discount: a term for a lower price | S4: Add continuity | T4: Fix the one number that fell
A5: Paid ads | B5: Paid ads | D5: A video opener | E5: The format it runs in | G5: Reactivate: send the short check-in to the whole old list | H5: Handoff: write the script so someone else can run it | I5: Guarantee: back the biggest doubt with a promise | J5: Search text | K5: Scale: the ratio holds, spend more | L5: Winback: reactivate the ones who left | M5: A longer stay | N5: Cut the cost to acquire (see GOATed Ads, Marketing Machine) | O5: Bigger: stand beside a name they already trust | Q5: Add a lower entry below it (see Promo Cash) | R5: Giveaway: a prize that collects many leads | S5: Cut delivery cost in the first 30 days | T5: Hire for the biggest owner-only task
A6: None yet | D6: A direct message opener | R6: Decoy: a lesser option that makes the real one obvious

Sheet Readings
B1: Readings: every figure the binder earns, as live formulas
B2: Nothing here is typed. Each figure reads the facts on its playbook sheet and says "not yet" until they exist. Rules of thumb are rules of thumb, not findings.
B4: Sales: Closing Handbook
B5: Show rate (showed / booked) | C5: =IF(OR('Closing Handbook'!$D$31="",'Closing Handbook'!$D$30="",'Closing Handbook'!$D$30=0),"not yet",'Closing Handbook'!$D$31/'Closing Handbook'!$D$30) -> not yet | H5: Seven of ten is the rule of thumb to beat.
B6: Close rate, before (bought / showed) | C6: =IF(OR('Closing Handbook'!$D$32="",'Closing Handbook'!$D$31="",'Closing Handbook'!$D$31=0),"not yet",'Closing Handbook'!$D$32/'Closing Handbook'!$D$31) -> not yet
B7: Close rate, after the run | C7: =IF(OR('Closing Handbook'!$D$75="",'Closing Handbook'!$D$74="",'Closing Handbook'!$D$74=0),"not yet",'Closing Handbook'!$D$75/'Closing Handbook'!$D$74) -> not yet
B8: Cash collected per sale | C8: =IF(OR('Closing Handbook'!$D$33="",'Closing Handbook'!$D$32="",'Closing Handbook'!$D$32=0),"not yet",'Closing Handbook'!$D$33/'Closing Handbook'!$D$32) -> not yet | H8: Compare with the price in Lifetime Value.
B9: Share of the price collected at the close | C9: =IF(OR('Lifetime Value'!$D$29="",'Lifetime Value'!$D$29=0,$C$8="not yet"),"not yet",$C$8/'Lifetime Value'!$D$29) -> not yet
B10: The funnel, last month
B11: Step | C11: Count
B12: Booked | C12: ='Closing Handbook'!$D$30 -> 0
B13: Showed | C13: ='Closing Handbook'!$D$31 -> 0
B14: Bought | C14: ='Closing Handbook'!$D$32 -> 0
B15: Objections heard
B16: Objection | C16: Times heard | D16: Answered well
B17: =IF('Closing Handbook'!$C$79="","",'Closing Handbook'!$C$79) | C17: =IF('Closing Handbook'!$D$79="","",'Closing Handbook'!$D$79) | D17: =IF('Closing Handbook'!$E$79="","",'Closing Handbook'!$E$79)
B18: =IF('Closing Handbook'!$C$80="","",'Closing Handbook'!$C$80) | C18: =IF('Closing Handbook'!$D$80="","",'Closing Handbook'!$D$80) | D18: =IF('Closing Handbook'!$E$80="","",'Closing Handbook'!$E$80)
B19: =IF('Closing Handbook'!$C$81="","",'Closing Handbook'!$C$81) | C19: =IF('Closing Handbook'!$D$81="","",'Closing Handbook'!$D$81) | D19: =IF('Closing Handbook'!$E$81="","",'Closing Handbook'!$E$81)
B20: =IF('Closing Handbook'!$C$82="","",'Closing Handbook'!$C$82) | C20: =IF('Closing Handbook'!$D$82="","",'Closing Handbook'!$D$82) | D20: =IF('Closing Handbook'!$E$82="","",'Closing Handbook'!$E$82)
B21: =IF('Closing Handbook'!$C$83="","",'Closing Handbook'!$C$83) | C21: =IF('Closing Handbook'!$D$83="","",'Closing Handbook'!$D$83) | D21: =IF('Closing Handbook'!$E$83="","",'Closing Handbook'!$E$83)
B22: =IF('Closing Handbook'!$C$84="","",'Closing Handbook'!$C$84) | C22: =IF('Closing Handbook'!$D$84="","",'Closing Handbook'!$D$84) | D22: =IF('Closing Handbook'!$E$84="","",'Closing Handbook'!$E$84)
B23: =IF('Closing Handbook'!$C$85="","",'Closing Handbook'!$C$85) | C23: =IF('Closing Handbook'!$D$85="","",'Closing Handbook'!$D$85) | D23: =IF('Closing Handbook'!$E$85="","",'Closing Handbook'!$E$85)
B24: =IF('Closing Handbook'!$C$86="","",'Closing Handbook'!$C$86) | C24: =IF('Closing Handbook'!$D$86="","",'Closing Handbook'!$D$86) | D24: =IF('Closing Handbook'!$E$86="","",'Closing Handbook'!$E$86)
B26: Sales: Proof Checklist
B27: Proof by kind
B28: Kind | C28: Count
B29: Results with a number | C29: ='Proof Checklist'!$D$30 -> 0
B30: Named testimonials | C30: ='Proof Checklist'!$D$31 -> 0
B31: Before and after | C31: ='Proof Checklist'!$D$32 -> 0
B32: Third-party marks | C32: ='Proof Checklist'!$D$33 -> 0
B33: Demonstrations | C33: ='Proof Checklist'!$D$34 -> 0
B34: Claims listed | C34: =IF('Proof Checklist'!$D$42="",0,LEN('Proof Checklist'!$D$42)-LEN(SUBSTITUTE('Proof Checklist'!$D$42,CHAR(10),""))+1) -> 0
B35: Claims with a proof beside them | C35: =COUNTIFS('Proof Checklist'!$D$63:$D$70,"<>",'Proof Checklist'!$D$63:$D$70,"<>cut") -> 0 | H35: Rows of the proof map whose second column is filled and is not the word cut.
B36: Coverage (claims with proof / claims) | C36: =IF($C$34=0,"not yet",MIN(1,$C$35/$C$34)) -> not yet
B37: Testimonials per 100 customers | C37: =IF(OR('Proof Checklist'!$D$31="",'Proof Checklist'!$D$35="",'Proof Checklist'!$D$35=0),"not yet",'Proof Checklist'!$D$31/'Proof Checklist'!$D$35*100) -> not yet
B38: Asks that came back | C38: =IF(OR('Proof Checklist'!$D$83="",'Proof Checklist'!$D$82="",'Proof Checklist'!$D$82=0),"not yet",'Proof Checklist'!$D$83/'Proof Checklist'!$D$82) -> not yet
B40: Sales: GOATed Ads
B41: The ad chain, last month
B42: Step | C42: Count
B43: Shown | C43: ='GOATed Ads'!$D$31 -> 0
...

Sheet Marketing Machine
C1: Marketing Machine | D1: Leads system
C2: Four ways to let people know you exist, and how much of each you need.
C3: Advertising is letting people know about the thing you sell. There are only four ways to do it: reach out to people who already know you, post content for people who do not know you yet, reach out cold to strangers, and pay to put your message in front of them. Anyone else who gets you leads is doing one of those four on your behalf. The machine is the amount of each you do every day, on purpose, counted.
C5: Where you stand on this planet
B6: # | C6: Band | D6: Answered | E6: Of | F6: Ticked | G6: Of | H6: Status
B7: 1 | C7: Read: The one idea, and where you stand on it today | D7: =SUMIFS($E$19:$E$400,$A$19:$A$400,B7,$B$19:$B$400,"exercise") -> 0 | E7: =COUNTIFS($A$19:$A$400,B7,$B$19:$B$400,"exercise") -> 3 | F7: =SUMIFS($E$19:$E$400,$A$19:$A$400,B7,$B$19:$B$400,"check") -> 0 | G7: =COUNTIFS($A$19:$A$400,B7,$B$19:$B$400,"check") -> 2 | H7: =IF(AND(D7=E7,F7=G7),"done",IF(D7+F7>0,"started","not yet")) -> not yet | I7: =IF(H7="done",99,B7) -> 1
B8: 2 | C8: Facts: The few numbers this playbook runs on | D8: =SUMIFS($E$19:$E$400,$A$19:$A$400,B8,$B$19:$B$400,"exercise") -> 0 | E8: =COUNTIFS($A$19:$A$400,B8,$B$19:$B$400,"exercise") -> 6 | F8: =SUMIFS($E$19:$E$400,$A$19:$A$400,B8,$B$19:$B$400,"check") -> 0 | G8: =COUNTIFS($A$19:$A$400,B8,$B$19:$B$400,"check") -> 1 | H8: =IF(AND(D8=E8,F8=G8),"done",IF(D8+F8>0,"started","not yet")) -> not yet | I8: =IF(H8="done",99,B8) -> 2
B9: 3 | C9: Exercises: The pen and paper work the playbook asks for | D9: =SUMIFS($E$19:$E$400,$A$19:$A$400,B9,$B$19:$B$400,"exercise") -> 0 | E9: =COUNTIFS($A$19:$A$400,B9,$B$19:$B$400,"exercise") -> 4 | F9: =SUMIFS($E$19:$E$400,$A$19:$A$400,B9,$B$19:$B$400,"check") -> 0 | G9: =COUNTIFS($A$19:$A$400,B9,$B$19:$B$400,"check") -> 2 | H9: =IF(AND(D9=E9,F9=G9),"done",IF(D9+F9>0,"started","not yet")) -> not yet | I9: =IF(H9="done",99,B9) -> 3
B10: 4 | C10: Build: Assemble the thing you will use, and tick it off | D10: =SUMIFS($E$19:$E$400,$A$19:$A$400,B10,$B$19:$B$400,"exercise") -> 0 | E10: =COUNTIFS($A$19:$A$400,B10,$B$19:$B$400,"exercise") -> 2 | F10: =SUMIFS($E$19:$E$400,$A$19:$A$400,B10,$B$19:$B$400,"check") -> 0 | G10: =COUNTIFS($A$19:$A$400,B10,$B$19:$B$400,"check") -> 5 | H10: =IF(AND(D10=E10,F10=G10),"done",IF(D10+F10>0,"started","not yet")) -> not yet | I10: =IF(H10="done",99,B10) -> 4
B11: 5 | C11: Run: Use it for a stretch and log what happened | D11: =SUMIFS($E$19:$E$400,$A$19:$A$400,B11,$B$19:$B$400,"exercise") -> 0 | E11: =COUNTIFS($A$19:$A$400,B11,$B$19:$B$400,"exercise") -> 4 | F11: =SUMIFS($E$19:$E$400,$A$19:$A$400,B11,$B$19:$B$400,"check") -> 0 | G11: =COUNTIFS($A$19:$A$400,B11,$B$19:$B$400,"check") -> 1 | H11: =IF(AND(D11=E11,F11=G11),"done",IF(D11+F11>0,"started","not yet")) -> not yet | I11: =IF(H11="done",99,B11) -> 5
B12: 6 | C12: Sharpen: The moves only visible once the numbers are real | D12: =SUMIFS($E$19:$E$400,$A$19:$A$400,B12,$B$19:$B$400,"exercise") -> 0 | E12: =COUNTIFS($A$19:$A$400,B12,$B$19:$B$400,"exercise") -> 2 | F12: =SUMIFS($E$19:$E$400,$A$19:$A$400,B12,$B$19:$B$400,"check") -> 0 | G12: =COUNTIFS($A$19:$A$400,B12,$B$19:$B$400,"check") -> 3 | H12: =IF(AND(D12=E12,F12=G12),"done",IF(D12+F12>0,"started","not yet")) -> not yet | I12: =IF(H12="done",99,B12) -> 6
C13: Levels done | D13: =COUNTIF(H7:H12,"done") -> 0 | F13: Yellow cells are yours to fill. A band is done when every yellow cell in it holds an answer and every checklist item is Y.
C14: Working on band | D14: =IF(MIN(I7:I12)=99,"complete",MIN(I7:I12)) -> 1
C15: Share of this planet answered | D15: =IF(SUM(E7:E12,G7:G12)=0,0,SUM(D7:D12,F7:F12)/SUM(E7:E12,G7:G12)) -> 0
A18: Band | B18: Kind | C18: Exercise or step | D18: Your answer | E18: ✓ | F18: Example | G18: What counts, where to look
A19: 1 | B19: band | C19: Band 1 · Read · reveal · about 6 min: The four ways, and what you do now
B20: why | C20: Most lead problems are volume problems wearing a strategy costume. Before choosing anything, write down what actually happened last week.
A21: 1 | B21: exercise | C21: How steady is your lead flow, 1 to 5 | E21: =IF(D21<>"",1,0) -> 0 | F21: 2 | G21: One is not at all, five is fully. Your honest read today.
A22: 1 | B22: exercise | C22: What you did last week to get leads, literally | E22: =IF(D22<>"",1,0) -> 0 | F22: About thirty warm messages, five posts, twenty cold DMs. No ads worth counting. | G22: How many messages, how many posts, how many cold contacts, how many dollars. Count, do not describe.
A23: 1 | B23: exercise | C23: The channel that brings most of your leads today | E23: =IF(D23<>"",1,0) -> 0 | F23: Warm outreach: people who know me | G23: Pick one from the dropdown.
B24: head | C24: Checklist
A25: 1 | B25: check | C25: ☐ I can name the four ways to get leads without looking | E25: =IF(D25="Y",1,0) -> 0 | G25: Y when it is true.
A26: 1 | B26: check | C26: ☐ I wrote what I actually did last week, not what I meant to do | E26: =IF(D26="Y",1,0) -> 0 | G26: Y when it is true.
B27: checkpoint | C27: When this band is done: The planet shows where you start and the four ways are named.
A29: 2 | B29: band | C29: Band 2 · Facts · reveal · about 8 min: The weekly counts
B30: why | C30: A machine has dials. These are the dials: how much of each way you do in a normal week, and how many people raise a hand because of it.
A31: 2 | B31: exercise | C31: Warm reach-outs per week | E31: =IF(D31<>"",1,0) -> 0 | F31: 30 | G31: Messages to people who already know you: contacts, followers, past customers.
A32: 2 | B32: exercise | C32: Pieces of content per week | E32: =IF(D32<>"",1,0) -> 0 | F32: 5 | G32: Posts, emails, videos: anything for people who do not know you yet.
A33: 2 | B33: exercise | C33: Cold contacts per week | E33: =IF(D33<>"",1,0) -> 0 | F33: 20 | G33: Strangers you reached out to first: calls, DMs, emails, doors.
A34: 2 | B34: exercise | C34: Ad spend per week | E34: =IF(D34<>"",1,0) -> 0 | F34: 100 | G34: Dollars paid for attention. Zero is a number; leave it blank if you do not know. Whole dollars.
A35: 2 | B35: exercise | C35: Engaged leads per month | E35: =IF(D35<>"",1,0) -> 0 | F35: 25 | G35: People who replied, booked, or opted in. A view is not a lead.
A36: 2 | B36: exercise | C36: New customers you want per month | E36: =IF(D36<>"",1,0) -> 0 | F36: 8 | G36: The target the machine has to produce.
B37: head | C37: Checklist
A38: 2 | B38: check | C38: ☐ Every count comes from a log, a sent folder or a receipt, not from memory | E38: =IF(D38="Y",1,0) -> 0 | G38: Y when it is true.
B39: checkpoint | C39: When this band is done: The machine mix draws, and the leads-needed figure computes once Closing and Lead Nurture have their rates.
A41: 3 | B41: band | C41: Band 3 · Exercises · reveal · about 25 min: The warm list, the topics, the cold sources
B42: why | C42: Warm outreach is the cheapest lead you will ever get, and almost nobody does it fully. Content starts with questions you already get asked. Cold outreach starts with a list that already exists somewhere.
A43: 3 | B43: exercise | C43: Your warm list, one name a line | E43: =IF(D43<>"",1,0) -> 0 | F43: Jordan (old colleague) Sam (gym) Priya (newsletter reply) Alex (cousin) Dev (podcast guest) | G43: Everyone who has your number, follows you, or has emailed you. Aim for 100. Stop when you run out, not when you get bored. One a line: Alt+Enter starts a new line inside the cell.
A44: 3 | B44: exercise | C44: Ten things a customer asked you this month, one a line | E44: =IF(D44<>"",1,0) -> 0 | F44: Should I pay off the loan or invest? How much emergency fund is enough? Is my 401k match worth it? | G44: Each is a piece of content. Their question is the hook. One a line: Alt+Enter starts a new line inside the cell.
A45: 3 | B45: exercise | C45: Three places a list of your strangers already exists | E45: =IF(D45<>"",1,0) -> 0 | G45: A directory, a group, a conference list, a public register. One a line: Alt+Enter starts a new line inside the cell.
...

Sheet Hooks
C1: Hooks | D1: Leads system
C2: The first line earns the second. Nothing you make gets read without one.
C3: A hook is the part of a message people see before they decide whether to keep going: the headline, the first sentence, the first second of a video, the subject line. Most attention is lost right there. The work is not to write one good hook and hope. It is to write many, score them, run the best few, and keep the winners in a bank you draw on for years.
C5: Where you stand on this planet
B6: # | C6: Band | D6: Answered | E6: Of | F6: Ticked | G6: Of | H6: Status
B7: 1 | C7: Read: The one idea, and where you stand on it today | D7: =SUMIFS($E$19:$E$400,$A$19:$A$400,B7,$B$19:$B$400,"exercise") -> 0 | E7: =COUNTIFS($A$19:$A$400,B7,$B$19:$B$400,"exercise") -> 2 | F7: =SUMIFS($E$19:$E$400,$A$19:$A$400,B7,$B$19:$B$400,"check") -> 0 | G7: =COUNTIFS($A$19:$A$400,B7,$B$19:$B$400,"check") -> 2 | H7: =IF(AND(D7=E7,F7=G7),"done",IF(D7+F7>0,"started","not yet")) -> not yet | I7: =IF(H7="done",99,B7) -> 1
B8: 2 | C8: Facts: The few numbers this playbook runs on | D8: =SUMIFS($E$19:$E$400,$A$19:$A$400,B8,$B$19:$B$400,"exercise") -> 0 | E8: =COUNTIFS($A$19:$A$400,B8,$B$19:$B$400,"exercise") -> 3 | F8: =SUMIFS($E$19:$E$400,$A$19:$A$400,B8,$B$19:$B$400,"check") -> 0 | G8: =COUNTIFS($A$19:$A$400,B8,$B$19:$B$400,"check") -> 1 | H8: =IF(AND(D8=E8,F8=G8),"done",IF(D8+F8>0,"started","not yet")) -> not yet | I8: =IF(H8="done",99,B8) -> 2
B9: 3 | C9: Exercises: The pen and paper work the playbook asks for | D9: =SUMIFS($E$19:$E$400,$A$19:$A$400,B9,$B$19:$B$400,"exercise") -> 0 | E9: =COUNTIFS($A$19:$A$400,B9,$B$19:$B$400,"exercise") -> 3 | F9: =SUMIFS($E$19:$E$400,$A$19:$A$400,B9,$B$19:$B$400,"check") -> 0 | G9: =COUNTIFS($A$19:$A$400,B9,$B$19:$B$400,"check") -> 3 | H9: =IF(AND(D9=E9,F9=G9),"done",IF(D9+F9>0,"started","not yet")) -> not yet | I9: =IF(H9="done",99,B9) -> 3
B10: 4 | C10: Build: Assemble the thing you will use, and tick it off | D10: =SUMIFS($E$19:$E$400,$A$19:$A$400,B10,$B$19:$B$400,"exercise") -> 0 | E10: =COUNTIFS($A$19:$A$400,B10,$B$19:$B$400,"exercise") -> 2 | F10: =SUMIFS($E$19:$E$400,$A$19:$A$400,B10,$B$19:$B$400,"check") -> 0 | G10: =COUNTIFS($A$19:$A$400,B10,$B$19:$B$400,"check") -> 4 | H10: =IF(AND(D10=E10,F10=G10),"done",IF(D10+F10>0,"started","not yet")) -> not yet | I10: =IF(H10="done",99,B10) -> 4
B11: 5 | C11: Run: Use it for a stretch and log what happened | D11: =SUMIFS($E$19:$E$400,$A$19:$A$400,B11,$B$19:$B$400,"exercise") -> 0 | E11: =COUNTIFS($A$19:$A$400,B11,$B$19:$B$400,"exercise") -> 3 | F11: =SUMIFS($E$19:$E$400,$A$19:$A$400,B11,$B$19:$B$400,"check") -> 0 | G11: =COUNTIFS($A$19:$A$400,B11,$B$19:$B$400,"check") -> 1 | H11: =IF(AND(D11=E11,F11=G11),"done",IF(D11+F11>0,"started","not yet")) -> not yet | I11: =IF(H11="done",99,B11) -> 5
B12: 6 | C12: Sharpen: The moves only visible once the numbers are real | D12: =SUMIFS($E$19:$E$400,$A$19:$A$400,B12,$B$19:$B$400,"exercise") -> 0 | E12: =COUNTIFS($A$19:$A$400,B12,$B$19:$B$400,"exercise") -> 2 | F12: =SUMIFS($E$19:$E$400,$A$19:$A$400,B12,$B$19:$B$400,"check") -> 0 | G12: =COUNTIFS($A$19:$A$400,B12,$B$19:$B$400,"check") -> 3 | H12: =IF(AND(D12=E12,F12=G12),"done",IF(D12+F12>0,"started","not yet")) -> not yet | I12: =IF(H12="done",99,B12) -> 6
C13: Levels done | D13: =COUNTIF(H7:H12,"done") -> 0 | F13: Yellow cells are yours to fill. A band is done when every yellow cell in it holds an answer and every checklist item is Y.
C14: Working on band | D14: =IF(MIN(I7:I12)=99,"complete",MIN(I7:I12)) -> 1
C15: Share of this planet answered | D15: =IF(SUM(E7:E12,G7:G12)=0,0,SUM(D7:D12,F7:F12)/SUM(E7:E12,G7:G12)) -> 0
A18: Band | B18: Kind | C18: Exercise or step | D18: Your answer | E18: ✓ | F18: Example | G18: What counts, where to look
A19: 1 | B19: band | C19: Band 1 · Read · reveal · about 5 min: Read your last three first lines as a stranger
B20: why | C20: You cannot fix what you have not looked at. Pull up the last three things you sent or posted and read only the first line of each.
A21: 1 | B21: exercise | C21: How often does what you post or send get a reply or a click, 1 to 5 | E21: =IF(D21<>"",1,0) -> 0 | F21: 2 | G21: One is not at all, five is fully. Your honest read today.
A22: 1 | B22: exercise | C22: Your last three hooks, pasted in | E22: =IF(D22<>"",1,0) -> 0 | G22: The headline, the first line, the subject line. As they were, not as you would fix them.
B23: head | C23: Checklist
A24: 1 | B24: check | C24: ☐ I read my last three first lines as a stranger would | E24: =IF(D24="Y",1,0) -> 0 | G24: Y when it is true.
A25: 1 | B25: check | C25: ☐ I can say who each one was for | E25: =IF(D25="Y",1,0) -> 0 | G25: Y when it is true.
B26: checkpoint | C26: When this band is done: Your starting point on the planet is set.
A28: 2 | B28: band | C28: Band 2 · Facts · reveal · about 5 min: Last week's attention
B29: why | C29: Two counts turn a feeling into a rate: how many people saw the first line, and how many did anything after it.
A30: 2 | B30: exercise | C30: Views or opens last week, total | E30: =IF(D30<>"",1,0) -> 0 | F30: 4000 | G30: Across every post, email and ad.
A31: 2 | B31: exercise | C31: Replies, clicks or saves last week, total | E31: =IF(D31<>"",1,0) -> 0 | F31: 90
A32: 2 | B32: exercise | C32: Hooks you drafted last week | E32: =IF(D32<>"",1,0) -> 0 | F32: 3 | G32: Drafts, not posts. Zero is a number.
B33: head | C33: Checklist
A34: 2 | B34: check | C34: ☐ The counts come from the platform, not a guess | E34: =IF(D34="Y",1,0) -> 0 | G34: Y when it is true.
B35: checkpoint | C35: When this band is done: Your hook rate shows.
A37: 3 | B37: band | C37: Band 3 · Exercises · reveal · about 25 min: Twenty hooks for one idea
B38: why | C38: Volume is the method. Twenty hooks for one idea, using different frames, gets you two good ones. One hook gets you one hope.
A39: 3 | B39: exercise | C39: Who it is for, in the words they use for themselves | E39: =IF(D39<>"",1,0) -> 0
A40: 3 | B40: exercise | C40: The one fact or result that backs the idea | E40: =IF(D40<>"",1,0) -> 0 | G40: A number, a name, a before and after. If there is none, see Proof Checklist.
A41: 3 | B41: exercise | C41: Twenty hooks for the idea, one a line | E41: =IF(D41<>"",1,0) -> 0 | G41: Frames to rotate: a question, a number, a claim with a condition, a common mistake, a before and after, a call-out of who it is for, a short story opener. One a line: Alt+Enter starts a new line inside the cell.
B42: head | C42: Checklist
A43: 3 | B43: check | C43: ☐ All twenty are for the same idea | E43: =IF(D43="Y",1,0) -> 0 | G43: Y when it is true.
A44: 3 | B44: check | C44: ☐ At least five different frames were used | E44: =IF(D44="Y",1,0) -> 0 | G44: Y when it is true.
A45: 3 | B45: check | C45: ☐ None promises more than the proof can back | E45: =IF(D45="Y",1,0) -> 0 | G45: Y when it is true.
...

Sheet Lead Nurture
C1: Lead Nurture | D1: Leads system
C2: A lead is a person who raised a hand. The next hour and the next thirty days decide whether it counts.
C3: Most leads are lost between the hand-raise and the conversation. Speed is the first lever: a reply inside minutes is worth many replies tomorrow. Persistence is the second: most people need to hear from you more times than feels polite, and they are not annoyed, they are busy. A lead magnet, a small free thing that solves one narrow problem and shows the next one, gives every follow-up a reason to exist.
C5: Where you stand on this planet
B6: # | C6: Band | D6: Answered | E6: Of | F6: Ticked | G6: Of | H6: Status
B7: 1 | C7: Read: The one idea, and where you stand on it today | D7: =SUMIFS($E$19:$E$400,$A$19:$A$400,B7,$B$19:$B$400,"exercise") -> 0 | E7: =COUNTIFS($A$19:$A$400,B7,$B$19:$B$400,"exercise") -> 2 | F7: =SUMIFS($E$19:$E$400,$A$19:$A$400,B7,$B$19:$B$400,"check") -> 0 | G7: =COUNTIFS($A$19:$A$400,B7,$B$19:$B$400,"check") -> 2 | H7: =IF(AND(D7=E7,F7=G7),"done",IF(D7+F7>0,"started","not yet")) -> not yet | I7: =IF(H7="done",99,B7) -> 1
B8: 2 | C8: Facts: The few numbers this playbook runs on | D8: =SUMIFS($E$19:$E$400,$A$19:$A$400,B8,$B$19:$B$400,"exercise") -> 0 | E8: =COUNTIFS($A$19:$A$400,B8,$B$19:$B$400,"exercise") -> 3 | F8: =SUMIFS($E$19:$E$400,$A$19:$A$400,B8,$B$19:$B$400,"check") -> 0 | G8: =COUNTIFS($A$19:$A$400,B8,$B$19:$B$400,"check") -> 1 | H8: =IF(AND(D8=E8,F8=G8),"done",IF(D8+F8>0,"started","not yet")) -> not yet | I8: =IF(H8="done",99,B8) -> 2
B9: 3 | C9: Exercises: The pen and paper work the playbook asks for | D9: =SUMIFS($E$19:$E$400,$A$19:$A$400,B9,$B$19:$B$400,"exercise") -> 0 | E9: =COUNTIFS($A$19:$A$400,B9,$B$19:$B$400,"exercise") -> 4 | F9: =SUMIFS($E$19:$E$400,$A$19:$A$400,B9,$B$19:$B$400,"check") -> 0 | G9: =COUNTIFS($A$19:$A$400,B9,$B$19:$B$400,"check") -> 3 | H9: =IF(AND(D9=E9,F9=G9),"done",IF(D9+F9>0,"started","not yet")) -> not yet | I9: =IF(H9="done",99,B9) -> 3
B10: 4 | C10: Build: Assemble the thing you will use, and tick it off | D10: =SUMIFS($E$19:$E$400,$A$19:$A$400,B10,$B$19:$B$400,"exercise") -> 0 | E10: =COUNTIFS($A$19:$A$400,B10,$B$19:$B$400,"exercise") -> 2 | F10: =SUMIFS($E$19:$E$400,$A$19:$A$400,B10,$B$19:$B$400,"check") -> 0 | G10: =COUNTIFS($A$19:$A$400,B10,$B$19:$B$400,"check") -> 5 | H10: =IF(AND(D10=E10,F10=G10),"done",IF(D10+F10>0,"started","not yet")) -> not yet | I10: =IF(H10="done",99,B10) -> 4
B11: 5 | C11: Run: Use it for a stretch and log what happened | D11: =SUMIFS($E$19:$E$400,$A$19:$A$400,B11,$B$19:$B$400,"exercise") -> 0 | E11: =COUNTIFS($A$19:$A$400,B11,$B$19:$B$400,"exercise") -> 4 | F11: =SUMIFS($E$19:$E$400,$A$19:$A$400,B11,$B$19:$B$400,"check") -> 0 | G11: =COUNTIFS($A$19:$A$400,B11,$B$19:$B$400,"check") -> 1 | H11: =IF(AND(D11=E11,F11=G11),"done",IF(D11+F11>0,"started","not yet")) -> not yet | I11: =IF(H11="done",99,B11) -> 5
B12: 6 | C12: Sharpen: The moves only visible once the numbers are real | D12: =SUMIFS($E$19:$E$400,$A$19:$A$400,B12,$B$19:$B$400,"exercise") -> 0 | E12: =COUNTIFS($A$19:$A$400,B12,$B$19:$B$400,"exercise") -> 2 | F12: =SUMIFS($E$19:$E$400,$A$19:$A$400,B12,$B$19:$B$400,"check") -> 0 | G12: =COUNTIFS($A$19:$A$400,B12,$B$19:$B$400,"check") -> 3 | H12: =IF(AND(D12=E12,F12=G12),"done",IF(D12+F12>0,"started","not yet")) -> not yet | I12: =IF(H12="done",99,B12) -> 6
C13: Levels done | D13: =COUNTIF(H7:H12,"done") -> 0 | F13: Yellow cells are yours to fill. A band is done when every yellow cell in it holds an answer and every checklist item is Y.
C14: Working on band | D14: =IF(MIN(I7:I12)=99,"complete",MIN(I7:I12)) -> 1
C15: Share of this planet answered | D15: =IF(SUM(E7:E12,G7:G12)=0,0,SUM(D7:D12,F7:F12)/SUM(E7:E12,G7:G12)) -> 0
A18: Band | B18: Kind | C18: Exercise or step | D18: Your answer | E18: ✓ | F18: Example | G18: What counts, where to look
A19: 1 | B19: band | C19: Band 1 · Read · reveal · about 6 min: What happens when a hand goes up
B20: why | C20: Time it. Count it. Most people are shocked by both numbers the first time they look.
A21: 1 | B21: exercise | C21: How fast and how many times a new lead hears from you, 1 to 5 | E21: =IF(D21<>"",1,0) -> 0 | F21: 2 | G21: One is not at all, five is fully. Your honest read today.
A22: 1 | B22: exercise | C22: What happens today when someone raises a hand | E22: =IF(D22<>"",1,0) -> 0 | G22: Who replies, in how long, how many times, with what. Step by step.
B23: head | C23: Checklist
A24: 1 | B24: check | C24: ☐ I timed my last reply to a new lead | E24: =IF(D24="Y",1,0) -> 0 | G24: Y when it is true.
A25: 1 | B25: check | C25: ☐ I counted how many touches a lead gets before I stop | E25: =IF(D25="Y",1,0) -> 0 | G25: Y when it is true.
B26: checkpoint | C26: When this band is done: Your starting point on the planet is set.
A28: 2 | B28: band | C28: Band 2 · Facts · reveal · about 6 min: Speed, touches, and the booking rate
B29: why | C29: Three numbers describe the whole system: how fast, how many times, and what share of leads end up in a conversation.
A30: 2 | B30: exercise | C30: Minutes from hand-raise to first reply, typical | E30: =IF(D30<>"",1,0) -> 0 | F30: 90 | G30: In working hours. Look at the last five leads and take the middle one.
A31: 2 | B31: exercise | C31: Touches a lead gets before you stop | E31: =IF(D31<>"",1,0) -> 0 | F31: 3 | G31: Messages, calls, emails: every attempt counts as one.
A32: 2 | B32: exercise | C32: Of engaged leads, the share who book a conversation [shared: other playbooks read this] | E32: =IF(D32<>"",1,0) -> 0 | F32: 0.4 | G32: Booked, not shown. Showing is measured in Closing Handbook. Type it as a percentage, for example 80%.
B33: head | C33: Checklist
A34: 2 | B34: check | C34: ☐ The reply time is measured from five real leads, not one | E34: =IF(D34="Y",1,0) -> 0 | G34: Y when it is true.
B35: checkpoint | C35: When this band is done: Reply speed and the booking rate show.
A37: 3 | B37: band | C37: Band 3 · Exercises · reveal · about 30 min: The magnet, the sequence, the short check-in
B38: why | C38: A lead magnet is a free thing that solves a narrow problem completely and reveals the next problem, which your paid thing solves. The sequence is the nine or so touches after it. The short check-in is the one-line question you send to every lead that has gone quiet.
A39: 3 | B39: exercise | C39: Your lead magnet kind | E39: =IF(D39<>"",1,0) -> 0 | G39: Pick one from the dropdown.
A40: 3 | B40: exercise | C40: Name it as the result it gives | E40: =IF(D40<>"",1,0) -> 0 | G40: Not what it is, what they get.
A41: 3 | B41: exercise | C41: The follow-up sequence, one touch a line: day, channel, what it says | E41: =IF(D41<>"",1,0) -> 0 | G41: Aim for nine touches over thirty days, on at least two channels. Every touch has one ask. One a line: Alt+Enter starts a new line inside the cell.
A42: 3 | B42: exercise | C42: Your short check-in for a quiet lead | E42: =IF(D42<>"",1,0) -> 0 | G42: One question, under fifteen words, easy to answer with one word.
B43: head | C43: Checklist
A44: 3 | B44: check | C44: ☐ The magnet solves its problem completely, not a teaser | E44: =IF(D44="Y",1,0) -> 0 | G44: Y when it is true.
A45: 3 | B45: check | C45: ☐ The sequence uses at least two channels | E45: =IF(D45="Y",1,0) -> 0 | G45: Y when it is true.
...

Sheet Closing Handbook
C1: Closing Handbook | D1: Sales system
C2: A sale is a conversation with a shape. Learn the shape and the pressure goes out of it.
C3: The conversation runs in six moves, and the letters spell CLOSER: clarify why they came, label the problem back to them in their words, overview what they have tried and why it did not hold, sell the outcome and not the method, explain away the concerns that remain, and reinforce the decision the moment they say yes. Concerns come in three kinds: about circumstances (time, money), about other people (a partner, a boss), and about themselves (fit, doubt). Each kind has an answer you write once and say many times.
C5: Where you stand on this planet
B6: # | C6: Band | D6: Answered | E6: Of | F6: Ticked | G6: Of | H6: Status
B7: 1 | C7: Read: The one idea, and where you stand on it today | D7: =SUMIFS($E$19:$E$400,$A$19:$A$400,B7,$B$19:$B$400,"exercise") -> 0 | E7: =COUNTIFS($A$19:$A$400,B7,$B$19:$B$400,"exercise") -> 2 | F7: =SUMIFS($E$19:$E$400,$A$19:$A$400,B7,$B$19:$B$400,"check") -> 0 | G7: =COUNTIFS($A$19:$A$400,B7,$B$19:$B$400,"check") -> 2 | H7: =IF(AND(D7=E7,F7=G7),"done",IF(D7+F7>0,"started","not yet")) -> not yet | I7: =IF(H7="done",99,B7) -> 1
B8: 2 | C8: Facts: The few numbers this playbook runs on | D8: =SUMIFS($E$19:$E$400,$A$19:$A$400,B8,$B$19:$B$400,"exercise") -> 0 | E8: =COUNTIFS($A$19:$A$400,B8,$B$19:$B$400,"exercise") -> 4 | F8: =SUMIFS($E$19:$E$400,$A$19:$A$400,B8,$B$19:$B$400,"check") -> 0 | G8: =COUNTIFS($A$19:$A$400,B8,$B$19:$B$400,"check") -> 1 | H8: =IF(AND(D8=E8,F8=G8),"done",IF(D8+F8>0,"started","not yet")) -> not yet | I8: =IF(H8="done",99,B8) -> 2
B9: 3 | C9: Exercises: The pen and paper work the playbook asks for | D9: =SUMIFS($E$19:$E$400,$A$19:$A$400,B9,$B$19:$B$400,"exercise") -> 0 | E9: =COUNTIFS($A$19:$A$400,B9,$B$19:$B$400,"exercise") -> 6 | F9: =SUMIFS($E$19:$E$400,$A$19:$A$400,B9,$B$19:$B$400,"check") -> 0 | G9: =COUNTIFS($A$19:$A$400,B9,$B$19:$B$400,"check") -> 2 | H9: =IF(AND(D9=E9,F9=G9),"done",IF(D9+F9>0,"started","not yet")) -> not yet | I9: =IF(H9="done",99,B9) -> 3
B10: 4 | C10: Build: Assemble the thing you will use, and tick it off | D10: =SUMIFS($E$19:$E$400,$A$19:$A$400,B10,$B$19:$B$400,"exercise") -> 0 | E10: =COUNTIFS($A$19:$A$400,B10,$B$19:$B$400,"exercise") -> 1 | F10: =SUMIFS($E$19:$E$400,$A$19:$A$400,B10,$B$19:$B$400,"check") -> 0 | G10: =COUNTIFS($A$19:$A$400,B10,$B$19:$B$400,"check") -> 6 | H10: =IF(AND(D10=E10,F10=G10),"done",IF(D10+F10>0,"started","not yet")) -> not yet | I10: =IF(H10="done",99,B10) -> 4
B11: 5 | C11: Run: Use it for a stretch and log what happened | D11: =SUMIFS($E$19:$E$400,$A$19:$A$400,B11,$B$19:$B$400,"exercise") -> 0 | E11: =COUNTIFS($A$19:$A$400,B11,$B$19:$B$400,"exercise") -> 4 | F11: =SUMIFS($E$19:$E$400,$A$19:$A$400,B11,$B$19:$B$400,"check") -> 0 | G11: =COUNTIFS($A$19:$A$400,B11,$B$19:$B$400,"check") -> 2 | H11: =IF(AND(D11=E11,F11=G11),"done",IF(D11+F11>0,"started","not yet")) -> not yet | I11: =IF(H11="done",99,B11) -> 5
B12: 6 | C12: Sharpen: The moves only visible once the numbers are real | D12: =SUMIFS($E$19:$E$400,$A$19:$A$400,B12,$B$19:$B$400,"exercise") -> 0 | E12: =COUNTIFS($A$19:$A$400,B12,$B$19:$B$400,"exercise") -> 2 | F12: =SUMIFS($E$19:$E$400,$A$19:$A$400,B12,$B$19:$B$400,"check") -> 0 | G12: =COUNTIFS($A$19:$A$400,B12,$B$19:$B$400,"check") -> 4 | H12: =IF(AND(D12=E12,F12=G12),"done",IF(D12+F12>0,"started","not yet")) -> not yet | I12: =IF(H12="done",99,B12) -> 6
C13: Levels done | D13: =COUNTIF(H7:H12,"done") -> 0 | F13: Yellow cells are yours to fill. A band is done when every yellow cell in it holds an answer and every checklist item is Y.
C14: Working on band | D14: =IF(MIN(I7:I12)=99,"complete",MIN(I7:I12)) -> 1
C15: Share of this planet answered | D15: =IF(SUM(E7:E12,G7:G12)=0,0,SUM(D7:D12,F7:F12)/SUM(E7:E12,G7:G12)) -> 0
A18: Band | B18: Kind | C18: Exercise or step | D18: Your answer | E18: ✓ | F18: Example | G18: What counts, where to look
A19: 1 | B19: band | C19: Band 1 · Read · reveal · about 8 min: Your last conversation, in six lines
B20: why | C20: Write up your last sales conversation from open to close. Where did it drift? Where did you talk most? Where did you lose them, if you did?
A21: 1 | B21: exercise | C21: How confident are you in a sales conversation, 1 to 5 | E21: =IF(D21<>"",1,0) -> 0 | F21: 3 | G21: One is not at all, five is fully. Your honest read today.
A22: 1 | B22: exercise | C22: Your last sales conversation, open to close, in six lines | E22: =IF(D22<>"",1,0) -> 0 | F22: Opened with my story, showed the programme, said the price, got a maybe. | G22: One line per move if you can. If you cannot find six moves, that is the finding.
B23: head | C23: Checklist
A24: 1 | B24: check | C24: ☐ I recorded or wrote up my last call | E24: =IF(D24="Y",1,0) -> 0 | G24: Y when it is true.
A25: 1 | B25: check | C25: ☐ I know where in the call I lose people | E25: =IF(D25="Y",1,0) -> 0 | G25: Y when it is true.
B26: checkpoint | C26: When this band is done: Your starting point on the planet is set.
A28: 2 | B28: band | C28: Band 2 · Facts · reveal · about 8 min: The funnel of one month
B29: why | C29: Booked, shown, bought, paid. Four counts make three rates, and each rate has its own playbook.
A30: 2 | B30: exercise | C30: Conversations booked last month | E30: =IF(D30<>"",1,0) -> 0 | F30: 20
A31: 2 | B31: exercise | C31: Of those, how many showed up | E31: =IF(D31<>"",1,0) -> 0 | F31: 14
A32: 2 | B32: exercise | C32: Of those, how many bought | E32: =IF(D32<>"",1,0) -> 0 | F32: 5
A33: 2 | B33: exercise | C33: Cash collected at the close last month, total | E33: =IF(D33<>"",1,0) -> 0 | F33: 6000 | G33: What actually arrived, not what was promised. Whole dollars.
B34: head | C34: Checklist
A35: 2 | B35: check | C35: ☐ The four counts come from a calendar and a bank statement, not memory | E35: =IF(D35="Y",1,0) -> 0 | G35: Y when it is true.
B36: checkpoint | C36: When this band is done: Show rate, close rate and cash per sale show, and the Marketing Machine can compute leads needed.
A38: 3 | B38: band | C38: Band 3 · Exercises · reveal · about 35 min: Write your six moves
B39: why | C39: One paragraph per letter, in your own words, as you would say it to a friend across a table.
A40: 3 | B40: exercise | C40: Clarify: the two questions you open with | E40: =IF(D40<>"",1,0) -> 0 | G40: Why now? What made you reach out? Their answer is the rest of the call.
A41: 3 | B41: exercise | C41: Label: the sentence that names their problem back to them | E41: =IF(D41<>"",1,0) -> 0 | G41: In their words. Then ask: is that right?
A42: 3 | B42: exercise | C42: Overview: the question that draws out what they tried and why it did not hold | E42: =IF(D42<>"",1,0) -> 0 | G42: The point is that they hear themselves say it.
A43: 3 | B43: exercise | C43: Sell the vacation: the outcome, in three sentences, with no method in it | E43: =IF(D43<>"",1,0) -> 0 | G43: The beach, not the plane.
A44: 3 | B44: exercise | C44: Explain away: your answer to each of the three kinds of concern | E44: =IF(D44<>"",1,0) -> 0 | G44: Circumstances (time, money). Other people (a partner, a boss). Themselves (fit, doubt). One answer each.
A45: 3 | B45: exercise | C45: Reinforce: what happens in the first 24 hours after yes | E45: =IF(D45<>"",1,0) -> 0 | G45: A message, a call, a small gift. The decision needs a second yes from their future self.
...

Sheet Proof Checklist
C1: Proof Checklist | D1: Sales system
C2: People do not buy the promise. They buy the evidence that the promise held for someone like them.
C3: Whether someone believes an outcome will happen for them is half of what a thing is worth to them. Proof moves that belief. It comes in kinds: results with a number, before and after pairs, named testimonials, third-party marks (reviews, press, credentials), and demonstrations. The checklist is a habit rather than a project: collect proof at every win, put a proof beside every claim, and match the kind of proof to the doubt it answers.
C5: Where you stand on this planet
B6: # | C6: Band | D6: Answered | E6: Of | F6: Ticked | G6: Of | H6: Status
B7: 1 | C7: Read: The one idea, and where you stand on it today | D7: =SUMIFS($E$19:$E$400,$A$19:$A$400,B7,$B$19:$B$400,"exercise") -> 0 | E7: =COUNTIFS($A$19:$A$400,B7,$B$19:$B$400,"exercise") -> 2 | F7: =SUMIFS($E$19:$E$400,$A$19:$A$400,B7,$B$19:$B$400,"check") -> 0 | G7: =COUNTIFS($A$19:$A$400,B7,$B$19:$B$400,"check") -> 2 | H7: =IF(AND(D7=E7,F7=G7),"done",IF(D7+F7>0,"started","not yet")) -> not yet | I7: =IF(H7="done",99,B7) -> 1
B8: 2 | C8: Facts: The few numbers this playbook runs on | D8: =SUMIFS($E$19:$E$400,$A$19:$A$400,B8,$B$19:$B$400,"exercise") -> 0 | E8: =COUNTIFS($A$19:$A$400,B8,$B$19:$B$400,"exercise") -> 6 | F8: =SUMIFS($E$19:$E$400,$A$19:$A$400,B8,$B$19:$B$400,"check") -> 0 | G8: =COUNTIFS($A$19:$A$400,B8,$B$19:$B$400,"check") -> 1 | H8: =IF(AND(D8=E8,F8=G8),"done",IF(D8+F8>0,"started","not yet")) -> not yet | I8: =IF(H8="done",99,B8) -> 2
B9: 3 | C9: Exercises: The pen and paper work the playbook asks for | D9: =SUMIFS($E$19:$E$400,$A$19:$A$400,B9,$B$19:$B$400,"exercise") -> 0 | E9: =COUNTIFS($A$19:$A$400,B9,$B$19:$B$400,"exercise") -> 3 | F9: =SUMIFS($E$19:$E$400,$A$19:$A$400,B9,$B$19:$B$400,"check") -> 0 | G9: =COUNTIFS($A$19:$A$400,B9,$B$19:$B$400,"check") -> 2 | H9: =IF(AND(D9=E9,F9=G9),"done",IF(D9+F9>0,"started","not yet")) -> not yet | I9: =IF(H9="done",99,B9) -> 3
B10: 4 | C10: Build: Assemble the thing you will use, and tick it off | D10: =SUMIFS($E$19:$E$400,$A$19:$A$400,B10,$B$19:$B$400,"exercise") -> 0 | E10: =COUNTIFS($A$19:$A$400,B10,$B$19:$B$400,"exercise") -> 2 | F10: =SUMIFS($E$19:$E$400,$A$19:$A$400,B10,$B$19:$B$400,"check") -> 0 | G10: =COUNTIFS($A$19:$A$400,B10,$B$19:$B$400,"check") -> 5 | H10: =IF(AND(D10=E10,F10=G10),"done",IF(D10+F10>0,"started","not yet")) -> not yet | I10: =IF(H10="done",99,B10) -> 4
B11: 5 | C11: Run: Use it for a stretch and log what happened | D11: =SUMIFS($E$19:$E$400,$A$19:$A$400,B11,$B$19:$B$400,"exercise") -> 0 | E11: =COUNTIFS($A$19:$A$400,B11,$B$19:$B$400,"exercise") -> 3 | F11: =SUMIFS($E$19:$E$400,$A$19:$A$400,B11,$B$19:$B$400,"check") -> 0 | G11: =COUNTIFS($A$19:$A$400,B11,$B$19:$B$400,"check") -> 2 | H11: =IF(AND(D11=E11,F11=G11),"done",IF(D11+F11>0,"started","not yet")) -> not yet | I11: =IF(H11="done",99,B11) -> 5
B12: 6 | C12: Sharpen: The moves only visible once the numbers are real | D12: =SUMIFS($E$19:$E$400,$A$19:$A$400,B12,$B$19:$B$400,"exercise") -> 0 | E12: =COUNTIFS($A$19:$A$400,B12,$B$19:$B$400,"exercise") -> 2 | F12: =SUMIFS($E$19:$E$400,$A$19:$A$400,B12,$B$19:$B$400,"check") -> 0 | G12: =COUNTIFS($A$19:$A$400,B12,$B$19:$B$400,"check") -> 3 | H12: =IF(AND(D12=E12,F12=G12),"done",IF(D12+F12>0,"started","not yet")) -> not yet | I12: =IF(H12="done",99,B12) -> 6
C13: Levels done | D13: =COUNTIF(H7:H12,"done") -> 0 | F13: Yellow cells are yours to fill. A band is done when every yellow cell in it holds an answer and every checklist item is Y.
C14: Working on band | D14: =IF(MIN(I7:I12)=99,"complete",MIN(I7:I12)) -> 1
C15: Share of this planet answered | D15: =IF(SUM(E7:E12,G7:G12)=0,0,SUM(D7:D12,F7:F12)/SUM(E7:E12,G7:G12)) -> 0
A18: Band | B18: Kind | C18: Exercise or step | D18: Your answer | E18: ✓ | F18: Example | G18: What counts, where to look
A19: 1 | B19: band | C19: Band 1 · Read · reveal · about 8 min: Read your pitch as a doubter
B20: why | C20: Open your sales page or your pitch and read it as someone who has been burned before. Mark every claim that has nothing beside it.
A21: 1 | B21: exercise | C21: How much evidence backs your offer today, 1 to 5 | E21: =IF(D21<>"",1,0) -> 0 | F21: 2 | G21: One is not at all, five is fully. Your honest read today.
A22: 1 | B22: exercise | C22: Every piece of proof you can put your hands on in five minutes | E22: =IF(D22<>"",1,0) -> 0 | G22: Screenshots, messages, reviews, numbers. List them.
B23: head | C23: Checklist
A24: 1 | B24: check | C24: ☐ I read my pitch as a doubter | E24: =IF(D24="Y",1,0) -> 0 | G24: Y when it is true.
A25: 1 | B25: check | C25: ☐ I marked every claim with no proof beside it | E25: =IF(D25="Y",1,0) -> 0 | G25: Y when it is true.
B26: checkpoint | C26: When this band is done: Your starting point on the planet is set.
A28: 2 | B28: band | C28: Band 2 · Facts · reveal · about 8 min: Count the proof by kind
B29: why | C29: Five kinds, five counts. The shape of the count tells you what to collect next.
A30: 2 | B30: exercise | C30: Results with a number | E30: =IF(D30<>"",1,0) -> 0 | F30: 2 | G30: A client got X in Y. Counted individually.
A31: 2 | B31: exercise | C31: Named testimonials, written or on video | E31: =IF(D31<>"",1,0) -> 0 | F31: 6
A32: 2 | B32: exercise | C32: Before and after pairs | E32: =IF(D32<>"",1,0) -> 0 | F32: 1 | G32: Pictures, screenshots, two numbers.
A33: 2 | B33: exercise | C33: Third-party marks | E33: =IF(D33<>"",1,0) -> 0 | F33: 3 | G33: Reviews on a platform, press, credentials, awards.
A34: 2 | B34: exercise | C34: Demonstrations | E34: =IF(D34<>"",1,0) -> 0 | F34: 1 | G34: A free sample, a live walkthrough, a recorded one.
A35: 2 | B35: exercise | C35: Customers you have served, total | E35: =IF(D35<>"",1,0) -> 0 | F35: 40 | G35: Ever. The proof inventory is measured against this.
B36: head | C36: Checklist
A37: 2 | B37: check | C37: ☐ Each count is of things I could show today, not things I could get | E37: =IF(D37="Y",1,0) -> 0 | G37: Y when it is true.
B38: checkpoint | C38: When this band is done: The proof inventory draws, by kind.
A40: 3 | B40: band | C40: Band 3 · Exercises · reveal · about 20 min: Claims, doubts, and ten people to ask
B41: why | C41: Every claim your offer makes needs a proof or a cut. Every doubt a buyer has needs a proof that answers it. And ten past customers are one message away from a testimonial.
A42: 3 | B42: exercise | C42: Every claim your offer makes, one a line | E42: =IF(D42<>"",1,0) -> 0 | F42: Control of your money in eight weeks No finance degree needed Keep the life you have | G42: One a line: Alt+Enter starts a new line inside the cell.
A43: 3 | B43: exercise | C43: The five doubts a buyer has before paying, in their words | E43: =IF(D43<>"",1,0) -> 0 | G43: Will it work for me? What if I fail? Is this person real? One a line: Alt+Enter starts a new line inside the cell.
A44: 3 | B44: exercise | C44: Ten past customers to ask this week, one a line, with what to ask each for | D44: =IF(COUNTA(C46:E53)>0,"logged","") | E44: =IF(COUNTA(C46:E53)>0,1,0) -> 0 | G44: Name | the specific result to ask about | the kind of proof (a number, a story, a screenshot). Fill the small table below, one row a line.
B45: logrow | C45: Name | D45: Result to ask about | E45: Kind of proof
...

Sheet GOATed Ads
C1: GOATed Ads | D1: Sales system
C2: A paid ad is a call-out, a reason, and an ask, bought by the thousand and judged by the cost of a customer.
C3: Paid ads are the fourth of the four ways to get leads and the one that scales fastest once the math works. An ad has three parts: a call-out that says who it is for, value that gives them a reason to keep watching, and a call to action that says the one thing to do next. The math is a chain: cost per thousand views, the share who click, the share who become leads, the share who book, the share who buy. An ad is good when the lifetime gross profit of a customer is at least three times what it cost to get them.
C5: Where you stand on this planet
B6: # | C6: Band | D6: Answered | E6: Of | F6: Ticked | G6: Of | H6: Status
B7: 1 | C7: Read: The one idea, and where you stand on it today | D7: =SUMIFS($E$19:$E$400,$A$19:$A$400,B7,$B$19:$B$400,"exercise") -> 0 | E7: =COUNTIFS($A$19:$A$400,B7,$B$19:$B$400,"exercise") -> 2 | F7: =SUMIFS($E$19:$E$400,$A$19:$A$400,B7,$B$19:$B$400,"check") -> 0 | G7: =COUNTIFS($A$19:$A$400,B7,$B$19:$B$400,"check") -> 2 | H7: =IF(AND(D7=E7,F7=G7),"done",IF(D7+F7>0,"started","not yet")) -> not yet | I7: =IF(H7="done",99,B7) -> 1
B8: 2 | C8: Facts: The few numbers this playbook runs on | D8: =SUMIFS($E$19:$E$400,$A$19:$A$400,B8,$B$19:$B$400,"exercise") -> 0 | E8: =COUNTIFS($A$19:$A$400,B8,$B$19:$B$400,"exercise") -> 6 | F8: =SUMIFS($E$19:$E$400,$A$19:$A$400,B8,$B$19:$B$400,"check") -> 0 | G8: =COUNTIFS($A$19:$A$400,B8,$B$19:$B$400,"check") -> 1 | H8: =IF(AND(D8=E8,F8=G8),"done",IF(D8+F8>0,"started","not yet")) -> not yet | I8: =IF(H8="done",99,B8) -> 2
