Workbook

Sheet Start Here
A1: SLAM
A2: Stress Less About Money. How every decision flows to profit, in one workbook.
A4: Three steps
A5: 1 | B5: Open the My Numbers tab and fill the pink cells. | C5: Start with just three: contacts last month, how many booked, and your price. Every other pink cell already holds a typical number; change it when you know better.
A6: 2 | B6: Read This Month. | C6: Your profit, what each business brings, and the one step where the money leaks. Everything on it updates itself.
A7: 3 | B7: Each week, add a row to Check-in. | C7: Five numbers, one minute. After four weeks the sheet tells you whether your real weeks match the model.
A9: How to read the cells
B10: Pink cell | C10: Yours to type. Nothing else needs touching.
B11: White cell | C11: Computed. It updates itself; leave it alone.
B12: Gold note | C12: An estimate or a caution the sheet wants you to see.
B13: Green note | C13: Good news: on track, or above the goal.
A15: The tabs
B16: My Numbers | C16: Every number you can change, with a typical value and where to find yours.
B17: This Month | C17: Profit, gross profit, hours, each business, the bottleneck, and the charts.
B18: Levers | C18: What one small move on each number does to your month.
B19: Three Futures | C19: Normal, Dream and Disaster side by side, and how long your cash lasts.
B20: Plan | C20: What your goal needs, what your offer is worth per hour, and what a client is worth over time.
B21: Check-in | C21: One row a week. Four weeks in, the sheet compares your real weeks to the model.
B22: Clients | C22: A list of aliases and stages. Never names, never documents.
B23: Definitions | C23: Every word and every formula, in plain English.
A25: Three promises
B26: Empty is not zero. Leave a pink cell blank and This Month counts the blanks and tells you, rather than quietly treating it as a zero.
B27: Screening is never a sales step. Nothing here suggests loosening it.
B28: This file is yours. Keep it somewhere private. Its name says nothing about what you do.
B30: SLAM gives no legal, tax or investment advice; for those, ask a professional. Some frameworks follow ideas published by Alex Hormozi; SLAM is independent and not affiliated.

Sheet My Numbers
A1: My Numbers
A2: Pink cells are yours. Each one comes with a typical number already in it, so every tab works from the first minute. Change what you know; leave the rest.
A4: Shared: the numbers every business reads
B5: What | C5: Yours | D5: Typical | E5: Where to look, and what to do with no idea
B6: Hours a week you can work (all of it: sessions, messages, posting, admin) | C6: 40 | D6: 30 | E6: Think of last week: days worked times hours each. Most land between 20 and 40.
B7: Days off a week (never zero) | C7: 2 | D7: 2 | E7: How many days in the last two weeks were fully off? Two is common.
B8: Money that leaves every month whether you work or not | C8: 1500 | D8: 1500 | E8: Last month's bank statement: rent for a space, subscriptions, phone, insurance, tools. Guess low rather than skip.
B9: What you want left for yourself each month | C9: 10000 | D9: 6000 | E9: Your rent and bills plus what you want on top. Start with what makes you feel safe.
B10: Share to set aside for tax (a reminder line only) | C10: 0.25 | D10: 0.25 | E10: Ask an accountant for your rate; a quarter is a common placeholder. No tax advice here.
B11: Cash you could live on if nothing came in | C11: 9000 | E11: Savings you could reach this week. Leave empty and Runway says "not yet".
B12: What an hour of your time is worth to you | C12: 100 | D12: 100 | E12: Profit last month divided by hours worked is a fine start. Used to compare a move's hours with its money.
B13: Money spent finding clients a month (ads, listings, promo) | C13: 0 | D13: 0 | E13: Card statement. If you pay nothing to be found, 0 is right.
B14: Hours a month spent finding clients (posting, replying, listings) | C14: 0 | D14: 10 | E14: A normal week times four.
A16: In person
B17: What | C17: Yours | D17: Typical | E17: Where to look, and what to do with no idea
B18: Counted? (Yes or No) | C18: Yes | D18: Yes | E18: No means it leaves every total.
B19: Priority (1 = your main engine; it gets your hours first) | C19: 1 | D19: 1 | E19: Each counted business needs a different number.
B20: People who contacted you last month | C20: 60 | D20: 60 | E20: Inbox, DMs, booking form. Count new names once, before screening. No idea? Count last week and multiply by four.
B21: Share who pass your screening | C21: 0.5 | D21: 0.5 | E21: Of the last 10 who contacted you, how many passed? Times 10 is the percent. Your screening is yours; nothing here suggests loosening it.
B22: Share of screened people who book | C22: 0.4 | D22: 0.4 | E22: Of the last 10 who passed, how many booked? Type contacts and bookings on This Month if that is easier.
B23: Share of bookings who turn up | C23: 0.85 | D23: 0.85 | E23: Of your last 10 bookings, how many happened? 8 or 9 in 10 with a deposit.
B24: Extra sessions per new client (30% = every 10 new clients bring 3 more sessions) | C24: 0.3 | D24: 0.3 | E24: Of your last 10 new clients, how many booked again? Times 10 is the percent.
B25: Most sessions you want in a month (blank = no cap; your hours still cap it) | C25: 18 | E25: Your busiest month you would happily repeat.
B26: Price of one session | C26: 500 | D26: 500 | E26: Your rate card.
B27: What one session costs you to deliver (space, travel, supplies) | C27: 100 | D27: 100 | E27: Think of your last one and what you paid out to make it happen. Guess low.
B28: Hours one session really takes, all in (prep, travel, the session, recovery, messages) | C28: 4 | D28: 4 | E28: Most people undercount. Double what the session itself takes.
B29: Cut a platform or processor takes from each sale | C29: 0.05 | D29: 0.05 | E29: Payouts page, or the gap between the price and what lands in your account.
B30: Add-on offered? (Yes or No) | C30: Yes | D30: Yes
B31: Add-on price | C31: 200 | D31: 200 | E31: Your rate card.
B32: Share of new clients who take the add-on | C32: 0.25 | D32: 0.25 | E32: Of your last 10 new clients, how many took it?
B33: Retainer offered? (Yes or No) | C33: Yes | D33: Yes
B34: Retainer price a month | C34: 1500 | D34: 1500 | E34: Your arrangement.
B35: Sessions a month the retainer includes | C35: 2 | D35: 2
B36: Share of new clients who take the retainer | C36: 0.1 | D36: 0.1 | E36: One in ten is a common start.
B37: Months a retainer client usually stays | C37: 4 | D37: 4 | E37: Think of the last few. How long did they stay?
B38: Program (several sessions over weeks) as the main offer? (Yes or No) | C38: No | D38: No | E38: Yes turns the funnel into consultations: price, sessions, close rate and hours below apply, and the single session, add-on and retainer are not counted.
B39: Program price | C39: 3000 | D39: 3000
B40: Sessions the program includes | C40: 4 | D40: 4
B41: Share of consultations that say yes | C41: 0.4 | D41: 0.4 | E41: Of your last 10 conversations, how many went ahead?
B42: What the whole program costs you to deliver | C42: 400 | D42: 400
...

Sheet This Month
A1: This Month
A2: From your numbers. Every white cell recomputes when a pink cell changes. Charts are on the right.
A4: The month in four numbers
B5: Profit this month | C5: ='This Month'!$C$75 -> 13155.217
B6: Gross profit | C6: ='This Month'!$C$72 -> 14655.217
B7: Sessions (in person) | C7: ='This Month'!$C$29 -> 18
B8: Hours used of sellable | C8: =IF('This Month'!$C$12="",TEXT('This Month'!$E$69,"0")&" (set your hours)",TEXT('This Month'!$E$69,"0")&" of "&TEXT('This Month'!$C$12,"0")) -> 144 of 173
B9: The bottleneck | C9: ='This Month'!$C$86 -> Capacity: you are full. Raise price or add a retainer or program.
B10: Blank pink cells on My Numbers | C10: =IF((COUNTBLANK('My Numbers'!$C$6:$C$14)+COUNTBLANK('My Numbers'!$C$18:$C$24)+COUNTBLANK('My Numbers'!$C$26:$C$44)+COUNTBLANK('My Numbers'!$C$48:$C$63)+COUNTBLANK('My Numbers'!$C$67:$C$74)+COUNTBLANK('My Numbers'!$C$78:$C$88)+COUNTBLANK('My Numbers'!$C$92:$C$100))=0,"None. Every number is filled in.",(COUNTBLANK('My Numbers'!$C$6:$C$14)+COUNTBLANK('My Numbers'!$C$18:$C$24)+COUNTBLANK('My Numbers'!$C$26:$C$44)+COUNTBLANK('My Numbers'!$C$48:$C$63)+COUNTBLANK('My Numbers'!$C$67:$C$74)+COUNTBLANK('My Numbers'!$C$78:$C$88)+COUNTBLANK('My Numbers'!$C$92:$C$100))&" blank. A blank counts as zero here, so fill it in or copy the typical number.") -> None. Every number is filled in.
A11: Shared hours
B12: Sellable hours a month (hours a week × 52 ÷ 12) | C12: =IF('My Numbers'!$C$6="","",'My Numbers'!$C$6*52/12) -> 173.33333
B13: Working days a week | C13: =7-'My Numbers'!$C$7 -> 5
A15: In person: from contacts to sessions
B16: New clients = contacts × pass × booking × show | C16: ='My Numbers'!$C$20*'My Numbers'!$C$21*'My Numbers'!$C$22*'My Numbers'!$C$23 -> 10.2
B17: Retainer clients = new clients × retainer take | C17: =IF(('My Numbers'!$C$33="Yes"),'This Month'!$C$16*'My Numbers'!$C$36,0) -> 1.02
B18: Single sessions = (new − retainer clients) × (1 + rebook) + retainer clients' first sessions | C18: =('This Month'!$C$16-'This Month'!$C$17)*(1+'My Numbers'!$C$24)+'This Month'!$C$17 -> 12.954
B19: Continuity sessions = retainer clients × sessions a month × months | C19: ='This Month'!$C$17*'My Numbers'!$C$35*'My Numbers'!$C$37 -> 8.16
B20: Program clients = new clients × close rate (only when the program is the main offer) | C20: =IF(('My Numbers'!$C$38="Yes"),'This Month'!$C$16*'My Numbers'!$C$41,0) -> 0
B21: Sessions wanted (demand) | C21: =IF(('My Numbers'!$C$38="Yes"),'This Month'!$C$20*'My Numbers'!$C$40,'This Month'!$C$18+'This Month'!$C$19) -> 21.114
B22: Hours per session, all in | C22: =IF(('My Numbers'!$C$38="Yes"),IF('My Numbers'!$C$40>0,'My Numbers'!$C$44/'My Numbers'!$C$40,0),'My Numbers'!$C$28) -> 4
B23: Hours the demand would take | C23: ='This Month'!$C$21*'This Month'!$C$22 -> 84.456
B24: Hours available to in person (after higher-priority businesses) | C24: =IF('This Month'!$C$12="","",IFERROR(INDEX('This Month'!$G$58:$G$61,MATCH("In person",'This Month'!$C$58:$C$61,0)),0)) -> 173.33333
B25: Cap from hours = hours available ÷ hours per session | C25: =IF(OR('This Month'!$C$12="",'This Month'!$C$22=0),"",'This Month'!$C$24/'This Month'!$C$22) -> 43.333333
B26: Cap from your session ceiling | C26: =IF('My Numbers'!$C$25="","",'My Numbers'!$C$25) -> 18
B27: Capacity = the tighter of the two | C27: =IF(AND('This Month'!$C$25="",'This Month'!$C$26=""),"",IF('This Month'!$C$25="",'This Month'!$C$26,IF('This Month'!$C$26="",'This Month'!$C$25,MIN('This Month'!$C$25,'This Month'!$C$26)))) -> 18
B28: Scale = capacity ÷ demand when demand is above it, else 1 | C28: =IF('This Month'!$C$27="",1,IF('This Month'!$C$21>'This Month'!$C$27,'This Month'!$C$27/'This Month'!$C$21,1)) -> 0.85251492
B29: Sessions this month | C29: ='This Month'!$C$21*'This Month'!$C$28 -> 18
B30: Gross profit per session = price × (1 − cut) − delivery | C30: ='My Numbers'!$C$26*(1-'My Numbers'!$C$29)-'My Numbers'!$C$27 -> 375
B31: From single sessions | C31: =IF(('My Numbers'!$C$38="Yes"),0,'This Month'!$C$18*'This Month'!$C$28*'This Month'!$C$30) -> 4141.3043
B32: From add-ons = new clients × take × add-on price × (1 − cut) | C32: =IF(AND(('My Numbers'!$C$30="Yes"),NOT(('My Numbers'!$C$38="Yes"))),'This Month'!$C$16*'My Numbers'!$C$32*'This Month'!$C$28*'My Numbers'!$C$31*(1-'My Numbers'!$C$29),0) -> 413.04348
B33: From retainers = retainer clients × months × (price × (1 − cut) − sessions × delivery) | C33: =IF(AND(('My Numbers'!$C$33="Yes"),NOT(('My Numbers'!$C$38="Yes"))),'This Month'!$C$17*'My Numbers'!$C$37*'This Month'!$C$28*('My Numbers'!$C$34*(1-'My Numbers'!$C$29)-'My Numbers'!$C$35*'My Numbers'!$C$27),0) -> 4260.8696
B34: From the program = program clients × (price × (1 − cut) − delivery) | C34: =IF(('My Numbers'!$C$38="Yes"),'This Month'!$C$20*'This Month'!$C$28*('My Numbers'!$C$39*(1-'My Numbers'!$C$43)-'My Numbers'!$C$42),0) -> 0
B35: In person gross profit a month | C35: =IF(('My Numbers'!$C$18="Yes"),'This Month'!$C$31+'This Month'!$C$32+'This Month'!$C$33+'This Month'!$C$34,0) -> 8815.2174
B36: In person hours used | C36: =IF(('My Numbers'!$C$18="Yes"),'This Month'!$C$29*'This Month'!$C$22,0) -> 72 | M36: The funnel this month (feeds the chart)
B37: Gross profit per contact (before any cap) | C37: =IF('My Numbers'!$C$20>0,IF(('My Numbers'!$C$38="Yes"),'This Month'!$C$20*('My Numbers'!$C$39*(1-'My Numbers'!$C$43)-'My Numbers'!$C$42),'This Month'!$C$18*'This Month'!$C$30+IF(('My Numbers'!$C$30="Yes"),'This Month'!$C$16*'My Numbers'!$C$32*'My Numbers'!$C$31*(1-'My Numbers'!$C$29),0)+IF(('My Numbers'!$C$33="Yes"),'This Month'!$C$17*'My Numbers'!$C$37*('My Numbers'!$C$34*(1-'My Numbers'!$C$29)-'My Numbers'!$C$35*'My Numbers'!$C$27),0))/'My Numbers'!$C$20,"") -> 172.3375 | M37: Contacts | N37: ='My Numbers'!$C$20 -> 60
B38: Sessions per contact (before any cap) | C38: =IF('My Numbers'!$C$20>0,'This Month'!$C$21/'My Numbers'!$C$20,"") -> 0.3519 | M38: Passed | N38: ='My Numbers'!$C$20*'My Numbers'!$C$21 -> 30
M39: Booked | N39: ='My Numbers'!$C$20*'My Numbers'!$C$21*'My Numbers'!$C$22 -> 12
A40: Content, Calls, Regulars | M40: Showed | N40: ='This Month'!$C$16 -> 10.2
B41: Content: subscriptions = subscribers × price × (1 − cut) | C41: ='My Numbers'!$C$52*'My Numbers'!$C$54*(1-'My Numbers'!$C$55) -> 1800 | M41: Sessions | N41: ='This Month'!$C$29 -> 18
B42: Content: customs = customs × price × (1 − cut) | C42: ='My Numbers'!$C$56*'My Numbers'!$C$57*(1-'My Numbers'!$C$58) -> 800
...

Sheet Levers
A1: Levers
A2: What one small move on each number does to in-person gross profit this month. Biggest first is the one to work on. Screening is not here on purpose.
B4: Move | C4: Change a month | D4: How it is worked out
B5: Booking rate +1 point | C5: =IF(('My Numbers'!$C$38="Yes"),"program on",(((('My Numbers'!$C$20*'My Numbers'!$C$21*('My Numbers'!$C$22+0.01)*'My Numbers'!$C$23)-(IF(('My Numbers'!$C$33="Yes"),('My Numbers'!$C$20*'My Numbers'!$C$21*('My Numbers'!$C$22+0.01)*'My Numbers'!$C$23)*'My Numbers'!$C$36,0)))*(1+'My Numbers'!$C$24)+(IF(('My Numbers'!$C$33="Yes"),('My Numbers'!$C$20*'My Numbers'!$C$21*('My Numbers'!$C$22+0.01)*'My Numbers'!$C$23)*'My Numbers'!$C$36,0)))*('My Numbers'!$C$26*(1-'My Numbers'!$C$29)-'My Numbers'!$C$27)+IF(('My Numbers'!$C$30="Yes"),('My Numbers'!$C$20*'My Numbers'!$C$21*('My Numbers'!$C$22+0.01)*'My Numbers'!$C$23)*'My Numbers'!$C$32*'My Numbers'!$C$31*(1-'My Numbers'!$C$29),0)+IF(('My Numbers'!$C$33="Yes"),(IF(('My Numbers'!$C$33="Yes"),('My Numbers'!$C$20*'My Numbers'!$C$21*('My Numbers'!$C$22+0.01)*'My Numbers'!$C$23)*'My Numbers'!$C$36,0))*'My Numbers'!$C$37*('My Numbers'!$C$34*(1-'My Numbers'!$C$29)-'My Numbers'!$C$35*'My Numbers'!$C$27),0))*(IF('This Month'!$C$27="",1,IF((((('My Numbers'!$C$20*'My Numbers'!$C$21*('My Numbers'!$C$22+0.01)*'My Numbers'!$C$23)-(IF(('My Numbers'!$C$33="Yes"),('My Numbers'!$C$20*'My Numbers'!$C$21*('My Numbers'!$C$22+0.01)*'My Numbers'!$C$23)*'My Numbers'!$C$36,0)))*(1+'My Numbers'!$C$24)+(IF(('My Numbers'!$C$33="Yes"),('My Numbers'!$C$20*'My Numbers'!$C$21*('My Numbers'!$C$22+0.01)*'My Numbers'!$C$23)*'My Numbers'!$C$36,0)))+((IF(('My Numbers'!$C$33="Yes"),('My Numbers'!$C$20*'My Numbers'!$C$21*('My Numbers'!$C$22+0.01)*'My Numbers'!$C$23)*'My Numbers'!$C$36,0))*'My Numbers'!$C$35*'My Numbers'!$C$37))>'This Month'!$C$27,'This Month'!$C$27/(((('My Numbers'!$C$20*'My Numbers'!$C$21*('My Numbers'!$C$22+0.01)*'My Numbers'!$C$23)-(IF(('My Numbers'!$C$33="Yes"),('My Numbers'!$C$20*'My Numbers'!$C$21*('My Numbers'!$C$22+0.01)*'My Numbers'!$C$23)*'My Numbers'!$C$36,0)))*(1+'My Numbers'!$C$24)+(IF(('My Numbers'!$C$33="Yes"),('My Numbers'!$C$20*'My Numbers'!$C$21*('My Numbers'!$C$22+0.01)*'My Numbers'!$C$23)*'My Numbers'!$C$36,0)))+((IF(('My Numbers'!$C$33="Yes"),('My Numbers'!$C$20*'My Numbers'!$C$21*('My Numbers'!$C$22+0.01)*'My Numbers'!$C$23)*'My Numbers'!$C$36,0))*'My Numbers'!$C$35*'My Numbers'!$C$37)),1)))-(((('My Numbers'!$C$20*'My Numbers'!$C$21*'My Numbers'!$C$22*'My Numbers'!$C$23)-(IF(('My Numbers'!$C$33="Yes"),('My Numbers'!$C$20*'My Numbers'!$C$21*'My Numbers'!$C$22*'My Numbers'!$C$23)*'My Numbers'!$C$36,0)))*(1+'My Numbers'!$C$24)+(IF(('My Numbers'!$C$33="Yes"),('My Numbers'!$C$20*'My Numbers'!$C$21*'My Numbers'!$C$22*'My Numbers'!$C$23)*'My Numbers'!$C$36,0)))*('My Numbers'!$C$26*(1-'My Numbers'!$C$29)-'My Numbers'!$C$27)+IF(('My Numbers'!$C$30="Yes"),('My Numbers'!$C$20*'My Numbers'!$C$21*'My Numbers'!$C$22*'My Numbers'!$C$23)*'My Numbers'!$C$32*'My Numbers'!$C$31*(1-'My Numbers'!$C$29),0)+IF(('My Numbers'!$C$33="Yes"),(IF(('My Numbers'!$C$33="Yes"),('My Numbers'!$C$20*'My Numbers'!$C$21*'My Numbers'!$C$22*'My Numbers'!$C$23)*'My Numbers'!$C$36,0))*'My Numbers'!$C$37*('My Numbers'!$C$34*(1-'My Numbers'!$C$29)-'My Numbers'!$C$35*'My Numbers'!$C$27),0))*(IF('This Month'!$C$27="",1,IF((((('My Numbers'!$C$20*'My Numbers'!$C$21*'My Numbers'!$C$22*'My Numbers'!$C$23)-(IF(('My Numbers'!$C$33="Yes"),('My Numbers'!$C$20*'My Numbers'!$C$21*'My Numbers'!$C$22*'My Numbers'!$C$23)*'My Numbers'!$C$36,0)))*(1+'My Numbers'!$C$24)+(IF(('My Numbers'!$C$33="Yes"),('My Numbers'!$C$20*'My Numbers'!$C$21*'My Numbers'!$C$22*'My Numbers'!$C$23)*'My Numbers'!$C$36,0)))+((IF(('My Numbers'!$C$33="Yes"),('My Numbers'!$C$20*'My Numbers'!$C$21*'My Numbers'!$C$22*'My Numbers'!$C$23)*'My Numbers'!$C$36,0))*'My Numbers'!$C$35*'My Numbers'!$C$37))>'This Month'!$C$27,'This Month'!$C$27/(((('My Numbers'!$C$20*'My Numbers'!$C$21*'My Numbers'!$C$22*'My Numbers'!$C$23)-(IF(('My Numbers'!$C$33="Yes"),('My Numbers'!$C$20*'My Numbers'!$C$21*'My Numbers'!$C$22*'My Numbers'!$C$23)*'My Numbers'!$C$36,0)))*(1+'My Numbers'!$C$24)+(IF(('My Numbers'!$C$33="Yes"),('My Numbers'!$C$20*'My Numbers'!$C$21*'My Numbers'!$C$22*'My Numbers'!$C$23)*'My Numbers'!$C$36,0)))+((IF(('My Numbers'!$C$33="Yes"),('My Numbers'!$C$20*'My Numbers'!$C$21*'My Numbers'!$C$22*'My Numbers'!$C$23)*'My Numbers'!$C$36,0))*'My Numbers'!$C$35*'My Numbers'!$C$37)),1)))) -> 0 | D5: The booking rate raised by one point, everything else the same.
B6: Show rate +1 point | C6: =IF(('My Numbers'!$C$38="Yes"),"program on",(((('My Numbers'!$C$20*'My Numbers'!$C$21*'My Numbers'!$C$22*('My Numbers'!$C$23+0.01))-(IF(('My Numbers'!$C$33="Yes"),('My Numbers'!$C$20*'My Numbers'!$C$21*'My Numbers'!$C$22*('My Numbers'!$C$23+0.01))*'My Numbers'!$C$36,0)))*(1+'My Numbers'!$C$24)+(IF(('My Numbers'!$C$33="Yes"),('My Numbers'!$C$20*'My Numbers'!$C$21*'My Numbers'!$C$22*('My Numbers'!$C$23+0.01))*'My Numbers'!$C$36,0)))*('My Numbers'!$C$26*(1-'My Numbers'!$C$29)-'My Numbers'!$C$27)+IF(('My Numbers'!$C$30="Yes"),('My Numbers'!$C$20*'My Numbers'!$C$21*'My Numbers'!$C$22*('My Numbers'!$C$23+0.01))*'My Numbers'!$C$32*'My Numbers'!$C$31*(1-'My Numbers'!$C$29),0)+IF(('My Numbers'!$C$33="Yes"),(IF(('My Numbers'!$C$33="Yes"),('My Numbers'!$C$20*'My Numbers'!$C$21*'My Numbers'!$C$22*('My Numbers'!$C$23+0.01))*'My Numbers'!$C$36,0))*'My Numbers'!$C$37*('My Numbers'!$C$34*(1-'My Numbers'!$C$29)-'My Numbers'!$C$35*'My Numbers'!$C$27),0))*(IF('This Month'!$C$27="",1,IF((((('My Numbers'!$C$20*'My Numbers'!$C$21*'My Numbers'!$C$22*('My Numbers'!$C$23+0.01))-(IF(('My Numbers'!$C$33="Yes"),('My Numbers'!$C$20*'My Numbers'!$C$21*'My Numbers'!$C$22*('My Numbers'!$C$23+0.01))*'My Numbers'!$C$36,0)))*(1+'My Numbers'!$C$24)+(IF(('My Numbers'!$C$33="Yes"),('My Numbers'!$C$20*'My Numbers'!$C$21*'My Numbers'!$C$22*('My Numbers'!$C$23+0.01))*'My Numbers'!$C$36,0)))+((IF(('My Numbers'!$C$33="Yes"),('My Numbers'!$C$20*'My Numbers'!$C$21*'My Numbers'!$C$22*('My Numbers'!$C$23+0.01))*'My Numbers'!$C$36,0))*'My Numbers'!$C$35*'My Numbers'!$C$37))>'This Month'!$C$27,'This Month'!$C$27/(((('My Numbers'!$C$20*'My Numbers'!$C$21*'My Numbers'!$C$22*('My Numbers'!$C$23+0.01))-(IF(('My Numbers'!$C$33="Yes"),('My Numbers'!$C$20*'My Numbers'!$C$21*'My Numbers'!$C$22*('My Numbers'!$C$23+0.01))*'My Numbers'!$C$36,0)))*(1+'My Numbers'!$C$24)+(IF(('My Numbers'!$C$33="Yes"),('My Numbers'!$C$20*'My Numbers'!$C$21*'My Numbers'!$C$22*('My Numbers'!$C$23+0.01))*'My Numbers'!$C$36,0)))+((IF(('My Numbers'!$C$33="Yes"),('My Numbers'!$C$20*'My Numbers'!$C$21*'My Numbers'!$C$22*('My Numbers'!$C$23+0.01))*'My Numbers'!$C$36,0))*'My Numbers'!$C$35*'My Numbers'!$C$37)),1)))-(((('My Numbers'!$C$20*'My Numbers'!$C$21*'My Numbers'!$C$22*'My Numbers'!$C$23)-(IF(('My Numbers'!$C$33="Yes"),('My Numbers'!$C$20*'My Numbers'!$C$21*'My Numbers'!$C$22*'My Numbers'!$C$23)*'My Numbers'!$C$36,0)))*(1+'My Numbers'!$C$24)+(IF(('My Numbers'!$C$33="Yes"),('My Numbers'!$C$20*'My Numbers'!$C$21*'My Numbers'!$C$22*'My Numbers'!$C$23)*'My Numbers'!$C$36,0)))*('My Numbers'!$C$26*(1-'My Numbers'!$C$29)-'My Numbers'!$C$27)+IF(('My Numbers'!$C$30="Yes"),('My Numbers'!$C$20*'My Numbers'!$C$21*'My Numbers'!$C$22*'My Numbers'!$C$23)*'My Numbers'!$C$32*'My Numbers'!$C$31*(1-'My Numbers'!$C$29),0)+IF(('My Numbers'!$C$33="Yes"),(IF(('My Numbers'!$C$33="Yes"),('My Numbers'!$C$20*'My Numbers'!$C$21*'My Numbers'!$C$22*'My Numbers'!$C$23)*'My Numbers'!$C$36,0))*'My Numbers'!$C$37*('My Numbers'!$C$34*(1-'My Numbers'!$C$29)-'My Numbers'!$C$35*'My Numbers'!$C$27),0))*(IF('This Month'!$C$27="",1,IF((((('My Numbers'!$C$20*'My Numbers'!$C$21*'My Numbers'!$C$22*'My Numbers'!$C$23)-(IF(('My Numbers'!$C$33="Yes"),('My Numbers'!$C$20*'My Numbers'!$C$21*'My Numbers'!$C$22*'My Numbers'!$C$23)*'My Numbers'!$C$36,0)))*(1+'My Numbers'!$C$24)+(IF(('My Numbers'!$C$33="Yes"),('My Numbers'!$C$20*'My Numbers'!$C$21*'My Numbers'!$C$22*'My Numbers'!$C$23)*'My Numbers'!$C$36,0)))+((IF(('My Numbers'!$C$33="Yes"),('My Numbers'!$C$20*'My Numbers'!$C$21*'My Numbers'!$C$22*'My Numbers'!$C$23)*'My Numbers'!$C$36,0))*'My Numbers'!$C$35*'My Numbers'!$C$37))>'This Month'!$C$27,'This Month'!$C$27/(((('My Numbers'!$C$20*'My Numbers'!$C$21*'My Numbers'!$C$22*'My Numbers'!$C$23)-(IF(('My Numbers'!$C$33="Yes"),('My Numbers'!$C$20*'My Numbers'!$C$21*'My Numbers'!$C$22*'My Numbers'!$C$23)*'My Numbers'!$C$36,0)))*(1+'My Numbers'!$C$24)+(IF(('My Numbers'!$C$33="Yes"),('My Numbers'!$C$20*'My Numbers'!$C$21*'My Numbers'!$C$22*'My Numbers'!$C$23)*'My Numbers'!$C$36,0)))+((IF(('My Numbers'!$C$33="Yes"),('My Numbers'!$C$20*'My Numbers'!$C$21*'My Numbers'!$C$22*'My Numbers'!$C$23)*'My Numbers'!$C$36,0))*'My Numbers'!$C$35*'My Numbers'!$C$37)),1)))) -> 0
B7: Rebook rate +1 point | C7: =IF(('My Numbers'!$C$38="Yes"),"program on",(((('My Numbers'!$C$20*'My Numbers'!$C$21*'My Numbers'!$C$22*'My Numbers'!$C$23)-(IF(('My Numbers'!$C$33="Yes"),('My Numbers'!$C$20*'My Numbers'!$C$21*'My Numbers'!$C$22*'My Numbers'!$C$23)*'My Numbers'!$C$36,0)))*(1+('My Numbers'!$C$24+0.01))+(IF(('My Numbers'!$C$33="Yes"),('My Numbers'!$C$20*'My Numbers'!$C$21*'My Numbers'!$C$22*'My Numbers'!$C$23)*'My Numbers'!$C$36,0)))*('My Numbers'!$C$26*(1-'My Numbers'!$C$29)-'My Numbers'!$C$27)+IF(('My Numbers'!$C$30="Yes"),('My Numbers'!$C$20*'My Numbers'!$C$21*'My Numbers'!$C$22*'My Numbers'!$C$23)*'My Numbers'!$C$32*'My Numbers'!$C$31*(1-'My Numbers'!$C$29),0)+IF(('My Numbers'!$C$33="Yes"),(IF(('My Numbers'!$C$33="Yes"),('My Numbers'!$C$20*'My Numbers'!$C$21*'My Numbers'!$C$22*'My Numbers'!$C$23)*'My Numbers'!$C$36,0))*'My Numbers'!$C$37*('My Numbers'!$C$34*(1-'My Numbers'!$C$29)-'My Numbers'!$C$35*'My Numbers'!$C$27),0))*(IF('This Month'!$C$27="",1,IF((((('My Numbers'!$C$20*'My Numbers'!$C$21*'My Numbers'!$C$22*'My Numbers'!$C$23)-(IF(('My Numbers'!$C$33="Yes"),('My Numbers'!$C$20*'My Numbers'!$C$21*'My Numbers'!$C$22*'My Numbers'!$C$23)*'My Numbers'!$C$36,0)))*(1+('My Numbers'!$C$24+0.01))+(IF(('My Numbers'!$C$33="Yes"),('My Numbers'!$C$20*'My Numbers'!$C$21*'My Numbers'!$C$22*'My Numbers'!$C$23)*'My Numbers'!$C$36,0)))+((IF(('My Numbers'!$C$33="Yes"),('My Numbers'!$C$20*'My Numbers'!$C$21*'My Numbers'!$C$22*'My Numbers'!$C$23)*'My Numbers'!$C$36,0))*'My Numbers'!$C$35*'My Numbers'!$C$37))>'This Month'!$C$27,'This Month'!$C$27/(((('My Numbers'!$C$20*'My Numbers'!$C$21*'My Numbers'!$C$22*'My Numbers'!$C$23)-(IF(('My Numbers'!$C$33="Yes"),('My Numbers'!$C$20*'My Numbers'!$C$21*'My Numbers'!$C$22*'My Numbers'!$C$23)*'My Numbers'!$C$36,0)))*(1+('My Numbers'!$C$24+0.01))+(IF(('My Numbers'!$C$33="Yes"),('My Numbers'!$C$20*'My Numbers'!$C$21*'My Numbers'!$C$22*'My Numbers'!$C$23)*'My Numbers'!$C$36,0)))+((IF(('My Numbers'!$C$33="Yes"),('My Numbers'!$C$20*'My Numbers'!$C$21*'My Numbers'!$C$22*'My Numbers'!$C$23)*'My Numbers'!$C$36,0))*'My Numbers'!$C$35*'My Numbers'!$C$37)),1)))-(((('My Numbers'!$C$20*'My Numbers'!$C$21*'My Numbers'!$C$22*'My Numbers'!$C$23)-(IF(('My Numbers'!$C$33="Yes"),('My Numbers'!$C$20*'My Numbers'!$C$21*'My Numbers'!$C$22*'My Numbers'!$C$23)*'My Numbers'!$C$36,0)))*(1+'My Numbers'!$C$24)+(IF(('My Numbers'!$C$33="Yes"),('My Numbers'!$C$20*'My Numbers'!$C$21*'My Numbers'!$C$22*'My Numbers'!$C$23)*'My Numbers'!$C$36,0)))*('My Numbers'!$C$26*(1-'My Numbers'!$C$29)-'My Numbers'!$C$27)+IF(('My Numbers'!$C$30="Yes"),('My Numbers'!$C$20*'My Numbers'!$C$21*'My Numbers'!$C$22*'My Numbers'!$C$23)*'My Numbers'!$C$32*'My Numbers'!$C$31*(1-'My Numbers'!$C$29),0)+IF(('My Numbers'!$C$33="Yes"),(IF(('My Numbers'!$C$33="Yes"),('My Numbers'!$C$20*'My Numbers'!$C$21*'My Numbers'!$C$22*'My Numbers'!$C$23)*'My Numbers'!$C$36,0))*'My Numbers'!$C$37*('My Numbers'!$C$34*(1-'My Numbers'!$C$29)-'My Numbers'!$C$35*'My Numbers'!$C$27),0))*(IF('This Month'!$C$27="",1,IF((((('My Numbers'!$C$20*'My Numbers'!$C$21*'My Numbers'!$C$22*'My Numbers'!$C$23)-(IF(('My Numbers'!$C$33="Yes"),('My Numbers'!$C$20*'My Numbers'!$C$21*'My Numbers'!$C$22*'My Numbers'!$C$23)*'My Numbers'!$C$36,0)))*(1+'My Numbers'!$C$24)+(IF(('My Numbers'!$C$33="Yes"),('My Numbers'!$C$20*'My Numbers'!$C$21*'My Numbers'!$C$22*'My Numbers'!$C$23)*'My Numbers'!$C$36,0)))+((IF(('My Numbers'!$C$33="Yes"),('My Numbers'!$C$20*'My Numbers'!$C$21*'My Numbers'!$C$22*'My Numbers'!$C$23)*'My Numbers'!$C$36,0))*'My Numbers'!$C$35*'My Numbers'!$C$37))>'This Month'!$C$27,'This Month'!$C$27/(((('My Numbers'!$C$20*'My Numbers'!$C$21*'My Numbers'!$C$22*'My Numbers'!$C$23)-(IF(('My Numbers'!$C$33="Yes"),('My Numbers'!$C$20*'My Numbers'!$C$21*'My Numbers'!$C$22*'My Numbers'!$C$23)*'My Numbers'!$C$36,0)))*(1+'My Numbers'!$C$24)+(IF(('My Numbers'!$C$33="Yes"),('My Numbers'!$C$20*'My Numbers'!$C$21*'My Numbers'!$C$22*'My Numbers'!$C$23)*'My Numbers'!$C$36,0)))+((IF(('My Numbers'!$C$33="Yes"),('My Numbers'!$C$20*'My Numbers'!$C$21*'My Numbers'!$C$22*'My Numbers'!$C$23)*'My Numbers'!$C$36,0))*'My Numbers'!$C$35*'My Numbers'!$C$37)),1)))) -> -8.940335
B8: Session price +1% | C8: =IF(('My Numbers'!$C$38="Yes"),"program on",(((('My Numbers'!$C$20*'My Numbers'!$C$21*'My Numbers'!$C$22*'My Numbers'!$C$23)-(IF(('My Numbers'!$C$33="Yes"),('My Numbers'!$C$20*'My Numbers'!$C$21*'My Numbers'!$C$22*'My Numbers'!$C$23)*'My Numbers'!$C$36,0)))*(1+'My Numbers'!$C$24)+(IF(('My Numbers'!$C$33="Yes"),('My Numbers'!$C$20*'My Numbers'!$C$21*'My Numbers'!$C$22*'My Numbers'!$C$23)*'My Numbers'!$C$36,0)))*(('My Numbers'!$C$26*1.01)*(1-'My Numbers'!$C$29)-'My Numbers'!$C$27)+IF(('My Numbers'!$C$30="Yes"),('My Numbers'!$C$20*'My Numbers'!$C$21*'My Numbers'!$C$22*'My Numbers'!$C$23)*'My Numbers'!$C$32*'My Numbers'!$C$31*(1-'My Numbers'!$C$29),0)+IF(('My Numbers'!$C$33="Yes"),(IF(('My Numbers'!$C$33="Yes"),('My Numbers'!$C$20*'My Numbers'!$C$21*'My Numbers'!$C$22*'My Numbers'!$C$23)*'My Numbers'!$C$36,0))*'My Numbers'!$C$37*('My Numbers'!$C$34*(1-'My Numbers'!$C$29)-'My Numbers'!$C$35*'My Numbers'!$C$27),0))*(IF('This Month'!$C$27="",1,IF((((('My Numbers'!$C$20*'My Numbers'!$C$21*'My Numbers'!$C$22*'My Numbers'!$C$23)-(IF(('My Numbers'!$C$33="Yes"),('My Numbers'!$C$20*'My Numbers'!$C$21*'My Numbers'!$C$22*'My Numbers'!$C$23)*'My Numbers'!$C$36,0)))*(1+'My Numbers'!$C$24)+(IF(('My Numbers'!$C$33="Yes"),('My Numbers'!$C$20*'My Numbers'!$C$21*'My Numbers'!$C$22*'My Numbers'!$C$23)*'My Numbers'!$C$36,0)))+((IF(('My Numbers'!$C$33="Yes"),('My Numbers'!$C$20*'My Numbers'!$C$21*'My Numbers'!$C$22*'My Numbers'!$C$23)*'My Numbers'!$C$36,0))*'My Numbers'!$C$35*'My Numbers'!$C$37))>'This Month'!$C$27,'This Month'!$C$27/(((('My Numbers'!$C$20*'My Numbers'!$C$21*'My Numbers'!$C$22*'My Numbers'!$C$23)-(IF(('My Numbers'!$C$33="Yes"),('My Numbers'!$C$20*'My Numbers'!$C$21*'My Numbers'!$C$22*'My Numbers'!$C$23)*'My Numbers'!$C$36,0)))*(1+'My Numbers'!$C$24)+(IF(('My Numbers'!$C$33="Yes"),('My Numbers'!$C$20*'My Numbers'!$C$21*'My Numbers'!$C$22*'My Numbers'!$C$23)*'My Numbers'!$C$36,0)))+((IF(('My Numbers'!$C$33="Yes"),('My Numbers'!$C$20*'My Numbers'!$C$21*'My Numbers'!$C$22*'My Numbers'!$C$23)*'My Numbers'!$C$36,0))*'My Numbers'!$C$35*'My Numbers'!$C$37)),1)))-(((('My Numbers'!$C$20*'My Numbers'!$C$21*'My Numbers'!$C$22*'My Numbers'!$C$23)-(IF(('My Numbers'!$C$33="Yes"),('My Numbers'!$C$20*'My Numbers'!$C$21*'My Numbers'!$C$22*'My Numbers'!$C$23)*'My Numbers'!$C$36,0)))*(1+'My Numbers'!$C$24)+(IF(('My Numbers'!$C$33="Yes"),('My Numbers'!$C$20*'My Numbers'!$C$21*'My Numbers'!$C$22*'My Numbers'!$C$23)*'My Numbers'!$C$36,0)))*('My Numbers'!$C$26*(1-'My Numbers'!$C$29)-'My Numbers'!$C$27)+IF(('My Numbers'!$C$30="Yes"),('My Numbers'!$C$20*'My Numbers'!$C$21*'My Numbers'!$C$22*'My Numbers'!$C$23)*'My Numbers'!$C$32*'My Numbers'!$C$31*(1-'My Numbers'!$C$29),0)+IF(('My Numbers'!$C$33="Yes"),(IF(('My Numbers'!$C$33="Yes"),('My Numbers'!$C$20*'My Numbers'!$C$21*'My Numbers'!$C$22*'My Numbers'!$C$23)*'My Numbers'!$C$36,0))*'My Numbers'!$C$37*('My Numbers'!$C$34*(1-'My Numbers'!$C$29)-'My Numbers'!$C$35*'My Numbers'!$C$27),0))*(IF('This Month'!$C$27="",1,IF((((('My Numbers'!$C$20*'My Numbers'!$C$21*'My Numbers'!$C$22*'My Numbers'!$C$23)-(IF(('My Numbers'!$C$33="Yes"),('My Numbers'!$C$20*'My Numbers'!$C$21*'My Numbers'!$C$22*'My Numbers'!$C$23)*'My Numbers'!$C$36,0)))*(1+'My Numbers'!$C$24)+(IF(('My Numbers'!$C$33="Yes"),('My Numbers'!$C$20*'My Numbers'!$C$21*'My Numbers'!$C$22*'My Numbers'!$C$23)*'My Numbers'!$C$36,0)))+((IF(('My Numbers'!$C$33="Yes"),('My Numbers'!$C$20*'My Numbers'!$C$21*'My Numbers'!$C$22*'My Numbers'!$C$23)*'My Numbers'!$C$36,0))*'My Numbers'!$C$35*'My Numbers'!$C$37))>'This Month'!$C$27,'This Month'!$C$27/(((('My Numbers'!$C$20*'My Numbers'!$C$21*'My Numbers'!$C$22*'My Numbers'!$C$23)-(IF(('My Numbers'!$C$33="Yes"),('My Numbers'!$C$20*'My Numbers'!$C$21*'My Numbers'!$C$22*'My Numbers'!$C$23)*'My Numbers'!$C$36,0)))*(1+'My Numbers'!$C$24)+(IF(('My Numbers'!$C$33="Yes"),('My Numbers'!$C$20*'My Numbers'!$C$21*'My Numbers'!$C$22*'My Numbers'!$C$23)*'My Numbers'!$C$36,0)))+((IF(('My Numbers'!$C$33="Yes"),('My Numbers'!$C$20*'My Numbers'!$C$21*'My Numbers'!$C$22*'My Numbers'!$C$23)*'My Numbers'!$C$36,0))*'My Numbers'!$C$35*'My Numbers'!$C$37)),1)))) -> 52.456522
B9: Contacts +1% | C9: =IF(('My Numbers'!$C$38="Yes"),"program on",((((('My Numbers'!$C$20*1.01)*'My Numbers'!$C$21*'My Numbers'!$C$22*'My Numbers'!$C$23)-(IF(('My Numbers'!$C$33="Yes"),(('My Numbers'!$C$20*1.01)*'My Numbers'!$C$21*'My Numbers'!$C$22*'My Numbers'!$C$23)*'My Numbers'!$C$36,0)))*(1+'My Numbers'!$C$24)+(IF(('My Numbers'!$C$33="Yes"),(('My Numbers'!$C$20*1.01)*'My Numbers'!$C$21*'My Numbers'!$C$22*'My Numbers'!$C$23)*'My Numbers'!$C$36,0)))*('My Numbers'!$C$26*(1-'My Numbers'!$C$29)-'My Numbers'!$C$27)+IF(('My Numbers'!$C$30="Yes"),(('My Numbers'!$C$20*1.01)*'My Numbers'!$C$21*'My Numbers'!$C$22*'My Numbers'!$C$23)*'My Numbers'!$C$32*'My Numbers'!$C$31*(1-'My Numbers'!$C$29),0)+IF(('My Numbers'!$C$33="Yes"),(IF(('My Numbers'!$C$33="Yes"),(('My Numbers'!$C$20*1.01)*'My Numbers'!$C$21*'My Numbers'!$C$22*'My Numbers'!$C$23)*'My Numbers'!$C$36,0))*'My Numbers'!$C$37*('My Numbers'!$C$34*(1-'My Numbers'!$C$29)-'My Numbers'!$C$35*'My Numbers'!$C$27),0))*(IF('This Month'!$C$27="",1,IF(((((('My Numbers'!$C$20*1.01)*'My Numbers'!$C$21*'My Numbers'!$C$22*'My Numbers'!$C$23)-(IF(('My Numbers'!$C$33="Yes"),(('My Numbers'!$C$20*1.01)*'My Numbers'!$C$21*'My Numbers'!$C$22*'My Numbers'!$C$23)*'My Numbers'!$C$36,0)))*(1+'My Numbers'!$C$24)+(IF(('My Numbers'!$C$33="Yes"),(('My Numbers'!$C$20*1.01)*'My Numbers'!$C$21*'My Numbers'!$C$22*'My Numbers'!$C$23)*'My Numbers'!$C$36,0)))+((IF(('My Numbers'!$C$33="Yes"),(('My Numbers'!$C$20*1.01)*'My Numbers'!$C$21*'My Numbers'!$C$22*'My Numbers'!$C$23)*'My Numbers'!$C$36,0))*'My Numbers'!$C$35*'My Numbers'!$C$37))>'This Month'!$C$27,'This Month'!$C$27/((((('My Numbers'!$C$20*1.01)*'My Numbers'!$C$21*'My Numbers'!$C$22*'My Numbers'!$C$23)-(IF(('My Numbers'!$C$33="Yes"),(('My Numbers'!$C$20*1.01)*'My Numbers'!$C$21*'My Numbers'!$C$22*'My Numbers'!$C$23)*'My Numbers'!$C$36,0)))*(1+'My Numbers'!$C$24)+(IF(('My Numbers'!$C$33="Yes"),(('My Numbers'!$C$20*1.01)*'My Numbers'!$C$21*'My Numbers'!$C$22*'My Numbers'!$C$23)*'My Numbers'!$C$36,0)))+((IF(('My Numbers'!$C$33="Yes"),(('My Numbers'!$C$20*1.01)*'My Numbers'!$C$21*'My Numbers'!$C$22*'My Numbers'!$C$23)*'My Numbers'!$C$36,0))*'My Numbers'!$C$35*'My Numbers'!$C$37)),1)))-(((('My Numbers'!$C$20*'My Numbers'!$C$21*'My Numbers'!$C$22*'My Numbers'!$C$23)-(IF(('My Numbers'!$C$33="Yes"),('My Numbers'!$C$20*'My Numbers'!$C$21*'My Numbers'!$C$22*'My Numbers'!$C$23)*'My Numbers'!$C$36,0)))*(1+'My Numbers'!$C$24)+(IF(('My Numbers'!$C$33="Yes"),('My Numbers'!$C$20*'My Numbers'!$C$21*'My Numbers'!$C$22*'My Numbers'!$C$23)*'My Numbers'!$C$36,0)))*('My Numbers'!$C$26*(1-'My Numbers'!$C$29)-'My Numbers'!$C$27)+IF(('My Numbers'!$C$30="Yes"),('My Numbers'!$C$20*'My Numbers'!$C$21*'My Numbers'!$C$22*'My Numbers'!$C$23)*'My Numbers'!$C$32*'My Numbers'!$C$31*(1-'My Numbers'!$C$29),0)+IF(('My Numbers'!$C$33="Yes"),(IF(('My Numbers'!$C$33="Yes"),('My Numbers'!$C$20*'My Numbers'!$C$21*'My Numbers'!$C$22*'My Numbers'!$C$23)*'My Numbers'!$C$36,0))*'My Numbers'!$C$37*('My Numbers'!$C$34*(1-'My Numbers'!$C$29)-'My Numbers'!$C$35*'My Numbers'!$C$27),0))*(IF('This Month'!$C$27="",1,IF((((('My Numbers'!$C$20*'My Numbers'!$C$21*'My Numbers'!$C$22*'My Numbers'!$C$23)-(IF(('My Numbers'!$C$33="Yes"),('My Numbers'!$C$20*'My Numbers'!$C$21*'My Numbers'!$C$22*'My Numbers'!$C$23)*'My Numbers'!$C$36,0)))*(1+'My Numbers'!$C$24)+(IF(('My Numbers'!$C$33="Yes"),('My Numbers'!$C$20*'My Numbers'!$C$21*'My Numbers'!$C$22*'My Numbers'!$C$23)*'My Numbers'!$C$36,0)))+((IF(('My Numbers'!$C$33="Yes"),('My Numbers'!$C$20*'My Numbers'!$C$21*'My Numbers'!$C$22*'My Numbers'!$C$23)*'My Numbers'!$C$36,0))*'My Numbers'!$C$35*'My Numbers'!$C$37))>'This Month'!$C$27,'This Month'!$C$27/(((('My Numbers'!$C$20*'My Numbers'!$C$21*'My Numbers'!$C$22*'My Numbers'!$C$23)-(IF(('My Numbers'!$C$33="Yes"),('My Numbers'!$C$20*'My Numbers'!$C$21*'My Numbers'!$C$22*'My Numbers'!$C$23)*'My Numbers'!$C$36,0)))*(1+'My Numbers'!$C$24)+(IF(('My Numbers'!$C$33="Yes"),('My Numbers'!$C$20*'My Numbers'!$C$21*'My Numbers'!$C$22*'My Numbers'!$C$23)*'My Numbers'!$C$36,0)))+((IF(('My Numbers'!$C$33="Yes"),('My Numbers'!$C$20*'My Numbers'!$C$21*'My Numbers'!$C$22*'My Numbers'!$C$23)*'My Numbers'!$C$36,0))*'My Numbers'!$C$35*'My Numbers'!$C$37)),1)))) -> 0
B10: Delivery cost −1% | C10: =IF(('My Numbers'!$C$38="Yes"),"program on",(((('My Numbers'!$C$20*'My Numbers'!$C$21*'My Numbers'!$C$22*'My Numbers'!$C$23)-(IF(('My Numbers'!$C$33="Yes"),('My Numbers'!$C$20*'My Numbers'!$C$21*'My Numbers'!$C$22*'My Numbers'!$C$23)*'My Numbers'!$C$36,0)))*(1+'My Numbers'!$C$24)+(IF(('My Numbers'!$C$33="Yes"),('My Numbers'!$C$20*'My Numbers'!$C$21*'My Numbers'!$C$22*'My Numbers'!$C$23)*'My Numbers'!$C$36,0)))*('My Numbers'!$C$26*(1-'My Numbers'!$C$29)-('My Numbers'!$C$27*0.99))+IF(('My Numbers'!$C$30="Yes"),('My Numbers'!$C$20*'My Numbers'!$C$21*'My Numbers'!$C$22*'My Numbers'!$C$23)*'My Numbers'!$C$32*'My Numbers'!$C$31*(1-'My Numbers'!$C$29),0)+IF(('My Numbers'!$C$33="Yes"),(IF(('My Numbers'!$C$33="Yes"),('My Numbers'!$C$20*'My Numbers'!$C$21*'My Numbers'!$C$22*'My Numbers'!$C$23)*'My Numbers'!$C$36,0))*'My Numbers'!$C$37*('My Numbers'!$C$34*(1-'My Numbers'!$C$29)-'My Numbers'!$C$35*('My Numbers'!$C$27*0.99)),0))*(IF('This Month'!$C$27="",1,IF((((('My Numbers'!$C$20*'My Numbers'!$C$21*'My Numbers'!$C$22*'My Numbers'!$C$23)-(IF(('My Numbers'!$C$33="Yes"),('My Numbers'!$C$20*'My Numbers'!$C$21*'My Numbers'!$C$22*'My Numbers'!$C$23)*'My Numbers'!$C$36,0)))*(1+'My Numbers'!$C$24)+(IF(('My Numbers'!$C$33="Yes"),('My Numbers'!$C$20*'My Numbers'!$C$21*'My Numbers'!$C$22*'My Numbers'!$C$23)*'My Numbers'!$C$36,0)))+((IF(('My Numbers'!$C$33="Yes"),('My Numbers'!$C$20*'My Numbers'!$C$21*'My Numbers'!$C$22*'My Numbers'!$C$23)*'My Numbers'!$C$36,0))*'My Numbers'!$C$35*'My Numbers'!$C$37))>'This Month'!$C$27,'This Month'!$C$27/(((('My Numbers'!$C$20*'My Numbers'!$C$21*'My Numbers'!$C$22*'My Numbers'!$C$23)-(IF(('My Numbers'!$C$33="Yes"),('My Numbers'!$C$20*'My Numbers'!$C$21*'My Numbers'!$C$22*'My Numbers'!$C$23)*'My Numbers'!$C$36,0)))*(1+'My Numbers'!$C$24)+(IF(('My Numbers'!$C$33="Yes"),('My Numbers'!$C$20*'My Numbers'!$C$21*'My Numbers'!$C$22*'My Numbers'!$C$23)*'My Numbers'!$C$36,0)))+((IF(('My Numbers'!$C$33="Yes"),('My Numbers'!$C$20*'My Numbers'!$C$21*'My Numbers'!$C$22*'My Numbers'!$C$23)*'My Numbers'!$C$36,0))*'My Numbers'!$C$35*'My Numbers'!$C$37)),1)))-(((('My Numbers'!$C$20*'My Numbers'!$C$21*'My Numbers'!$C$22*'My Numbers'!$C$23)-(IF(('My Numbers'!$C$33="Yes"),('My Numbers'!$C$20*'My Numbers'!$C$21*'My Numbers'!$C$22*'My Numbers'!$C$23)*'My Numbers'!$C$36,0)))*(1+'My Numbers'!$C$24)+(IF(('My Numbers'!$C$33="Yes"),('My Numbers'!$C$20*'My Numbers'!$C$21*'My Numbers'!$C$22*'My Numbers'!$C$23)*'My Numbers'!$C$36,0)))*('My Numbers'!$C$26*(1-'My Numbers'!$C$29)-'My Numbers'!$C$27)+IF(('My Numbers'!$C$30="Yes"),('My Numbers'!$C$20*'My Numbers'!$C$21*'My Numbers'!$C$22*'My Numbers'!$C$23)*'My Numbers'!$C$32*'My Numbers'!$C$31*(1-'My Numbers'!$C$29),0)+IF(('My Numbers'!$C$33="Yes"),(IF(('My Numbers'!$C$33="Yes"),('My Numbers'!$C$20*'My Numbers'!$C$21*'My Numbers'!$C$22*'My Numbers'!$C$23)*'My Numbers'!$C$36,0))*'My Numbers'!$C$37*('My Numbers'!$C$34*(1-'My Numbers'!$C$29)-'My Numbers'!$C$35*'My Numbers'!$C$27),0))*(IF('This Month'!$C$27="",1,IF((((('My Numbers'!$C$20*'My Numbers'!$C$21*'My Numbers'!$C$22*'My Numbers'!$C$23)-(IF(('My Numbers'!$C$33="Yes"),('My Numbers'!$C$20*'My Numbers'!$C$21*'My Numbers'!$C$22*'My Numbers'!$C$23)*'My Numbers'!$C$36,0)))*(1+'My Numbers'!$C$24)+(IF(('My Numbers'!$C$33="Yes"),('My Numbers'!$C$20*'My Numbers'!$C$21*'My Numbers'!$C$22*'My Numbers'!$C$23)*'My Numbers'!$C$36,0)))+((IF(('My Numbers'!$C$33="Yes"),('My Numbers'!$C$20*'My Numbers'!$C$21*'My Numbers'!$C$22*'My Numbers'!$C$23)*'My Numbers'!$C$36,0))*'My Numbers'!$C$35*'My Numbers'!$C$37))>'This Month'!$C$27,'This Month'!$C$27/(((('My Numbers'!$C$20*'My Numbers'!$C$21*'My Numbers'!$C$22*'My Numbers'!$C$23)-(IF(('My Numbers'!$C$33="Yes"),('My Numbers'!$C$20*'My Numbers'!$C$21*'My Numbers'!$C$22*'My Numbers'!$C$23)*'My Numbers'!$C$36,0)))*(1+'My Numbers'!$C$24)+(IF(('My Numbers'!$C$33="Yes"),('My Numbers'!$C$20*'My Numbers'!$C$21*'My Numbers'!$C$22*'My Numbers'!$C$23)*'My Numbers'!$C$36,0)))+((IF(('My Numbers'!$C$33="Yes"),('My Numbers'!$C$20*'My Numbers'!$C$21*'My Numbers'!$C$22*'My Numbers'!$C$23)*'My Numbers'!$C$36,0))*'My Numbers'!$C$35*'My Numbers'!$C$37)),1)))) -> 18
B12: The biggest single move | C12: =IFERROR(INDEX(B5:B10,MATCH(MAX(C5:C10),C5:C10,0)),"") -> Session price +1%
B13: =IF('This Month'!$C$27="","",IF('This Month'!$C$21>'This Month'!$C$27,"You are at capacity, so more contacts or bookings add nothing until you raise the price, add a retainer, or lift the cap. A move can even read below zero: it fills the same hours with cheaper sessions.","")) -> You are at capacity, so more contacts or bookings add nothing until you raise the price, add a retainer, or lift the cap. A move can even read below zero: it fills the same hours with cheaper sessions.

Sheet Three Futures
A1: Three Futures
A2: Normal is your numbers as they stand. Dream and Disaster move contacts, audience and conversion by the amounts on My Numbers; the Disaster switches add events. Runway is how many months your cash covers the gap to your goal.
C4: Disaster | D4: Normal | E4: Dream
B5: In person | C5: =IF(('My Numbers'!$C$18="Yes"),IF(('My Numbers'!$C$38="Yes"),(((('My Numbers'!$C$20*(1+'My Numbers'!$C$94)*IF(('My Numbers'!$C$98="Yes"),1-'My Numbers'!$C$96,1)*IF(('My Numbers'!$C$100="Yes"),0,1))*'My Numbers'!$C$21*'My Numbers'!$C$22*'My Numbers'!$C$23)*MIN(1,'My Numbers'!$C$41*(1+'My Numbers'!$C$95)))*('My Numbers'!$C$39*IF(('My Numbers'!$C$99="Yes"),1-'My Numbers'!$C$97,1)*(1-'My Numbers'!$C$43)-'My Numbers'!$C$42)),((((('My Numbers'!$C$20*(1+'My Numbers'!$C$94)*IF(('My Numbers'!$C$98="Yes"),1-'My Numbers'!$C$96,1)*IF(('My Numbers'!$C$100="Yes"),0,1))*'My Numbers'!$C$21*'My Numbers'!$C$22*'My Numbers'!$C$23)-(IF(('My Numbers'!$C$33="Yes"),(('My Numbers'!$C$20*(1+'My Numbers'!$C$94)*IF(('My Numbers'!$C$98="Yes"),1-'My Numbers'!$C$96,1)*IF(('My Numbers'!$C$100="Yes"),0,1))*'My Numbers'!$C$21*'My Numbers'!$C$22*'My Numbers'!$C$23)*'My Numbers'!$C$36,0)))*(1+'My Numbers'!$C$24)+(IF(('My Numbers'!$C$33="Yes"),(('My Numbers'!$C$20*(1+'My Numbers'!$C$94)*IF(('My Numbers'!$C$98="Yes"),1-'My Numbers'!$C$96,1)*IF(('My Numbers'!$C$100="Yes"),0,1))*'My Numbers'!$C$21*'My Numbers'!$C$22*'My Numbers'!$C$23)*'My Numbers'!$C$36,0)))*(('My Numbers'!$C$26*IF(('My Numbers'!$C$99="Yes"),1-'My Numbers'!$C$97,1))*(1-'My Numbers'!$C$29)-'My Numbers'!$C$27)+IF(('My Numbers'!$C$30="Yes"),(('My Numbers'!$C$20*(1+'My Numbers'!$C$94)*IF(('My Numbers'!$C$98="Yes"),1-'My Numbers'!$C$96,1)*IF(('My Numbers'!$C$100="Yes"),0,1))*'My Numbers'!$C$21*'My Numbers'!$C$22*'My Numbers'!$C$23)*'My Numbers'!$C$32*'My Numbers'!$C$31*IF(('My Numbers'!$C$99="Yes"),1-'My Numbers'!$C$97,1)*(1-'My Numbers'!$C$29),0)+IF(('My Numbers'!$C$33="Yes"),(IF(('My Numbers'!$C$33="Yes"),(('My Numbers'!$C$20*(1+'My Numbers'!$C$94)*IF(('My Numbers'!$C$98="Yes"),1-'My Numbers'!$C$96,1)*IF(('My Numbers'!$C$100="Yes"),0,1))*'My Numbers'!$C$21*'My Numbers'!$C$22*'My Numbers'!$C$23)*'My Numbers'!$C$36,0))*'My Numbers'!$C$37*('My Numbers'!$C$34*IF(('My Numbers'!$C$99="Yes"),1-'My Numbers'!$C$97,1)*(1-'My Numbers'!$C$29)-'My Numbers'!$C$35*'My Numbers'!$C$27),0)))*(IF('This Month'!$C$27="",1,IF((IF(('My Numbers'!$C$38="Yes"),((('My Numbers'!$C$20*(1+'My Numbers'!$C$94)*IF(('My Numbers'!$C$98="Yes"),1-'My Numbers'!$C$96,1)*IF(('My Numbers'!$C$100="Yes"),0,1))*'My Numbers'!$C$21*'My Numbers'!$C$22*'My Numbers'!$C$23)*MIN(1,'My Numbers'!$C$41*(1+'My Numbers'!$C$95)))*'My Numbers'!$C$40,(((('My Numbers'!$C$20*(1+'My Numbers'!$C$94)*IF(('My Numbers'!$C$98="Yes"),1-'My Numbers'!$C$96,1)*IF(('My Numbers'!$C$100="Yes"),0,1))*'My Numbers'!$C$21*'My Numbers'!$C$22*'My Numbers'!$C$23)-(IF(('My Numbers'!$C$33="Yes"),(('My Numbers'!$C$20*(1+'My Numbers'!$C$94)*IF(('My Numbers'!$C$98="Yes"),1-'My Numbers'!$C$96,1)*IF(('My Numbers'!$C$100="Yes"),0,1))*'My Numbers'!$C$21*'My Numbers'!$C$22*'My Numbers'!$C$23)*'My Numbers'!$C$36,0)))*(1+'My Numbers'!$C$24)+(IF(('My Numbers'!$C$33="Yes"),(('My Numbers'!$C$20*(1+'My Numbers'!$C$94)*IF(('My Numbers'!$C$98="Yes"),1-'My Numbers'!$C$96,1)*IF(('My Numbers'!$C$100="Yes"),0,1))*'My Numbers'!$C$21*'My Numbers'!$C$22*'My Numbers'!$C$23)*'My Numbers'!$C$36,0)))+((IF(('My Numbers'!$C$33="Yes"),(('My Numbers'!$C$20*(1+'My Numbers'!$C$94)*IF(('My Numbers'!$C$98="Yes"),1-'My Numbers'!$C$96,1)*IF(('My Numbers'!$C$100="Yes"),0,1))*'My Numbers'!$C$21*'My Numbers'!$C$22*'My Numbers'!$C$23)*'My Numbers'!$C$36,0))*'My Numbers'!$C$35*'My Numbers'!$C$37)))>'This Month'!$C$27,'This Month'!$C$27/(IF(('My Numbers'!$C$38="Yes"),((('My Numbers'!$C$20*(1+'My Numbers'!$C$94)*IF(('My Numbers'!$C$98="Yes"),1-'My Numbers'!$C$96,1)*IF(('My Numbers'!$C$100="Yes"),0,1))*'My Numbers'!$C$21*'My Numbers'!$C$22*'My Numbers'!$C$23)*MIN(1,'My Numbers'!$C$41*(1+'My Numbers'!$C$95)))*'My Numbers'!$C$40,(((('My Numbers'!$C$20*(1+'My Numbers'!$C$94)*IF(('My Numbers'!$C$98="Yes"),1-'My Numbers'!$C$96,1)*IF(('My Numbers'!$C$100="Yes"),0,1))*'My Numbers'!$C$21*'My Numbers'!$C$22*'My Numbers'!$C$23)-(IF(('My Numbers'!$C$33="Yes"),(('My Numbers'!$C$20*(1+'My Numbers'!$C$94)*IF(('My Numbers'!$C$98="Yes"),1-'My Numbers'!$C$96,1)*IF(('My Numbers'!$C$100="Yes"),0,1))*'My Numbers'!$C$21*'My Numbers'!$C$22*'My Numbers'!$C$23)*'My Numbers'!$C$36,0)))*(1+'My Numbers'!$C$24)+(IF(('My Numbers'!$C$33="Yes"),(('My Numbers'!$C$20*(1+'My Numbers'!$C$94)*IF(('My Numbers'!$C$98="Yes"),1-'My Numbers'!$C$96,1)*IF(('My Numbers'!$C$100="Yes"),0,1))*'My Numbers'!$C$21*'My Numbers'!$C$22*'My Numbers'!$C$23)*'My Numbers'!$C$36,0)))+((IF(('My Numbers'!$C$33="Yes"),(('My Numbers'!$C$20*(1+'My Numbers'!$C$94)*IF(('My Numbers'!$C$98="Yes"),1-'My Numbers'!$C$96,1)*IF(('My Numbers'!$C$100="Yes"),0,1))*'My Numbers'!$C$21*'My Numbers'!$C$22*'My Numbers'!$C$23)*'My Numbers'!$C$36,0))*'My Numbers'!$C$35*'My Numbers'!$C$37))),1))),0) -> 6204.15 | D5: =IF(('My Numbers'!$C$18="Yes"),IF(('My Numbers'!$C$38="Yes"),(((('My Numbers'!$C$20*1*IF(FALSE(),1-'My Numbers'!$C$96,1)*IF(FALSE(),0,1))*'My Numbers'!$C$21*'My Numbers'!$C$22*'My Numbers'!$C$23)*MIN(1,'My Numbers'!$C$41*1))*('My Numbers'!$C$39*IF(FALSE(),1-'My Numbers'!$C$97,1)*(1-'My Numbers'!$C$43)-'My Numbers'!$C$42)),((((('My Numbers'!$C$20*1*IF(FALSE(),1-'My Numbers'!$C$96,1)*IF(FALSE(),0,1))*'My Numbers'!$C$21*'My Numbers'!$C$22*'My Numbers'!$C$23)-(IF(('My Numbers'!$C$33="Yes"),(('My Numbers'!$C$20*1*IF(FALSE(),1-'My Numbers'!$C$96,1)*IF(FALSE(),0,1))*'My Numbers'!$C$21*'My Numbers'!$C$22*'My Numbers'!$C$23)*'My Numbers'!$C$36,0)))*(1+'My Numbers'!$C$24)+(IF(('My Numbers'!$C$33="Yes"),(('My Numbers'!$C$20*1*IF(FALSE(),1-'My Numbers'!$C$96,1)*IF(FALSE(),0,1))*'My Numbers'!$C$21*'My Numbers'!$C$22*'My Numbers'!$C$23)*'My Numbers'!$C$36,0)))*(('My Numbers'!$C$26*IF(FALSE(),1-'My Numbers'!$C$97,1))*(1-'My Numbers'!$C$29)-'My Numbers'!$C$27)+IF(('My Numbers'!$C$30="Yes"),(('My Numbers'!$C$20*1*IF(FALSE(),1-'My Numbers'!$C$96,1)*IF(FALSE(),0,1))*'My Numbers'!$C$21*'My Numbers'!$C$22*'My Numbers'!$C$23)*'My Numbers'!$C$32*'My Numbers'!$C$31*IF(FALSE(),1-'My Numbers'!$C$97,1)*(1-'My Numbers'!$C$29),0)+IF(('My Numbers'!$C$33="Yes"),(IF(('My Numbers'!$C$33="Yes"),(('My Numbers'!$C$20*1*IF(FALSE(),1-'My Numbers'!$C$96,1)*IF(FALSE(),0,1))*'My Numbers'!$C$21*'My Numbers'!$C$22*'My Numbers'!$C$23)*'My Numbers'!$C$36,0))*'My Numbers'!$C$37*('My Numbers'!$C$34*IF(FALSE(),1-'My Numbers'!$C$97,1)*(1-'My Numbers'!$C$29)-'My Numbers'!$C$35*'My Numbers'!$C$27),0)))*(IF('This Month'!$C$27="",1,IF((IF(('My Numbers'!$C$38="Yes"),((('My Numbers'!$C$20*1*IF(FALSE(),1-'My Numbers'!$C$96,1)*IF(FALSE(),0,1))*'My Numbers'!$C$21*'My Numbers'!$C$22*'My Numbers'!$C$23)*MIN(1,'My Numbers'!$C$41*1))*'My Numbers'!$C$40,(((('My Numbers'!$C$20*1*IF(FALSE(),1-'My Numbers'!$C$96,1)*IF(FALSE(),0,1))*'My Numbers'!$C$21*'My Numbers'!$C$22*'My Numbers'!$C$23)-(IF(('My Numbers'!$C$33="Yes"),(('My Numbers'!$C$20*1*IF(FALSE(),1-'My Numbers'!$C$96,1)*IF(FALSE(),0,1))*'My Numbers'!$C$21*'My Numbers'!$C$22*'My Numbers'!$C$23)*'My Numbers'!$C$36,0)))*(1+'My Numbers'!$C$24)+(IF(('My Numbers'!$C$33="Yes"),(('My Numbers'!$C$20*1*IF(FALSE(),1-'My Numbers'!$C$96,1)*IF(FALSE(),0,1))*'My Numbers'!$C$21*'My Numbers'!$C$22*'My Numbers'!$C$23)*'My Numbers'!$C$36,0)))+((IF(('My Numbers'!$C$33="Yes"),(('My Numbers'!$C$20*1*IF(FALSE(),1-'My Numbers'!$C$96,1)*IF(FALSE(),0,1))*'My Numbers'!$C$21*'My Numbers'!$C$22*'My Numbers'!$C$23)*'My Numbers'!$C$36,0))*'My Numbers'!$C$35*'My Numbers'!$C$37)))>'This Month'!$C$27,'This Month'!$C$27/(IF(('My Numbers'!$C$38="Yes"),((('My Numbers'!$C$20*1*IF(FALSE(),1-'My Numbers'!$C$96,1)*IF(FALSE(),0,1))*'My Numbers'!$C$21*'My Numbers'!$C$22*'My Numbers'!$C$23)*MIN(1,'My Numbers'!$C$41*1))*'My Numbers'!$C$40,(((('My Numbers'!$C$20*1*IF(FALSE(),1-'My Numbers'!$C$96,1)*IF(FALSE(),0,1))*'My Numbers'!$C$21*'My Numbers'!$C$22*'My Numbers'!$C$23)-(IF(('My Numbers'!$C$33="Yes"),(('My Numbers'!$C$20*1*IF(FALSE(),1-'My Numbers'!$C$96,1)*IF(FALSE(),0,1))*'My Numbers'!$C$21*'My Numbers'!$C$22*'My Numbers'!$C$23)*'My Numbers'!$C$36,0)))*(1+'My Numbers'!$C$24)+(IF(('My Numbers'!$C$33="Yes"),(('My Numbers'!$C$20*1*IF(FALSE(),1-'My Numbers'!$C$96,1)*IF(FALSE(),0,1))*'My Numbers'!$C$21*'My Numbers'!$C$22*'My Numbers'!$C$23)*'My Numbers'!$C$36,0)))+((IF(('My Numbers'!$C$33="Yes"),(('My Numbers'!$C$20*1*IF(FALSE(),1-'My Numbers'!$C$96,1)*IF(FALSE(),0,1))*'My Numbers'!$C$21*'My Numbers'!$C$22*'My Numbers'!$C$23)*'My Numbers'!$C$36,0))*'My Numbers'!$C$35*'My Numbers'!$C$37))),1))),0) -> 8815.2174 | E5: =IF(('My Numbers'!$C$18="Yes"),IF(('My Numbers'!$C$38="Yes"),(((('My Numbers'!$C$20*(1+'My Numbers'!$C$92)*IF(FALSE(),1-'My Numbers'!$C$96,1)*IF(FALSE(),0,1))*'My Numbers'!$C$21*'My Numbers'!$C$22*'My Numbers'!$C$23)*MIN(1,'My Numbers'!$C$41*(1+'My Numbers'!$C$93)))*('My Numbers'!$C$39*IF(FALSE(),1-'My Numbers'!$C$97,1)*(1-'My Numbers'!$C$43)-'My Numbers'!$C$42)),((((('My Numbers'!$C$20*(1+'My Numbers'!$C$92)*IF(FALSE(),1-'My Numbers'!$C$96,1)*IF(FALSE(),0,1))*'My Numbers'!$C$21*'My Numbers'!$C$22*'My Numbers'!$C$23)-(IF(('My Numbers'!$C$33="Yes"),(('My Numbers'!$C$20*(1+'My Numbers'!$C$92)*IF(FALSE(),1-'My Numbers'!$C$96,1)*IF(FALSE(),0,1))*'My Numbers'!$C$21*'My Numbers'!$C$22*'My Numbers'!$C$23)*'My Numbers'!$C$36,0)))*(1+'My Numbers'!$C$24)+(IF(('My Numbers'!$C$33="Yes"),(('My Numbers'!$C$20*(1+'My Numbers'!$C$92)*IF(FALSE(),1-'My Numbers'!$C$96,1)*IF(FALSE(),0,1))*'My Numbers'!$C$21*'My Numbers'!$C$22*'My Numbers'!$C$23)*'My Numbers'!$C$36,0)))*(('My Numbers'!$C$26*IF(FALSE(),1-'My Numbers'!$C$97,1))*(1-'My Numbers'!$C$29)-'My Numbers'!$C$27)+IF(('My Numbers'!$C$30="Yes"),(('My Numbers'!$C$20*(1+'My Numbers'!$C$92)*IF(FALSE(),1-'My Numbers'!$C$96,1)*IF(FALSE(),0,1))*'My Numbers'!$C$21*'My Numbers'!$C$22*'My Numbers'!$C$23)*'My Numbers'!$C$32*'My Numbers'!$C$31*IF(FALSE(),1-'My Numbers'!$C$97,1)*(1-'My Numbers'!$C$29),0)+IF(('My Numbers'!$C$33="Yes"),(IF(('My Numbers'!$C$33="Yes"),(('My Numbers'!$C$20*(1+'My Numbers'!$C$92)*IF(FALSE(),1-'My Numbers'!$C$96,1)*IF(FALSE(),0,1))*'My Numbers'!$C$21*'My Numbers'!$C$22*'My Numbers'!$C$23)*'My Numbers'!$C$36,0))*'My Numbers'!$C$37*('My Numbers'!$C$34*IF(FALSE(),1-'My Numbers'!$C$97,1)*(1-'My Numbers'!$C$29)-'My Numbers'!$C$35*'My Numbers'!$C$27),0)))*(IF('This Month'!$C$27="",1,IF((IF(('My Numbers'!$C$38="Yes"),((('My Numbers'!$C$20*(1+'My Numbers'!$C$92)*IF(FALSE(),1-'My Numbers'!$C$96,1)*IF(FALSE(),0,1))*'My Numbers'!$C$21*'My Numbers'!$C$22*'My Numbers'!$C$23)*MIN(1,'My Numbers'!$C$41*(1+'My Numbers'!$C$93)))*'My Numbers'!$C$40,(((('My Numbers'!$C$20*(1+'My Numbers'!$C$92)*IF(FALSE(),1-'My Numbers'!$C$96,1)*IF(FALSE(),0,1))*'My Numbers'!$C$21*'My Numbers'!$C$22*'My Numbers'!$C$23)-(IF(('My Numbers'!$C$33="Yes"),(('My Numbers'!$C$20*(1+'My Numbers'!$C$92)*IF(FALSE(),1-'My Numbers'!$C$96,1)*IF(FALSE(),0,1))*'My Numbers'!$C$21*'My Numbers'!$C$22*'My Numbers'!$C$23)*'My Numbers'!$C$36,0)))*(1+'My Numbers'!$C$24)+(IF(('My Numbers'!$C$33="Yes"),(('My Numbers'!$C$20*(1+'My Numbers'!$C$92)*IF(FALSE(),1-'My Numbers'!$C$96,1)*IF(FALSE(),0,1))*'My Numbers'!$C$21*'My Numbers'!$C$22*'My Numbers'!$C$23)*'My Numbers'!$C$36,0)))+((IF(('My Numbers'!$C$33="Yes"),(('My Numbers'!$C$20*(1+'My Numbers'!$C$92)*IF(FALSE(),1-'My Numbers'!$C$96,1)*IF(FALSE(),0,1))*'My Numbers'!$C$21*'My Numbers'!$C$22*'My Numbers'!$C$23)*'My Numbers'!$C$36,0))*'My Numbers'!$C$35*'My Numbers'!$C$37)))>'This Month'!$C$27,'This Month'!$C$27/(IF(('My Numbers'!$C$38="Yes"),((('My Numbers'!$C$20*(1+'My Numbers'!$C$92)*IF(FALSE(),1-'My Numbers'!$C$96,1)*IF(FALSE(),0,1))*'My Numbers'!$C$21*'My Numbers'!$C$22*'My Numbers'!$C$23)*MIN(1,'My Numbers'!$C$41*(1+'My Numbers'!$C$93)))*'My Numbers'!$C$40,(((('My Numbers'!$C$20*(1+'My Numbers'!$C$92)*IF(FALSE(),1-'My Numbers'!$C$96,1)*IF(FALSE(),0,1))*'My Numbers'!$C$21*'My Numbers'!$C$22*'My Numbers'!$C$23)-(IF(('My Numbers'!$C$33="Yes"),(('My Numbers'!$C$20*(1+'My Numbers'!$C$92)*IF(FALSE(),1-'My Numbers'!$C$96,1)*IF(FALSE(),0,1))*'My Numbers'!$C$21*'My Numbers'!$C$22*'My Numbers'!$C$23)*'My Numbers'!$C$36,0)))*(1+'My Numbers'!$C$24)+(IF(('My Numbers'!$C$33="Yes"),(('My Numbers'!$C$20*(1+'My Numbers'!$C$92)*IF(FALSE(),1-'My Numbers'!$C$96,1)*IF(FALSE(),0,1))*'My Numbers'!$C$21*'My Numbers'!$C$22*'My Numbers'!$C$23)*'My Numbers'!$C$36,0)))+((IF(('My Numbers'!$C$33="Yes"),(('My Numbers'!$C$20*(1+'My Numbers'!$C$92)*IF(FALSE(),1-'My Numbers'!$C$96,1)*IF(FALSE(),0,1))*'My Numbers'!$C$21*'My Numbers'!$C$22*'My Numbers'!$C$23)*'My Numbers'!$C$36,0))*'My Numbers'!$C$35*'My Numbers'!$C$37))),1))),0) -> 8815.2174
B6: Content | C6: =IF(('My Numbers'!$C$48="Yes"),('My Numbers'!$C$52*(1+'My Numbers'!$C$94)*'My Numbers'!$C$54*IF(('My Numbers'!$C$99="Yes"),1-'My Numbers'!$C$97,1)*(1-'My Numbers'!$C$55)+IF(('My Numbers'!$C$100="Yes"),0,'My Numbers'!$C$56*(1+'My Numbers'!$C$94)*'My Numbers'!$C$57*IF(('My Numbers'!$C$99="Yes"),1-'My Numbers'!$C$97,1)*(1-'My Numbers'!$C$58)+'My Numbers'!$C$60*(1+'My Numbers'!$C$94)*'My Numbers'!$C$62*IF(('My Numbers'!$C$99="Yes"),1-'My Numbers'!$C$97,1)))*IFERROR(INDEX('This Month'!$F$58:$F$61,MATCH("Content",'This Month'!$C$58:$C$61,0)),1),0) -> 1560 | D6: =IF(('My Numbers'!$C$48="Yes"),('My Numbers'!$C$52*1*'My Numbers'!$C$54*IF(FALSE(),1-'My Numbers'!$C$97,1)*(1-'My Numbers'!$C$55)+IF(FALSE(),0,'My Numbers'!$C$56*1*'My Numbers'!$C$57*IF(FALSE(),1-'My Numbers'!$C$97,1)*(1-'My Numbers'!$C$58)+'My Numbers'!$C$60*1*'My Numbers'!$C$62*IF(FALSE(),1-'My Numbers'!$C$97,1)))*IFERROR(INDEX('This Month'!$F$58:$F$61,MATCH("Content",'This Month'!$C$58:$C$61,0)),1),0) -> 2600 | E6: =IF(('My Numbers'!$C$48="Yes"),('My Numbers'!$C$52*(1+'My Numbers'!$C$92)*'My Numbers'!$C$54*IF(FALSE(),1-'My Numbers'!$C$97,1)*(1-'My Numbers'!$C$55)+IF(FALSE(),0,'My Numbers'!$C$56*(1+'My Numbers'!$C$92)*'My Numbers'!$C$57*IF(FALSE(),1-'My Numbers'!$C$97,1)*(1-'My Numbers'!$C$58)+'My Numbers'!$C$60*(1+'My Numbers'!$C$92)*'My Numbers'!$C$62*IF(FALSE(),1-'My Numbers'!$C$97,1)))*IFERROR(INDEX('This Month'!$F$58:$F$61,MATCH("Content",'This Month'!$C$58:$C$61,0)),1),0) -> 3380
B7: Calls | C7: =IF(('My Numbers'!$C$67="Yes"),IF(('My Numbers'!$C$100="Yes"),0,'My Numbers'!$C$69*(1+'My Numbers'!$C$94)*(1-'My Numbers'!$C$70*IF(('My Numbers'!$C$71="Yes"),0,1))*'My Numbers'!$C$72*IF(('My Numbers'!$C$99="Yes"),1-'My Numbers'!$C$97,1)*(1-'My Numbers'!$C$73))*IFERROR(INDEX('This Month'!$F$58:$F$61,MATCH("Calls",'This Month'!$C$58:$C$61,0)),1),0) -> 864 | D7: =IF(('My Numbers'!$C$67="Yes"),IF(FALSE(),0,'My Numbers'!$C$69*1*(1-'My Numbers'!$C$70*IF(('My Numbers'!$C$71="Yes"),0,1))*'My Numbers'!$C$72*IF(FALSE(),1-'My Numbers'!$C$97,1)*(1-'My Numbers'!$C$73))*IFERROR(INDEX('This Month'!$F$58:$F$61,MATCH("Calls",'This Month'!$C$58:$C$61,0)),1),0) -> 1440 | E7: =IF(('My Numbers'!$C$67="Yes"),IF(FALSE(),0,'My Numbers'!$C$69*(1+'My Numbers'!$C$92)*(1-'My Numbers'!$C$70*IF(('My Numbers'!$C$71="Yes"),0,1))*'My Numbers'!$C$72*IF(FALSE(),1-'My Numbers'!$C$97,1)*(1-'My Numbers'!$C$73))*IFERROR(INDEX('This Month'!$F$58:$F$61,MATCH("Calls",'This Month'!$C$58:$C$61,0)),1),0) -> 1872
B8: Regulars | C8: =IF(('My Numbers'!$C$78="Yes"),('My Numbers'!$C$80*(1+'My Numbers'!$C$94)*'My Numbers'!$C$81*IF(('My Numbers'!$C$99="Yes"),1-'My Numbers'!$C$97,1)*(1-'My Numbers'!$C$84)*(1-'My Numbers'!$C$82)+IF(('My Numbers'!$C$100="Yes"),0,'My Numbers'!$C$85*(1+'My Numbers'!$C$94)*MIN(1,'My Numbers'!$C$86*(1+'My Numbers'!$C$95))*'My Numbers'!$C$87*IF(('My Numbers'!$C$99="Yes"),1-'My Numbers'!$C$97,1)*(1-'My Numbers'!$C$84)*(1-'My Numbers'!$C$82)))*IFERROR(INDEX('This Month'!$F$58:$F$61,MATCH("Regulars",'This Month'!$C$58:$C$61,0)),1),0) -> 1080 | D8: =IF(('My Numbers'!$C$78="Yes"),('My Numbers'!$C$80*1*'My Numbers'!$C$81*IF(FALSE(),1-'My Numbers'!$C$97,1)*(1-'My Numbers'!$C$84)*(1-'My Numbers'!$C$82)+IF(FALSE(),0,'My Numbers'!$C$85*1*MIN(1,'My Numbers'!$C$86*1)*'My Numbers'!$C$87*IF(FALSE(),1-'My Numbers'!$C$97,1)*(1-'My Numbers'!$C$84)*(1-'My Numbers'!$C$82)))*IFERROR(INDEX('This Month'!$F$58:$F$61,MATCH("Regulars",'This Month'!$C$58:$C$61,0)),1),0) -> 1800 | E8: =IF(('My Numbers'!$C$78="Yes"),('My Numbers'!$C$80*(1+'My Numbers'!$C$92)*'My Numbers'!$C$81*IF(FALSE(),1-'My Numbers'!$C$97,1)*(1-'My Numbers'!$C$84)*(1-'My Numbers'!$C$82)+IF(FALSE(),0,'My Numbers'!$C$85*(1+'My Numbers'!$C$92)*MIN(1,'My Numbers'!$C$86*(1+'My Numbers'!$C$93))*'My Numbers'!$C$87*IF(FALSE(),1-'My Numbers'!$C$97,1)*(1-'My Numbers'!$C$84)*(1-'My Numbers'!$C$82)))*IFERROR(INDEX('This Month'!$F$58:$F$61,MATCH("Regulars",'This Month'!$C$58:$C$61,0)),1),0) -> 2340
B9: Gross profit | C9: =SUM(C5:C8) -> 9708.15 | D9: =SUM(D5:D8) -> 14655.217 | E9: =SUM(E5:E8) -> 16407.217
B10: Fixed costs and finding clients | C10: =-'My Numbers'!$C$8-'My Numbers'!$C$13 -> -1500 | D10: =-'My Numbers'!$C$8-'My Numbers'!$C$13 -> -1500 | E10: =-'My Numbers'!$C$8-'My Numbers'!$C$13 -> -1500
B11: Profit | C11: =C9+C10 -> 8208.15 | D11: =D9+D10 -> 13155.217 | E11: =E9+E10 -> 14907.217
B12: Gap to your goal (negative = short) | C12: =C11-'My Numbers'!$C$9 -> -1791.85 | D12: =D11-'My Numbers'!$C$9 -> 3155.2174 | E12: =E11-'My Numbers'!$C$9 -> 4907.2174
B13: Runway: months your cash covers the gap | C13: =IF('My Numbers'!$C$11="","not yet",IF(C12>=0,"not needed",'My Numbers'!$C$11/(-C12))) -> 5.0227419 | D13: =IF('My Numbers'!$C$11="","not yet",IF(D12>=0,"not needed",'My Numbers'!$C$11/(-D12))) -> not needed | E13: =IF('My Numbers'!$C$11="","not yet",IF(E12>=0,"not needed",'My Numbers'!$C$11/(-E12))) -> not needed
B15: Disaster switches live on My Numbers: the source stops, a price war, a month off sick. Dream adds nothing on top of its multipliers; add your own upside in the pink cells.

Sheet Plan
A1: Plan
A2: What your goal needs, what your offer is worth per hour of you, and what a client is worth over time against what one costs to find.
A4: What the goal needs (in person)
B5: Gross profit needed = goal + fixed costs + finding clients | C5: ='My Numbers'!$C$9+'My Numbers'!$C$8+'My Numbers'!$C$13 -> 11500
B6: Gross profit one contact brings (before any cap) | C6: ='This Month'!$C$37 -> 172.3375
B7: Contacts a month the goal needs | C7: =IF(OR(C6="",C6<=0),"not yet",ROUNDUP(C5/C6,0)) -> 67
B8: You have | C8: ='My Numbers'!$C$20 -> 60
B9: Sessions that would mean | C9: =IF(C7="not yet","not yet",C7*'This Month'!$C$38) -> 23.5773
B10: Within your capacity? | C10: =IF(C9="not yet","not yet",IF('This Month'!$C$27="","No cap set",IF(C9<='This Month'!$C$27,"Yes","No: at these prices the goal needs more than you can deliver. Raise price or add an offer before chasing volume."))) -> No: at these prices the goal needs more than you can deliver. Raise price or add an offer before chasing volume.
A12: Your offer, per hour of you
B13: Gross profit per session = price × (1 − cut) − delivery | C13: ='This Month'!$C$30 -> 375
B14: Per all-in hour = (price − delivery) ÷ all-in hours | C14: =IF('My Numbers'!$C$28>0,('My Numbers'!$C$26-'My Numbers'!$C$27)/'My Numbers'!$C$28,"not yet") -> 100
B15: Program: gross profit per client | C15: ='My Numbers'!$C$39*(1-'My Numbers'!$C$43)-'My Numbers'!$C$42 -> 2450
B16: Program: clients a month for the goal, and hours | C16: =IF(C15>0,'My Numbers'!$C$9/C15,"not yet") -> 4.0816327 | D16: =IF(C15>0,TEXT('My Numbers'!$C$9/C15*'My Numbers'!$C$44,"0.0")&" hours a month","") -> 57.1 hours a month
A18: The value stack: what a client gets, in dollars, next to the price
B19: Piece | C19: Worth to them | D19: Leave a piece empty if it does not apply
B20: The core result: what the time itself is worth to them | C20: 800
B21: Preparation done for them before they arrive | C21: 200
B22: Aftercare and follow-up | C22: 150
B23: Priority access or a guaranteed date | C23: 300
B24: Something only you do | C24: 400
B25: A bonus that costs you little and means a lot | C25: 100
B26: The stack adds up to | C26: =SUM(C20:C25) -> 1950
B27: Stack ÷ price (3x or more makes the price feel small) | C27: =IF('My Numbers'!$C$26>0,C26/'My Numbers'!$C$26,"") -> 3.9
B28: Price the stack supports at 3x | C28: =C26/3 -> 650
B29: Value equation and value stack after Alex Hormozi ($100M Offers). SLAM is independent; no book text is reproduced.
A31: What a client is worth, against what one costs to find
