Workbook

Sheet Start here
A1: Marketing Scoreboard
A2: What gets measured gets managed. Three logs, one scoreboard, nothing hidden: every number is a formula you can click on.
A4: The tabs
A5: Posts: one row a post. Type the date, channel, format, topic, hook and ask when it goes out. Come back three days later and type the platform's numbers (reach, likes, comments, shares, saves, clicks, DMs, new followers, leads). Rows waiting for results turn yellow.
A6: People: one row a person. Stage, how you met them, and three dates that drive everything: became a lead on, call booked on, became a client on. The grey columns on the right work out their last touch, next touch and status.
A7: Touches: one row each time you and a person are in contact. Pick the person, the kind, the lane, who started it and what happened.
A8: Scoreboard: this week against the targets with pace; the period's numbers against the period before; the funnel; by channel, by ask, by format, by lane; conversion; who to contact today.
A9: Weekly: the last twelve weeks, one row a week, and the posting streak. Three charts.
A10: Lists: the dropdowns, the weekly targets, and each stage's rhythm (days between touches) and how to reach out.
A12: The rules
A13: Blank is not zero. A result you have not checked stays blank; the Scoreboard says blank, never 0%. A typed 0 is a real zero.
A14: Cream cells with blue text are yours to change (targets, rhythms, the period). Grey cells are formulas; leave them alone.
... A24: Rhythm: days between touches for a stage. A person's own number or a "contact them on" date wins over it.

Sheet Scoreboard
A1: Marketing Scoreboard
A2: What gets measured gets managed. Every number here is a formula over the Posts, People and Touches tabs. Blank means not entered, never zero.
A4: Period from | B4: =TODAY()-29 -> 46262 | C4: Type dates over these two cells to read any period. The columns to the right compare it with the period of the same length just before.
A5: Period to | B5: =TODAY() -> 46291
A6: The period before, from | B6: =B4-(B5-B4+1) -> 46232 | C6: to | D6: =B4-1 -> 46261
A8: This week against the targets
A9: Week starting | B9: =TODAY()-WEEKDAY(TODAY(),2)+1 -> 46286 | C9: to | D9: =B9+6 -> 46292 | E9: Share of the week gone | F9: =(TODAY()-B9+1)/7 -> 0.85714286
B10: Target | C10: So far | D10: Should be by now | E10: Still to do | F10: Status
A11: Posts | B11: =Lists!$E$5 -> 5 | C11: =COUNTIFS(Posts!$A$2:$A$251,">="&$B$9,Posts!$A$2:$A$251,"<="&$D$9) -> 2 | D11: =ROUND(B11*$F$9,1) -> 4.3 | E11: =MAX(0,B11-C11) -> 3 | F11: =IF(C11>=B11,"Hit",IF(C11>=D11,"On pace",IF(C11>=D11*0.6,"A little behind","Behind"))) -> Behind
A12: Reach-outs (touches I started) | B12: =Lists!$E$6 -> 25 | C12: =COUNTIFS(Touches!$A$2:$A$501,">="&$B$9,Touches!$A$2:$A$501,"<="&$D$9,Touches!$E$2:$E$501,"Me") -> 2 | D12: =ROUND(B12*$F$9,1) -> 21.4 | E12: =MAX(0,B12-C12) -> 23 | F12: =IF(C12>=B12,"Hit",IF(C12>=D12,"On pace",IF(C12>=D12*0.6,"A little behind","Behind"))) -> Behind
A13: Conversations (they replied or wrote first) | B13: =Lists!$E$7 -> 10 | C13: =COUNTIFS(Touches!$A$2:$A$501,">="&$B$9,Touches!$A$2:$A$501,"<="&$D$9,Touches!$E$2:$E$501,"Them")+COUNTIFS(Touches!$A$2:$A$501,">="&$B$9,Touches!$A$2:$A$501,"<="&$D$9,Touches!$E$2:$E$501,"Me",Touches!$F$2:$F$501,"They replied") -> 0 | D13: =ROUND(B13*$F$9,1) -> 8.6 | E13: =MAX(0,B13-C13) -> 10 | F13: =IF(C13>=B13,"Hit",IF(C13>=D13,"On pace",IF(C13>=D13*0.6,"A little behind","Behind"))) -> Behind
A14: Leads (became a lead on) | B14: =Lists!$E$8 -> 3 | C14: =COUNTIFS(People!$J$2:$J$151,">="&$B$9,People!$J$2:$J$151,"<="&$D$9) -> 0 | D14: =ROUND(B14*$F$9,1) -> 2.6 | E14: =MAX(0,B14-C14) -> 3 | F14: =IF(C14>=B14,"Hit",IF(C14>=D14,"On pace",IF(C14>=D14*0.6,"A little behind","Behind"))) -> Behind
A15: Calls booked (call booked on) | B15: =Lists!$E$9 -> 2 | C15: =COUNTIFS(People!$K$2:$K$151,">="&$B$9,People!$K$2:$K$151,"<="&$D$9) -> 1 | D15: =ROUND(B15*$F$9,1) -> 1.7 | E15: =MAX(0,B15-C15) -> 1 | F15: =IF(C15>=B15,"Hit",IF(C15>=D15,"On pace",IF(C15>=D15*0.6,"A little behind","Behind"))) -> Behind
A17: The numbers for the period, against the period before
B18: This period | C18: Before | D18: Change | E18: Change % | F18: What it is
A19: Posts | B19: =COUNTIFS(Posts!$A$2:$A$251,">="&$B$4,Posts!$A$2:$A$251,"<="&$B$5) -> 8 | C19: =COUNTIFS(Posts!$A$2:$A$251,">="&$B$6,Posts!$A$2:$A$251,"<="&$D$6) -> 0 | D19: =IF(OR(B19="",C19=""),"",B19-C19) -> 8 | E19: =IF(OR(B19="",C19="",C19=0),"",(B19-C19)/ABS(C19)) | F19: Rows on Posts with a date in the period.
A20: Posts with results typed | B20: =COUNTIFS(Posts!$I$2:$I$251,"<>",Posts!$A$2:$A$251,">="&$B$4,Posts!$A$2:$A$251,"<="&$B$5) -> 6 | C20: =COUNTIFS(Posts!$I$2:$I$251,"<>",Posts!$A$2:$A$251,">="&$B$6,Posts!$A$2:$A$251,"<="&$D$6) -> 0 | D20: =IF(OR(B20="",C20=""),"",B20-C20) -> 6 | E20: =IF(OR(B20="",C20="",C20=0),"",(B20-C20)/ABS(C20)) | F20: Of those, how many have Reach typed.
A21: Reach | B21: =IF(COUNTIFS(Posts!$I$2:$I$251,"<>",Posts!$A$2:$A$251,">="&$B$4,Posts!$A$2:$A$251,"<="&$B$5)=0,"",SUMIFS(Posts!$I$2:$I$251,Posts!$A$2:$A$251,">="&$B$4,Posts!$A$2:$A$251,"<="&$B$5)) -> 10070 | C21: =IF(COUNTIFS(Posts!$I$2:$I$251,"<>",Posts!$A$2:$A$251,">="&$B$6,Posts!$A$2:$A$251,"<="&$D$6)=0,"",SUMIFS(Posts!$I$2:$I$251,Posts!$A$2:$A$251,">="&$B$6,Posts!$A$2:$A$251,"<="&$D$6)) | D21: =IF(OR(B21="",C21=""),"",B21-C21) | E21: =IF(OR(B21="",C21="",C21=0),"",(B21-C21)/ABS(C21)) | F21: Reach added up. Blank until a post in the period has it.
A22: Engagements | B22: =IF(COUNTIFS(Posts!$T$2:$T$251,"<>",Posts!$A$2:$A$251,">="&$B$4,Posts!$A$2:$A$251,"<="&$B$5)=0,"",SUMIFS(Posts!$T$2:$T$251,Posts!$A$2:$A$251,">="&$B$4,Posts!$A$2:$A$251,"<="&$B$5)) -> 736 | C22: =IF(COUNTIFS(Posts!$T$2:$T$251,"<>",Posts!$A$2:$A$251,">="&$B$6,Posts!$A$2:$A$251,"<="&$D$6)=0,"",SUMIFS(Posts!$T$2:$T$251,Posts!$A$2:$A$251,">="&$B$6,Posts!$A$2:$A$251,"<="&$D$6)) | D22: =IF(OR(B22="",C22=""),"",B22-C22) | E22: =IF(OR(B22="",C22="",C22=0),"",(B22-C22)/ABS(C22)) | F22: Likes + comments + shares + saves.
A23: Engagement rate | B23: =IF(OR(B22="",B21="",B21=0),"",B22/B21) -> 0.073088381 | C23: =IF(OR(C22="",C21="",C21=0),"",C22/C21) | D23: =IF(OR(B23="",C23=""),"",B23-C23) | E23: =IF(OR(B23="",C23="",C23=0),"",(B23-C23)/ABS(C23)) | F23: Engagements over reach. Above 2% is fine, above 5% is good.
A24: Saves | B24: =IF(COUNTIFS(Posts!$M$2:$M$251,"<>",Posts!$A$2:$A$251,">="&$B$4,Posts!$A$2:$A$251,"<="&$B$5)=0,"",SUMIFS(Posts!$M$2:$M$251,Posts!$A$2:$A$251,">="&$B$4,Posts!$A$2:$A$251,"<="&$B$5)) -> 111 | C24: =IF(COUNTIFS(Posts!$M$2:$M$251,"<>",Posts!$A$2:$A$251,">="&$B$6,Posts!$A$2:$A$251,"<="&$D$6)=0,"",SUMIFS(Posts!$M$2:$M$251,Posts!$A$2:$A$251,">="&$B$6,Posts!$A$2:$A$251,"<="&$D$6)) | D24: =IF(OR(B24="",C24=""),"",B24-C24) | E24: =IF(OR(B24="",C24="",C24=0),"",(B24-C24)/ABS(C24)) | F24: Saves are worth more than likes.
A25: New followers | B25: =IF(COUNTIFS(Posts!$P$2:$P$251,"<>",Posts!$A$2:$A$251,">="&$B$4,Posts!$A$2:$A$251,"<="&$B$5)=0,"",SUMIFS(Posts!$P$2:$P$251,Posts!$A$2:$A$251,">="&$B$4,Posts!$A$2:$A$251,"<="&$B$5)) -> 75 | C25: =IF(COUNTIFS(Posts!$P$2:$P$251,"<>",Posts!$A$2:$A$251,">="&$B$6,Posts!$A$2:$A$251,"<="&$D$6)=0,"",SUMIFS(Posts!$P$2:$P$251,Posts!$A$2:$A$251,">="&$B$6,Posts!$A$2:$A$251,"<="&$D$6)) | D25: =IF(OR(B25="",C25=""),"",B25-C25) | E25: =IF(OR(B25="",C25="",C25=0),"",(B25-C25)/ABS(C25)) | F25: From what you typed on each post.
A26: Leads credited to posts | B26: =IF(COUNTIFS(Posts!$Q$2:$Q$251,"<>",Posts!$A$2:$A$251,">="&$B$4,Posts!$A$2:$A$251,"<="&$B$5)=0,"",SUMIFS(Posts!$Q$2:$Q$251,Posts!$A$2:$A$251,">="&$B$4,Posts!$A$2:$A$251,"<="&$B$5)) -> 6 | C26: =IF(COUNTIFS(Posts!$Q$2:$Q$251,"<>",Posts!$A$2:$A$251,">="&$B$6,Posts!$A$2:$A$251,"<="&$D$6)=0,"",SUMIFS(Posts!$Q$2:$Q$251,Posts!$A$2:$A$251,">="&$B$6,Posts!$A$2:$A$251,"<="&$D$6)) | D26: =IF(OR(B26="",C26=""),"",B26-C26) | E26: =IF(OR(B26="",C26="",C26=0),"",(B26-C26)/ABS(C26)) | F26: The Leads column on Posts.
A27: Content hours | B27: =IF(COUNTIFS(Posts!$H$2:$H$251,"<>",Posts!$A$2:$A$251,">="&$B$4,Posts!$A$2:$A$251,"<="&$B$5)=0,"",SUMIFS(Posts!$H$2:$H$251,Posts!$A$2:$A$251,">="&$B$4,Posts!$A$2:$A$251,"<="&$B$5)/60) -> 9 | C27: =IF(COUNTIFS(Posts!$H$2:$H$251,"<>",Posts!$A$2:$A$251,">="&$B$6,Posts!$A$2:$A$251,"<="&$D$6)=0,"",SUMIFS(Posts!$H$2:$H$251,Posts!$A$2:$A$251,">="&$B$6,Posts!$A$2:$A$251,"<="&$D$6)/60) | D27: =IF(OR(B27="",C27=""),"",B27-C27) | E27: =IF(OR(B27="",C27="",C27=0),"",(B27-C27)/ABS(C27)) | F27: Minutes to make, added up, over 60.
A28: Reach-outs | B28: =COUNTIFS(Touches!$A$2:$A$501,">="&$B$4,Touches!$A$2:$A$501,"<="&$B$5,Touches!$E$2:$E$501,"Me") -> 7 | C28: =COUNTIFS(Touches!$A$2:$A$501,">="&$B$6,Touches!$A$2:$A$501,"<="&$D$6,Touches!$E$2:$E$501,"Me") -> 0 | D28: =IF(OR(B28="",C28=""),"",B28-C28) -> 7 | E28: =IF(OR(B28="",C28="",C28=0),"",(B28-C28)/ABS(C28)) | F28: Touches you started.
A29: Conversations | B29: =COUNTIFS(Touches!$A$2:$A$501,">="&$B$4,Touches!$A$2:$A$501,"<="&$B$5,Touches!$E$2:$E$501,"Them")+COUNTIFS(Touches!$A$2:$A$501,">="&$B$4,Touches!$A$2:$A$501,"<="&$B$5,Touches!$E$2:$E$501,"Me",Touches!$F$2:$F$501,"They replied") -> 4 | C29: =COUNTIFS(Touches!$A$2:$A$501,">="&$B$6,Touches!$A$2:$A$501,"<="&$D$6,Touches!$E$2:$E$501,"Them")+COUNTIFS(Touches!$A$2:$A$501,">="&$B$6,Touches!$A$2:$A$501,"<="&$D$6,Touches!$E$2:$E$501,"Me",Touches!$F$2:$F$501,"They replied") -> 0 | D29: =IF(OR(B29="",C29=""),"",B29-C29) -> 4 | E29: =IF(OR(B29="",C29="",C29=0),"",(B29-C29)/ABS(C29)) | F29: Touches they started, plus yours marked "They replied".
A30: Reply rate | B30: =IF(OR(B29="",B28="",B28=0),"",B29/B28) -> 0.57142857 | C30: =IF(OR(C29="",C28="",C28=0),"",C29/C28) | D30: =IF(OR(B30="",C30=""),"",B30-C30) | E30: =IF(OR(B30="",C30="",C30=0),"",(B30-C30)/ABS(C30)) | F30: Conversations over reach-outs. Above 30% warm, above 10% cold.
A31: Leads | B31: =COUNTIFS(People!$J$2:$J$151,">="&$B$4,People!$J$2:$J$151,"<="&$B$5) -> 2 | C31: =COUNTIFS(People!$J$2:$J$151,">="&$B$6,People!$J$2:$J$151,"<="&$D$6) -> 1 | D31: =IF(OR(B31="",C31=""),"",B31-C31) -> 1 | E31: =IF(OR(B31="",C31="",C31=0),"",(B31-C31)/ABS(C31)) -> 1 | F31: People whose "Became a lead on" is in the period.
A32: Calls booked | B32: =COUNTIFS(People!$K$2:$K$151,">="&$B$4,People!$K$2:$K$151,"<="&$B$5) -> 1 | C32: =COUNTIFS(People!$K$2:$K$151,">="&$B$6,People!$K$2:$K$151,"<="&$D$6) -> 1 | D32: =IF(OR(B32="",C32=""),"",B32-C32) -> 0 | E32: =IF(OR(B32="",C32="",C32=0),"",(B32-C32)/ABS(C32)) -> 0 | F32: People whose "Call booked on" is in the period.
A33: Clients won | B33: =COUNTIFS(People!$L$2:$L$151,">="&$B$4,People!$L$2:$L$151,"<="&$B$5) -> 1 | C33: =COUNTIFS(People!$L$2:$L$151,">="&$B$6,People!$L$2:$L$151,"<="&$D$6) -> 0 | D33: =IF(OR(B33="",C33=""),"",B33-C33) -> 1 | E33: =IF(OR(B33="",C33="",C33=0),"",(B33-C33)/ABS(C33)) | F33: People whose "Became a client on" is in the period.
A34: Revenue agreed | B34: =IF(COUNTIFS(People!$L$2:$L$151,">="&$B$4,People!$L$2:$L$151,"<="&$B$5)=0,"",SUMIFS(People!$M$2:$M$151,People!$L$2:$L$151,">="&$B$4,People!$L$2:$L$151,"<="&$B$5)) -> 2500 | C34: =IF(COUNTIFS(People!$L$2:$L$151,">="&$B$6,People!$L$2:$L$151,"<="&$D$6)=0,"",SUMIFS(People!$M$2:$M$151,People!$L$2:$L$151,">="&$B$6,People!$L$2:$L$151,"<="&$D$6)) | D34: =IF(OR(B34="",C34=""),"",B34-C34) | E34: =IF(OR(B34="",C34="",C34=0),"",(B34-C34)/ABS(C34)) | F34: What those clients paid.
A35: Hours a lead | B35: =IF(OR(B27="",B31=0),"",B27/B31) -> 4.5 | C35: =IF(OR(C27="",C31=0),"",C27/C31) | D35: =IF(OR(B35="",C35=""),"",B35-C35) | E35: =IF(OR(B35="",C35="",C35=0),"",(B35-C35)/ABS(C35)) | F35: Content hours over leads. Lower is better.
A37: The funnel, each step as a share of the one before
B38: This period | C38: Share of the step before
A39: Reached | B39: =B21 -> 10070
A40: Engaged | B40: =B22 -> 736 | C40: =IF(OR(B40="",B39="",B39=0),"",B40/B39) -> 0.073088381
A41: Followed | B41: =B25 -> 75 | C41: =IF(OR(B41="",B40="",B40=0),"",B41/B40) -> 0.10190217
A42: Talked to me | B42: =B29 -> 4 | C42: =IF(OR(B42="",B41="",B41=0),"",B42/B41) -> 0.053333333
A43: Became a lead | B43: =B31 -> 2 | C43: =IF(OR(B43="",B42="",B42=0),"",B43/B42) -> 0.5
A44: Booked a call | B44: =B32 -> 1 | C44: =IF(OR(B44="",B43="",B43=0),"",B44/B43) -> 0.5
...

Sheet Lists
A1: Lists and targets
A2: The dropdowns read these. Change a target here and the Scoreboard follows. Add a channel or a format by typing it below the last one.
A4: Channels | B4: Formats | C4: Asks | D4: Targets | E4: Target | G4: Stage | H4: Days between touches | I4: How to reach out at this stage | J4: How we met (lanes) | K4: Touch kinds | L4: What happened | M4: Who started
A5: Instagram | B5: Short video | C5: No ask | D5: Posts a week | E5: 5 | G5: Stranger | H5: never | I5: Comment on something of theirs first. No pitch. | J5: Warm (they know me) | K5: Comment | L5: No reply yet | M5: Me
A6: TikTok | B6: Long video | C6: Follow | D6: Reach-outs a week | E6: 25 | G6: Follower | H6: 30 | I6: Reply to their content, or a DM about something they posted. | J6: Cold (they do not) | K6: DM | L6: They replied | M6: Them
A7: YouTube | B7: Carousel | C7: Comment a word | D7: Conversations a week | E7: 10 | G7: In conversation | H7: 7 | I7: A DM or a message that asks a question about them. | J7: From content | K7: Email | L7: Call booked
A8: LinkedIn | B8: Image | C8: DM me | D8: Leads a week | E8: 3 | G8: Lead | H8: 3 | I8: An email or a voice note. Offer the next step plainly. | J8: Paid | K8: Text | L8: They bought
A9: X | B9: Text post | C9: Click the link | D9: Calls booked a week | E9: 2 | G9: Call booked | H9: 1 | I9: Confirm the call the day before. Send what to bring. | J9: Referral | K9: Call | L9: Not now
A10: Threads | B10: Story | C10: Book a call | G10: Client | H10: 30 | I10: A check-in call or email. Ask what changed. | K10: Voice note
A11: Facebook | B11: Live | C11: Buy | G11: Advocate | H11: 90 | I11: Thank them. Ask who else should hear about this. | K11: Met in person
A12: Newsletter | B12: Email | C12: Share it | G12: Not now | H12: never | I12: Leave it. A kind note in six months if they said so. | K12: Gift or card
A13: Podcast | B13: Article
A14: Blog | B14: Episode
A15: Other

Sheet Posts
A1: Date | B1: Channel | C1: Format | D1: Topic | E1: Hook (the first line) | F1: Ask | G1: Link | H1: Minutes to make | I1: Reach | J1: Likes | K1: Comments | L1: Shares | M1: Saves | N1: Link clicks | O1: DMs it started | P1: New followers | Q1: Leads | R1: Results typed on | S1: Notes | T1: Engagements | U1: Engagement rate | V1: Week starting
A2: 46271 | B2: Instagram | C2: Carousel | D2: money habits | E2: The one number nobody checks | F2: Comment a word | H2: 60 | I2: 1840 | J2: 96 | K2: 14 | L2: 9 | M2: 31 | O2: 3 | P2: 12 | Q2: 1 | R2: 46274 | S2: EXAMPLE | T2: =IF(COUNT(J2:M2)=0,"",SUM(J2:M2)) -> 150 | U2: =IF(OR(T2="",I2="",I2=0),"",T2/I2) -> 0.081521739 | V2: =IF(A2="","",A2-WEEKDAY(A2,2)+1) -> 46265
A3: 46273 | B3: LinkedIn | C3: Text post | D3: client story | E3: What a client asked me this week | F3: DM me | H3: 25 | I3: 2210 | J3: 118 | K3: 22 | L3: 11 | M3: 19 | O3: 6 | P3: 15 | Q3: 2 | R3: 46276 | S3: EXAMPLE | T3: =IF(COUNT(J3:M3)=0,"",SUM(J3:M3)) -> 170 | U3: =IF(OR(T3="",I3="",I3=0),"",T3/I3) -> 0.076923077 | V3: =IF(A3="","",A3-WEEKDAY(A3,2)+1) -> 46272
A4: 46276 | B4: YouTube | C4: Long video | D4: how to | E4: The spreadsheet that runs my life | F4: Click the link | G4: https://example.com/video | H4: 240 | I4: 960 | J4: 41 | K4: 8 | L4: 3 | M4: 12 | N4: 38 | P4: 9 | Q4: 1 | R4: 46279 | S4: EXAMPLE | T4: =IF(COUNT(J4:M4)=0,"",SUM(J4:M4)) -> 64 | U4: =IF(OR(T4="",I4="",I4=0),"",T4/I4) -> 0.066666667 | V4: =IF(A4="","",A4-WEEKDAY(A4,2)+1) -> 46272
A5: 46279 | B5: Instagram | C5: Short video | D5: a mistake I made | E5: I did this wrong for ten years | F5: Follow | H5: 25 | I5: 3120 | J5: 155 | K5: 19 | L5: 24 | M5: 27 | O5: 2 | P5: 31 | Q5: 0 | R5: 46282 | S5: EXAMPLE | T5: =IF(COUNT(J5:M5)=0,"",SUM(J5:M5)) -> 225 | U5: =IF(OR(T5="",I5="",I5=0),"",T5/I5) -> 0.072115385 | V5: =IF(A5="","",A5-WEEKDAY(A5,2)+1) -> 46279
A6: 46282 | B6: Newsletter | C6: Email | D6: money habits | E6: Why your emergency fund is the wrong size | F6: Book a call | H6: 90 | I6: 410 | K6: 4 | N6: 22 | Q6: 2 | R6: 46285 | S6: EXAMPLE | T6: =IF(COUNT(J6:M6)=0,"",SUM(J6:M6)) -> 4 | U6: =IF(OR(T6="",I6="",I6=0),"",T6/I6) -> 0.0097560976 | V6: =IF(A6="","",A6-WEEKDAY(A6,2)+1) -> 46279
A7: 46285 | B7: LinkedIn | C7: Carousel | D7: behind the scenes | E7: Three minutes on the thing you keep putting off | F7: No ask | H7: 60 | I7: 1530 | J7: 84 | K7: 11 | L7: 6 | M7: 22 | O7: 1 | P7: 8 | Q7: 0 | R7: 46288 | S7: EXAMPLE | T7: =IF(COUNT(J7:M7)=0,"",SUM(J7:M7)) -> 123 | U7: =IF(OR(T7="",I7="",I7=0),"",T7/I7) -> 0.080392157 | V7: =IF(A7="","",A7-WEEKDAY(A7,2)+1) -> 46279
A8: 46289 | B8: Instagram | C8: Story | D8: behind the scenes | E8: Sunday planning, live | F8: DM me | H8: 15 | S8: EXAMPLE | T8: =IF(COUNT(J8:M8)=0,"",SUM(J8:M8)) | U8: =IF(OR(T8="",I8="",I8=0),"",T8/I8) | V8: =IF(A8="","",A8-WEEKDAY(A8,2)+1) -> 46286
A9: 46291 | B9: TikTok | C9: Short video | D9: how to | E9: Stop budgeting. Do this instead. | F9: Follow | H9: 25 | S9: EXAMPLE | T9: =IF(COUNT(J9:M9)=0,"",SUM(J9:M9)) | U9: =IF(OR(T9="",I9="",I9=0),"",T9/I9) | V9: =IF(A9="","",A9-WEEKDAY(A9,2)+1) -> 46286
T10: =IF(COUNT(J10:M10)=0,"",SUM(J10:M10)) | U10: =IF(OR(T10="",I10="",I10=0),"",T10/I10) | V10: =IF(A10="","",A10-WEEKDAY(A10,2)+1)
T11: =IF(COUNT(J11:M11)=0,"",SUM(J11:M11)) | U11: =IF(OR(T11="",I11="",I11=0),"",T11/I11) | V11: =IF(A11="","",A11-WEEKDAY(A11,2)+1)
T12: =IF(COUNT(J12:M12)=0,"",SUM(J12:M12)) | U12: =IF(OR(T12="",I12="",I12=0),"",T12/I12) | V12: =IF(A12="","",A12-WEEKDAY(A12,2)+1)
T13: =IF(COUNT(J13:M13)=0,"",SUM(J13:M13)) | U13: =IF(OR(T13="",I13="",I13=0),"",T13/I13) | V13: =IF(A13="","",A13-WEEKDAY(A13,2)+1)
T14: =IF(COUNT(J14:M14)=0,"",SUM(J14:M14)) | U14: =IF(OR(T14="",I14="",I14=0),"",T14/I14) | V14: =IF(A14="","",A14-WEEKDAY(A14,2)+1)
T15: =IF(COUNT(J15:M15)=0,"",SUM(J15:M15)) | U15: =IF(OR(T15="",I15="",I15=0),"",T15/I15) | V15: =IF(A15="","",A15-WEEKDAY(A15,2)+1)
T16: =IF(COUNT(J16:M16)=0,"",SUM(J16:M16)) | U16: =IF(OR(T16="",I16="",I16=0),"",T16/I16) | V16: =IF(A16="","",A16-WEEKDAY(A16,2)+1)
T17: =IF(COUNT(J17:M17)=0,"",SUM(J17:M17)) | U17: =IF(OR(T17="",I17="",I17=0),"",T17/I17) | V17: =IF(A17="","",A17-WEEKDAY(A17,2)+1)
T18: =IF(COUNT(J18:M18)=0,"",SUM(J18:M18)) | U18: =IF(OR(T18="",I18="",I18=0),"",T18/I18) | V18: =IF(A18="","",A18-WEEKDAY(A18,2)+1)
T19: =IF(COUNT(J19:M19)=0,"",SUM(J19:M19)) | U19: =IF(OR(T19="",I19="",I19=0),"",T19/I19) | V19: =IF(A19="","",A19-WEEKDAY(A19,2)+1)
T20: =IF(COUNT(J20:M20)=0,"",SUM(J20:M20)) | U20: =IF(OR(T20="",I20="",I20=0),"",T20/I20) | V20: =IF(A20="","",A20-WEEKDAY(A20,2)+1)
T21: =IF(COUNT(J21:M21)=0,"",SUM(J21:M21)) | U21: =IF(OR(T21="",I21="",I21=0),"",T21/I21) | V21: =IF(A21="","",A21-WEEKDAY(A21,2)+1)
... T251: =IF(COUNT(J251:M251)=0,"",SUM(J251:M251)) | U251: =IF(OR(T251="",I251="",I251=0),"",T251/I251) | V251: =IF(A251="","",A251-WEEKDAY(A251,2)+1)

Sheet People
A1: Name | B1: Company | C1: Role | D1: Email | E1: Phone | F1: Platform | G1: Handle or link | H1: How we met | I1: Stage | J1: Became a lead on | K1: Call booked on | L1: Became a client on | M1: Paid ($) | N1: Days between touches | O1: Contact them on | P1: Tags | Q1: Came from this post | R1: Notes | S1: Added on | T1: Last touch | U1: Rhythm (days) | V1: Next touch | W1: Status | X1: Days over | Y1: How to reach out | Z1: sort key
A2: Ada Okafor | B2: Northwind Studio | C2: Founder | D2: ada@example.com | F2: Instagram | G2: @ada.demo | H2: From content | I2: Lead | J2: 46285 | P2: small business | Q2: What a client asked me this week | R2: EXAMPLE | S2: 46277 | T2: =IF(A2="","",IF(COUNTIF(Touches!$B$2:$B$501,A2)=0,"",SUMPRODUCT(MAX((Touches!$B$2:$B$501=A2)*Touches!$A$2:$A$501)))) -> 46285 | U2: =IF(A2="","",IF(N2<>"",N2,IFERROR(INDEX(Lists!$H$5:$H$12,MATCH(I2,Lists!$G$5:$G$12,0)),""))) -> 3 | V2: =IF(A2="","",IF(O2<>"",O2,IF(OR(U2="",U2="never",U2=0),"",IF(T2="",TODAY(),T2+U2)))) -> 46288 | W2: =IF(A2="","",IF(V2="","no rhythm",IF(V2<TODAY(),"Overdue",IF(V2=TODAY(),"Today",IF(V2<=TODAY()+7,"Soon","Later"))))) -> Overdue | X2: =IF(OR(A2="",V2=""),"",TODAY()-V2) -> 3 | Y2: =IF(A2="","",IFERROR(INDEX(Lists!$I$5:$I$12,MATCH(I2,Lists!$G$5:$G$12,0)),"")) -> An email or a voice note. Offer the next step plainly. | Z2: =IF(AND(X2<>"",X2>=0),X2+ROW()/100000,"") -> 3.00002
A3: Ben Sato | B3: Bramble & Co | C3: Owner | D3: ben@example.com | F3: LinkedIn | H3: Referral | I3: Call booked | J3: 46281 | K3: 46287 | R3: EXAMPLE | S3: 46271 | T3: =IF(A3="","",IF(COUNTIF(Touches!$B$2:$B$501,A3)=0,"",SUMPRODUCT(MAX((Touches!$B$2:$B$501=A3)*Touches!$A$2:$A$501)))) -> 46287 | U3: =IF(A3="","",IF(N3<>"",N3,IFERROR(INDEX(Lists!$H$5:$H$12,MATCH(I3,Lists!$G$5:$G$12,0)),""))) -> 1 | V3: =IF(A3="","",IF(O3<>"",O3,IF(OR(U3="",U3="never",U3=0),"",IF(T3="",TODAY(),T3+U3)))) -> 46288 | W3: =IF(A3="","",IF(V3="","no rhythm",IF(V3<TODAY(),"Overdue",IF(V3=TODAY(),"Today",IF(V3<=TODAY()+7,"Soon","Later"))))) -> Overdue | X3: =IF(OR(A3="",V3=""),"",TODAY()-V3) -> 3 | Y3: =IF(A3="","",IFERROR(INDEX(Lists!$I$5:$I$12,MATCH(I3,Lists!$G$5:$G$12,0)),"")) -> Confirm the call the day before. Send what to bring. | Z3: =IF(AND(X3<>"",X3>=0),X3+ROW()/100000,"") -> 3.00003
A4: Cleo Marsh | B4: Halcyon Physio | D4: cleo@example.com | E4: 555-0100 | F4: Email | H4: Warm (they know me) | I4: Client | J4: 46251 | K4: 46258 | L4: 46270 | M4: 2500 | P4: parent | R4: EXAMPLE | S4: 46241 | T4: =IF(A4="","",IF(COUNTIF(Touches!$B$2:$B$501,A4)=0,"",SUMPRODUCT(MAX((Touches!$B$2:$B$501=A4)*Touches!$A$2:$A$501)))) -> 46270 | U4: =IF(A4="","",IF(N4<>"",N4,IFERROR(INDEX(Lists!$H$5:$H$12,MATCH(I4,Lists!$G$5:$G$12,0)),""))) -> 30 | V4: =IF(A4="","",IF(O4<>"",O4,IF(OR(U4="",U4="never",U4=0),"",IF(T4="",TODAY(),T4+U4)))) -> 46300 | W4: =IF(A4="","",IF(V4="","no rhythm",IF(V4<TODAY(),"Overdue",IF(V4=TODAY(),"Today",IF(V4<=TODAY()+7,"Soon","Later"))))) -> Later | X4: =IF(OR(A4="",V4=""),"",TODAY()-V4) -> -9 | Y4: =IF(A4="","",IFERROR(INDEX(Lists!$I$5:$I$12,MATCH(I4,Lists!$G$5:$G$12,0)),"")) -> A check-in call or email. Ask what changed. | Z4: =IF(AND(X4<>"",X4>=0),X4+ROW()/100000,"")
A5: Dev Patel | D5: dev@example.com | F5: Instagram | G5: @dev.demo | H5: From content | I5: In conversation | Q5: The one number nobody checks | R5: EXAMPLE | S5: 46279 | T5: =IF(A5="","",IF(COUNTIF(Touches!$B$2:$B$501,A5)=0,"",SUMPRODUCT(MAX((Touches!$B$2:$B$501=A5)*Touches!$A$2:$A$501)))) -> 46279 | U5: =IF(A5="","",IF(N5<>"",N5,IFERROR(INDEX(Lists!$H$5:$H$12,MATCH(I5,Lists!$G$5:$G$12,0)),""))) -> 7 | V5: =IF(A5="","",IF(O5<>"",O5,IF(OR(U5="",U5="never",U5=0),"",IF(T5="",TODAY(),T5+U5)))) -> 46286 | W5: =IF(A5="","",IF(V5="","no rhythm",IF(V5<TODAY(),"Overdue",IF(V5=TODAY(),"Today",IF(V5<=TODAY()+7,"Soon","Later"))))) -> Overdue | X5: =IF(OR(A5="",V5=""),"",TODAY()-V5) -> 5 | Y5: =IF(A5="","",IFERROR(INDEX(Lists!$I$5:$I$12,MATCH(I5,Lists!$G$5:$G$12,0)),"")) -> A DM or a message that asks a question about them. | Z5: =IF(AND(X5<>"",X5>=0),X5+ROW()/100000,"") -> 5.00005
A6: Esme Haddad | B6: Ferro Fitness | C6: Coach | D6: esme@example.com | F6: LinkedIn | H6: Cold (they do not) | I6: Follower | R6: EXAMPLE | S6: 46282 | T6: =IF(A6="","",IF(COUNTIF(Touches!$B$2:$B$501,A6)=0,"",SUMPRODUCT(MAX((Touches!$B$2:$B$501=A6)*Touches!$A$2:$A$501)))) -> 46289 | U6: =IF(A6="","",IF(N6<>"",N6,IFERROR(INDEX(Lists!$H$5:$H$12,MATCH(I6,Lists!$G$5:$G$12,0)),""))) -> 30 | V6: =IF(A6="","",IF(O6<>"",O6,IF(OR(U6="",U6="never",U6=0),"",IF(T6="",TODAY(),T6+U6)))) -> 46319 | W6: =IF(A6="","",IF(V6="","no rhythm",IF(V6<TODAY(),"Overdue",IF(V6=TODAY(),"Today",IF(V6<=TODAY()+7,"Soon","Later"))))) -> Later | X6: =IF(OR(A6="",V6=""),"",TODAY()-V6) -> -28 | Y6: =IF(A6="","",IFERROR(INDEX(Lists!$I$5:$I$12,MATCH(I6,Lists!$G$5:$G$12,0)),"")) -> Reply to their content, or a DM about something they posted. | Z6: =IF(AND(X6<>"",X6>=0),X6+ROW()/100000,"")
A7: Femi Lindqvist | B7: Oak Lane Dental | D7: femi@example.com | F7: Email | H7: Referral | I7: Advocate | J7: 46171 | K7: 46181 | L7: 46196 | M7: 4800 | R7: EXAMPLE | S7: 46161 | T7: =IF(A7="","",IF(COUNTIF(Touches!$B$2:$B$501,A7)=0,"",SUMPRODUCT(MAX((Touches!$B$2:$B$501=A7)*Touches!$A$2:$A$501)))) | U7: =IF(A7="","",IF(N7<>"",N7,IFERROR(INDEX(Lists!$H$5:$H$12,MATCH(I7,Lists!$G$5:$G$12,0)),""))) -> 90 | V7: =IF(A7="","",IF(O7<>"",O7,IF(OR(U7="",U7="never",U7=0),"",IF(T7="",TODAY(),T7+U7)))) -> 46291 | W7: =IF(A7="","",IF(V7="","no rhythm",IF(V7<TODAY(),"Overdue",IF(V7=TODAY(),"Today",IF(V7<=TODAY()+7,"Soon","Later"))))) -> Today | X7: =IF(OR(A7="",V7=""),"",TODAY()-V7) -> 0 | Y7: =IF(A7="","",IFERROR(INDEX(Lists!$I$5:$I$12,MATCH(I7,Lists!$G$5:$G$12,0)),"")) -> Thank them. Ask who else should hear about this. | Z7: =IF(AND(X7<>"",X7>=0),X7+ROW()/100000,"") -> 7e-05
T8: =IF(A8="","",IF(COUNTIF(Touches!$B$2:$B$501,A8)=0,"",SUMPRODUCT(MAX((Touches!$B$2:$B$501=A8)*Touches!$A$2:$A$501)))) | U8: =IF(A8="","",IF(N8<>"",N8,IFERROR(INDEX(Lists!$H$5:$H$12,MATCH(I8,Lists!$G$5:$G$12,0)),""))) | V8: =IF(A8="","",IF(O8<>"",O8,IF(OR(U8="",U8="never",U8=0),"",IF(T8="",TODAY(),T8+U8)))) | W8: =IF(A8="","",IF(V8="","no rhythm",IF(V8<TODAY(),"Overdue",IF(V8=TODAY(),"Today",IF(V8<=TODAY()+7,"Soon","Later"))))) | X8: =IF(OR(A8="",V8=""),"",TODAY()-V8) | Y8: =IF(A8="","",IFERROR(INDEX(Lists!$I$5:$I$12,MATCH(I8,Lists!$G$5:$G$12,0)),"")) | Z8: =IF(AND(X8<>"",X8>=0),X8+ROW()/100000,"")
T9: =IF(A9="","",IF(COUNTIF(Touches!$B$2:$B$501,A9)=0,"",SUMPRODUCT(MAX((Touches!$B$2:$B$501=A9)*Touches!$A$2:$A$501)))) | U9: =IF(A9="","",IF(N9<>"",N9,IFERROR(INDEX(Lists!$H$5:$H$12,MATCH(I9,Lists!$G$5:$G$12,0)),""))) | V9: =IF(A9="","",IF(O9<>"",O9,IF(OR(U9="",U9="never",U9=0),"",IF(T9="",TODAY(),T9+U9)))) | W9: =IF(A9="","",IF(V9="","no rhythm",IF(V9<TODAY(),"Overdue",IF(V9=TODAY(),"Today",IF(V9<=TODAY()+7,"Soon","Later"))))) | X9: =IF(OR(A9="",V9=""),"",TODAY()-V9) | Y9: =IF(A9="","",IFERROR(INDEX(Lists!$I$5:$I$12,MATCH(I9,Lists!$G$5:$G$12,0)),"")) | Z9: =IF(AND(X9<>"",X9>=0),X9+ROW()/100000,"")
T10: =IF(A10="","",IF(COUNTIF(Touches!$B$2:$B$501,A10)=0,"",SUMPRODUCT(MAX((Touches!$B$2:$B$501=A10)*Touches!$A$2:$A$501)))) | U10: =IF(A10="","",IF(N10<>"",N10,IFERROR(INDEX(Lists!$H$5:$H$12,MATCH(I10,Lists!$G$5:$G$12,0)),""))) | V10: =IF(A10="","",IF(O10<>"",O10,IF(OR(U10="",U10="never",U10=0),"",IF(T10="",TODAY(),T10+U10)))) | W10: =IF(A10="","",IF(V10="","no rhythm",IF(V10<TODAY(),"Overdue",IF(V10=TODAY(),"Today",IF(V10<=TODAY()+7,"Soon","Later"))))) | X10: =IF(OR(A10="",V10=""),"",TODAY()-V10) | Y10: =IF(A10="","",IFERROR(INDEX(Lists!$I$5:$I$12,MATCH(I10,Lists!$G$5:$G$12,0)),"")) | Z10: =IF(AND(X10<>"",X10>=0),X10+ROW()/100000,"")
T11: =IF(A11="","",IF(COUNTIF(Touches!$B$2:$B$501,A11)=0,"",SUMPRODUCT(MAX((Touches!$B$2:$B$501=A11)*Touches!$A$2:$A$501)))) | U11: =IF(A11="","",IF(N11<>"",N11,IFERROR(INDEX(Lists!$H$5:$H$12,MATCH(I11,Lists!$G$5:$G$12,0)),""))) | V11: =IF(A11="","",IF(O11<>"",O11,IF(OR(U11="",U11="never",U11=0),"",IF(T11="",TODAY(),T11+U11)))) | W11: =IF(A11="","",IF(V11="","no rhythm",IF(V11<TODAY(),"Overdue",IF(V11=TODAY(),"Today",IF(V11<=TODAY()+7,"Soon","Later"))))) | X11: =IF(OR(A11="",V11=""),"",TODAY()-V11) | Y11: =IF(A11="","",IFERROR(INDEX(Lists!$I$5:$I$12,MATCH(I11,Lists!$G$5:$G$12,0)),"")) | Z11: =IF(AND(X11<>"",X11>=0),X11+ROW()/100000,"")
T12: =IF(A12="","",IF(COUNTIF(Touches!$B$2:$B$501,A12)=0,"",SUMPRODUCT(MAX((Touches!$B$2:$B$501=A12)*Touches!$A$2:$A$501)))) | U12: =IF(A12="","",IF(N12<>"",N12,IFERROR(INDEX(Lists!$H$5:$H$12,MATCH(I12,Lists!$G$5:$G$12,0)),""))) | V12: =IF(A12="","",IF(O12<>"",O12,IF(OR(U12="",U12="never",U12=0),"",IF(T12="",TODAY(),T12+U12)))) | W12: =IF(A12="","",IF(V12="","no rhythm",IF(V12<TODAY(),"Overdue",IF(V12=TODAY(),"Today",IF(V12<=TODAY()+7,"Soon","Later"))))) | X12: =IF(OR(A12="",V12=""),"",TODAY()-V12) | Y12: =IF(A12="","",IFERROR(INDEX(Lists!$I$5:$I$12,MATCH(I12,Lists!$G$5:$G$12,0)),"")) | Z12: =IF(AND(X12<>"",X12>=0),X12+ROW()/100000,"")
T13: =IF(A13="","",IF(COUNTIF(Touches!$B$2:$B$501,A13)=0,"",SUMPRODUCT(MAX((Touches!$B$2:$B$501=A13)*Touches!$A$2:$A$501)))) | U13: =IF(A13="","",IF(N13<>"",N13,IFERROR(INDEX(Lists!$H$5:$H$12,MATCH(I13,Lists!$G$5:$G$12,0)),""))) | V13: =IF(A13="","",IF(O13<>"",O13,IF(OR(U13="",U13="never",U13=0),"",IF(T13="",TODAY(),T13+U13)))) | W13: =IF(A13="","",IF(V13="","no rhythm",IF(V13<TODAY(),"Overdue",IF(V13=TODAY(),"Today",IF(V13<=TODAY()+7,"Soon","Later"))))) | X13: =IF(OR(A13="",V13=""),"",TODAY()-V13) | Y13: =IF(A13="","",IFERROR(INDEX(Lists!$I$5:$I$12,MATCH(I13,Lists!$G$5:$G$12,0)),"")) | Z13: =IF(AND(X13<>"",X13>=0),X13+ROW()/100000,"")
T14: =IF(A14="","",IF(COUNTIF(Touches!$B$2:$B$501,A14)=0,"",SUMPRODUCT(MAX((Touches!$B$2:$B$501=A14)*Touches!$A$2:$A$501)))) | U14: =IF(A14="","",IF(N14<>"",N14,IFERROR(INDEX(Lists!$H$5:$H$12,MATCH(I14,Lists!$G$5:$G$12,0)),""))) | V14: =IF(A14="","",IF(O14<>"",O14,IF(OR(U14="",U14="never",U14=0),"",IF(T14="",TODAY(),T14+U14)))) | W14: =IF(A14="","",IF(V14="","no rhythm",IF(V14<TODAY(),"Overdue",IF(V14=TODAY(),"Today",IF(V14<=TODAY()+7,"Soon","Later"))))) | X14: =IF(OR(A14="",V14=""),"",TODAY()-V14) | Y14: =IF(A14="","",IFERROR(INDEX(Lists!$I$5:$I$12,MATCH(I14,Lists!$G$5:$G$12,0)),"")) | Z14: =IF(AND(X14<>"",X14>=0),X14+ROW()/100000,"")
T15: =IF(A15="","",IF(COUNTIF(Touches!$B$2:$B$501,A15)=0,"",SUMPRODUCT(MAX((Touches!$B$2:$B$501=A15)*Touches!$A$2:$A$501)))) | U15: =IF(A15="","",IF(N15<>"",N15,IFERROR(INDEX(Lists!$H$5:$H$12,MATCH(I15,Lists!$G$5:$G$12,0)),""))) | V15: =IF(A15="","",IF(O15<>"",O15,IF(OR(U15="",U15="never",U15=0),"",IF(T15="",TODAY(),T15+U15)))) | W15: =IF(A15="","",IF(V15="","no rhythm",IF(V15<TODAY(),"Overdue",IF(V15=TODAY(),"Today",IF(V15<=TODAY()+7,"Soon","Later"))))) | X15: =IF(OR(A15="",V15=""),"",TODAY()-V15) | Y15: =IF(A15="","",IFERROR(INDEX(Lists!$I$5:$I$12,MATCH(I15,Lists!$G$5:$G$12,0)),"")) | Z15: =IF(AND(X15<>"",X15>=0),X15+ROW()/100000,"")
T16: =IF(A16="","",IF(COUNTIF(Touches!$B$2:$B$501,A16)=0,"",SUMPRODUCT(MAX((Touches!$B$2:$B$501=A16)*Touches!$A$2:$A$501)))) | U16: =IF(A16="","",IF(N16<>"",N16,IFERROR(INDEX(Lists!$H$5:$H$12,MATCH(I16,Lists!$G$5:$G$12,0)),""))) | V16: =IF(A16="","",IF(O16<>"",O16,IF(OR(U16="",U16="never",U16=0),"",IF(T16="",TODAY(),T16+U16)))) | W16: =IF(A16="","",IF(V16="","no rhythm",IF(V16<TODAY(),"Overdue",IF(V16=TODAY(),"Today",IF(V16<=TODAY()+7,"Soon","Later"))))) | X16: =IF(OR(A16="",V16=""),"",TODAY()-V16) | Y16: =IF(A16="","",IFERROR(INDEX(Lists!$I$5:$I$12,MATCH(I16,Lists!$G$5:$G$12,0)),"")) | Z16: =IF(AND(X16<>"",X16>=0),X16+ROW()/100000,"")
T17: =IF(A17="","",IF(COUNTIF(Touches!$B$2:$B$501,A17)=0,"",SUMPRODUCT(MAX((Touches!$B$2:$B$501=A17)*Touches!$A$2:$A$501)))) | U17: =IF(A17="","",IF(N17<>"",N17,IFERROR(INDEX(Lists!$H$5:$H$12,MATCH(I17,Lists!$G$5:$G$12,0)),""))) | V17: =IF(A17="","",IF(O17<>"",O17,IF(OR(U17="",U17="never",U17=0),"",IF(T17="",TODAY(),T17+U17)))) | W17: =IF(A17="","",IF(V17="","no rhythm",IF(V17<TODAY(),"Overdue",IF(V17=TODAY(),"Today",IF(V17<=TODAY()+7,"Soon","Later"))))) | X17: =IF(OR(A17="",V17=""),"",TODAY()-V17) | Y17: =IF(A17="","",IFERROR(INDEX(Lists!$I$5:$I$12,MATCH(I17,Lists!$G$5:$G$12,0)),"")) | Z17: =IF(AND(X17<>"",X17>=0),X17+ROW()/100000,"")
T18: =IF(A18="","",IF(COUNTIF(Touches!$B$2:$B$501,A18)=0,"",SUMPRODUCT(MAX((Touches!$B$2:$B$501=A18)*Touches!$A$2:$A$501)))) | U18: =IF(A18="","",IF(N18<>"",N18,IFERROR(INDEX(Lists!$H$5:$H$12,MATCH(I18,Lists!$G$5:$G$12,0)),""))) | V18: =IF(A18="","",IF(O18<>"",O18,IF(OR(U18="",U18="never",U18=0),"",IF(T18="",TODAY(),T18+U18)))) | W18: =IF(A18="","",IF(V18="","no rhythm",IF(V18<TODAY(),"Overdue",IF(V18=TODAY(),"Today",IF(V18<=TODAY()+7,"Soon","Later"))))) | X18: =IF(OR(A18="",V18=""),"",TODAY()-V18) | Y18: =IF(A18="","",IFERROR(INDEX(Lists!$I$5:$I$12,MATCH(I18,Lists!$G$5:$G$12,0)),"")) | Z18: =IF(AND(X18<>"",X18>=0),X18+ROW()/100000,"")
T19: =IF(A19="","",IF(COUNTIF(Touches!$B$2:$B$501,A19)=0,"",SUMPRODUCT(MAX((Touches!$B$2:$B$501=A19)*Touches!$A$2:$A$501)))) | U19: =IF(A19="","",IF(N19<>"",N19,IFERROR(INDEX(Lists!$H$5:$H$12,MATCH(I19,Lists!$G$5:$G$12,0)),""))) | V19: =IF(A19="","",IF(O19<>"",O19,IF(OR(U19="",U19="never",U19=0),"",IF(T19="",TODAY(),T19+U19)))) | W19: =IF(A19="","",IF(V19="","no rhythm",IF(V19<TODAY(),"Overdue",IF(V19=TODAY(),"Today",IF(V19<=TODAY()+7,"Soon","Later"))))) | X19: =IF(OR(A19="",V19=""),"",TODAY()-V19) | Y19: =IF(A19="","",IFERROR(INDEX(Lists!$I$5:$I$12,MATCH(I19,Lists!$G$5:$G$12,0)),"")) | Z19: =IF(AND(X19<>"",X19>=0),X19+ROW()/100000,"")
... T151: =IF(A151="","",IF(COUNTIF(Touches!$B$2:$B$501,A151)=0,"",SUMPRODUCT(MAX((Touches!$B$2:$B$501=A151)*Touches!$A$2:$A$501)))) | U151: =IF(A151="","",IF(N151<>"",N151,IFERROR(INDEX(Lists!$H$5:$H$12,MATCH(I151,Lists!$G$5:$G$12,0)),""))) | V151: =IF(A151="","",IF(O151<>"",O151,IF(OR(U151="",U151="never",U151=0),"",IF(T151="",TODAY(),T151+U151)))) | W151: =IF(A151="","",IF(V151="","no rhythm",IF(V151<TODAY(),"Overdue",IF(V151=TODAY(),"Today",IF(V151<=TODAY()+7,"Soon","Later"))))) | X151: =IF(OR(A151="",V151=""),"",TODAY()-V151) | Y151: =IF(A151="","",IFERROR(INDEX(Lists!$I$5:$I$12,MATCH(I151,Lists!$G$5:$G$12,0)),"")) | Z151: =IF(AND(X151<>"",X151>=0),X151+ROW()/100000,"")

Sheet Touches
A1: Date | B1: Person | C1: Kind | D1: Lane | E1: Who started it | F1: What happened | G1: Note
A2: 46278 | B2: Ada Okafor | C2: DM | D2: From content | E2: Them | F2: They replied | G2: Asked about the carousel
A3: 46280 | B3: Ada Okafor | C3: DM | D3: From content | E3: Me | F3: They replied | G3: Sent the worksheet
A4: 46285 | B4: Ada Okafor | C4: Email | D4: From content | E4: Me | F4: No reply yet | G4: Offered a call
A5: 46272 | B5: Ben Sato | C5: Email | D5: Referral | E5: Me | F5: They replied
A6: 46287 | B6: Ben Sato | C6: Call | D6: Referral | E6: Me | F6: Call booked | G6: Thursday 10am
A7: 46270 | B7: Cleo Marsh | C7: Call | D7: Warm (they know me) | E7: Me | F7: They bought | G7: Six sessions
A8: 46279 | B8: Dev Patel | C8: Comment | D8: From content | E8: Them | F8: No reply yet | G8: Commented "yes" on the post
A9: 46282 | B9: Esme Haddad | C9: DM | D9: Cold (they do not) | E9: Me | F9: No reply yet
A10: 46289 | B10: Esme Haddad | C10: DM | D10: Cold (they do not) | E10: Me | F10: No reply yet | G10: Second try

Sheet Weekly
A1: The last twelve weeks
A2: One row a week, newest at the bottom. The streak counts weeks in a row on the posting target.
A4: Week starting | B4: Posts | C4: Reach | D4: Engagement rate | E4: New followers | F4: Reach-outs | G4: Conversations | H4: Leads | I4: Calls booked | J4: On target? | K4: Streak
A5: =TODAY()-WEEKDAY(TODAY(),2)+1-7*11 -> 46209 | B5: =COUNTIFS(Posts!$A$2:$A$251,">="&$A5,Posts!$A$2:$A$251,"<="&$A5+6) -> 0 | C5: =IF(COUNTIFS(Posts!$I$2:$I$251,"<>",Posts!$A$2:$A$251,">="&$A5,Posts!$A$2:$A$251,"<="&$A5+6)=0,"",SUMIFS(Posts!$I$2:$I$251,Posts!$A$2:$A$251,">="&$A5,Posts!$A$2:$A$251,"<="&$A5+6)) | D5: =IF(OR(C5="",C5=0,COUNTIFS(Posts!$T$2:$T$251,"<>",Posts!$A$2:$A$251,">="&$A5,Posts!$A$2:$A$251,"<="&$A5+6)=0),"",SUMIFS(Posts!$T$2:$T$251,Posts!$A$2:$A$251,">="&$A5,Posts!$A$2:$A$251,"<="&$A5+6)/C5) | E5: =IF(COUNTIFS(Posts!$P$2:$P$251,"<>",Posts!$A$2:$A$251,">="&$A5,Posts!$A$2:$A$251,"<="&$A5+6)=0,"",SUMIFS(Posts!$P$2:$P$251,Posts!$A$2:$A$251,">="&$A5,Posts!$A$2:$A$251,"<="&$A5+6)) | F5: =COUNTIFS(Touches!$A$2:$A$501,">="&$A5,Touches!$A$2:$A$501,"<="&$A5+6,Touches!$E$2:$E$501,"Me") -> 0 | G5: =COUNTIFS(Touches!$A$2:$A$501,">="&$A5,Touches!$A$2:$A$501,"<="&$A5+6,Touches!$E$2:$E$501,"Them")+COUNTIFS(Touches!$A$2:$A$501,">="&$A5,Touches!$A$2:$A$501,"<="&$A5+6,Touches!$E$2:$E$501,"Me",Touches!$F$2:$F$501,"They replied") -> 0 | H5: =COUNTIFS(People!$J$2:$J$151,">="&$A5,People!$J$2:$J$151,"<="&$A5+6) -> 0 | I5: =COUNTIFS(People!$K$2:$K$151,">="&$A5,People!$K$2:$K$151,"<="&$A5+6) -> 0 | J5: =IF(B5>=Lists!$E$5,"yes","no") -> no | K5: =IF(J5="yes",0+1,0) -> 0
A6: =TODAY()-WEEKDAY(TODAY(),2)+1-7*10 -> 46216 | B6: =COUNTIFS(Posts!$A$2:$A$251,">="&$A6,Posts!$A$2:$A$251,"<="&$A6+6) -> 0 | C6: =IF(COUNTIFS(Posts!$I$2:$I$251,"<>",Posts!$A$2:$A$251,">="&$A6,Posts!$A$2:$A$251,"<="&$A6+6)=0,"",SUMIFS(Posts!$I$2:$I$251,Posts!$A$2:$A$251,">="&$A6,Posts!$A$2:$A$251,"<="&$A6+6)) | D6: =IF(OR(C6="",C6=0,COUNTIFS(Posts!$T$2:$T$251,"<>",Posts!$A$2:$A$251,">="&$A6,Posts!$A$2:$A$251,"<="&$A6+6)=0),"",SUMIFS(Posts!$T$2:$T$251,Posts!$A$2:$A$251,">="&$A6,Posts!$A$2:$A$251,"<="&$A6+6)/C6) | E6: =IF(COUNTIFS(Posts!$P$2:$P$251,"<>",Posts!$A$2:$A$251,">="&$A6,Posts!$A$2:$A$251,"<="&$A6+6)=0,"",SUMIFS(Posts!$P$2:$P$251,Posts!$A$2:$A$251,">="&$A6,Posts!$A$2:$A$251,"<="&$A6+6)) | F6: =COUNTIFS(Touches!$A$2:$A$501,">="&$A6,Touches!$A$2:$A$501,"<="&$A6+6,Touches!$E$2:$E$501,"Me") -> 0 | G6: =COUNTIFS(Touches!$A$2:$A$501,">="&$A6,Touches!$A$2:$A$501,"<="&$A6+6,Touches!$E$2:$E$501,"Them")+COUNTIFS(Touches!$A$2:$A$501,">="&$A6,Touches!$A$2:$A$501,"<="&$A6+6,Touches!$E$2:$E$501,"Me",Touches!$F$2:$F$501,"They replied") -> 0 | H6: =COUNTIFS(People!$J$2:$J$151,">="&$A6,People!$J$2:$J$151,"<="&$A6+6) -> 0 | I6: =COUNTIFS(People!$K$2:$K$151,">="&$A6,People!$K$2:$K$151,"<="&$A6+6) -> 0 | J6: =IF(B6>=Lists!$E$5,"yes","no") -> no | K6: =IF(J6="yes",K5+1,0) -> 0
A7: =TODAY()-WEEKDAY(TODAY(),2)+1-7*9 -> 46223 | B7: =COUNTIFS(Posts!$A$2:$A$251,">="&$A7,Posts!$A$2:$A$251,"<="&$A7+6) -> 0 | C7: =IF(COUNTIFS(Posts!$I$2:$I$251,"<>",Posts!$A$2:$A$251,">="&$A7,Posts!$A$2:$A$251,"<="&$A7+6)=0,"",SUMIFS(Posts!$I$2:$I$251,Posts!$A$2:$A$251,">="&$A7,Posts!$A$2:$A$251,"<="&$A7+6)) | D7: =IF(OR(C7="",C7=0,COUNTIFS(Posts!$T$2:$T$251,"<>",Posts!$A$2:$A$251,">="&$A7,Posts!$A$2:$A$251,"<="&$A7+6)=0),"",SUMIFS(Posts!$T$2:$T$251,Posts!$A$2:$A$251,">="&$A7,Posts!$A$2:$A$251,"<="&$A7+6)/C7) | E7: =IF(COUNTIFS(Posts!$P$2:$P$251,"<>",Posts!$A$2:$A$251,">="&$A7,Posts!$A$2:$A$251,"<="&$A7+6)=0,"",SUMIFS(Posts!$P$2:$P$251,Posts!$A$2:$A$251,">="&$A7,Posts!$A$2:$A$251,"<="&$A7+6)) | F7: =COUNTIFS(Touches!$A$2:$A$501,">="&$A7,Touches!$A$2:$A$501,"<="&$A7+6,Touches!$E$2:$E$501,"Me") -> 0 | G7: =COUNTIFS(Touches!$A$2:$A$501,">="&$A7,Touches!$A$2:$A$501,"<="&$A7+6,Touches!$E$2:$E$501,"Them")+COUNTIFS(Touches!$A$2:$A$501,">="&$A7,Touches!$A$2:$A$501,"<="&$A7+6,Touches!$E$2:$E$501,"Me",Touches!$F$2:$F$501,"They replied") -> 0 | H7: =COUNTIFS(People!$J$2:$J$151,">="&$A7,People!$J$2:$J$151,"<="&$A7+6) -> 0 | I7: =COUNTIFS(People!$K$2:$K$151,">="&$A7,People!$K$2:$K$151,"<="&$A7+6) -> 0 | J7: =IF(B7>=Lists!$E$5,"yes","no") -> no | K7: =IF(J7="yes",K6+1,0) -> 0
A8: =TODAY()-WEEKDAY(TODAY(),2)+1-7*8 -> 46230 | B8: =COUNTIFS(Posts!$A$2:$A$251,">="&$A8,Posts!$A$2:$A$251,"<="&$A8+6) -> 0 | C8: =IF(COUNTIFS(Posts!$I$2:$I$251,"<>",Posts!$A$2:$A$251,">="&$A8,Posts!$A$2:$A$251,"<="&$A8+6)=0,"",SUMIFS(Posts!$I$2:$I$251,Posts!$A$2:$A$251,">="&$A8,Posts!$A$2:$A$251,"<="&$A8+6)) | D8: =IF(OR(C8="",C8=0,COUNTIFS(Posts!$T$2:$T$251,"<>",Posts!$A$2:$A$251,">="&$A8,Posts!$A$2:$A$251,"<="&$A8+6)=0),"",SUMIFS(Posts!$T$2:$T$251,Posts!$A$2:$A$251,">="&$A8,Posts!$A$2:$A$251,"<="&$A8+6)/C8) | E8: =IF(COUNTIFS(Posts!$P$2:$P$251,"<>",Posts!$A$2:$A$251,">="&$A8,Posts!$A$2:$A$251,"<="&$A8+6)=0,"",SUMIFS(Posts!$P$2:$P$251,Posts!$A$2:$A$251,">="&$A8,Posts!$A$2:$A$251,"<="&$A8+6)) | F8: =COUNTIFS(Touches!$A$2:$A$501,">="&$A8,Touches!$A$2:$A$501,"<="&$A8+6,Touches!$E$2:$E$501,"Me") -> 0 | G8: =COUNTIFS(Touches!$A$2:$A$501,">="&$A8,Touches!$A$2:$A$501,"<="&$A8+6,Touches!$E$2:$E$501,"Them")+COUNTIFS(Touches!$A$2:$A$501,">="&$A8,Touches!$A$2:$A$501,"<="&$A8+6,Touches!$E$2:$E$501,"Me",Touches!$F$2:$F$501,"They replied") -> 0 | H8: =COUNTIFS(People!$J$2:$J$151,">="&$A8,People!$J$2:$J$151,"<="&$A8+6) -> 0 | I8: =COUNTIFS(People!$K$2:$K$151,">="&$A8,People!$K$2:$K$151,"<="&$A8+6) -> 0 | J8: =IF(B8>=Lists!$E$5,"yes","no") -> no | K8: =IF(J8="yes",K7+1,0) -> 0
A9: =TODAY()-WEEKDAY(TODAY(),2)+1-7*7 -> 46237 | B9: =COUNTIFS(Posts!$A$2:$A$251,">="&$A9,Posts!$A$2:$A$251,"<="&$A9+6) -> 0 | C9: =IF(COUNTIFS(Posts!$I$2:$I$251,"<>",Posts!$A$2:$A$251,">="&$A9,Posts!$A$2:$A$251,"<="&$A9+6)=0,"",SUMIFS(Posts!$I$2:$I$251,Posts!$A$2:$A$251,">="&$A9,Posts!$A$2:$A$251,"<="&$A9+6)) | D9: =IF(OR(C9="",C9=0,COUNTIFS(Posts!$T$2:$T$251,"<>",Posts!$A$2:$A$251,">="&$A9,Posts!$A$2:$A$251,"<="&$A9+6)=0),"",SUMIFS(Posts!$T$2:$T$251,Posts!$A$2:$A$251,">="&$A9,Posts!$A$2:$A$251,"<="&$A9+6)/C9) | E9: =IF(COUNTIFS(Posts!$P$2:$P$251,"<>",Posts!$A$2:$A$251,">="&$A9,Posts!$A$2:$A$251,"<="&$A9+6)=0,"",SUMIFS(Posts!$P$2:$P$251,Posts!$A$2:$A$251,">="&$A9,Posts!$A$2:$A$251,"<="&$A9+6)) | F9: =COUNTIFS(Touches!$A$2:$A$501,">="&$A9,Touches!$A$2:$A$501,"<="&$A9+6,Touches!$E$2:$E$501,"Me") -> 0 | G9: =COUNTIFS(Touches!$A$2:$A$501,">="&$A9,Touches!$A$2:$A$501,"<="&$A9+6,Touches!$E$2:$E$501,"Them")+COUNTIFS(Touches!$A$2:$A$501,">="&$A9,Touches!$A$2:$A$501,"<="&$A9+6,Touches!$E$2:$E$501,"Me",Touches!$F$2:$F$501,"They replied") -> 0 | H9: =COUNTIFS(People!$J$2:$J$151,">="&$A9,People!$J$2:$J$151,"<="&$A9+6) -> 0 | I9: =COUNTIFS(People!$K$2:$K$151,">="&$A9,People!$K$2:$K$151,"<="&$A9+6) -> 0 | J9: =IF(B9>=Lists!$E$5,"yes","no") -> no | K9: =IF(J9="yes",K8+1,0) -> 0
A10: =TODAY()-WEEKDAY(TODAY(),2)+1-7*6 -> 46244 | B10: =COUNTIFS(Posts!$A$2:$A$251,">="&$A10,Posts!$A$2:$A$251,"<="&$A10+6) -> 0 | C10: =IF(COUNTIFS(Posts!$I$2:$I$251,"<>",Posts!$A$2:$A$251,">="&$A10,Posts!$A$2:$A$251,"<="&$A10+6)=0,"",SUMIFS(Posts!$I$2:$I$251,Posts!$A$2:$A$251,">="&$A10,Posts!$A$2:$A$251,"<="&$A10+6)) | D10: =IF(OR(C10="",C10=0,COUNTIFS(Posts!$T$2:$T$251,"<>",Posts!$A$2:$A$251,">="&$A10,Posts!$A$2:$A$251,"<="&$A10+6)=0),"",SUMIFS(Posts!$T$2:$T$251,Posts!$A$2:$A$251,">="&$A10,Posts!$A$2:$A$251,"<="&$A10+6)/C10) | E10: =IF(COUNTIFS(Posts!$P$2:$P$251,"<>",Posts!$A$2:$A$251,">="&$A10,Posts!$A$2:$A$251,"<="&$A10+6)=0,"",SUMIFS(Posts!$P$2:$P$251,Posts!$A$2:$A$251,">="&$A10,Posts!$A$2:$A$251,"<="&$A10+6)) | F10: =COUNTIFS(Touches!$A$2:$A$501,">="&$A10,Touches!$A$2:$A$501,"<="&$A10+6,Touches!$E$2:$E$501,"Me") -> 0 | G10: =COUNTIFS(Touches!$A$2:$A$501,">="&$A10,Touches!$A$2:$A$501,"<="&$A10+6,Touches!$E$2:$E$501,"Them")+COUNTIFS(Touches!$A$2:$A$501,">="&$A10,Touches!$A$2:$A$501,"<="&$A10+6,Touches!$E$2:$E$501,"Me",Touches!$F$2:$F$501,"They replied") -> 0 | H10: =COUNTIFS(People!$J$2:$J$151,">="&$A10,People!$J$2:$J$151,"<="&$A10+6) -> 0 | I10: =COUNTIFS(People!$K$2:$K$151,">="&$A10,People!$K$2:$K$151,"<="&$A10+6) -> 0 | J10: =IF(B10>=Lists!$E$5,"yes","no") -> no | K10: =IF(J10="yes",K9+1,0) -> 0
A11: =TODAY()-WEEKDAY(TODAY(),2)+1-7*5 -> 46251 | B11: =COUNTIFS(Posts!$A$2:$A$251,">="&$A11,Posts!$A$2:$A$251,"<="&$A11+6) -> 0 | C11: =IF(COUNTIFS(Posts!$I$2:$I$251,"<>",Posts!$A$2:$A$251,">="&$A11,Posts!$A$2:$A$251,"<="&$A11+6)=0,"",SUMIFS(Posts!$I$2:$I$251,Posts!$A$2:$A$251,">="&$A11,Posts!$A$2:$A$251,"<="&$A11+6)) | D11: =IF(OR(C11="",C11=0,COUNTIFS(Posts!$T$2:$T$251,"<>",Posts!$A$2:$A$251,">="&$A11,Posts!$A$2:$A$251,"<="&$A11+6)=0),"",SUMIFS(Posts!$T$2:$T$251,Posts!$A$2:$A$251,">="&$A11,Posts!$A$2:$A$251,"<="&$A11+6)/C11) | E11: =IF(COUNTIFS(Posts!$P$2:$P$251,"<>",Posts!$A$2:$A$251,">="&$A11,Posts!$A$2:$A$251,"<="&$A11+6)=0,"",SUMIFS(Posts!$P$2:$P$251,Posts!$A$2:$A$251,">="&$A11,Posts!$A$2:$A$251,"<="&$A11+6)) | F11: =COUNTIFS(Touches!$A$2:$A$501,">="&$A11,Touches!$A$2:$A$501,"<="&$A11+6,Touches!$E$2:$E$501,"Me") -> 0 | G11: =COUNTIFS(Touches!$A$2:$A$501,">="&$A11,Touches!$A$2:$A$501,"<="&$A11+6,Touches!$E$2:$E$501,"Them")+COUNTIFS(Touches!$A$2:$A$501,">="&$A11,Touches!$A$2:$A$501,"<="&$A11+6,Touches!$E$2:$E$501,"Me",Touches!$F$2:$F$501,"They replied") -> 0 | H11: =COUNTIFS(People!$J$2:$J$151,">="&$A11,People!$J$2:$J$151,"<="&$A11+6) -> 1 | I11: =COUNTIFS(People!$K$2:$K$151,">="&$A11,People!$K$2:$K$151,"<="&$A11+6) -> 0 | J11: =IF(B11>=Lists!$E$5,"yes","no") -> no | K11: =IF(J11="yes",K10+1,0) -> 0
A12: =TODAY()-WEEKDAY(TODAY(),2)+1-7*4 -> 46258 | B12: =COUNTIFS(Posts!$A$2:$A$251,">="&$A12,Posts!$A$2:$A$251,"<="&$A12+6) -> 0 | C12: =IF(COUNTIFS(Posts!$I$2:$I$251,"<>",Posts!$A$2:$A$251,">="&$A12,Posts!$A$2:$A$251,"<="&$A12+6)=0,"",SUMIFS(Posts!$I$2:$I$251,Posts!$A$2:$A$251,">="&$A12,Posts!$A$2:$A$251,"<="&$A12+6)) | D12: =IF(OR(C12="",C12=0,COUNTIFS(Posts!$T$2:$T$251,"<>",Posts!$A$2:$A$251,">="&$A12,Posts!$A$2:$A$251,"<="&$A12+6)=0),"",SUMIFS(Posts!$T$2:$T$251,Posts!$A$2:$A$251,">="&$A12,Posts!$A$2:$A$251,"<="&$A12+6)/C12) | E12: =IF(COUNTIFS(Posts!$P$2:$P$251,"<>",Posts!$A$2:$A$251,">="&$A12,Posts!$A$2:$A$251,"<="&$A12+6)=0,"",SUMIFS(Posts!$P$2:$P$251,Posts!$A$2:$A$251,">="&$A12,Posts!$A$2:$A$251,"<="&$A12+6)) | F12: =COUNTIFS(Touches!$A$2:$A$501,">="&$A12,Touches!$A$2:$A$501,"<="&$A12+6,Touches!$E$2:$E$501,"Me") -> 0 | G12: =COUNTIFS(Touches!$A$2:$A$501,">="&$A12,Touches!$A$2:$A$501,"<="&$A12+6,Touches!$E$2:$E$501,"Them")+COUNTIFS(Touches!$A$2:$A$501,">="&$A12,Touches!$A$2:$A$501,"<="&$A12+6,Touches!$E$2:$E$501,"Me",Touches!$F$2:$F$501,"They replied") -> 0 | H12: =COUNTIFS(People!$J$2:$J$151,">="&$A12,People!$J$2:$J$151,"<="&$A12+6) -> 0 | I12: =COUNTIFS(People!$K$2:$K$151,">="&$A12,People!$K$2:$K$151,"<="&$A12+6) -> 1 | J12: =IF(B12>=Lists!$E$5,"yes","no") -> no | K12: =IF(J12="yes",K11+1,0) -> 0
A13: =TODAY()-WEEKDAY(TODAY(),2)+1-7*3 -> 46265 | B13: =COUNTIFS(Posts!$A$2:$A$251,">="&$A13,Posts!$A$2:$A$251,"<="&$A13+6) -> 1 | C13: =IF(COUNTIFS(Posts!$I$2:$I$251,"<>",Posts!$A$2:$A$251,">="&$A13,Posts!$A$2:$A$251,"<="&$A13+6)=0,"",SUMIFS(Posts!$I$2:$I$251,Posts!$A$2:$A$251,">="&$A13,Posts!$A$2:$A$251,"<="&$A13+6)) -> 1840 | D13: =IF(OR(C13="",C13=0,COUNTIFS(Posts!$T$2:$T$251,"<>",Posts!$A$2:$A$251,">="&$A13,Posts!$A$2:$A$251,"<="&$A13+6)=0),"",SUMIFS(Posts!$T$2:$T$251,Posts!$A$2:$A$251,">="&$A13,Posts!$A$2:$A$251,"<="&$A13+6)/C13) -> 0.081521739 | E13: =IF(COUNTIFS(Posts!$P$2:$P$251,"<>",Posts!$A$2:$A$251,">="&$A13,Posts!$A$2:$A$251,"<="&$A13+6)=0,"",SUMIFS(Posts!$P$2:$P$251,Posts!$A$2:$A$251,">="&$A13,Posts!$A$2:$A$251,"<="&$A13+6)) -> 12 | F13: =COUNTIFS(Touches!$A$2:$A$501,">="&$A13,Touches!$A$2:$A$501,"<="&$A13+6,Touches!$E$2:$E$501,"Me") -> 1 | G13: =COUNTIFS(Touches!$A$2:$A$501,">="&$A13,Touches!$A$2:$A$501,"<="&$A13+6,Touches!$E$2:$E$501,"Them")+COUNTIFS(Touches!$A$2:$A$501,">="&$A13,Touches!$A$2:$A$501,"<="&$A13+6,Touches!$E$2:$E$501,"Me",Touches!$F$2:$F$501,"They replied") -> 0 | H13: =COUNTIFS(People!$J$2:$J$151,">="&$A13,People!$J$2:$J$151,"<="&$A13+6) -> 0 | I13: =COUNTIFS(People!$K$2:$K$151,">="&$A13,People!$K$2:$K$151,"<="&$A13+6) -> 0 | J13: =IF(B13>=Lists!$E$5,"yes","no") -> no | K13: =IF(J13="yes",K12+1,0) -> 0
A14: =TODAY()-WEEKDAY(TODAY(),2)+1-7*2 -> 46272 | B14: =COUNTIFS(Posts!$A$2:$A$251,">="&$A14,Posts!$A$2:$A$251,"<="&$A14+6) -> 2 | C14: =IF(COUNTIFS(Posts!$I$2:$I$251,"<>",Posts!$A$2:$A$251,">="&$A14,Posts!$A$2:$A$251,"<="&$A14+6)=0,"",SUMIFS(Posts!$I$2:$I$251,Posts!$A$2:$A$251,">="&$A14,Posts!$A$2:$A$251,"<="&$A14+6)) -> 3170 | D14: =IF(OR(C14="",C14=0,COUNTIFS(Posts!$T$2:$T$251,"<>",Posts!$A$2:$A$251,">="&$A14,Posts!$A$2:$A$251,"<="&$A14+6)=0),"",SUMIFS(Posts!$T$2:$T$251,Posts!$A$2:$A$251,">="&$A14,Posts!$A$2:$A$251,"<="&$A14+6)/C14) -> 0.073817035 | E14: =IF(COUNTIFS(Posts!$P$2:$P$251,"<>",Posts!$A$2:$A$251,">="&$A14,Posts!$A$2:$A$251,"<="&$A14+6)=0,"",SUMIFS(Posts!$P$2:$P$251,Posts!$A$2:$A$251,">="&$A14,Posts!$A$2:$A$251,"<="&$A14+6)) -> 24 | F14: =COUNTIFS(Touches!$A$2:$A$501,">="&$A14,Touches!$A$2:$A$501,"<="&$A14+6,Touches!$E$2:$E$501,"Me") -> 1 | G14: =COUNTIFS(Touches!$A$2:$A$501,">="&$A14,Touches!$A$2:$A$501,"<="&$A14+6,Touches!$E$2:$E$501,"Them")+COUNTIFS(Touches!$A$2:$A$501,">="&$A14,Touches!$A$2:$A$501,"<="&$A14+6,Touches!$E$2:$E$501,"Me",Touches!$F$2:$F$501,"They replied") -> 2 | H14: =COUNTIFS(People!$J$2:$J$151,">="&$A14,People!$J$2:$J$151,"<="&$A14+6) -> 0 | I14: =COUNTIFS(People!$K$2:$K$151,">="&$A14,People!$K$2:$K$151,"<="&$A14+6) -> 0 | J14: =IF(B14>=Lists!$E$5,"yes","no") -> no | K14: =IF(J14="yes",K13+1,0) -> 0
A15: =TODAY()-WEEKDAY(TODAY(),2)+1-7*1 -> 46279 | B15: =COUNTIFS(Posts!$A$2:$A$251,">="&$A15,Posts!$A$2:$A$251,"<="&$A15+6) -> 3 | C15: =IF(COUNTIFS(Posts!$I$2:$I$251,"<>",Posts!$A$2:$A$251,">="&$A15,Posts!$A$2:$A$251,"<="&$A15+6)=0,"",SUMIFS(Posts!$I$2:$I$251,Posts!$A$2:$A$251,">="&$A15,Posts!$A$2:$A$251,"<="&$A15+6)) -> 5060 | D15: =IF(OR(C15="",C15=0,COUNTIFS(Posts!$T$2:$T$251,"<>",Posts!$A$2:$A$251,">="&$A15,Posts!$A$2:$A$251,"<="&$A15+6)=0),"",SUMIFS(Posts!$T$2:$T$251,Posts!$A$2:$A$251,">="&$A15,Posts!$A$2:$A$251,"<="&$A15+6)/C15) -> 0.069565217 | E15: =IF(COUNTIFS(Posts!$P$2:$P$251,"<>",Posts!$A$2:$A$251,">="&$A15,Posts!$A$2:$A$251,"<="&$A15+6)=0,"",SUMIFS(Posts!$P$2:$P$251,Posts!$A$2:$A$251,">="&$A15,Posts!$A$2:$A$251,"<="&$A15+6)) -> 39 | F15: =COUNTIFS(Touches!$A$2:$A$501,">="&$A15,Touches!$A$2:$A$501,"<="&$A15+6,Touches!$E$2:$E$501,"Me") -> 3 | G15: =COUNTIFS(Touches!$A$2:$A$501,">="&$A15,Touches!$A$2:$A$501,"<="&$A15+6,Touches!$E$2:$E$501,"Them")+COUNTIFS(Touches!$A$2:$A$501,">="&$A15,Touches!$A$2:$A$501,"<="&$A15+6,Touches!$E$2:$E$501,"Me",Touches!$F$2:$F$501,"They replied") -> 2 | H15: =COUNTIFS(People!$J$2:$J$151,">="&$A15,People!$J$2:$J$151,"<="&$A15+6) -> 2 | I15: =COUNTIFS(People!$K$2:$K$151,">="&$A15,People!$K$2:$K$151,"<="&$A15+6) -> 0 | J15: =IF(B15>=Lists!$E$5,"yes","no") -> no | K15: =IF(J15="yes",K14+1,0) -> 0
A16: =TODAY()-WEEKDAY(TODAY(),2)+1-7*0 -> 46286 | B16: =COUNTIFS(Posts!$A$2:$A$251,">="&$A16,Posts!$A$2:$A$251,"<="&$A16+6) -> 2 | C16: =IF(COUNTIFS(Posts!$I$2:$I$251,"<>",Posts!$A$2:$A$251,">="&$A16,Posts!$A$2:$A$251,"<="&$A16+6)=0,"",SUMIFS(Posts!$I$2:$I$251,Posts!$A$2:$A$251,">="&$A16,Posts!$A$2:$A$251,"<="&$A16+6)) | D16: =IF(OR(C16="",C16=0,COUNTIFS(Posts!$T$2:$T$251,"<>",Posts!$A$2:$A$251,">="&$A16,Posts!$A$2:$A$251,"<="&$A16+6)=0),"",SUMIFS(Posts!$T$2:$T$251,Posts!$A$2:$A$251,">="&$A16,Posts!$A$2:$A$251,"<="&$A16+6)/C16) | E16: =IF(COUNTIFS(Posts!$P$2:$P$251,"<>",Posts!$A$2:$A$251,">="&$A16,Posts!$A$2:$A$251,"<="&$A16+6)=0,"",SUMIFS(Posts!$P$2:$P$251,Posts!$A$2:$A$251,">="&$A16,Posts!$A$2:$A$251,"<="&$A16+6)) | F16: =COUNTIFS(Touches!$A$2:$A$501,">="&$A16,Touches!$A$2:$A$501,"<="&$A16+6,Touches!$E$2:$E$501,"Me") -> 2 | G16: =COUNTIFS(Touches!$A$2:$A$501,">="&$A16,Touches!$A$2:$A$501,"<="&$A16+6,Touches!$E$2:$E$501,"Them")+COUNTIFS(Touches!$A$2:$A$501,">="&$A16,Touches!$A$2:$A$501,"<="&$A16+6,Touches!$E$2:$E$501,"Me",Touches!$F$2:$F$501,"They replied") -> 0 | H16: =COUNTIFS(People!$J$2:$J$151,">="&$A16,People!$J$2:$J$151,"<="&$A16+6) -> 0 | I16: =COUNTIFS(People!$K$2:$K$151,">="&$A16,People!$K$2:$K$151,"<="&$A16+6) -> 1 | J16: =IF(B16>=Lists!$E$5,"yes","no") -> no | K16: =IF(J16="yes",K15+1,0) -> 0
A18: Streak now | B18: =IF(J16="yes",K16,IF(J16="no",K15,0)) -> 0 | C18: weeks in a row (this week counts once it is on target)
