Workbook

Sheet Dashboard
A1: 🏠 BUY vs. RENT + FIRE CALCULATOR
A2: 🟡 Yellow cells = YOUR INPUTS │ Gray cells = auto-calculated (do not edit) │ All formulas locked & protected
B4: 🏡 BUYING | E4: 🏢 RENTING | H4: 📊 RESULTS | K4: 🔥 FIRE
B5: PROPERTY | E5: RENT COSTS | H5: SELECT VIEW YEAR | K5: YOUR FINANCES
B6: Home Price | C6: 500000 | E6: Monthly Rent | F6: 2500 | H6: View at Year → | I6: 30 | K6: Annual Gross Income | L6: 75000
B7: Down Payment % | C7: 0.2 | E7: Annual Rent Increase | F7: 0.03 | K7: Annual Expenses | L7: 48000
B8: Down Payment $ | C8: =C6*C7 -> 100000 | E8: Renters Insurance ($/mo) | F8: 20 | H8: BUYER NET WORTH | K8: Savings Rate | L8: 0.3
B9: MORTGAGE | E9: Security Deposit (mo.) | F9: 2 | H9: =IFERROR(INDEX(Schedule!$H:$H,I6+3),0) -> -1927405.9 | K9: Current Savings/Invest. | L9: 25000
B10: Interest Rate (annual) | C10: 0.07 | E10: INVESTMENT ASSUMPTIONS | K10: FIRE SETTINGS
B11: Loan Term (years) | C11: 30 | E11: Stock Return (annual) | F11: 0.08 | H11: RENTER NET WORTH | K11: Withdrawal Rate (4% rule) | L11: 0.04
B12: ONGOING COSTS | E12: Capital Gains Tax Rate | F12: 0.15 | H12: =IFERROR(INDEX(Schedule!$S:$S,I6+3),0) -> 1044391 | K12: Investment Return | L12: 0.07
B13: Property Tax (% of value/yr) | C13: 0.012 | E13: Extra Monthly Invest ($) | F13: 0 | K13: Inflation Rate | L13: 0.03
B14: Home Insurance ($/mo) | C14: 150 | E14: ANALYSIS PERIOD | H14: =IFERROR(IF(INDEX(Schedule!$H:$H,I6+3)>INDEX(Schedule!$S:$S,I6+3),"🏡 BUYING wins by $"&TEXT(INDEX(Schedule!$H:$H,I6+3)-INDEX(Schedule!$S:$S,I6+3),"#,##0"),"🏢 RENTING wins by $"&TEXT(INDEX(Schedule!$S:$S,I6+3)-INDEX(Schedule!$H:$H,I6+3),"#,##0")),"—") -> 🏢 RENTING wins by $2,971,797 | K14: FIRE — BUY vs RENT
B15: HOA Fees ($/mo) | C15: 0 | E15: Years to Analyze (1–100) | F15: 30 | K15: Monthly Savings if Renting | L15: =MAX(C6*C19+C8,0)/12 -> 9583.3333
B16: Maintenance (% value/yr) | C16: 0.01 | H16: Monthly Cost | I16: =TEXT(C29,"$#,##0") -> $1,067 | K16: Monthly Savings if Buying | L16: =MAX(0,0) -> 0
B17: PMI Rate (if <20% down) | C17: 0.005 | H17: Cum. Cash Spent | I17: =TEXT(IFERROR(INDEX(Schedule!$G:$G,I6+3),0),"$#,##0") -> $756,724 | K17: Your FIRE Number (25x expenses) | L17: =L7*25 -> 1200000
B18: TRANSACTION & GROWTH | H18: Asset Value | I18: =TEXT(IFERROR(INDEX(Schedule!$B:$B,I6+3),0),"$#,##0") -> $1,403,397 | K18: Yrs to FIRE — If Renting | L18: =IFERROR(LOG((L17*L12/(L6*L8)+1),(1+L12)),99) -> 22.977546
B19: Buying Closing Costs % | C19: 0.03 | H19: Cum. Interest Paid | I19: =TEXT(IFERROR(INDEX(Schedule!$E:$E,I6+3),0),"$#,##0") -> $3,488,323 | K19: Yrs to FIRE — If Buying | L19: =IFERROR(LOG((L17*L12/(L6*L8*0.8)+1),(1+L12)),99) -> 25.637536
B20: Selling Costs % | C20: 0.06
B21: Home Appreciation (yr %) | C21: 0.035
B22: Marginal Tax Rate | C22: 0.28
B25: MONTHLY PAYMENT BREAKDOWN | E25: RENTER MATH
B26: Monthly Mortgage (P&I) | C26: =IFERROR((C6-C8)*($$c10/12)*(1+$$c10/12)^($$c11*12)/((1+$$c10/12)^($$c11*12)-1),0) -> 0 | E26: Renter Invests Upfront | F26: =C8+C6*C19 -> 115000
B27: Monthly Property Tax | C27: =C6*C13/12 -> 500 | E27: Renter Security Deposit | F27: =F6*F9 -> 5000
B28: Monthly PMI | C28: =IF(C7<0.2,(C6-C8)*C17/12,0) -> 0 | E28: Monthly Diff Invested by Renter | F28: =MAX(C26+C27+C14+C15+C6*C16/12+C28-(F6+F8),0)+F13 -> 0
B29: TOTAL Monthly (Buyer) | C29: =C26+C27+C14+C15+C6*C16/12+C28 -> 1066.6667 | E29: TOTAL Monthly (Renter) | F29: =F6+F8 -> 2520

Sheet Schedule
A1: Yr | B1: Home Value | C1: Loan Balance | D1: Annual Buyer Cost | E1: Cum. Interest | F1: Cum. Principal | G1: Buyer Cash Spent | H1: Buyer Net Worth ★ | I1: Ann. Mortgage | J1: Ann. Prop Tax | K1: Ann. Insurance | L1: Ann. Mainten. | M1: Ann. PMI | O1: Cum. Rent | P1: Annual Rent Cost | Q1: Portfolio Value | R1: Renter Cash Spent | S1: Renter Net Worth ★ | T1: Annual Rent | U1: Ann. RentIns
A2: ★ Buyer Net Worth = home sale proceeds − loan balance ★ Renter Net Worth = portfolio after cap gains tax Year 0 = row 3, Year 100 = row 103 | Yellow cells = inputs on Dashboard
A3: 0 | B3: =Dashboard!$C6 -> 500000 | C3: =Dashboard!$C6-Dashboard!$C8 -> 400000 | D3: 0 | E3: 0 | F3: 0 | G3: =Dashboard!$C8+Dashboard!$C6*Dashboard!$C19 -> 115000 | H3: =B3*(1-Dashboard!$C20)-C3 -> 70000 | I3: 0 | J3: 0 | K3: 0 | L3: 0 | M3: 0 | O3: 0 | P3: 0 | Q3: =Dashboard!$C8+Dashboard!$C6*Dashboard!$C19+Dashboard!$F6*Dashboard!$F9 -> 120000 | R3: =Dashboard!$F6*Dashboard!$F9 -> 5000 | S3: =Q3 -> 120000 | T3: 0 | U3: 0
A4: 1 | B4: =B3*(1+Dashboard!$C21) -> 517500 | C4: =MAX((Dashboard!$C6-Dashboard!$C8)*(1+Dashboard!$C10/12)^(1*12)-Dashboard!$C26*((1+Dashboard!$C10/12)^(1*12)-1)/(Dashboard!$C10/12),0) -> 428916.03 | D4: =I4+J4+K4+L4+M4 -> 13185 | E4: =E3+(D4-(C3-C4)) -> 42101.032 | F4: =(Dashboard!$C6-Dashboard!$C8)-C4 -> -28916.032 | G4: =G3+D4 -> 128185 | H4: =B4*(1-Dashboard!$C20)-C4 -> 57533.968 | I4: =IF(C3>0,Dashboard!$C26*12,0) -> 0 | J4: =B4*Dashboard!$C13 -> 6210 | K4: =Dashboard!$C14*12 -> 1800 | L4: =B4*Dashboard!$C16 -> 5175 | M4: =IF(Dashboard!$C7<0.2,C4*Dashboard!$C17,0) -> 0 | O4: =O3+T4 -> 30000 | P4: =T4+U4 -> 30240 | Q4: =Q3*(1+Dashboard!$F11)+Dashboard!$F28*12 -> 129600 | R4: =Dashboard!$F6*Dashboard!$F9+O4+U4*1 -> 35240 | S4: =Q4-MAX(Q4-(Dashboard!$C8+Dashboard!$C6*Dashboard!$C19+Dashboard!$F6*Dashboard!$F9),0)*Dashboard!$F12 -> 128160 | T4: =Dashboard!$F6*(1+Dashboard!$F7)^(1-1)*12 -> 30000 | U4: =Dashboard!$F8*12 -> 240
A5: 2 | B5: =B4*(1+Dashboard!$C21) -> 535612.5 | C5: =MAX((Dashboard!$C6-Dashboard!$C8)*(1+Dashboard!$C10/12)^(2*12)-Dashboard!$C26*((1+Dashboard!$C10/12)^(2*12)-1)/(Dashboard!$C10/12),0) -> 459922.41 | D5: =I5+J5+K5+L5+M5 -> 13583.475 | E5: =E4+(D5-(C4-C5)) -> 86690.882 | F5: =(Dashboard!$C6-Dashboard!$C8)-C5 -> -59922.407 | G5: =G4+D5 -> 141768.48 | H5: =B5*(1-Dashboard!$C20)-C5 -> 43553.343 | I5: =IF(C4>0,Dashboard!$C26*12,0) -> 0 | J5: =B5*Dashboard!$C13 -> 6427.35 | K5: =Dashboard!$C14*12 -> 1800 | L5: =B5*Dashboard!$C16 -> 5356.125 | M5: =IF(Dashboard!$C7<0.2,C5*Dashboard!$C17,0) -> 0 | O5: =O4+T5 -> 60900 | P5: =T5+U5 -> 31140 | Q5: =Q4*(1+Dashboard!$F11)+Dashboard!$F28*12 -> 139968 | R5: =Dashboard!$F6*Dashboard!$F9+O5+U5*2 -> 66380 | S5: =Q5-MAX(Q5-(Dashboard!$C8+Dashboard!$C6*Dashboard!$C19+Dashboard!$F6*Dashboard!$F9),0)*Dashboard!$F12 -> 136972.8 | T5: =Dashboard!$F6*(1+Dashboard!$F7)^(2-1)*12 -> 30900 | U5: =Dashboard!$F8*12 -> 240
A6: 3 | B6: =B5*(1+Dashboard!$C21) -> 554358.94 | C6: =MAX((Dashboard!$C6-Dashboard!$C8)*(1+Dashboard!$C10/12)^(3*12)-Dashboard!$C26*((1+Dashboard!$C10/12)^(3*12)-1)/(Dashboard!$C10/12),0) -> 493170.23 | D6: =I6+J6+K6+L6+M6 -> 13995.897 | E6: =E5+(D6-(C5-C6)) -> 133934.61 | F6: =(Dashboard!$C6-Dashboard!$C8)-C6 -> -93170.235 | G6: =G5+D6 -> 155764.37 | H6: =B6*(1-Dashboard!$C20)-C6 -> 27927.166 | I6: =IF(C5>0,Dashboard!$C26*12,0) -> 0 | J6: =B6*Dashboard!$C13 -> 6652.3072 | K6: =Dashboard!$C14*12 -> 1800 | L6: =B6*Dashboard!$C16 -> 5543.5894 | M6: =IF(Dashboard!$C7<0.2,C6*Dashboard!$C17,0) -> 0 | O6: =O5+T6 -> 92727 | P6: =T6+U6 -> 32067 | Q6: =Q5*(1+Dashboard!$F11)+Dashboard!$F28*12 -> 151165.44 | R6: =Dashboard!$F6*Dashboard!$F9+O6+U6*3 -> 98447 | S6: =Q6-MAX(Q6-(Dashboard!$C8+Dashboard!$C6*Dashboard!$C19+Dashboard!$F6*Dashboard!$F9),0)*Dashboard!$F12 -> 146490.62 | T6: =Dashboard!$F6*(1+Dashboard!$F7)^(3-1)*12 -> 31827 | U6: =Dashboard!$F8*12 -> 240
A7: 4 | B7: =B6*(1+Dashboard!$C21) -> 573761.5 | C7: =MAX((Dashboard!$C6-Dashboard!$C8)*(1+Dashboard!$C10/12)^(4*12)-Dashboard!$C26*((1+Dashboard!$C10/12)^(4*12)-1)/(Dashboard!$C10/12),0) -> 528821.55 | D7: =I7+J7+K7+L7+M7 -> 14422.753 | E7: =E6+(D7-(C6-C7)) -> 184008.68 | F7: =(Dashboard!$C6-Dashboard!$C8)-C7 -> -128821.55 | G7: =G6+D7 -> 170187.12 | H7: =B7*(1-Dashboard!$C20)-C7 -> 10514.259 | I7: =IF(C6>0,Dashboard!$C26*12,0) -> 0 | J7: =B7*Dashboard!$C13 -> 6885.138 | K7: =Dashboard!$C14*12 -> 1800 | L7: =B7*Dashboard!$C16 -> 5737.615 | M7: =IF(Dashboard!$C7<0.2,C7*Dashboard!$C17,0) -> 0 | O7: =O6+T7 -> 125508.81 | P7: =T7+U7 -> 33021.81 | Q7: =Q6*(1+Dashboard!$F11)+Dashboard!$F28*12 -> 163258.68 | R7: =Dashboard!$F6*Dashboard!$F9+O7+U7*4 -> 131468.81 | S7: =Q7-MAX(Q7-(Dashboard!$C8+Dashboard!$C6*Dashboard!$C19+Dashboard!$F6*Dashboard!$F9),0)*Dashboard!$F12 -> 156769.87 | T7: =Dashboard!$F6*(1+Dashboard!$F7)^(4-1)*12 -> 32781.81 | U7: =Dashboard!$F8*12 -> 240
A8: 5 | B8: =B7*(1+Dashboard!$C21) -> 593843.15 | C8: =MAX((Dashboard!$C6-Dashboard!$C8)*(1+Dashboard!$C10/12)^(5*12)-Dashboard!$C26*((1+Dashboard!$C10/12)^(5*12)-1)/(Dashboard!$C10/12),0) -> 567050.1 | D8: =I8+J8+K8+L8+M8 -> 14864.549 | E8: =E7+(D8-(C7-C8)) -> 237101.78 | F8: =(Dashboard!$C6-Dashboard!$C8)-C8 -> -167050.1 | G8: =G7+D8 -> 185051.67 | H8: =B8*(1-Dashboard!$C20)-C8 -> -8837.5402 | I8: =IF(C7>0,Dashboard!$C26*12,0) -> 0 | J8: =B8*Dashboard!$C13 -> 7126.1178 | K8: =Dashboard!$C14*12 -> 1800 | L8: =B8*Dashboard!$C16 -> 5938.4315 | M8: =IF(Dashboard!$C7<0.2,C8*Dashboard!$C17,0) -> 0 | O8: =O7+T8 -> 159274.07 | P8: =T8+U8 -> 34005.264 | Q8: =Q7*(1+Dashboard!$F11)+Dashboard!$F28*12 -> 176319.37 | R8: =Dashboard!$F6*Dashboard!$F9+O8+U8*5 -> 165474.07 | S8: =Q8-MAX(Q8-(Dashboard!$C8+Dashboard!$C6*Dashboard!$C19+Dashboard!$F6*Dashboard!$F9),0)*Dashboard!$F12 -> 167871.46 | T8: =Dashboard!$F6*(1+Dashboard!$F7)^(5-1)*12 -> 33765.264 | U8: =Dashboard!$F8*12 -> 240
A9: 6 | B9: =B8*(1+Dashboard!$C21) -> 614627.66 | C9: =MAX((Dashboard!$C6-Dashboard!$C8)*(1+Dashboard!$C10/12)^(6*12)-Dashboard!$C26*((1+Dashboard!$C10/12)^(6*12)-1)/(Dashboard!$C10/12),0) -> 608042.2 | D9: =I9+J9+K9+L9+M9 -> 15321.809 | E9: =E8+(D9-(C8-C9)) -> 293415.68 | F9: =(Dashboard!$C6-Dashboard!$C8)-C9 -> -208042.2 | G9: =G8+D9 -> 200373.48 | H9: =B9*(1-Dashboard!$C20)-C9 -> -30292.198 | I9: =IF(C8>0,Dashboard!$C26*12,0) -> 0 | J9: =B9*Dashboard!$C13 -> 7375.532 | K9: =Dashboard!$C14*12 -> 1800 | L9: =B9*Dashboard!$C16 -> 6146.2766 | M9: =IF(Dashboard!$C7<0.2,C9*Dashboard!$C17,0) -> 0 | O9: =O8+T9 -> 194052.3 | P9: =T9+U9 -> 35018.222 | Q9: =Q8*(1+Dashboard!$F11)+Dashboard!$F28*12 -> 190424.92 | R9: =Dashboard!$F6*Dashboard!$F9+O9+U9*6 -> 200492.3 | S9: =Q9-MAX(Q9-(Dashboard!$C8+Dashboard!$C6*Dashboard!$C19+Dashboard!$F6*Dashboard!$F9),0)*Dashboard!$F12 -> 179861.18 | T9: =Dashboard!$F6*(1+Dashboard!$F7)^(6-1)*12 -> 34778.222 | U9: =Dashboard!$F8*12 -> 240
A10: 7 | B10: =B9*(1+Dashboard!$C21) -> 636139.63 | C10: =MAX((Dashboard!$C6-Dashboard!$C8)*(1+Dashboard!$C10/12)^(7*12)-Dashboard!$C26*((1+Dashboard!$C10/12)^(7*12)-1)/(Dashboard!$C10/12),0) -> 651997.62 | D10: =I10+J10+K10+L10+M10 -> 15795.072 | E10: =E9+(D10-(C9-C10)) -> 353166.18 | F10: =(Dashboard!$C6-Dashboard!$C8)-C10 -> -251997.62 | G10: =G9+D10 -> 216168.55 | H10: =B10*(1-Dashboard!$C20)-C10 -> -54026.368 | I10: =IF(C9>0,Dashboard!$C26*12,0) -> 0 | J10: =B10*Dashboard!$C13 -> 7633.6756 | K10: =Dashboard!$C14*12 -> 1800 | L10: =B10*Dashboard!$C16 -> 6361.3963 | M10: =IF(Dashboard!$C7<0.2,C10*Dashboard!$C17,0) -> 0 | O10: =O9+T10 -> 229873.87 | P10: =T10+U10 -> 36061.569 | Q10: =Q9*(1+Dashboard!$F11)+Dashboard!$F28*12 -> 205658.91 | R10: =Dashboard!$F6*Dashboard!$F9+O10+U10*7 -> 236553.87 | S10: =Q10-MAX(Q10-(Dashboard!$C8+Dashboard!$C6*Dashboard!$C19+Dashboard!$F6*Dashboard!$F9),0)*Dashboard!$F12 -> 192810.08 | T10: =Dashboard!$F6*(1+Dashboard!$F7)^(7-1)*12 -> 35821.569 | U10: =Dashboard!$F8*12 -> 240
A11: 8 | B11: =B10*(1+Dashboard!$C21) -> 658404.52 | C11: =MAX((Dashboard!$C6-Dashboard!$C8)*(1+Dashboard!$C10/12)^(8*12)-Dashboard!$C26*((1+Dashboard!$C10/12)^(8*12)-1)/(Dashboard!$C10/12),0) -> 699130.58 | D11: =I11+J11+K11+L11+M11 -> 16284.899 | E11: =E10+(D11-(C10-C11)) -> 416584.04 | F11: =(Dashboard!$C6-Dashboard!$C8)-C11 -> -299130.58 | G11: =G10+D11 -> 232453.45 | H11: =B11*(1-Dashboard!$C20)-C11 -> -80230.335 | I11: =IF(C10>0,Dashboard!$C26*12,0) -> 0 | J11: =B11*Dashboard!$C13 -> 7900.8542 | K11: =Dashboard!$C14*12 -> 1800 | L11: =B11*Dashboard!$C16 -> 6584.0452 | M11: =IF(Dashboard!$C7<0.2,C11*Dashboard!$C17,0) -> 0 | O11: =O10+T11 -> 266770.08 | P11: =T11+U11 -> 37136.216 | Q11: =Q10*(1+Dashboard!$F11)+Dashboard!$F28*12 -> 222111.63 | R11: =Dashboard!$F6*Dashboard!$F9+O11+U11*8 -> 273690.08 | S11: =Q11-MAX(Q11-(Dashboard!$C8+Dashboard!$C6*Dashboard!$C19+Dashboard!$F6*Dashboard!$F9),0)*Dashboard!$F12 -> 206794.88 | T11: =Dashboard!$F6*(1+Dashboard!$F7)^(8-1)*12 -> 36896.216 | U11: =Dashboard!$F8*12 -> 240
A12: 9 | B12: =B11*(1+Dashboard!$C21) -> 681448.68 | C12: =MAX((Dashboard!$C6-Dashboard!$C8)*(1+Dashboard!$C10/12)^(9*12)-Dashboard!$C26*((1+Dashboard!$C10/12)^(9*12)-1)/(Dashboard!$C10/12),0) -> 749670.79 | D12: =I12+J12+K12+L12+M12 -> 16791.871 | E12: =E11+(D12-(C11-C12)) -> 483916.11 | F12: =(Dashboard!$C6-Dashboard!$C8)-C12 -> -349670.79 | G12: =G11+D12 -> 249245.32 | H12: =B12*(1-Dashboard!$C20)-C12 -> -109109.03 | I12: =IF(C11>0,Dashboard!$C26*12,0) -> 0 | J12: =B12*Dashboard!$C13 -> 8177.3841 | K12: =Dashboard!$C14*12 -> 1800 | L12: =B12*Dashboard!$C16 -> 6814.4868 | M12: =IF(Dashboard!$C7<0.2,C12*Dashboard!$C17,0) -> 0 | O12: =O11+T12 -> 304773.18 | P12: =T12+U12 -> 38243.102 | Q12: =Q11*(1+Dashboard!$F11)+Dashboard!$F28*12 -> 239880.56 | R12: =Dashboard!$F6*Dashboard!$F9+O12+U12*9 -> 311933.18 | S12: =Q12-MAX(Q12-(Dashboard!$C8+Dashboard!$C6*Dashboard!$C19+Dashboard!$F6*Dashboard!$F9),0)*Dashboard!$F12 -> 221898.47 | T12: =Dashboard!$F6*(1+Dashboard!$F7)^(9-1)*12 -> 38003.102 | U12: =Dashboard!$F8*12 -> 240
A13: 10 | B13: =B12*(1+Dashboard!$C21) -> 705299.38 | C13: =MAX((Dashboard!$C6-Dashboard!$C8)*(1+Dashboard!$C10/12)^(10*12)-Dashboard!$C26*((1+Dashboard!$C10/12)^(10*12)-1)/(Dashboard!$C10/12),0) -> 803864.55 | D13: =I13+J13+K13+L13+M13 -> 17316.586 | E13: =E12+(D13-(C12-C13)) -> 555426.46 | F13: =(Dashboard!$C6-Dashboard!$C8)-C13 -> -403864.55 | G13: =G12+D13 -> 266561.91 | H13: =B13*(1-Dashboard!$C20)-C13 -> -140883.13 | I13: =IF(C12>0,Dashboard!$C26*12,0) -> 0 | J13: =B13*Dashboard!$C13 -> 8463.5926 | K13: =Dashboard!$C14*12 -> 1800 | L13: =B13*Dashboard!$C16 -> 7052.9938 | M13: =IF(Dashboard!$C7<0.2,C13*Dashboard!$C17,0) -> 0 | O13: =O12+T13 -> 343916.38 | P13: =T13+U13 -> 39383.196 | Q13: =Q12*(1+Dashboard!$F11)+Dashboard!$F28*12 -> 259071 | R13: =Dashboard!$F6*Dashboard!$F9+O13+U13*10 -> 351316.38 | S13: =Q13-MAX(Q13-(Dashboard!$C8+Dashboard!$C6*Dashboard!$C19+Dashboard!$F6*Dashboard!$F9),0)*Dashboard!$F12 -> 238210.35 | T13: =Dashboard!$F6*(1+Dashboard!$F7)^(10-1)*12 -> 39143.196 | U13: =Dashboard!$F8*12 -> 240
A14: 11 | B14: =B13*(1+Dashboard!$C21) -> 729984.86 | C14: =MAX((Dashboard!$C6-Dashboard!$C8)*(1+Dashboard!$C10/12)^(11*12)-Dashboard!$C26*((1+Dashboard!$C10/12)^(11*12)-1)/(Dashboard!$C10/12),0) -> 861975.98 | D14: =I14+J14+K14+L14+M14 -> 17859.667 | E14: =E13+(D14-(C13-C14)) -> 631397.56 | F14: =(Dashboard!$C6-Dashboard!$C8)-C14 -> -461975.98 | G14: =G13+D14 -> 284421.58 | H14: =B14*(1-Dashboard!$C20)-C14 -> -175790.22 | I14: =IF(C13>0,Dashboard!$C26*12,0) -> 0 | J14: =B14*Dashboard!$C13 -> 8759.8183 | K14: =Dashboard!$C14*12 -> 1800 | L14: =B14*Dashboard!$C16 -> 7299.8486 | M14: =IF(Dashboard!$C7<0.2,C14*Dashboard!$C17,0) -> 0 | O14: =O13+T14 -> 384233.87 | P14: =T14+U14 -> 40557.491 | Q14: =Q13*(1+Dashboard!$F11)+Dashboard!$F28*12 -> 279796.68 | R14: =Dashboard!$F6*Dashboard!$F9+O14+U14*11 -> 391873.87 | S14: =Q14-MAX(Q14-(Dashboard!$C8+Dashboard!$C6*Dashboard!$C19+Dashboard!$F6*Dashboard!$F9),0)*Dashboard!$F12 -> 255827.18 | T14: =Dashboard!$F6*(1+Dashboard!$F7)^(11-1)*12 -> 40317.491 | U14: =Dashboard!$F8*12 -> 240
A15: 12 | B15: =B14*(1+Dashboard!$C21) -> 755534.33 | C15: =MAX((Dashboard!$C6-Dashboard!$C8)*(1+Dashboard!$C10/12)^(12*12)-Dashboard!$C26*((1+Dashboard!$C10/12)^(12*12)-1)/(Dashboard!$C10/12),0) -> 924288.3 | D15: =I15+J15+K15+L15+M15 -> 18421.755 | E15: =E14+(D15-(C14-C15)) -> 712131.63 | F15: =(Dashboard!$C6-Dashboard!$C8)-C15 -> -524288.3 | G15: =G14+D15 -> 302843.33 | H15: =B15*(1-Dashboard!$C20)-C15 -> -214086.03 | I15: =IF(C14>0,Dashboard!$C26*12,0) -> 0 | J15: =B15*Dashboard!$C13 -> 9066.4119 | K15: =Dashboard!$C14*12 -> 1800 | L15: =B15*Dashboard!$C16 -> 7555.3433 | M15: =IF(Dashboard!$C7<0.2,C15*Dashboard!$C17,0) -> 0 | O15: =O14+T15 -> 425760.89 | P15: =T15+U15 -> 41767.016 | Q15: =Q14*(1+Dashboard!$F11)+Dashboard!$F28*12 -> 302180.41 | R15: =Dashboard!$F6*Dashboard!$F9+O15+U15*12 -> 433640.89 | S15: =Q15-MAX(Q15-(Dashboard!$C8+Dashboard!$C6*Dashboard!$C19+Dashboard!$F6*Dashboard!$F9),0)*Dashboard!$F12 -> 274853.35 | T15: =Dashboard!$F6*(1+Dashboard!$F7)^(12-1)*12 -> 41527.016 | U15: =Dashboard!$F8*12 -> 240
A16: 13 | B16: =B15*(1+Dashboard!$C21) -> 781978.03 | C16: =MAX((Dashboard!$C6-Dashboard!$C8)*(1+Dashboard!$C10/12)^(13*12)-Dashboard!$C26*((1+Dashboard!$C10/12)^(13*12)-1)/(Dashboard!$C10/12),0) -> 991105.17 | D16: =I16+J16+K16+L16+M16 -> 19003.517 | E16: =E15+(D16-(C15-C16)) -> 797952.02 | F16: =(Dashboard!$C6-Dashboard!$C8)-C16 -> -591105.17 | G16: =G15+D16 -> 321846.85 | H16: =B16*(1-Dashboard!$C20)-C16 -> -256045.83 | I16: =IF(C15>0,Dashboard!$C26*12,0) -> 0 | J16: =B16*Dashboard!$C13 -> 9383.7364 | K16: =Dashboard!$C14*12 -> 1800 | L16: =B16*Dashboard!$C16 -> 7819.7803 | M16: =IF(Dashboard!$C7<0.2,C16*Dashboard!$C17,0) -> 0 | O16: =O15+T16 -> 468533.71 | P16: =T16+U16 -> 43012.827 | Q16: =Q15*(1+Dashboard!$F11)+Dashboard!$F28*12 -> 326354.85 | R16: =Dashboard!$F6*Dashboard!$F9+O16+U16*13 -> 476653.71 | S16: =Q16-MAX(Q16-(Dashboard!$C8+Dashboard!$C6*Dashboard!$C19+Dashboard!$F6*Dashboard!$F9),0)*Dashboard!$F12 -> 295401.62 | T16: =Dashboard!$F6*(1+Dashboard!$F7)^(13-1)*12 -> 42772.827 | U16: =Dashboard!$F8*12 -> 240
A17: 14 | B17: =B16*(1+Dashboard!$C21) -> 809347.26 | C17: =MAX((Dashboard!$C6-Dashboard!$C8)*(1+Dashboard!$C10/12)^(14*12)-Dashboard!$C26*((1+Dashboard!$C10/12)^(14*12)-1)/(Dashboard!$C10/12),0) -> 1062752.2 | D17: =I17+J17+K17+L17+M17 -> 19605.64 | E17: =E16+(D17-(C16-C17)) -> 889204.74 | F17: =(Dashboard!$C6-Dashboard!$C8)-C17 -> -662752.25 | G17: =G16+D17 -> 341452.49 | H17: =B17*(1-Dashboard!$C20)-C17 -> -301965.82 | I17: =IF(C16>0,Dashboard!$C26*12,0) -> 0 | J17: =B17*Dashboard!$C13 -> 9712.1671 | K17: =Dashboard!$C14*12 -> 1800 | L17: =B17*Dashboard!$C16 -> 8093.4726 | M17: =IF(Dashboard!$C7<0.2,C17*Dashboard!$C17,0) -> 0 | O17: =O16+T17 -> 512589.72 | P17: =T17+U17 -> 44296.011 | Q17: =Q16*(1+Dashboard!$F11)+Dashboard!$F28*12 -> 352463.23 | R17: =Dashboard!$F6*Dashboard!$F9+O17+U17*14 -> 520949.72 | S17: =Q17-MAX(Q17-(Dashboard!$C8+Dashboard!$C6*Dashboard!$C19+Dashboard!$F6*Dashboard!$F9),0)*Dashboard!$F12 -> 317593.75 | T17: =Dashboard!$F6*(1+Dashboard!$F7)^(14-1)*12 -> 44056.011 | U17: =Dashboard!$F8*12 -> 240
A18: 15 | B18: =B17*(1+Dashboard!$C21) -> 837674.42 | C18: =MAX((Dashboard!$C6-Dashboard!$C8)*(1+Dashboard!$C10/12)^(15*12)-Dashboard!$C26*((1+Dashboard!$C10/12)^(15*12)-1)/(Dashboard!$C10/12),0) -> 1139578.7 | D18: =I18+J18+K18+L18+M18 -> 20228.837 | E18: =E17+(D18-(C17-C18)) -> 986260.02 | F18: =(Dashboard!$C6-Dashboard!$C8)-C18 -> -739578.69 | G18: =G17+D18 -> 361681.33 | H18: =B18*(1-Dashboard!$C20)-C18 -> -352164.74 | I18: =IF(C17>0,Dashboard!$C26*12,0) -> 0 | J18: =B18*Dashboard!$C13 -> 10052.093 | K18: =Dashboard!$C14*12 -> 1800 | L18: =B18*Dashboard!$C16 -> 8376.7442 | M18: =IF(Dashboard!$C7<0.2,C18*Dashboard!$C17,0) -> 0 | O18: =O17+T18 -> 557967.42 | P18: =T18+U18 -> 45617.692 | Q18: =Q17*(1+Dashboard!$F11)+Dashboard!$F28*12 -> 380660.29 | R18: =Dashboard!$F6*Dashboard!$F9+O18+U18*15 -> 566567.42 | S18: =Q18-MAX(Q18-(Dashboard!$C8+Dashboard!$C6*Dashboard!$C19+Dashboard!$F6*Dashboard!$F9),0)*Dashboard!$F12 -> 341561.25 | T18: =Dashboard!$F6*(1+Dashboard!$F7)^(15-1)*12 -> 45377.692 | U18: =Dashboard!$F8*12 -> 240
A19: 16 | B19: =B18*(1+Dashboard!$C21) -> 866993.02 | C19: =MAX((Dashboard!$C6-Dashboard!$C8)*(1+Dashboard!$C10/12)^(16*12)-Dashboard!$C26*((1+Dashboard!$C10/12)^(16*12)-1)/(Dashboard!$C10/12),0) -> 1221958.9 | D19: =I19+J19+K19+L19+M19 -> 20873.846 | E19: =E18+(D19-(C18-C19)) -> 1089514.1 | F19: =(Dashboard!$C6-Dashboard!$C8)-C19 -> -821958.93 | G19: =G18+D19 -> 382555.17 | H19: =B19*(1-Dashboard!$C20)-C19 -> -406985.49 | I19: =IF(C18>0,Dashboard!$C26*12,0) -> 0 | J19: =B19*Dashboard!$C13 -> 10403.916 | K19: =Dashboard!$C14*12 -> 1800 | L19: =B19*Dashboard!$C16 -> 8669.9302 | M19: =IF(Dashboard!$C7<0.2,C19*Dashboard!$C17,0) -> 0 | O19: =O18+T19 -> 604706.44 | P19: =T19+U19 -> 46979.022 | Q19: =Q18*(1+Dashboard!$F11)+Dashboard!$F28*12 -> 411113.12 | R19: =Dashboard!$F6*Dashboard!$F9+O19+U19*16 -> 613546.44 | S19: =Q19-MAX(Q19-(Dashboard!$C8+Dashboard!$C6*Dashboard!$C19+Dashboard!$F6*Dashboard!$F9),0)*Dashboard!$F12 -> 367446.15 | T19: =Dashboard!$F6*(1+Dashboard!$F7)^(16-1)*12 -> 46739.022 | U19: =Dashboard!$F8*12 -> 240
A20: 17 | B20: =B19*(1+Dashboard!$C21) -> 897337.78 | C20: =MAX((Dashboard!$C6-Dashboard!$C8)*(1+Dashboard!$C10/12)^(17*12)-Dashboard!$C26*((1+Dashboard!$C10/12)^(17*12)-1)/(Dashboard!$C10/12),0) -> 1310294.4 | D20: =I20+J20+K20+L20+M20 -> 21541.431 | E20: =E19+(D20-(C19-C20)) -> 1199391 | F20: =(Dashboard!$C6-Dashboard!$C8)-C20 -> -910294.44 | G20: =G19+D20 -> 404096.6 | H20: =B20*(1-Dashboard!$C20)-C20 -> -466796.93 | I20: =IF(C19>0,Dashboard!$C26*12,0) -> 0 | J20: =B20*Dashboard!$C13 -> 10768.053 | K20: =Dashboard!$C14*12 -> 1800 | L20: =B20*Dashboard!$C16 -> 8973.3778 | M20: =IF(Dashboard!$C7<0.2,C20*Dashboard!$C17,0) -> 0 | O20: =O19+T20 -> 652847.63 | P20: =T20+U20 -> 48381.193 | Q20: =Q19*(1+Dashboard!$F11)+Dashboard!$F28*12 -> 444002.17 | R20: =Dashboard!$F6*Dashboard!$F9+O20+U20*17 -> 661927.63 | S20: =Q20-MAX(Q20-(Dashboard!$C8+Dashboard!$C6*Dashboard!$C19+Dashboard!$F6*Dashboard!$F9),0)*Dashboard!$F12 -> 395401.84 | T20: =Dashboard!$F6*(1+Dashboard!$F7)^(17-1)*12 -> 48141.193 | U20: =Dashboard!$F8*12 -> 240
A21: 18 | B21: =B20*(1+Dashboard!$C21) -> 928744.6 | C21: =MAX((Dashboard!$C6-Dashboard!$C8)*(1+Dashboard!$C10/12)^(18*12)-Dashboard!$C26*((1+Dashboard!$C10/12)^(18*12)-1)/(Dashboard!$C10/12),0) -> 1405015.7 | D21: =I21+J21+K21+L21+M21 -> 22232.381 | E21: =E20+(D21-(C20-C21)) -> 1316344.7 | F21: =(Dashboard!$C6-Dashboard!$C8)-C21 -> -1005015.7 | G21: =G20+D21 -> 426328.99 | H21: =B21*(1-Dashboard!$C20)-C21 -> -531995.81 | I21: =IF(C20>0,Dashboard!$C26*12,0) -> 0 | J21: =B21*Dashboard!$C13 -> 11144.935 | K21: =Dashboard!$C14*12 -> 1800 | L21: =B21*Dashboard!$C16 -> 9287.446 | M21: =IF(Dashboard!$C7<0.2,C21*Dashboard!$C17,0) -> 0 | O21: =O20+T21 -> 702433.06 | P21: =T21+U21 -> 49825.429 | Q21: =Q20*(1+Dashboard!$F11)+Dashboard!$F28*12 -> 479522.34 | R21: =Dashboard!$F6*Dashboard!$F9+O21+U21*18 -> 711753.06 | S21: =Q21-MAX(Q21-(Dashboard!$C8+Dashboard!$C6*Dashboard!$C19+Dashboard!$F6*Dashboard!$F9),0)*Dashboard!$F12 -> 425593.99 | T21: =Dashboard!$F6*(1+Dashboard!$F7)^(18-1)*12 -> 49585.429 | U21: =Dashboard!$F8*12 -> 240
A22: 19 | B22: =B21*(1+Dashboard!$C21) -> 961250.66 | C22: =MAX((Dashboard!$C6-Dashboard!$C8)*(1+Dashboard!$C10/12)^(19*12)-Dashboard!$C26*((1+Dashboard!$C10/12)^(19*12)-1)/(Dashboard!$C10/12),0) -> 1506584.4 | D22: =I22+J22+K22+L22+M22 -> 22947.514 | E22: =E21+(D22-(C21-C22)) -> 1440860.9 | F22: =(Dashboard!$C6-Dashboard!$C8)-C22 -> -1106584.4 | G22: =G21+D22 -> 449276.5 | H22: =B22*(1-Dashboard!$C20)-C22 -> -603008.81 | I22: =IF(C21>0,Dashboard!$C26*12,0) -> 0 | J22: =B22*Dashboard!$C13 -> 11535.008 | K22: =Dashboard!$C14*12 -> 1800 | L22: =B22*Dashboard!$C16 -> 9612.5066 | M22: =IF(Dashboard!$C7<0.2,C22*Dashboard!$C17,0) -> 0 | O22: =O21+T22 -> 753506.05 | P22: =T22+U22 -> 51312.992 | Q22: =Q21*(1+Dashboard!$F11)+Dashboard!$F28*12 -> 517884.13 | R22: =Dashboard!$F6*Dashboard!$F9+O22+U22*19 -> 763066.05 | S22: =Q22-MAX(Q22-(Dashboard!$C8+Dashboard!$C6*Dashboard!$C19+Dashboard!$F6*Dashboard!$F9),0)*Dashboard!$F12 -> 458201.51 | T22: =Dashboard!$F6*(1+Dashboard!$F7)^(19-1)*12 -> 51072.992 | U22: =Dashboard!$F8*12 -> 240
A23: 20 | B23: =B22*(1+Dashboard!$C21) -> 994894.43 | C23: =MAX((Dashboard!$C6-Dashboard!$C8)*(1+Dashboard!$C10/12)^(20*12)-Dashboard!$C26*((1+Dashboard!$C10/12)^(20*12)-1)/(Dashboard!$C10/12),0) -> 1615495.5 | D23: =I23+J23+K23+L23+M23 -> 23687.677 | E23: =E22+(D23-(C22-C23)) -> 1573459.7 | F23: =(Dashboard!$C6-Dashboard!$C8)-C23 -> -1215495.5 | G23: =G22+D23 -> 472964.18 | H23: =B23*(1-Dashboard!$C20)-C23 -> -680294.77 | I23: =IF(C22>0,Dashboard!$C26*12,0) -> 0 | J23: =B23*Dashboard!$C13 -> 11938.733 | K23: =Dashboard!$C14*12 -> 1800 | L23: =B23*Dashboard!$C16 -> 9948.9443 | M23: =IF(Dashboard!$C7<0.2,C23*Dashboard!$C17,0) -> 0 | O23: =O22+T23 -> 806111.23 | P23: =T23+U23 -> 52845.182 | Q23: =Q22*(1+Dashboard!$F11)+Dashboard!$F28*12 -> 559314.86 | R23: =Dashboard!$F6*Dashboard!$F9+O23+U23*20 -> 815911.23 | S23: =Q23-MAX(Q23-(Dashboard!$C8+Dashboard!$C6*Dashboard!$C19+Dashboard!$F6*Dashboard!$F9),0)*Dashboard!$F12 -> 493417.63 | T23: =Dashboard!$F6*(1+Dashboard!$F7)^(20-1)*12 -> 52605.182 | U23: =Dashboard!$F8*12 -> 240
A24: 21 | B24: =B23*(1+Dashboard!$C21) -> 1029715.7 | C24: =MAX((Dashboard!$C6-Dashboard!$C8)*(1+Dashboard!$C10/12)^(21*12)-Dashboard!$C26*((1+Dashboard!$C10/12)^(21*12)-1)/(Dashboard!$C10/12),0) -> 1732279.8 | D24: =I24+J24+K24+L24+M24 -> 24453.746 | E24: =E23+(D24-(C23-C24)) -> 1714697.8 | F24: =(Dashboard!$C6-Dashboard!$C8)-C24 -> -1332279.8 | G24: =G23+D24 -> 497417.92 | H24: =B24*(1-Dashboard!$C20)-C24 -> -764347.05 | I24: =IF(C23>0,Dashboard!$C26*12,0) -> 0 | J24: =B24*Dashboard!$C13 -> 12356.589 | K24: =Dashboard!$C14*12 -> 1800 | L24: =B24*Dashboard!$C16 -> 10297.157 | M24: =IF(Dashboard!$C7<0.2,C24*Dashboard!$C17,0) -> 0 | O24: =O23+T24 -> 860294.57 | P24: =T24+U24 -> 54423.337 | Q24: =Q23*(1+Dashboard!$F11)+Dashboard!$F28*12 -> 604060.05 | R24: =Dashboard!$F6*Dashboard!$F9+O24+U24*21 -> 870334.57 | S24: =Q24-MAX(Q24-(Dashboard!$C8+Dashboard!$C6*Dashboard!$C19+Dashboard!$F6*Dashboard!$F9),0)*Dashboard!$F12 -> 531451.04 | T24: =Dashboard!$F6*(1+Dashboard!$F7)^(21-1)*12 -> 54183.337 | U24: =Dashboard!$F8*12 -> 240
A25: 22 | B25: =B24*(1+Dashboard!$C21) -> 1065755.8 | C25: =MAX((Dashboard!$C6-Dashboard!$C8)*(1+Dashboard!$C10/12)^(22*12)-Dashboard!$C26*((1+Dashboard!$C10/12)^(22*12)-1)/(Dashboard!$C10/12),0) -> 1857506.5 | D25: =I25+J25+K25+L25+M25 -> 25246.627 | E25: =E24+(D25-(C24-C25)) -> 1865171 | F25: =(Dashboard!$C6-Dashboard!$C8)-C25 -> -1457506.5 | G25: =G24+D25 -> 522664.55 | H25: =B25*(1-Dashboard!$C20)-C25 -> -855696.05 | I25: =IF(C24>0,Dashboard!$C26*12,0) -> 0 | J25: =B25*Dashboard!$C13 -> 12789.069 | K25: =Dashboard!$C14*12 -> 1800 | L25: =B25*Dashboard!$C16 -> 10657.558 | M25: =IF(Dashboard!$C7<0.2,C25*Dashboard!$C17,0) -> 0 | O25: =O24+T25 -> 916103.41 | P25: =T25+U25 -> 56048.837 | Q25: =Q24*(1+Dashboard!$F11)+Dashboard!$F28*12 -> 652384.85 | R25: =Dashboard!$F6*Dashboard!$F9+O25+U25*22 -> 926383.41 | S25: =Q25-MAX(Q25-(Dashboard!$C8+Dashboard!$C6*Dashboard!$C19+Dashboard!$F6*Dashboard!$F9),0)*Dashboard!$F12 -> 572527.12 | T25: =Dashboard!$F6*(1+Dashboard!$F7)^(22-1)*12 -> 55808.837 | U25: =Dashboard!$F8*12 -> 240
A26: 23 | B26: =B25*(1+Dashboard!$C21) -> 1103057.2 | C26: =MAX((Dashboard!$C6-Dashboard!$C8)*(1+Dashboard!$C10/12)^(23*12)-Dashboard!$C26*((1+Dashboard!$C10/12)^(23*12)-1)/(Dashboard!$C10/12),0) -> 1991785.8 | D26: =I26+J26+K26+L26+M26 -> 26067.259 | E26: =E25+(D26-(C25-C26)) -> 2025517.6 | F26: =(Dashboard!$C6-Dashboard!$C8)-C26 -> -1591785.8 | G26: =G25+D26 -> 548731.81 | H26: =B26*(1-Dashboard!$C20)-C26 -> -954911.98 | I26: =IF(C25>0,Dashboard!$C26*12,0) -> 0 | J26: =B26*Dashboard!$C13 -> 13236.687 | K26: =Dashboard!$C14*12 -> 1800 | L26: =B26*Dashboard!$C16 -> 11030.572 | M26: =IF(Dashboard!$C7<0.2,C26*Dashboard!$C17,0) -> 0 | O26: =O25+T26 -> 973586.51 | P26: =T26+U26 -> 57723.102 | Q26: =Q25*(1+Dashboard!$F11)+Dashboard!$F28*12 -> 704575.64 | R26: =Dashboard!$F6*Dashboard!$F9+O26+U26*23 -> 984106.51 | S26: =Q26-MAX(Q26-(Dashboard!$C8+Dashboard!$C6*Dashboard!$C19+Dashboard!$F6*Dashboard!$F9),0)*Dashboard!$F12 -> 616889.29 | T26: =Dashboard!$F6*(1+Dashboard!$F7)^(23-1)*12 -> 57483.102 | U26: =Dashboard!$F8*12 -> 240
A27: 24 | B27: =B26*(1+Dashboard!$C21) -> 1141664.2 | C27: =MAX((Dashboard!$C6-Dashboard!$C8)*(1+Dashboard!$C10/12)^(24*12)-Dashboard!$C26*((1+Dashboard!$C10/12)^(24*12)-1)/(Dashboard!$C10/12),0) -> 2135772.1 | D27: =I27+J27+K27+L27+M27 -> 26916.613 | E27: =E26+(D27-(C26-C27)) -> 2196420.6 | F27: =(Dashboard!$C6-Dashboard!$C8)-C27 -> -1735772.1 | G27: =G26+D27 -> 575648.42 | H27: =B27*(1-Dashboard!$C20)-C27 -> -1062607.8 | I27: =IF(C26>0,Dashboard!$C26*12,0) -> 0 | J27: =B27*Dashboard!$C13 -> 13699.971 | K27: =Dashboard!$C14*12 -> 1800 | L27: =B27*Dashboard!$C16 -> 11416.642 | M27: =IF(Dashboard!$C7<0.2,C27*Dashboard!$C17,0) -> 0 | O27: =O26+T27 -> 1032794.1 | P27: =T27+U27 -> 59447.595 | Q27: =Q26*(1+Dashboard!$F11)+Dashboard!$F28*12 -> 760941.69 | R27: =Dashboard!$F6*Dashboard!$F9+O27+U27*24 -> 1043554.1 | S27: =Q27-MAX(Q27-(Dashboard!$C8+Dashboard!$C6*Dashboard!$C19+Dashboard!$F6*Dashboard!$F9),0)*Dashboard!$F12 -> 664800.44 | T27: =Dashboard!$F6*(1+Dashboard!$F7)^(24-1)*12 -> 59207.595 | U27: =Dashboard!$F8*12 -> 240
A28: 25 | B28: =B27*(1+Dashboard!$C21) -> 1181622.5 | C28: =MAX((Dashboard!$C6-Dashboard!$C8)*(1+Dashboard!$C10/12)^(25*12)-Dashboard!$C26*((1+Dashboard!$C10/12)^(25*12)-1)/(Dashboard!$C10/12),0) -> 2290167.3 | D28: =I28+J28+K28+L28+M28 -> 27795.695 | E28: =E27+(D28-(C27-C28)) -> 2378611.4 | F28: =(Dashboard!$C6-Dashboard!$C8)-C28 -> -1890167.3 | G28: =G27+D28 -> 603444.12 | H28: =B28*(1-Dashboard!$C20)-C28 -> -1179442.1 | I28: =IF(C27>0,Dashboard!$C26*12,0) -> 0 | J28: =B28*Dashboard!$C13 -> 14179.47 | K28: =Dashboard!$C14*12 -> 1800 | L28: =B28*Dashboard!$C16 -> 11816.225 | M28: =IF(Dashboard!$C7<0.2,C28*Dashboard!$C17,0) -> 0 | O28: =O27+T28 -> 1093777.9 | P28: =T28+U28 -> 61223.823 | Q28: =Q27*(1+Dashboard!$F11)+Dashboard!$F28*12 -> 821817.02 | R28: =Dashboard!$F6*Dashboard!$F9+O28+U28*25 -> 1104777.9 | S28: =Q28-MAX(Q28-(Dashboard!$C8+Dashboard!$C6*Dashboard!$C19+Dashboard!$F6*Dashboard!$F9),0)*Dashboard!$F12 -> 716544.47 | T28: =Dashboard!$F6*(1+Dashboard!$F7)^(25-1)*12 -> 60983.823 | U28: =Dashboard!$F8*12 -> 240
A29: 26 | B29: =B28*(1+Dashboard!$C21) -> 1222979.3 | C29: =MAX((Dashboard!$C6-Dashboard!$C8)*(1+Dashboard!$C10/12)^(26*12)-Dashboard!$C26*((1+Dashboard!$C10/12)^(26*12)-1)/(Dashboard!$C10/12),0) -> 2455723.7 | D29: =I29+J29+K29+L29+M29 -> 28705.544 | E29: =E28+(D29-(C28-C29)) -> 2572873.3 | F29: =(Dashboard!$C6-Dashboard!$C8)-C29 -> -2055723.7 | G29: =G28+D29 -> 632149.66 | H29: =B29*(1-Dashboard!$C20)-C29 -> -1306123.1 | I29: =IF(C28>0,Dashboard!$C26*12,0) -> 0 | J29: =B29*Dashboard!$C13 -> 14675.751 | K29: =Dashboard!$C14*12 -> 1800 | L29: =B29*Dashboard!$C16 -> 12229.793 | M29: =IF(Dashboard!$C7<0.2,C29*Dashboard!$C17,0) -> 0 | O29: =O28+T29 -> 1156591.3 | P29: =T29+U29 -> 63053.338 | Q29: =Q28*(1+Dashboard!$F11)+Dashboard!$F28*12 -> 887562.39 | R29: =Dashboard!$F6*Dashboard!$F9+O29+U29*26 -> 1167831.3 | S29: =Q29-MAX(Q29-(Dashboard!$C8+Dashboard!$C6*Dashboard!$C19+Dashboard!$F6*Dashboard!$F9),0)*Dashboard!$F12 -> 772428.03 | T29: =Dashboard!$F6*(1+Dashboard!$F7)^(26-1)*12 -> 62813.338 | U29: =Dashboard!$F8*12 -> 240
A30: 27 | B30: =B29*(1+Dashboard!$C21) -> 1265783.6 | C30: =MAX((Dashboard!$C6-Dashboard!$C8)*(1+Dashboard!$C10/12)^(27*12)-Dashboard!$C26*((1+Dashboard!$C10/12)^(27*12)-1)/(Dashboard!$C10/12),0) -> 2633248.1 | D30: =I30+J30+K30+L30+M30 -> 29647.238 | E30: =E29+(D30-(C29-C30)) -> 2780045 | F30: =(Dashboard!$C6-Dashboard!$C8)-C30 -> -2233248.1 | G30: =G29+D30 -> 661796.9 | H30: =B30*(1-Dashboard!$C20)-C30 -> -1443411.6 | I30: =IF(C29>0,Dashboard!$C26*12,0) -> 0 | J30: =B30*Dashboard!$C13 -> 15189.403 | K30: =Dashboard!$C14*12 -> 1800 | L30: =B30*Dashboard!$C16 -> 12657.836 | M30: =IF(Dashboard!$C7<0.2,C30*Dashboard!$C17,0) -> 0 | O30: =O29+T30 -> 1221289 | P30: =T30+U30 -> 64937.738 | Q30: =Q29*(1+Dashboard!$F11)+Dashboard!$F28*12 -> 958567.38 | R30: =Dashboard!$F6*Dashboard!$F9+O30+U30*27 -> 1232769 | S30: =Q30-MAX(Q30-(Dashboard!$C8+Dashboard!$C6*Dashboard!$C19+Dashboard!$F6*Dashboard!$F9),0)*Dashboard!$F12 -> 832782.27 | T30: =Dashboard!$F6*(1+Dashboard!$F7)^(27-1)*12 -> 64697.738 | U30: =Dashboard!$F8*12 -> 240
A31: 28 | B31: =B30*(1+Dashboard!$C21) -> 1310086 | C31: =MAX((Dashboard!$C6-Dashboard!$C8)*(1+Dashboard!$C10/12)^(28*12)-Dashboard!$C26*((1+Dashboard!$C10/12)^(28*12)-1)/(Dashboard!$C10/12),0) -> 2823605.8 | D31: =I31+J31+K31+L31+M31 -> 30621.892 | E31: =E30+(D31-(C30-C31)) -> 3001024.6 | F31: =(Dashboard!$C6-Dashboard!$C8)-C31 -> -2423605.8 | G31: =G30+D31 -> 692418.79 | H31: =B31*(1-Dashboard!$C20)-C31 -> -1592125 | I31: =IF(C30>0,Dashboard!$C26*12,0) -> 0 | J31: =B31*Dashboard!$C13 -> 15721.032 | K31: =Dashboard!$C14*12 -> 1800 | L31: =B31*Dashboard!$C16 -> 13100.86 | M31: =IF(Dashboard!$C7<0.2,C31*Dashboard!$C17,0) -> 0 | O31: =O30+T31 -> 1287927.7 | P31: =T31+U31 -> 66878.67 | Q31: =Q30*(1+Dashboard!$F11)+Dashboard!$F28*12 -> 1035252.8 | R31: =Dashboard!$F6*Dashboard!$F9+O31+U31*28 -> 1299647.7 | S31: =Q31-MAX(Q31-(Dashboard!$C8+Dashboard!$C6*Dashboard!$C19+Dashboard!$F6*Dashboard!$F9),0)*Dashboard!$F12 -> 897964.85 | T31: =Dashboard!$F6*(1+Dashboard!$F7)^(28-1)*12 -> 66638.67 | U31: =Dashboard!$F8*12 -> 240
A32: 29 | B32: =B31*(1+Dashboard!$C21) -> 1355939 | C32: =MAX((Dashboard!$C6-Dashboard!$C8)*(1+Dashboard!$C10/12)^(29*12)-Dashboard!$C26*((1+Dashboard!$C10/12)^(29*12)-1)/(Dashboard!$C10/12),0) -> 3027724.5 | D32: =I32+J32+K32+L32+M32 -> 31630.658 | E32: =E31+(D32-(C31-C32)) -> 3236774 | F32: =(Dashboard!$C6-Dashboard!$C8)-C32 -> -2627724.5 | G32: =G31+D32 -> 724049.45 | H32: =B32*(1-Dashboard!$C20)-C32 -> -1753141.9 | I32: =IF(C31>0,Dashboard!$C26*12,0) -> 0 | J32: =B32*Dashboard!$C13 -> 16271.268 | K32: =Dashboard!$C14*12 -> 1800 | L32: =B32*Dashboard!$C16 -> 13559.39 | M32: =IF(Dashboard!$C7<0.2,C32*Dashboard!$C17,0) -> 0 | O32: =O31+T32 -> 1356565.5 | P32: =T32+U32 -> 68877.83 | Q32: =Q31*(1+Dashboard!$F11)+Dashboard!$F28*12 -> 1118073 | R32: =Dashboard!$F6*Dashboard!$F9+O32+U32*29 -> 1368525.5 | S32: =Q32-MAX(Q32-(Dashboard!$C8+Dashboard!$C6*Dashboard!$C19+Dashboard!$F6*Dashboard!$F9),0)*Dashboard!$F12 -> 968362.04 | T32: =Dashboard!$F6*(1+Dashboard!$F7)^(29-1)*12 -> 68637.83 | U32: =Dashboard!$F8*12 -> 240
A33: 30 | B33: =B32*(1+Dashboard!$C21) -> 1403396.9 | C33: =MAX((Dashboard!$C6-Dashboard!$C8)*(1+Dashboard!$C10/12)^(30*12)-Dashboard!$C26*((1+Dashboard!$C10/12)^(30*12)-1)/(Dashboard!$C10/12),0) -> 3246599 | D33: =I33+J33+K33+L33+M33 -> 32674.731 | E33: =E32+(D33-(C32-C33)) -> 3488323.2 | F33: =(Dashboard!$C6-Dashboard!$C8)-C33 -> -2846599 | G33: =G32+D33 -> 756724.18 | H33: =B33*(1-Dashboard!$C20)-C33 -> -1927405.9 | I33: =IF(C32>0,Dashboard!$C26*12,0) -> 0 | J33: =B33*Dashboard!$C13 -> 16840.762 | K33: =Dashboard!$C14*12 -> 1800 | L33: =B33*Dashboard!$C16 -> 14033.969 | M33: =IF(Dashboard!$C7<0.2,C33*Dashboard!$C17,0) -> 0 | O33: =O32+T33 -> 1427262.5 | P33: =T33+U33 -> 70936.965 | Q33: =Q32*(1+Dashboard!$F11)+Dashboard!$F28*12 -> 1207518.8 | R33: =Dashboard!$F6*Dashboard!$F9+O33+U33*30 -> 1439462.5 | S33: =Q33-MAX(Q33-(Dashboard!$C8+Dashboard!$C6*Dashboard!$C19+Dashboard!$F6*Dashboard!$F9),0)*Dashboard!$F12 -> 1044391 | T33: =Dashboard!$F6*(1+Dashboard!$F7)^(30-1)*12 -> 70696.965 | U33: =Dashboard!$F8*12 -> 240
A34: 31 | B34: =B33*(1+Dashboard!$C21) -> 1452515.7 | C34: =MAX((Dashboard!$C6-Dashboard!$C8)*(1+Dashboard!$C10/12)^(31*12)-Dashboard!$C26*((1+Dashboard!$C10/12)^(31*12)-1)/(Dashboard!$C10/12),0) -> 3481295.9 | D34: =I34+J34+K34+L34+M34 -> 33755.346 | E34: =E33+(D34-(C33-C34)) -> 3756775.4 | F34: =(Dashboard!$C6-Dashboard!$C8)-C34 -> -3081295.9 | G34: =G33+D34 -> 790479.53 | H34: =B34*(1-Dashboard!$C20)-C34 -> -2115931.1 | I34: =IF(C33>0,Dashboard!$C26*12,0) -> 0 | J34: =B34*Dashboard!$C13 -> 17430.189 | K34: =Dashboard!$C14*12 -> 1800 | L34: =B34*Dashboard!$C16 -> 14525.157 | M34: =IF(Dashboard!$C7<0.2,C34*Dashboard!$C17,0) -> 0 | O34: =O33+T34 -> 1500080.3 | P34: =T34+U34 -> 73057.874 | Q34: =Q33*(1+Dashboard!$F11)+Dashboard!$F28*12 -> 1304120.3 | R34: =Dashboard!$F6*Dashboard!$F9+O34+U34*31 -> 1512520.3 | S34: =Q34-MAX(Q34-(Dashboard!$C8+Dashboard!$C6*Dashboard!$C19+Dashboard!$F6*Dashboard!$F9),0)*Dashboard!$F12 -> 1126502.3 | T34: =Dashboard!$F6*(1+Dashboard!$F7)^(31-1)*12 -> 72817.874 | U34: =Dashboard!$F8*12 -> 240
A35: 32 | B35: =B34*(1+Dashboard!$C21) -> 1503353.8 | C35: =MAX((Dashboard!$C6-Dashboard!$C8)*(1+Dashboard!$C10/12)^(32*12)-Dashboard!$C26*((1+Dashboard!$C10/12)^(32*12)-1)/(Dashboard!$C10/12),0) -> 3732959.1 | D35: =I35+J35+K35+L35+M35 -> 34873.783 | E35: =E34+(D35-(C34-C35)) -> 4043312.4 | F35: =(Dashboard!$C6-Dashboard!$C8)-C35 -> -3332959.1 | G35: =G34+D35 -> 825353.31 | H35: =B35*(1-Dashboard!$C20)-C35 -> -2319806.5 | I35: =IF(C34>0,Dashboard!$C26*12,0) -> 0 | J35: =B35*Dashboard!$C13 -> 18040.246 | K35: =Dashboard!$C14*12 -> 1800 | L35: =B35*Dashboard!$C16 -> 15033.538 | M35: =IF(Dashboard!$C7<0.2,C35*Dashboard!$C17,0) -> 0 | O35: =O34+T35 -> 1575082.8 | P35: =T35+U35 -> 75242.41 | Q35: =Q34*(1+Dashboard!$F11)+Dashboard!$F28*12 -> 1408450 | R35: =Dashboard!$F6*Dashboard!$F9+O35+U35*32 -> 1587762.8 | S35: =Q35-MAX(Q35-(Dashboard!$C8+Dashboard!$C6*Dashboard!$C19+Dashboard!$F6*Dashboard!$F9),0)*Dashboard!$F12 -> 1215182.5 | T35: =Dashboard!$F6*(1+Dashboard!$F7)^(32-1)*12 -> 75002.41 | U35: =Dashboard!$F8*12 -> 240
A36: 33 | B36: =B35*(1+Dashboard!$C21) -> 1555971.2 | C36: =MAX((Dashboard!$C6-Dashboard!$C8)*(1+Dashboard!$C10/12)^(33*12)-Dashboard!$C26*((1+Dashboard!$C10/12)^(33*12)-1)/(Dashboard!$C10/12),0) -> 4002815 | D36: =I36+J36+K36+L36+M36 -> 36031.366 | E36: =E35+(D36-(C35-C36)) -> 4349199.6 | F36: =(Dashboard!$C6-Dashboard!$C8)-C36 -> -3602815 | G36: =G35+D36 -> 861384.68 | H36: =B36*(1-Dashboard!$C20)-C36 -> -2540202.1 | I36: =IF(C35>0,Dashboard!$C26*12,0) -> 0 | J36: =B36*Dashboard!$C13 -> 18671.654 | K36: =Dashboard!$C14*12 -> 1800 | L36: =B36*Dashboard!$C16 -> 15559.712 | M36: =IF(Dashboard!$C7<0.2,C36*Dashboard!$C17,0) -> 0 | O36: =O35+T36 -> 1652335.2 | P36: =T36+U36 -> 77492.483 | Q36: =Q35*(1+Dashboard!$F11)+Dashboard!$F28*12 -> 1521126 | R36: =Dashboard!$F6*Dashboard!$F9+O36+U36*33 -> 1665255.2 | S36: =Q36-MAX(Q36-(Dashboard!$C8+Dashboard!$C6*Dashboard!$C19+Dashboard!$F6*Dashboard!$F9),0)*Dashboard!$F12 -> 1310957.1 | T36: =Dashboard!$F6*(1+Dashboard!$F7)^(33-1)*12 -> 77252.483 | U36: =Dashboard!$F8*12 -> 240
A37: 34 | B37: =B36*(1+Dashboard!$C21) -> 1610430.2 | C37: =MAX((Dashboard!$C6-Dashboard!$C8)*(1+Dashboard!$C10/12)^(34*12)-Dashboard!$C26*((1+Dashboard!$C10/12)^(34*12)-1)/(Dashboard!$C10/12),0) -> 4292178.8 | D37: =I37+J37+K37+L37+M37 -> 37229.464 | E37: =E36+(D37-(C36-C37)) -> 4675792.9 | F37: =(Dashboard!$C6-Dashboard!$C8)-C37 -> -3892178.8 | G37: =G36+D37 -> 898614.14 | H37: =B37*(1-Dashboard!$C20)-C37 -> -2778374.4 | I37: =IF(C36>0,Dashboard!$C26*12,0) -> 0 | J37: =B37*Dashboard!$C13 -> 19325.162 | K37: =Dashboard!$C14*12 -> 1800 | L37: =B37*Dashboard!$C16 -> 16104.302 | M37: =IF(Dashboard!$C7<0.2,C37*Dashboard!$C17,0) -> 0 | O37: =O36+T37 -> 1731905.3 | P37: =T37+U37 -> 79810.057 | Q37: =Q36*(1+Dashboard!$F11)+Dashboard!$F28*12 -> 1642816 | R37: =Dashboard!$F6*Dashboard!$F9+O37+U37*34 -> 1745065.3 | S37: =Q37-MAX(Q37-(Dashboard!$C8+Dashboard!$C6*Dashboard!$C19+Dashboard!$F6*Dashboard!$F9),0)*Dashboard!$F12 -> 1414393.6 | T37: =Dashboard!$F6*(1+Dashboard!$F7)^(34-1)*12 -> 79570.057 | U37: =Dashboard!$F8*12 -> 240
A38: 35 | B38: =B37*(1+Dashboard!$C21) -> 1666795.2 | C38: =MAX((Dashboard!$C6-Dashboard!$C8)*(1+Dashboard!$C10/12)^(35*12)-Dashboard!$C26*((1+Dashboard!$C10/12)^(35*12)-1)/(Dashboard!$C10/12),0) -> 4602460.7 | D38: =I38+J38+K38+L38+M38 -> 38469.495 | E38: =E37+(D38-(C37-C38)) -> 5024544.4 | F38: =(Dashboard!$C6-Dashboard!$C8)-C38 -> -4202460.7 | G38: =G37+D38 -> 937083.64 | H38: =B38*(1-Dashboard!$C20)-C38 -> -3035673.2 | I38: =IF(C37>0,Dashboard!$C26*12,0) -> 0 | J38: =B38*Dashboard!$C13 -> 20001.543 | K38: =Dashboard!$C14*12 -> 1800 | L38: =B38*Dashboard!$C16 -> 16667.952 | M38: =IF(Dashboard!$C7<0.2,C38*Dashboard!$C17,0) -> 0 | O38: =O37+T38 -> 1813862.5 | P38: =T38+U38 -> 82197.159 | Q38: =Q37*(1+Dashboard!$F11)+Dashboard!$F28*12 -> 1774241.3 | R38: =Dashboard!$F6*Dashboard!$F9+O38+U38*35 -> 1827262.5 | S38: =Q38-MAX(Q38-(Dashboard!$C8+Dashboard!$C6*Dashboard!$C19+Dashboard!$F6*Dashboard!$F9),0)*Dashboard!$F12 -> 1526105.1 | T38: =Dashboard!$F6*(1+Dashboard!$F7)^(35-1)*12 -> 81957.159 | U38: =Dashboard!$F8*12 -> 240
A39: 36 | B39: =B38*(1+Dashboard!$C21) -> 1725133.1 | C39: =MAX((Dashboard!$C6-Dashboard!$C8)*(1+Dashboard!$C10/12)^(36*12)-Dashboard!$C26*((1+Dashboard!$C10/12)^(36*12)-1)/(Dashboard!$C10/12),0) -> 4935173 | D39: =I39+J39+K39+L39+M39 -> 39752.927 | E39: =E38+(D39-(C38-C39)) -> 5397009.6 | F39: =(Dashboard!$C6-Dashboard!$C8)-C39 -> -4535173 | G39: =G38+D39 -> 976836.56 | H39: =B39*(1-Dashboard!$C20)-C39 -> -3313547.9 | I39: =IF(C38>0,Dashboard!$C26*12,0) -> 0 | J39: =B39*Dashboard!$C13 -> 20701.597 | K39: =Dashboard!$C14*12 -> 1800 | L39: =B39*Dashboard!$C16 -> 17251.331 | M39: =IF(Dashboard!$C7<0.2,C39*Dashboard!$C17,0) -> 0 | O39: =O38+T39 -> 1898278.3 | P39: =T39+U39 -> 84655.874 | Q39: =Q38*(1+Dashboard!$F11)+Dashboard!$F28*12 -> 1916180.6 | R39: =Dashboard!$F6*Dashboard!$F9+O39+U39*36 -> 1911918.3 | S39: =Q39-MAX(Q39-(Dashboard!$C8+Dashboard!$C6*Dashboard!$C19+Dashboard!$F6*Dashboard!$F9),0)*Dashboard!$F12 -> 1646753.5 | T39: =Dashboard!$F6*(1+Dashboard!$F7)^(36-1)*12 -> 84415.874 | U39: =Dashboard!$F8*12 -> 240
A40: 37 | B40: =B39*(1+Dashboard!$C21) -> 1785512.7 | C40: =MAX((Dashboard!$C6-Dashboard!$C8)*(1+Dashboard!$C10/12)^(37*12)-Dashboard!$C26*((1+Dashboard!$C10/12)^(37*12)-1)/(Dashboard!$C10/12),0) -> 5291937 | D40: =I40+J40+K40+L40+M40 -> 41081.28 | E40: =E39+(D40-(C39-C40)) -> 5794854.9 | F40: =(Dashboard!$C6-Dashboard!$C8)-C40 -> -4891937 | G40: =G39+D40 -> 1017917.8 | H40: =B40*(1-Dashboard!$C20)-C40 -> -3613555.1 | I40: =IF(C39>0,Dashboard!$C26*12,0) -> 0 | J40: =B40*Dashboard!$C13 -> 21426.153 | K40: =Dashboard!$C14*12 -> 1800 | L40: =B40*Dashboard!$C16 -> 17855.127 | M40: =IF(Dashboard!$C7<0.2,C40*Dashboard!$C17,0) -> 0 | O40: =O39+T40 -> 1985226.7 | P40: =T40+U40 -> 87188.35 | Q40: =Q39*(1+Dashboard!$F11)+Dashboard!$F28*12 -> 2069475.1 | R40: =Dashboard!$F6*Dashboard!$F9+O40+U40*37 -> 1999106.7 | S40: =Q40-MAX(Q40-(Dashboard!$C8+Dashboard!$C6*Dashboard!$C19+Dashboard!$F6*Dashboard!$F9),0)*Dashboard!$F12 -> 1777053.8 | T40: =Dashboard!$F6*(1+Dashboard!$F7)^(37-1)*12 -> 86948.35 | U40: =Dashboard!$F8*12 -> 240
...

Sheet Charts
A1: 📈 INTERACTIVE CHARTS — Net Worth Timeline & Expense Breakdown
A2: CHART CUSTOMIZATION — Change these to update charts
A3: Chart Start Year | B3: 1 | C3: Chart End Year | D3: 30
A5: CHART DATA (auto-calculated from Schedule & Dashboard)
A6: Year | B6: Buyer Net Worth | C6: Renter Net Worth | D6: Buyer Cash Spent | E6: Renter Cash Spent | F6: Home Value | G6: Portfolio Value | H6: Ann. Buyer Cost | I6: Ann. Rent Cost
A7: 0 | B7: =IFERROR(Schedule!$H$3,0) -> 70000 | C7: =IFERROR(Schedule!$S$3,0) -> 120000 | D7: =IFERROR(Schedule!$G$3,0) -> 115000 | E7: =IFERROR(Schedule!$R$3,0) -> 5000 | F7: =IFERROR(Schedule!$B$3,0) -> 500000 | G7: =IFERROR(Schedule!$Q$3,0) -> 120000 | H7: =IFERROR(Schedule!$D$3,0) -> 0 | I7: =IFERROR(Schedule!$P$3,0) -> 0
A8: 1 | B8: =IFERROR(Schedule!$H$4,0) -> 57533.968 | C8: =IFERROR(Schedule!$S$4,0) -> 128160 | D8: =IFERROR(Schedule!$G$4,0) -> 128185 | E8: =IFERROR(Schedule!$R$4,0) -> 35240 | F8: =IFERROR(Schedule!$B$4,0) -> 517500 | G8: =IFERROR(Schedule!$Q$4,0) -> 129600 | H8: =IFERROR(Schedule!$D$4,0) -> 13185 | I8: =IFERROR(Schedule!$P$4,0) -> 30240
A9: 2 | B9: =IFERROR(Schedule!$H$5,0) -> 43553.343 | C9: =IFERROR(Schedule!$S$5,0) -> 136972.8 | D9: =IFERROR(Schedule!$G$5,0) -> 141768.48 | E9: =IFERROR(Schedule!$R$5,0) -> 66380 | F9: =IFERROR(Schedule!$B$5,0) -> 535612.5 | G9: =IFERROR(Schedule!$Q$5,0) -> 139968 | H9: =IFERROR(Schedule!$D$5,0) -> 13583.475 | I9: =IFERROR(Schedule!$P$5,0) -> 31140
A10: 3 | B10: =IFERROR(Schedule!$H$6,0) -> 27927.166 | C10: =IFERROR(Schedule!$S$6,0) -> 146490.62 | D10: =IFERROR(Schedule!$G$6,0) -> 155764.37 | E10: =IFERROR(Schedule!$R$6,0) -> 98447 | F10: =IFERROR(Schedule!$B$6,0) -> 554358.94 | G10: =IFERROR(Schedule!$Q$6,0) -> 151165.44 | H10: =IFERROR(Schedule!$D$6,0) -> 13995.897 | I10: =IFERROR(Schedule!$P$6,0) -> 32067
A11: 4 | B11: =IFERROR(Schedule!$H$7,0) -> 10514.259 | C11: =IFERROR(Schedule!$S$7,0) -> 156769.87 | D11: =IFERROR(Schedule!$G$7,0) -> 170187.12 | E11: =IFERROR(Schedule!$R$7,0) -> 131468.81 | F11: =IFERROR(Schedule!$B$7,0) -> 573761.5 | G11: =IFERROR(Schedule!$Q$7,0) -> 163258.68 | H11: =IFERROR(Schedule!$D$7,0) -> 14422.753 | I11: =IFERROR(Schedule!$P$7,0) -> 33021.81
A12: 5 | B12: =IFERROR(Schedule!$H$8,0) -> -8837.5402 | C12: =IFERROR(Schedule!$S$8,0) -> 167871.46 | D12: =IFERROR(Schedule!$G$8,0) -> 185051.67 | E12: =IFERROR(Schedule!$R$8,0) -> 165474.07 | F12: =IFERROR(Schedule!$B$8,0) -> 593843.15 | G12: =IFERROR(Schedule!$Q$8,0) -> 176319.37 | H12: =IFERROR(Schedule!$D$8,0) -> 14864.549 | I12: =IFERROR(Schedule!$P$8,0) -> 34005.264
A13: 6 | B13: =IFERROR(Schedule!$H$9,0) -> -30292.198 | C13: =IFERROR(Schedule!$S$9,0) -> 179861.18 | D13: =IFERROR(Schedule!$G$9,0) -> 200373.48 | E13: =IFERROR(Schedule!$R$9,0) -> 200492.3 | F13: =IFERROR(Schedule!$B$9,0) -> 614627.66 | G13: =IFERROR(Schedule!$Q$9,0) -> 190424.92 | H13: =IFERROR(Schedule!$D$9,0) -> 15321.809 | I13: =IFERROR(Schedule!$P$9,0) -> 35018.222
A14: 7 | B14: =IFERROR(Schedule!$H$10,0) -> -54026.368 | C14: =IFERROR(Schedule!$S$10,0) -> 192810.08 | D14: =IFERROR(Schedule!$G$10,0) -> 216168.55 | E14: =IFERROR(Schedule!$R$10,0) -> 236553.87 | F14: =IFERROR(Schedule!$B$10,0) -> 636139.63 | G14: =IFERROR(Schedule!$Q$10,0) -> 205658.91 | H14: =IFERROR(Schedule!$D$10,0) -> 15795.072 | I14: =IFERROR(Schedule!$P$10,0) -> 36061.569
A15: 8 | B15: =IFERROR(Schedule!$H$11,0) -> -80230.335 | C15: =IFERROR(Schedule!$S$11,0) -> 206794.88 | D15: =IFERROR(Schedule!$G$11,0) -> 232453.45 | E15: =IFERROR(Schedule!$R$11,0) -> 273690.08 | F15: =IFERROR(Schedule!$B$11,0) -> 658404.52 | G15: =IFERROR(Schedule!$Q$11,0) -> 222111.63 | H15: =IFERROR(Schedule!$D$11,0) -> 16284.899 | I15: =IFERROR(Schedule!$P$11,0) -> 37136.216
A16: 9 | B16: =IFERROR(Schedule!$H$12,0) -> -109109.03 | C16: =IFERROR(Schedule!$S$12,0) -> 221898.47 | D16: =IFERROR(Schedule!$G$12,0) -> 249245.32 | E16: =IFERROR(Schedule!$R$12,0) -> 311933.18 | F16: =IFERROR(Schedule!$B$12,0) -> 681448.68 | G16: =IFERROR(Schedule!$Q$12,0) -> 239880.56 | H16: =IFERROR(Schedule!$D$12,0) -> 16791.871 | I16: =IFERROR(Schedule!$P$12,0) -> 38243.102
A17: 10 | B17: =IFERROR(Schedule!$H$13,0) -> -140883.13 | C17: =IFERROR(Schedule!$S$13,0) -> 238210.35 | D17: =IFERROR(Schedule!$G$13,0) -> 266561.91 | E17: =IFERROR(Schedule!$R$13,0) -> 351316.38 | F17: =IFERROR(Schedule!$B$13,0) -> 705299.38 | G17: =IFERROR(Schedule!$Q$13,0) -> 259071 | H17: =IFERROR(Schedule!$D$13,0) -> 17316.586 | I17: =IFERROR(Schedule!$P$13,0) -> 39383.196
A18: 11 | B18: =IFERROR(Schedule!$H$14,0) -> -175790.22 | C18: =IFERROR(Schedule!$S$14,0) -> 255827.18 | D18: =IFERROR(Schedule!$G$14,0) -> 284421.58 | E18: =IFERROR(Schedule!$R$14,0) -> 391873.87 | F18: =IFERROR(Schedule!$B$14,0) -> 729984.86 | G18: =IFERROR(Schedule!$Q$14,0) -> 279796.68 | H18: =IFERROR(Schedule!$D$14,0) -> 17859.667 | I18: =IFERROR(Schedule!$P$14,0) -> 40557.491
A19: 12 | B19: =IFERROR(Schedule!$H$15,0) -> -214086.03 | C19: =IFERROR(Schedule!$S$15,0) -> 274853.35 | D19: =IFERROR(Schedule!$G$15,0) -> 302843.33 | E19: =IFERROR(Schedule!$R$15,0) -> 433640.89 | F19: =IFERROR(Schedule!$B$15,0) -> 755534.33 | G19: =IFERROR(Schedule!$Q$15,0) -> 302180.41 | H19: =IFERROR(Schedule!$D$15,0) -> 18421.755 | I19: =IFERROR(Schedule!$P$15,0) -> 41767.016
A20: 13 | B20: =IFERROR(Schedule!$H$16,0) -> -256045.83 | C20: =IFERROR(Schedule!$S$16,0) -> 295401.62 | D20: =IFERROR(Schedule!$G$16,0) -> 321846.85 | E20: =IFERROR(Schedule!$R$16,0) -> 476653.71 | F20: =IFERROR(Schedule!$B$16,0) -> 781978.03 | G20: =IFERROR(Schedule!$Q$16,0) -> 326354.85 | H20: =IFERROR(Schedule!$D$16,0) -> 19003.517 | I20: =IFERROR(Schedule!$P$16,0) -> 43012.827
A21: 14 | B21: =IFERROR(Schedule!$H$17,0) -> -301965.82 | C21: =IFERROR(Schedule!$S$17,0) -> 317593.75 | D21: =IFERROR(Schedule!$G$17,0) -> 341452.49 | E21: =IFERROR(Schedule!$R$17,0) -> 520949.72 | F21: =IFERROR(Schedule!$B$17,0) -> 809347.26 | G21: =IFERROR(Schedule!$Q$17,0) -> 352463.23 | H21: =IFERROR(Schedule!$D$17,0) -> 19605.64 | I21: =IFERROR(Schedule!$P$17,0) -> 44296.011
A22: 15 | B22: =IFERROR(Schedule!$H$18,0) -> -352164.74 | C22: =IFERROR(Schedule!$S$18,0) -> 341561.25 | D22: =IFERROR(Schedule!$G$18,0) -> 361681.33 | E22: =IFERROR(Schedule!$R$18,0) -> 566567.42 | F22: =IFERROR(Schedule!$B$18,0) -> 837674.42 | G22: =IFERROR(Schedule!$Q$18,0) -> 380660.29 | H22: =IFERROR(Schedule!$D$18,0) -> 20228.837 | I22: =IFERROR(Schedule!$P$18,0) -> 45617.692
A23: 16 | B23: =IFERROR(Schedule!$H$19,0) -> -406985.49 | C23: =IFERROR(Schedule!$S$19,0) -> 367446.15 | D23: =IFERROR(Schedule!$G$19,0) -> 382555.17 | E23: =IFERROR(Schedule!$R$19,0) -> 613546.44 | F23: =IFERROR(Schedule!$B$19,0) -> 866993.02 | G23: =IFERROR(Schedule!$Q$19,0) -> 411113.12 | H23: =IFERROR(Schedule!$D$19,0) -> 20873.846 | I23: =IFERROR(Schedule!$P$19,0) -> 46979.022
A24: 17 | B24: =IFERROR(Schedule!$H$20,0) -> -466796.93 | C24: =IFERROR(Schedule!$S$20,0) -> 395401.84 | D24: =IFERROR(Schedule!$G$20,0) -> 404096.6 | E24: =IFERROR(Schedule!$R$20,0) -> 661927.63 | F24: =IFERROR(Schedule!$B$20,0) -> 897337.78 | G24: =IFERROR(Schedule!$Q$20,0) -> 444002.17 | H24: =IFERROR(Schedule!$D$20,0) -> 21541.431 | I24: =IFERROR(Schedule!$P$20,0) -> 48381.193
A25: 18 | B25: =IFERROR(Schedule!$H$21,0) -> -531995.81 | C25: =IFERROR(Schedule!$S$21,0) -> 425593.99 | D25: =IFERROR(Schedule!$G$21,0) -> 426328.99 | E25: =IFERROR(Schedule!$R$21,0) -> 711753.06 | F25: =IFERROR(Schedule!$B$21,0) -> 928744.6 | G25: =IFERROR(Schedule!$Q$21,0) -> 479522.34 | H25: =IFERROR(Schedule!$D$21,0) -> 22232.381 | I25: =IFERROR(Schedule!$P$21,0) -> 49825.429
A26: 19 | B26: =IFERROR(Schedule!$H$22,0) -> -603008.81 | C26: =IFERROR(Schedule!$S$22,0) -> 458201.51 | D26: =IFERROR(Schedule!$G$22,0) -> 449276.5 | E26: =IFERROR(Schedule!$R$22,0) -> 763066.05 | F26: =IFERROR(Schedule!$B$22,0) -> 961250.66 | G26: =IFERROR(Schedule!$Q$22,0) -> 517884.13 | H26: =IFERROR(Schedule!$D$22,0) -> 22947.514 | I26: =IFERROR(Schedule!$P$22,0) -> 51312.992
A27: 20 | B27: =IFERROR(Schedule!$H$23,0) -> -680294.77 | C27: =IFERROR(Schedule!$S$23,0) -> 493417.63 | D27: =IFERROR(Schedule!$G$23,0) -> 472964.18 | E27: =IFERROR(Schedule!$R$23,0) -> 815911.23 | F27: =IFERROR(Schedule!$B$23,0) -> 994894.43 | G27: =IFERROR(Schedule!$Q$23,0) -> 559314.86 | H27: =IFERROR(Schedule!$D$23,0) -> 23687.677 | I27: =IFERROR(Schedule!$P$23,0) -> 52845.182
A28: 21 | B28: =IFERROR(Schedule!$H$24,0) -> -764347.05 | C28: =IFERROR(Schedule!$S$24,0) -> 531451.04 | D28: =IFERROR(Schedule!$G$24,0) -> 497417.92 | E28: =IFERROR(Schedule!$R$24,0) -> 870334.57 | F28: =IFERROR(Schedule!$B$24,0) -> 1029715.7 | G28: =IFERROR(Schedule!$Q$24,0) -> 604060.05 | H28: =IFERROR(Schedule!$D$24,0) -> 24453.746 | I28: =IFERROR(Schedule!$P$24,0) -> 54423.337
A29: 22 | B29: =IFERROR(Schedule!$H$25,0) -> -855696.05 | C29: =IFERROR(Schedule!$S$25,0) -> 572527.12 | D29: =IFERROR(Schedule!$G$25,0) -> 522664.55 | E29: =IFERROR(Schedule!$R$25,0) -> 926383.41 | F29: =IFERROR(Schedule!$B$25,0) -> 1065755.8 | G29: =IFERROR(Schedule!$Q$25,0) -> 652384.85 | H29: =IFERROR(Schedule!$D$25,0) -> 25246.627 | I29: =IFERROR(Schedule!$P$25,0) -> 56048.837
A30: 23 | B30: =IFERROR(Schedule!$H$26,0) -> -954911.98 | C30: =IFERROR(Schedule!$S$26,0) -> 616889.29 | D30: =IFERROR(Schedule!$G$26,0) -> 548731.81 | E30: =IFERROR(Schedule!$R$26,0) -> 984106.51 | F30: =IFERROR(Schedule!$B$26,0) -> 1103057.2 | G30: =IFERROR(Schedule!$Q$26,0) -> 704575.64 | H30: =IFERROR(Schedule!$D$26,0) -> 26067.259 | I30: =IFERROR(Schedule!$P$26,0) -> 57723.102
A31: 24 | B31: =IFERROR(Schedule!$H$27,0) -> -1062607.8 | C31: =IFERROR(Schedule!$S$27,0) -> 664800.44 | D31: =IFERROR(Schedule!$G$27,0) -> 575648.42 | E31: =IFERROR(Schedule!$R$27,0) -> 1043554.1 | F31: =IFERROR(Schedule!$B$27,0) -> 1141664.2 | G31: =IFERROR(Schedule!$Q$27,0) -> 760941.69 | H31: =IFERROR(Schedule!$D$27,0) -> 26916.613 | I31: =IFERROR(Schedule!$P$27,0) -> 59447.595
A32: 25 | B32: =IFERROR(Schedule!$H$28,0) -> -1179442.1 | C32: =IFERROR(Schedule!$S$28,0) -> 716544.47 | D32: =IFERROR(Schedule!$G$28,0) -> 603444.12 | E32: =IFERROR(Schedule!$R$28,0) -> 1104777.9 | F32: =IFERROR(Schedule!$B$28,0) -> 1181622.5 | G32: =IFERROR(Schedule!$Q$28,0) -> 821817.02 | H32: =IFERROR(Schedule!$D$28,0) -> 27795.695 | I32: =IFERROR(Schedule!$P$28,0) -> 61223.823
A33: 26 | B33: =IFERROR(Schedule!$H$29,0) -> -1306123.1 | C33: =IFERROR(Schedule!$S$29,0) -> 772428.03 | D33: =IFERROR(Schedule!$G$29,0) -> 632149.66 | E33: =IFERROR(Schedule!$R$29,0) -> 1167831.3 | F33: =IFERROR(Schedule!$B$29,0) -> 1222979.3 | G33: =IFERROR(Schedule!$Q$29,0) -> 887562.39 | H33: =IFERROR(Schedule!$D$29,0) -> 28705.544 | I33: =IFERROR(Schedule!$P$29,0) -> 63053.338
A34: 27 | B34: =IFERROR(Schedule!$H$30,0) -> -1443411.6 | C34: =IFERROR(Schedule!$S$30,0) -> 832782.27 | D34: =IFERROR(Schedule!$G$30,0) -> 661796.9 | E34: =IFERROR(Schedule!$R$30,0) -> 1232769 | F34: =IFERROR(Schedule!$B$30,0) -> 1265783.6 | G34: =IFERROR(Schedule!$Q$30,0) -> 958567.38 | H34: =IFERROR(Schedule!$D$30,0) -> 29647.238 | I34: =IFERROR(Schedule!$P$30,0) -> 64937.738
A35: 28 | B35: =IFERROR(Schedule!$H$31,0) -> -1592125 | C35: =IFERROR(Schedule!$S$31,0) -> 897964.85 | D35: =IFERROR(Schedule!$G$31,0) -> 692418.79 | E35: =IFERROR(Schedule!$R$31,0) -> 1299647.7 | F35: =IFERROR(Schedule!$B$31,0) -> 1310086 | G35: =IFERROR(Schedule!$Q$31,0) -> 1035252.8 | H35: =IFERROR(Schedule!$D$31,0) -> 30621.892 | I35: =IFERROR(Schedule!$P$31,0) -> 66878.67
A36: 29 | B36: =IFERROR(Schedule!$H$32,0) -> -1753141.9 | C36: =IFERROR(Schedule!$S$32,0) -> 968362.04 | D36: =IFERROR(Schedule!$G$32,0) -> 724049.45 | E36: =IFERROR(Schedule!$R$32,0) -> 1368525.5 | F36: =IFERROR(Schedule!$B$32,0) -> 1355939 | G36: =IFERROR(Schedule!$Q$32,0) -> 1118073 | H36: =IFERROR(Schedule!$D$32,0) -> 31630.658 | I36: =IFERROR(Schedule!$P$32,0) -> 68877.83
A37: 30 | B37: =IFERROR(Schedule!$H$33,0) -> -1927405.9 | C37: =IFERROR(Schedule!$S$33,0) -> 1044391 | D37: =IFERROR(Schedule!$G$33,0) -> 756724.18 | E37: =IFERROR(Schedule!$R$33,0) -> 1439462.5 | F37: =IFERROR(Schedule!$B$33,0) -> 1403396.9 | G37: =IFERROR(Schedule!$Q$33,0) -> 1207518.8 | H37: =IFERROR(Schedule!$D$33,0) -> 32674.731 | I37: =IFERROR(Schedule!$P$33,0) -> 70936.965
A38: 31 | B38: =IFERROR(Schedule!$H$34,0) -> -2115931.1 | C38: =IFERROR(Schedule!$S$34,0) -> 1126502.3 | D38: =IFERROR(Schedule!$G$34,0) -> 790479.53 | E38: =IFERROR(Schedule!$R$34,0) -> 1512520.3 | F38: =IFERROR(Schedule!$B$34,0) -> 1452515.7 | G38: =IFERROR(Schedule!$Q$34,0) -> 1304120.3 | H38: =IFERROR(Schedule!$D$34,0) -> 33755.346 | I38: =IFERROR(Schedule!$P$34,0) -> 73057.874
A39: 32 | B39: =IFERROR(Schedule!$H$35,0) -> -2319806.5 | C39: =IFERROR(Schedule!$S$35,0) -> 1215182.5 | D39: =IFERROR(Schedule!$G$35,0) -> 825353.31 | E39: =IFERROR(Schedule!$R$35,0) -> 1587762.8 | F39: =IFERROR(Schedule!$B$35,0) -> 1503353.8 | G39: =IFERROR(Schedule!$Q$35,0) -> 1408450 | H39: =IFERROR(Schedule!$D$35,0) -> 34873.783 | I39: =IFERROR(Schedule!$P$35,0) -> 75242.41
A40: 33 | B40: =IFERROR(Schedule!$H$36,0) -> -2540202.1 | C40: =IFERROR(Schedule!$S$36,0) -> 1310957.1 | D40: =IFERROR(Schedule!$G$36,0) -> 861384.68 | E40: =IFERROR(Schedule!$R$36,0) -> 1665255.2 | F40: =IFERROR(Schedule!$B$36,0) -> 1555971.2 | G40: =IFERROR(Schedule!$Q$36,0) -> 1521126 | H40: =IFERROR(Schedule!$D$36,0) -> 36031.366 | I40: =IFERROR(Schedule!$P$36,0) -> 77492.483
A41: 34 | B41: =IFERROR(Schedule!$H$37,0) -> -2778374.4 | C41: =IFERROR(Schedule!$S$37,0) -> 1414393.6 | D41: =IFERROR(Schedule!$G$37,0) -> 898614.14 | E41: =IFERROR(Schedule!$R$37,0) -> 1745065.3 | F41: =IFERROR(Schedule!$B$37,0) -> 1610430.2 | G41: =IFERROR(Schedule!$Q$37,0) -> 1642816 | H41: =IFERROR(Schedule!$D$37,0) -> 37229.464 | I41: =IFERROR(Schedule!$P$37,0) -> 79810.057
...

Sheet Expense Breakdown
A1: 📊 ANNUAL EXPENSE BREAKDOWN — Buyer vs. Renter at Selected Year
A2: Year (linked from Dashboard): | B2: =Dashboard!$I6 -> 30 | D2: Change 'View at Year' on Dashboard to update all results & charts
A4: BUYER — Annual Expenses at Selected Year | D4: RENTER — Annual Expenses at Selected Year | G4: Category | H4: Buyer ($) | I4: Renter ($)
A5: Mortgage Payment (P&I) | B5: =IFERROR(INDEX(Schedule!$I:$I,B2+3),0) -> 0 | D5: Rent Payments | E5: =IFERROR(INDEX(Schedule!$T:$T,B2+3),0) -> 70696.965 | G5: Mortgage / Rent | H5: =IFERROR(INDEX(Schedule!$I:$I,B2+3),0) -> 0 | I5: =IFERROR(INDEX(Schedule!$T:$T,B2+3),0) -> 70696.965
A6: Property Tax | B6: =IFERROR(INDEX(Schedule!$J:$J,B2+3),0) -> 16840.762 | D6: Renters Insurance | E6: =IFERROR(INDEX(Schedule!$U:$U,B2+3),0) -> 240 | G6: Property Tax | H6: =IFERROR(INDEX(Schedule!$J:$J,B2+3),0) -> 16840.762 | I6: 0
A7: Homeowner Insurance | B7: =IFERROR(INDEX(Schedule!$K:$K,B2+3),0) -> 1800 | D7: Opp. Cost Invested (notional) | E7: =Dashboard!$F28*12 -> 0 | G7: Insurance | H7: =IFERROR(INDEX(Schedule!$K:$K,B2+3),0) -> 1800 | I7: =IFERROR(INDEX(Schedule!$U:$U,B2+3),0) -> 240
A8: Maintenance & Repairs | B8: =IFERROR(INDEX(Schedule!$L:$L,B2+3),0) -> 14033.969 | D8: — | E8: — | G8: Maintenance | H8: =IFERROR(INDEX(Schedule!$L:$L,B2+3),0) -> 14033.969 | I8: 0
A9: PMI | B9: =IFERROR(INDEX(Schedule!$M:$M,B2+3),0) -> 0 | D9: — | E9: — | G9: PMI / HOA | H9: =IFERROR(INDEX(Schedule!$M:$M,B2+3)+Dashboard!$C15*12,0) -> 0 | I9: 0
A10: HOA Fees | B10: =Dashboard!$C15*12 -> 0 | D10: — | E10: —
A11: TOTAL ANNUAL BUYER COST | B11: =SUM(B5:B10) -> 32674.731 | D11: TOTAL ANNUAL RENTER COST | E11: =E5+E6 -> 70936.965

Sheet FIRE Calculator
A1: 🔥 FIRE CALCULATOR — Financial Independence, Retire Early
A2: 🟡 Yellow = your inputs | How many years until you can retire early?
B4: YOUR FINANCIAL SITUATION
B5: Annual Gross Income | C5: 75000
B6: Annual Expenses | C6: 48000
B7: Current Savings/Investments | C7: 25000
B8: Savings Rate | C8: 0.3
B9: Current Age | C9: 30
B10: INVESTMENT ASSUMPTIONS
B11: Expected Annual Return | C11: 0.07
B12: Inflation Rate | C12: 0.03
B13: Safe Withdrawal Rate | C13: 0.04
B14: Expected Social Security/mo | C14: 0
B15: HOUSING SCENARIO
B16: Monthly Cost if Buying | C16: 2800
B17: Monthly Cost if Renting | C17: 2000
B19: FIRE RESULTS
B20: Your FIRE Number | C20: =C6/C13 -> 1200000
B21: Annual Savings | C21: =C5*C8 -> 22500
B22: Monthly Savings | C22: =C5*C8/12 -> 1875
B23: Savings Rate | C23: =C8 -> 0.3
B24: Years to FIRE (base case) | C24: =IFERROR(LOG((C6/C13*C11+C5*C8)/(C5*C8),1+C11),99) -> 22.977546
B25: Retirement Age (base case) | C25: =C9+C24 -> 52.977546
B26: FIRE Year if Buying (housing cost adj.) | C26: =IFERROR(LOG((C6/C13*C11+C5*C8-(C16-C17)*12)/(C5*C8-(C16-C17)*12),1+C11),99) -> 29.803318
B27: FIRE Year if Renting (housing cost adj.) | C27: =IFERROR(LOG((C6/C13*C11+C5*C8+(C16-C17)*12)/(C5*C8+(C16-C17)*12),1+C11),99) -> 19.001205
B29: FIRE SCHEDULE (Year-by-Year Portfolio Growth)
B30: Year | C30: Portfolio Value | D30: Annual Savings | E30: FIRE Number
B31: 0 | C31: =C7 -> 25000 | D31: =C5*C8 -> 22500 | E31: =C6/C13 -> 1200000
B32: 1 | C32: =C31*(1+C11)+D32 -> 49250 | D32: =C5*C8 -> 22500 | E32: =C6/C13 -> 1200000
B33: 2 | C33: =C32*(1+C11)+D33 -> 75197.5 | D33: =C5*C8 -> 22500 | E33: =C6/C13 -> 1200000
B34: 3 | C34: =C33*(1+C11)+D34 -> 102961.32 | D34: =C5*C8 -> 22500 | E34: =C6/C13 -> 1200000
B35: 4 | C35: =C34*(1+C11)+D35 -> 132668.62 | D35: =C5*C8 -> 22500 | E35: =C6/C13 -> 1200000
B36: 5 | C36: =C35*(1+C11)+D36 -> 164455.42 | D36: =C5*C8 -> 22500 | E36: =C6/C13 -> 1200000
B37: 6 | C37: =C36*(1+C11)+D37 -> 198467.3 | D37: =C5*C8 -> 22500 | E37: =C6/C13 -> 1200000
B38: 7 | C38: =C37*(1+C11)+D38 -> 234860.01 | D38: =C5*C8 -> 22500 | E38: =C6/C13 -> 1200000
B39: 8 | C39: =C38*(1+C11)+D39 -> 273800.21 | D39: =C5*C8 -> 22500 | E39: =C6/C13 -> 1200000
B40: 9 | C40: =C39*(1+C11)+D40 -> 315466.23 | D40: =C5*C8 -> 22500 | E40: =C6/C13 -> 1200000
