Workbook

Sheet Dashboard
B1: Offer Builder
B2: The exercises of $100M Offers (Alex Hormozi, 2021), one tab per part. Yellow cells are yours to fill in; grey cells work themselves out. Nothing here is advice; the book has the reasoning, this has the work. THIS COPY CARRIES THE EXAMPLE OFFER: a made-up strength program for new fathers, with invented numbers.
B4: How to use it
B5: example | C5: A yellow cell with blue text is yours to type in. Dropdowns open when you click the cell.
B6: example | C6: A grey cell works itself out. Leave it alone.
B7: example | C7: A checklist row turns green when you pick Yes.
B8: Go through the tabs in order, left to right. Each tab is one part of the book; each numbered section is one exercise. Every figure on this page comes from those tabs.
B10: Where you stand
B11: Part of the book | C11: Filled in | E11: Reading | F11: Figure
B12: 1 Crowd: the starving crowd | C12: =Progress_Crowd -> 1 | E12: Starving crowd score (of 20) | F12: =IF(MarketScore="","not yet",MarketScore) -> 15 | H12: The offer
B13: 2 Price: charge what it is worth | C13: =Progress_Price -> 1 | E13: Weakest sign of the four | F13: =IF(WeakestSign="","not yet",WeakestSign) -> Easy to target | H13: =IF(NameChosen="","Unnamed, so far",NameChosen) -> The 6 Week New Dad Carry Anything Challenge
B14: 3 Value: the value equation | C14: =Progress_Value -> 1 | E14: Margin today | F14: =IF(MarginNow="","not yet",MarginNow) -> 0.57575758
B15: 4 Offer: problems, solutions, the stack | C15: =Progress_Offer -> 1 | E15: Worth against today's price | F15: =IF(GapNow="","not yet",GapNow) -> 48.484848 | H15: =IF(OneLine="","The one-line offer is written on the Name tab, 6.2.",OneLine) -> New fathers in their first year get strong enough to carry the baby, the bags and the stroller up the stairs without thinking about it, in six weeks, twenty minutes at a time, without a gym, or I keep coaching them for free until they do.
B16: 5 Enhancers: scarcity, urgency, bonuses, guarantee | C16: =Progress_Enhancers -> 0.92307692 | E16: Clients needed a year, new price | F16: =IF(ClientsNew="","not yet",ClientsNew) -> 34
B17: 6 Name: MAGIC and the launch | C17: =Progress_Name -> 0.78571429 | E17: Value score, before | F17: =IF(ValueNow="","not yet",ValueNow) -> 0.57142857
B18: The whole offer | C18: =AVERAGE(C12:C17) -> 0.9514652 | E18: Value score, after | F18: =IF(ValueNew="","not yet",ValueNew) -> 7.1111111
E19: Pieces kept after the trim | F19: =IF(COUNTA(SolutionsRange)=0,"not yet",KeepCount+KeepSomeCount) -> 6
E20: The stack adds up to | F20: =IF(StackTotal="","not yet",StackTotal) -> 732
E21: Stack and bonuses against the price | F21: =IF(OfferMultiple="","not yet",OfferMultiple) -> 2.979798 | H21: =IF(GuaranteeText="","",GuaranteeText) -> Do the three sessions a week for six weeks and log your carry test. If it has not gone up by twenty pounds, I keep coaching you for free until it does.
E22: Enhancers in play | F22: =EnhancersInPlay -> 4 of 4
E23: Margin at the new price | F23: =IF(MarginNew="","not yet",MarginNew) -> 0.64646465
E24: Close rate, before | F24: =IF(CloseRateNow="","not yet",CloseRateNow) -> 0.2
E25: Close rate at the new price | F25: =IF(CloseRateNew="","not yet",CloseRateNew) -> not yet
B28: Pictures
B29: Sign | C29: Score of 5
B30: =INDEX(SignLabels,1) -> Massive pain | C30: =IF(INDEX(SignScores,1)="",0,INDEX(SignScores,1)) -> 4
B31: =INDEX(SignLabels,2) -> Purchasing power | C31: =IF(INDEX(SignScores,2)="",0,INDEX(SignScores,2)) -> 4
B32: =INDEX(SignLabels,3) -> Easy to target | C32: =IF(INDEX(SignScores,3)="",0,INDEX(SignScores,3)) -> 3
B33: =INDEX(SignLabels,4) -> Growing | C33: =IF(INDEX(SignScores,4)="",0,INDEX(SignScores,4)) -> 4
B35: Part of the equation | C35: Before | D35: After
B36: Dream outcome | C36: =IF(INDEX(RatingsNow,1)="",0,INDEX(RatingsNow,1)) -> 6 | D36: =IF(INDEX(RatingsNew,1)="",0,INDEX(RatingsNew,1)) -> 8
B37: Likelihood | C37: =IF(INDEX(RatingsNow,2)="",0,INDEX(RatingsNow,2)) -> 4 | D37: =IF(INDEX(RatingsNew,2)="",0,INDEX(RatingsNew,2)) -> 8
B38: Time delay | C38: =IF(INDEX(RatingsNow,3)="",0,INDEX(RatingsNow,3)) -> 6 | D38: =IF(INDEX(RatingsNew,3)="",0,INDEX(RatingsNew,3)) -> 3
B39: Effort | C39: =IF(INDEX(RatingsNow,4)="",0,INDEX(RatingsNow,4)) -> 7 | D39: =IF(INDEX(RatingsNew,4)="",0,INDEX(RatingsNew,4)) -> 3
B41: Price point | C41: Clients a year
B42: =IF(INDEX(CurvePrices,1)="","",INDEX(CurvePrices,1)) -> 49.5 | C42: =IF(INDEX(CurveClients,1)="",0,INDEX(CurveClients,1)) -> 203
B43: =IF(INDEX(CurvePrices,2)="","",INDEX(CurvePrices,2)) -> 74.25 | C43: =IF(INDEX(CurveClients,2)="",0,INDEX(CurveClients,2)) -> 135
B44: =IF(INDEX(CurvePrices,3)="","",INDEX(CurvePrices,3)) -> 99 | C44: =IF(INDEX(CurveClients,3)="",0,INDEX(CurveClients,3)) -> 102
B45: =IF(INDEX(CurvePrices,4)="","",INDEX(CurvePrices,4)) -> 123.75 | C45: =IF(INDEX(CurveClients,4)="",0,INDEX(CurveClients,4)) -> 81
B46: =IF(INDEX(CurvePrices,5)="","",INDEX(CurvePrices,5)) -> 148.5 | C46: =IF(INDEX(CurveClients,5)="",0,INDEX(CurveClients,5)) -> 68
...

Sheet 1 Crowd
B1: Crowd: the starving crowd | G1: Filled in | H1: =(IF('1 Crowd'!$C$7="",0,1)+IF('1 Crowd'!$C$8="",0,1)+IF('1 Crowd'!$C$13="",0,1)+IF('1 Crowd'!$C$14="",0,1)+IF('1 Crowd'!$C$18="",0,1)+IF('1 Crowd'!$C$19="",0,1)+IF('1 Crowd'!$C$20="",0,1)+IF('1 Crowd'!$C$21="",0,1)+IF('1 Crowd'!$B$29="",0,1)+IF('1 Crowd'!$B$39="",0,1)+IF('1 Crowd'!$C$48="",0,1)+IF('1 Crowd'!$H$50="",0,1)+IF('1 Crowd'!$B$59="",0,1)+IF('1 Crowd'!$H$69="",0,1))/14 -> 1
B2: Section II, chapters 3 and 4. A commodity is anything a buyer compares on price alone. The way out is a narrow crowd that badly wants what you do. A good market shows four signs: massive pain, purchasing power, easy to target, growing.
B5: 1.1 What you sell today | H5: Chapter 3
B6: Say it the way you would to a stranger. The second box is the book's commodity test.
B7: What you sell, and to whom | C7: Online strength coaching for busy people, sold by the month.
B8: When a prospect compares you with others, what do they decide on? | C8: Mostly price, with a bit of trust. | F8: Pick one. Price means commodity; the rest of this workbook is how to stop being one.
B9: Where you sit | C9: =IF(C8="","",IF(C8="Price. Cheapest wins.","A commodity today. Buyers pick on price.",IF(C8="Mostly price, with a bit of trust.","Mostly a commodity. Trust helps a little, price decides.",IF(C8="Mostly what they get, price second.","Mostly differentiated. Price comes second.","A category of one. Price barely comes up.")))) -> Mostly a commodity. Trust helps a little, price decides.
B11: 1.2 The market you are in | H11: Chapter 4
B12: The book names health, wealth and relationships as the three markets that never go away.
B13: The big market | C13: Health
B14: Who buys from you now, in a few words | C14: Men in their thirties who used to train
B16: 1.3 The four signs of a starving crowd | H16: Chapter 4
B17: Score each 1 to 5. Massive pain: they need it, not just want it. Purchasing power: they can pay. Easy to target: one place, list or group holds them. Growing: more of them every year.
B18: Massive pain | C18: 4 | F18: 1 to 5. 1 is a mild wish, 5 keeps them up at night
B19: Purchasing power | C19: 4 | F19: 1 to 5. 1 is no spare money, 5 is they already spend on this
B20: Easy to target | C20: 3 | F20: 1 to 5. 1 is scattered everywhere, 5 is one group holds them
B21: Growing | C21: 4 | F21: 1 to 5. 1 is shrinking, 5 is growing fast
B22: Starving crowd score (of 20) | C22: =IF(COUNT(C18:C21)<4,"",SUM(C18:C21)) -> 15 | F22: 16 or more is a starving crowd. Under 12, the book would look for a hungrier crowd first.
B23: The weakest sign | C23: =IF(COUNT(C18:C21)<4,"",INDEX(B18:B21,MATCH(MIN(C18:C21),C18:C21,0))) -> Easy to target
B24: What that means | C24: =IF(COUNT(C18:C21)<4,"",IF(SUM(C18:C21)>=16,"A starving crowd.",IF(SUM(C18:C21)>=12,"A decent market.","A thin market. Find a hungrier crowd before building more."))) -> A decent market.
B26: 1.4 The pain in their words | H26: Chapter 4
B27: Three or more things this crowd says or complains about, in their own words, not yours. These come back in the problems list.
B28: In their words
A29: 1 | B29: I have not slept properly in eight months and I am too tired to train.
A30: 2 | B30: I can barely lift the car seat without my back going.
A31: 3 | B31: Every plan I try assumes I have an hour and a gym.
A32: 4
A33: 5
B34: Lines written | C34: =IF(COUNTA(B29:B33)=0,"",COUNTA(B29:B33)&" of 3 or more") -> 3 of 3 or more
B36: 1.5 The niche ladder | H36: Chapter 4, riches in niches
B37: Start broad, then narrow three times. At each rung write the price the same help could sell for. The book's example goes from time management for anyone to time management for one industry's salespeople, with the price rising many times over.
B38: Rung: who it is for (broad at the top, narrow at the bottom) | E38: What it could sell for
A39: 1 | B39: Anyone who wants to get strong | E39: 29
A40: 2 | B40: Busy professionals in their thirties | E40: 99
A41: 3 | B41: New fathers in the first year | E41: 399
A42: 4 | B42: New fathers with a bad back and no gym | E42: 997
A43: 5
B44: Narrowest over broadest | C44: =IF(OR(COUNT(E39:E43)<2,E39=0),"",INDEX(E39:E43,COUNT(E39:E43))/E39) -> 34.37931 | D44: How many times the price rises from the first rung to the last one filled in (fill the rungs from the top).
B46: 1.6 Commit to one | H46: Chapter 4
B47: Pick the rung you will serve. The book's warning: people switch niches before the niche can pay them.
...

Sheet 2 Price
B1: Price: charge what it is worth | G1: Filled in | H1: =(IF('2 Price'!$C$7="",0,1)+IF('2 Price'!$C$8="",0,1)+IF('2 Price'!$C$9="",0,1)+IF('2 Price'!$C$15="",0,1)+IF('2 Price'!$C$16="",0,1)+IF('2 Price'!$H$21="",0,1)+IF('2 Price'!$H$30="",0,1)+IF('2 Price'!$C$41="",0,1)+IF('2 Price'!$C$42="",0,1)+IF('2 Price'!$C$47="",0,1)+IF('2 Price'!$C$48="",0,1)+IF('2 Price'!$H$66="",0,1)+IF('2 Price'!$B$75="",0,1))/13 -> 1
B2: Section II, chapter 5. Lowering a price starts a vicious cycle: less margin, less service, worse results, less proof, more pressure to lower it again. Raising it starts the opposite cycle. Charge so much it hurts, then build so much value the price feels small.
B5: 2.1 Your price today | H5: Chapter 5
B6: Cost is your time at the rate you would pay someone else, plus materials, tools and the refunds you eat.
B7: Price today | C7: 99
B8: Charged | C8: Per month
B9: What one delivery costs you, roughly | C9: 42
B10: Gross margin today | C10: =IF(OR(C7="",C9="",C7=0),"",(C7-C9)/C7) -> 0.57575758 | F10: Under half is where the vicious cycle starts.
B11: What you keep, per sale | C11: =IF(OR(C7="",C9=""),"",C7-C9) -> 57
B13: 2.2 Where you sit | H13: Chapter 5
B14: Be honest about the position. The close rate is your baseline for the Prove steps.
B15: Against the alternatives your crowd sees, your price is | C15: Below the middle
B16: Of ten people you pitch, how many say yes (as a percent) | C16: 0.2 | F16: Type 20% for two in ten.
B18: 2.3 Which cycle you are in | H18: Chapter 5, the two cycles
B19: Mark every line that is true of your business this year. The count says which loop you are riding.
B20: Step | H20: Done?
B21: I lower the price to win deals | H21: Yes
B22: Clients expect a lot and value it little
B23: I cannot afford to give the service I would like to | H23: Yes
B24: Clients get worse results than they could
B25: I am always chasing the next sale | H25: Yes
B26: I resent some of the work
G27: Done | H27: =COUNTIF(H21:H26,"Yes")&" of 6" -> 3 of 6
B29: Step | H29: Done?
B30: The clients who pay more are the most committed | H30: Yes
B31: The clients who pay more get better results
B32: I can afford to over-deliver
B33: The margin pays for better help and better marketing
B34: I am proud to say the price
B35: Good clients send more good clients
G36: Done | H36: =COUNTIF(H30:H35,"Yes")&" of 6" -> 1 of 6
B37: The loop you are riding | C37: =IF(COUNTIF(H21:H26,"Yes")+COUNTIF(H30:H35,"Yes")=0,"",IF(COUNTIF(H21:H26,"Yes")>COUNTIF(H30:H35,"Yes"),"The vicious cycle: "&COUNTIF(H21:H26,"Yes")&" of its six signs are true. The way out is the price, not the hours.",IF(COUNTIF(H30:H35,"Yes")>COUNTIF(H21:H26,"Yes"),"The virtuous cycle: "&COUNTIF(H30:H35,"Yes")&" of its six signs are true. Keep the price where it belongs.","A foot in each loop. The next price move decides."))) -> The vicious cycle: 3 of its six signs are true. The way out is the price, not the hours.
B39: 2.4 What the outcome is worth | H39: Chapter 5
B40: If the client gets the dream outcome, what is it worth to them in money over a year? Revenue gained, cost stopped, time back at their rate, a pain made to stop. The gap between this and your price is what makes an offer a Grand Slam.
B41: Worth to the client, a year | C41: 4800
B42: How you got the number | C42: A private trainer twice a week is about $400 a month; a bad back cost one of them $1,800 in physio last year; the sleep and energy are worth more than either to them.
B43: Worth against today's price | C43: =IF(OR(C41="",C7="",C7=0),"",C41/C7) -> 48.484848 | F43: 10x or more is a Grand Slam gap. 3x is real. Under 3x, the outcome is probably worth more than you wrote.
B45: 2.5 Charge so much it hurts | H45: Chapter 5
B46: Pick a price that makes you a little uncomfortable to say out loud, and the revenue you want in a year. The table shows how many clients each price needs.
B47: The new price (charged the same way as today) | C47: 297
...

Sheet 3 Value
B1: Value: the value equation | G1: Filled in | H1: =(IF('3 Value'!$C$7="",0,1)+IF('3 Value'!$C$8="",0,1)+IF('3 Value'!$C$9="",0,1)+IF('3 Value'!$C$10="",0,1)+IF('3 Value'!$C$16="",0,1)+IF('3 Value'!$C$17="",0,1)+IF('3 Value'!$B$22="",0,1)+IF('3 Value'!$C$32="",0,1)+IF('3 Value'!$C$33="",0,1)+IF('3 Value'!$C$34="",0,1)+IF('3 Value'!$B$40="",0,1)+IF('3 Value'!$H$51="",0,1)+IF('3 Value'!$C$59="",0,1)+IF('3 Value'!$C$60="",0,1)+IF('3 Value'!$C$61="",0,1)+IF('3 Value'!$C$62="",0,1))/16 -> 1
B2: Section III, chapter 6. Value = (dream outcome x perceived likelihood) / (time delay x effort and sacrifice). Raise the top, shrink the bottom. The bottom matters most, and the book's goal for it is zero.
B5: 3.1 Rate the offer as it is | H5: Chapter 6
B6: Score each 1 to 10. Dream outcome: how big and wanted (10 is life-changing). Likelihood: how sure they feel it works for them (10 is certain). Time delay: how long until they notice a result (10 is a very long wait). Effort: how much they must do and give up (10 is a great deal).
B7: Dream outcome (1 to 10) | C7: 6
B8: Perceived likelihood (1 to 10) | C8: 4
B9: Time delay, 10 is long (1 to 10) | C9: 6
B10: Effort and sacrifice, 10 is a lot (1 to 10) | C10: 7
B11: Value score, before | C11: =IF(COUNT(C7:C10)<4,"",(C7*C8)/(C9*C10)) -> 0.57142857 | F11: Top over bottom. Higher is better; 1 means the top only equals the bottom.
B12: What that says | C12: =IF(COUNT(C7:C10)<4,"",IF(C9*C10>=25,"The bottom is heavy: time and effort are where this offer loses value.",IF(C7*C8<=25,"The top is light: a bigger promise or more proof would lift it.","Both halves are working; the bottom still has room."))) -> The bottom is heavy: time and effort are where this offer loses value.
B14: 3.2 The dream outcome | H14: Chapter 6
B15: Write the result they want, in their words. Not what you do; what they get, and who they get to be.
B16: The dream outcome, in their words | C16: Strong enough to carry the baby, the bags and the stroller up the stairs without thinking about it, and to have energy left at the end of the day.
B17: Who they get to be, in the eyes of people they care about | C17: the dad who keeps up, not the one who is always tired
B19: 3.3 Why they will believe it | H19: Chapter 6, perceived likelihood
B20: The proof that makes a stranger believe this will work for someone like them. The more it looks like them, the more it counts.
B21: Kind | C21: What it is
A22: 1 | B22: A client's result | C22: Eleven new dads through the pilot; nine added twenty pounds to their carry test in six weeks
A23: 2 | B23: A result I got | C23: Trained through my own first year on twenty minute sessions
A24: 3 | B24: A credential | C24: Certified strength coach, eight years coaching
A25: 4 | B25: A guarantee | C25: A conditional guarantee on the carry test
A26: 5
A27: 6
B28: Pieces of proof | C28: =IF(COUNTA(B22:B27)=0,"",COUNTA(B22:B27)&IF(COUNTIF(B22:B27,"A client's result")=0,", none yet a client result (the kind that raises belief most)",", including a client result")) -> 4, including a client result
B30: 3.4 Time to the first win | H30: Chapter 6, time delay
B31: The book's fix for a long wait is a fast win: something real inside days, while the big result takes its time.
B32: The first thing they will notice | C32: less back pain lifting the car seat
B33: Days until they notice it | C33: 5
B34: Weeks to the full result | C34: 6
B35: Read | C35: =IF(OR(C33="",C34=""),"",IF(C33<=7,"A first win inside a week, which is what the book asks for. Full result in "&C34&" weeks.","The book would look for something they can feel inside the first week. Full result in "&C34&" weeks.")) -> A first win inside a week, which is what the book asks for. Full result in 6 weeks.
B37: 3.5 What it costs them beyond money | H37: Chapter 6, effort and sacrifice
B38: Every hour, habit and thing they must give up, and how the offer takes each one off them.
B39: What they must do or give up | E39: How the offer removes or softens it
A40: 1 | B40: Finding an hour to train | E40: Every session is twenty minutes, three a week
A41: 2 | B41: Getting to a gym | E41: One kettlebell and a doorway, nothing else
A42: 3 | B42: Planning what to do | E42: The session card tells them, in order, with a timer
A43: 4 | B43: Eating differently | E43: One rule a week, never a meal plan
A44: 5
A45: 6
B46: Sacrifices with a fix | C46: =IF(COUNTA(B40:B45)=0,"",COUNTA(E40:E45)&" of "&COUNTA(B40:B45)) -> 4 of 4
...

Sheet 4 Offer
B1: Offer: problems, solutions, trim and stack | G1: Filled in | H1: =(IF('4 Offer'!$B$8="",0,1)+IF('4 Offer'!$B$28="",0,1)+IF('4 Offer'!$B$40="",0,1)+IF('4 Offer'!$B$65="",0,1)+IF('4 Offer'!$B$87="",0,1)+IF('4 Offer'!$H$102="",0,1)+IF('4 Offer'!$B$112="",0,1))/7 -> 1
B2: Section III, chapters 8 to 10. Loosen up, list every problem on the way to the dream outcome, turn each into a solution, brainstorm ways to deliver every solution, sort by value and cost, keep the high value ones, drop the rest, then name and price what is left.
B5: 4.1 Warm up: the brick | H5: Chapter 8, divergent thinking
B6: Set a two minute timer and list every use you can think of for a brick. Quantity is the point; no judging.
B7: A use for a brick
A8: 1 | B8: doorstop
A9: 2 | B9: bookend
A10: 3 | B10: kettlebell stand-in
A11: 4 | B11: step for calf raises
A12: 5 | B12: paperweight
A13: 6 | B13: garden edging
A14: 7 | B14: phone stand
A15: 8 | B15: hot water bottle, warmed
A16: 9 | B16: a weight for a pressed flower
A17: 10
A18: 11
A19: 12
A20: 13
A21: 14
A22: 15
B23: Uses found | C23: =IF(COUNTA(B8:B22)=0,"",COUNTA(B8:B22)&IF(COUNTA(B8:B22)>=12," in two minutes: well warmed up",IF(COUNTA(B8:B22)>=8," in two minutes: warmed up"," so far; five or more counts"))) -> 9 in two minutes: warmed up
B25: 4.2 The trip from here to there | H25: Chapter 9
B26: The steps your client goes through, from today to the dream outcome, in order. Three to eight is typical. Every step is a place something goes wrong.
B27: Step
A28: 1 | B28: Decide to start again
A29: 2 | B29: Find a slot in the day
A30: 3 | B30: Do the first session without hurting the back
A31: 4 | B31: Keep going through a bad week of sleep
A32: 5 | B32: Notice the carry gets easier
A33: 6 | B33: Make it a habit that survives teething
A34: 7
A35: 8
B37: 4.3 Every problem, and its solution | H37: Chapter 9, steps 2 and 3
B38: For each step: what goes wrong, what they fear, what takes too long, what is a hassle. Aim past ten. Tag each with the part of the value equation it hurts. Then flip it: how to get the outcome even if, or without, the problem.
B39: The problem, in their words | D39: It hurts | E39: How to ... (the solution)
A40: 1 | B40: I do not have an hour | D40: Effort or sacrifice | E40: How to get strong in twenty minutes, three times a week
A41: 2 | B41: I will hurt my back | D41: Belief it will work | E41: How to train around a sore back with a movement screen first
A42: 3 | B42: I have no gym and no space | D42: Effort or sacrifice | E42: How to do it with one kettlebell in a doorway
A43: 4 | B43: I will stop when the baby stops sleeping | D43: Belief it will work | E43: How to keep going in a bad week with the five minute fallback
A44: 5 | B44: It will take months before anything changes | D44: Time | E44: How to feel the first change in five days with the carry test
...

Sheet 5 Enhancers
B1: Enhancers: scarcity, urgency, bonuses, guarantees | G1: Filled in | H1: =(IF('5 Enhancers'!$B$8="",0,1)+IF('5 Enhancers'!$C$17="",0,1)+IF('5 Enhancers'!$C$18="",0,1)+IF('5 Enhancers'!$C$19="",0,1)+IF('5 Enhancers'!$C$24="",0,1)+IF('5 Enhancers'!$C$25="",0,1)+IF('5 Enhancers'!$C$26="",0,1)+IF('5 Enhancers'!$B$33="",0,1)+IF('5 Enhancers'!$H$47="",0,1)+IF('5 Enhancers'!$C$57="",0,1)+IF('5 Enhancers'!$C$58="",0,1)+IF('5 Enhancers'!$H$64="",0,1)+IF('5 Enhancers'!$B$73="",0,1))/13 -> 0.92307692
B2: Section IV, chapters 11 to 14. Four things make a good offer irresistible without changing the core. All four must be true.
B5: 5.1 What holds them back | H5: Chapter 13
B6: The reasons people give for not buying, in their words. Every bonus answers one; the guarantee answers the biggest.
B7: In their words
A8: 1 | B8: What if I hurt my back doing it alone?
A9: 2 | B9: What if the baby stops sleeping and I fall off?
A10: 3 | B10: My partner will think I am being selfish with the time
A11: 4 | B11: I have paid for programs before and never used them
A12: 5
A13: 6
B15: 5.2 Scarcity, honestly | H15: Chapter 11
B16: A true limit on how many people can have this. Your hours, your capacity and the cohort size are where real limits come from. A false limit costs more trust than it earns.
B17: The kind | C17: A limited number of clients or seats each period
B18: The number | C18: 12
B19: Why the limit is real | C19: Twelve is the most Back Checks and same day answers I can give properly in a month alongside the pilot group.
B20: Your scarcity, in one line | C20: =IF(C17="","",IF(C17="None yet","No scarcity yet. How many you can serve well each month is usually the true limit.",IF(C18="","Add the number.",IF(C17="A limited number of clients or seats each period","Only "&C18&" places each round.",IF(C17="A bonus only for the first few","The bonus goes to the first "&C18&" only.","This version is sold "&C18&" more times, then it goes away."))))) -> Only 12 places each round.
B22: 5.3 Urgency, honestly | H22: Chapter 12
B23: A true reason the decision cannot wait. The date must be one you will hold.
B24: The kind | C24: A cohort with a start date
B25: The date | C25: 46328
B26: Why the date is real | C26: The group starts together so the weekly rule and the fallback land on the same days for everyone.
B27: Days left | C27: =IF(OR(C25="",C24="None yet"),"",C25-TODAY()) -> 37 | F27: Counted from the day the file is opened.
B28: Your urgency, in one line | C28: =IF(C24="","",IF(C24="None yet","No urgency yet. A cohort start date is the book's most natural kind.",IF(C25="","Add the date.",IF(C24="A cohort with a start date","The next group starts on ",IF(C24="A seasonal or themed promotion","This runs until ",IF(C24="A price or bonus deadline","The price and bonuses hold until ","The window closes on ")))&TEXT(C25,"mmmm d, yyyy")&"."))) -> The next group starts on November 2, 2026.
B30: 5.4 Bonuses | H30: Chapter 13
B31: Three or more. Each answers one worry, has a price of its own, and something that proves it. Offer them after the core price. Prefer tools, checklists and templates to more training. A partner's product can be a bonus.
B32: Name | C32: The worry it answers | D32: Kind | E32: Worth on its own | F32: Proof, or the picture it paints
A33: 1 | B33: The Partner Page | C33: My partner will think I am being selfish | D33: A tool or template | E33: 29 | F33: A one page note that shows the twenty minute slot and what it gives back
A34: 2 | B34: The Bad Week Checklist | C34: What if the baby stops sleeping | D34: A checklist | E34: 19 | F34: Nine of eleven pilot dads used it in week three
A35: 3 | B35: The Kit Guide | C35: I do not know what to buy | D35: A tool or template | E35: 15 | F35: One kettlebell, one door, the exact weight for their carry test
A36: 4 | B36: Pediatric Physio Back Session | C36: What if I hurt my back | D36: A partner's product | E36: 90 | F36: A recorded session from a physio who works with new parents
A37: 5
A38: 6
B39: Bonuses add up to | E39: =IF(COUNT(E33:E38)=0,"",SUM(E33:E38)) -> 153
B40: Stack and bonuses together | C40: =IF(AND(StackTotal="",BonusTotal=""),"",N(StackTotal)+N(BonusTotal)) -> 885
B41: Against the price | C41: =IF(OR(OfferTotal="",PriceUsed="",PriceUsed=0),"",OfferTotal/PriceUsed) -> 2.979798
B42: A tool or checklist among them? | C42: =IF(COUNTA(B33:B38)=0,"",IF(COUNTIF(D33:D38,"A tool or template")+COUNTIF(D33:D38,"A checklist")>0,"Yes, as the book prefers.","Not yet. The book prefers a tool or checklist to more training.")) -> Yes, as the book prefers.
B44: 5.5 The bonus checklist | H44: Chapter 13
B45: The book's own list for bonuses.
B46: Step | H46: Done?
...

Sheet 6 Name
B1: Name: MAGIC and the launch | G1: Filled in | H1: =(IF('6 Name'!$C$7="",0,1)+IF('6 Name'!$C$13="",0,1)+IF('6 Name'!$C$17="",0,1)+IF('6 Name'!$C$18="",0,1)+IF('6 Name'!$C$19="",0,1)+IF('6 Name'!$C$20="",0,1)+IF('6 Name'!$C$21="",0,1)+IF('6 Name'!$C$28="",0,1)+IF('6 Name'!$H$33="",0,1)+IF('6 Name'!$B$43="",0,1)+IF('6 Name'!$H$52="",0,1)+IF('6 Name'!$C$61="",0,1)+IF('6 Name'!$C$62="",0,1)+IF('6 Name'!$C$63="",0,1))/14 -> 0.78571429
B2: Section IV, chapter 15 and Section V. A name is the wrapper, and a wrapper can be refreshed without touching the offer. MAGIC: a Magnetic reason why, Announce the avatar, Give them a goal, Indicate a time interval, Complete with a container word.
B5: 6.1 What it is called today | H5: Chapter 15
B6: No name is a fine answer.
B7: Today | C7: It has a name
B8: The name, if it has one | C8: Strength Coaching
B10: 6.2 The offer in one line | H10: Section V
B11: Who gets what, by when, without what, or else what. A suggestion is built from the other tabs; write your own version in the box.
B12: Built from the other tabs | C12: =IF(AND(Niche="",Dream=""),"",IF(Niche="",MarketWho,Niche)&" get "&IF(Dream="","the result",Dream)&IF(FullWeeks=""," in "&FullWeeks&" weeks","")&IF(GuaranteeText="",""," Or: "&GuaranteeText)) -> New fathers in the first year, training at home with no gym get Strong enough to carry the baby, the bags and the stroller up the stairs without thinking about it, and to have energy left at the end of the day. Or: Do the three sessions a week for six weeks and log your carry test. If it has not gone up by twenty pounds, I keep coaching you for free until it does.
B13: The offer in one line, in your words | C13: New fathers in their first year get strong enough to carry the baby, the bags and the stroller up the stairs without thinking about it, in six weeks, twenty minutes at a time, without a gym, or I keep coaching them for free until they do.
B15: 6.3 M A G I C | H15: Chapter 15
B16: Fill the five parts; three names are built from them below.
B17: Magnetic reason why (a season, an event, a milestone, a group) | C17: First Year
B18: Announce the avatar (who it is for, short) | C18: New Dad
B19: Give them a goal (the result in a few words) | C19: Carry Anything
B20: Indicate a time interval (6 Week, 30 Day) | C20: 6 Week
B21: Complete with a container word | C21: Challenge
B22: Name 1 | C22: =IF(COUNTA(C17,C18,C19,C20,C21)<5,"","The "&C20&" "&C19&" "&C21) -> The 6 Week Carry Anything Challenge
B23: Name 2 | C23: =IF(COUNTA(C17,C18,C19,C20,C21)<5,"","The "&C17&" "&C19&" "&C21&" for "&C18) -> The First Year Carry Anything Challenge for New Dad
B24: Name 3 | C24: =IF(COUNTA(C17,C18,C19,C20,C21)<5,"","The "&C18&" "&C19&" "&C21&": "&C20) -> The New Dad Carry Anything Challenge: 6 Week
B26: 6.4 Pick the name | H26: Chapter 15
B27: Choose one of the built names or write your own version. Say it out loud three times.
B28: The name | C28: The 6 Week New Dad Carry Anything Challenge
B30: 6.5 Name every piece | H30: Chapter 15
B31: The book names the bonuses and the pieces of the stack the same way as the offer.
B32: Step | H32: Done?
B33: The name says who it is for | H33: Yes
B34: The name says the result | H34: Yes
B35: The name says how long | H35: Yes
B36: It ends in a container word | H36: Yes
B37: Each piece of the stack and each bonus has a name that makes sense on its own | H37: Yes
G38: Done | H38: =COUNTIF(H33:H37,"Yes")&" of 5" -> 5 of 5
B40: 6.6 Beat offer fatigue | H40: Chapter 15
B41: An offer gets tired in the market long before the core stops working. Plan to change the wrapper on a rhythm and leave the core alone.
B42: What changes | C42: When, roughly
A43: 1 | B43: The urgency | C43: every six weeks with each new group
A44: 2 | B44: A bonus | C44: swap one bonus each quarter
A45: 3 | B45: The name | C45: after the third group, if sign-ups slow
A46: 4
A47: 5
...

Sheet Offer Sheet
B1: =IF(NameChosen="","Unnamed offer",NameChosen) -> The 6 Week New Dad Carry Anything Challenge
B2: =IF(OneLine="","The one-line offer is written on the Name tab, 6.2.",OneLine) -> New fathers in their first year get strong enough to carry the baby, the bags and the stroller up the stairs without thinking about it, in six weeks, twenty minutes at a time, without a gym, or I keep coaching them for free until they do.
B4: WHO IT IS FOR
B5: =IF(Niche="",IF(MarketWho="","Not chosen yet (Crowd tab, 1.6)",MarketWho&" (the starting avatar; Crowd 1.6 narrows it)"),Niche) -> New fathers in the first year, training at home with no gym
B6: THE DREAM OUTCOME
B7: =IF(Dream="","Not written yet (Value tab, 3.2)",Dream) -> Strong enough to carry the baby, the bags and the stroller up the stairs without thinking about it, and to have energy left at the end of the day.
B8: =IF(DreamStatus="","","They get to be "&DreamStatus&".") -> They get to be the dad who keeps up, not the one who is always tired.
B9: =IF(FirstWinDays="","","First win: "&FirstWin&" in "&FirstWinDays&" days. Full result in "&FullWeeks&" weeks.") -> First win: less back pain lifting the car seat in 5 days. Full result in 6 weeks.
B10: WHAT YOU GET
B11: Piece | C11: What it solves | D11: Worth
B12: =IF(INDEX(StackNames,1)="","",INDEX(StackNames,1)) -> The Six Week Dad Strength Cards | C12: =IF(INDEX(StackSolves,1)="","",INDEX(StackSolves,1)) -> No time, no plan: twenty minutes, told what to do | D12: =IF(INDEX(StackWorth,1)="","",INDEX(StackWorth,1)) -> 297
B13: =IF(INDEX(StackNames,2)="","",INDEX(StackNames,2)) -> The Back Check | C13: =IF(INDEX(StackSolves,2)="","",INDEX(StackSolves,2)) -> Fear of getting hurt: a movement screen before day one | D13: =IF(INDEX(StackWorth,2)="","",INDEX(StackWorth,2)) -> 150
B14: =IF(INDEX(StackNames,3)="","",INDEX(StackNames,3)) -> Same Day Coach Line | C14: =IF(INDEX(StackSolves,3)="","",INDEX(StackSolves,3)) -> Nobody to ask: an answer within the day | D14: =IF(INDEX(StackWorth,3)="","",INDEX(StackWorth,3)) -> 197
B15: =IF(INDEX(StackNames,4)="","",INDEX(StackNames,4)) -> The Five Minute Fallback | C15: =IF(INDEX(StackSolves,4)="","",INDEX(StackSolves,4)) -> Bad weeks: a session you can always do | D15: =IF(INDEX(StackWorth,4)="","",INDEX(StackWorth,4)) -> 49
B16: =IF(INDEX(StackNames,5)="","",INDEX(StackNames,5)) -> The Carry Test Tracker | C16: =IF(INDEX(StackSolves,5)="","",INDEX(StackSolves,5)) -> Nothing changing: a number that moves in week one | D16: =IF(INDEX(StackWorth,5)="","",INDEX(StackWorth,5)) -> 39
B17: =IF(INDEX(StackNames,6)="","",INDEX(StackNames,6)) | C17: =IF(INDEX(StackSolves,6)="","",INDEX(StackSolves,6)) | D17: =IF(INDEX(StackWorth,6)="","",INDEX(StackWorth,6))
B18: =IF(INDEX(StackNames,7)="","",INDEX(StackNames,7)) | C18: =IF(INDEX(StackSolves,7)="","",INDEX(StackSolves,7)) | D18: =IF(INDEX(StackWorth,7)="","",INDEX(StackWorth,7))
B19: =IF(INDEX(StackNames,8)="","",INDEX(StackNames,8)) | C19: =IF(INDEX(StackSolves,8)="","",INDEX(StackSolves,8)) | D19: =IF(INDEX(StackWorth,8)="","",INDEX(StackWorth,8))
B20: The stack | D20: =IF(StackTotal="","",StackTotal) -> 732
B21: BONUSES
B22: Bonus | C22: The worry it answers | D22: Kind | E22: Worth
B23: =IF(INDEX(BonusNames,1)="","",INDEX(BonusNames,1)) -> The Partner Page | C23: =IF(INDEX(BonusSolves,1)="","",INDEX(BonusSolves,1)) -> My partner will think I am being selfish | D23: =IF(INDEX(BonusKinds,1)="","",INDEX(BonusKinds,1)) -> A tool or template | E23: =IF(INDEX(BonusWorth,1)="","",INDEX(BonusWorth,1)) -> 29
B24: =IF(INDEX(BonusNames,2)="","",INDEX(BonusNames,2)) -> The Bad Week Checklist | C24: =IF(INDEX(BonusSolves,2)="","",INDEX(BonusSolves,2)) -> What if the baby stops sleeping | D24: =IF(INDEX(BonusKinds,2)="","",INDEX(BonusKinds,2)) -> A checklist | E24: =IF(INDEX(BonusWorth,2)="","",INDEX(BonusWorth,2)) -> 19
B25: =IF(INDEX(BonusNames,3)="","",INDEX(BonusNames,3)) -> The Kit Guide | C25: =IF(INDEX(BonusSolves,3)="","",INDEX(BonusSolves,3)) -> I do not know what to buy | D25: =IF(INDEX(BonusKinds,3)="","",INDEX(BonusKinds,3)) -> A tool or template | E25: =IF(INDEX(BonusWorth,3)="","",INDEX(BonusWorth,3)) -> 15
B26: =IF(INDEX(BonusNames,4)="","",INDEX(BonusNames,4)) -> Pediatric Physio Back Session | C26: =IF(INDEX(BonusSolves,4)="","",INDEX(BonusSolves,4)) -> What if I hurt my back | D26: =IF(INDEX(BonusKinds,4)="","",INDEX(BonusKinds,4)) -> A partner's product | E26: =IF(INDEX(BonusWorth,4)="","",INDEX(BonusWorth,4)) -> 90
B27: =IF(INDEX(BonusNames,5)="","",INDEX(BonusNames,5)) | C27: =IF(INDEX(BonusSolves,5)="","",INDEX(BonusSolves,5)) | D27: =IF(INDEX(BonusKinds,5)="","",INDEX(BonusKinds,5)) | E27: =IF(INDEX(BonusWorth,5)="","",INDEX(BonusWorth,5))
B28: =IF(INDEX(BonusNames,6)="","",INDEX(BonusNames,6)) | C28: =IF(INDEX(BonusSolves,6)="","",INDEX(BonusSolves,6)) | D28: =IF(INDEX(BonusKinds,6)="","",INDEX(BonusKinds,6)) | E28: =IF(INDEX(BonusWorth,6)="","",INDEX(BonusWorth,6))
B29: The bonuses | E29: =IF(BonusTotal="","",BonusTotal) -> 153
B30: THE PRICE
B31: =IF(PriceUsed="","Not set yet (Price tab)",PriceUsed) -> 297 | C31: =IF(Period="","",IF(Period="Per month","a month",IF(Period="Per year","a year","one time"))) -> a month
B32: =IF(OfferMultiple="","","Everything above adds up to "&TEXT(OfferTotal,"$#,##0")&", "&TEXT(OfferMultiple,"0.0")&"x the price.") -> Everything above adds up to $885, 3.0x the price.
B33: =IF(OR(OutcomeWorth="",PriceUsed=""),"","The outcome is worth about "&TEXT(OutcomeWorth,"$#,##0")&" a year to them, "&TEXT(OutcomeWorth/PriceUsed,"0.0")&"x the price.") -> The outcome is worth about $4,800 a year to them, 16.2x the price.
B34: THE GUARANTEE
B35: =IF(GuaranteeText="","Not written yet (Enhancers tab, 5.6)",IF(GuaranteeKind="","",GuaranteeKind&": ")&GuaranteeText) -> Conditional: Do the three sessions a week for six weeks and log your carry test. If it has not gone up by twenty pounds, I keep coaching you for free until it does.
B36: =IF(GuaranteeCondition="","","It holds when the client "&GuaranteeCondition&".") -> It holds when the client does three sessions a week and logs the carry test.
B37: WHY NOW, AND WHY NOT EVERYONE
B38: =IF(ScarcityLine="","Scarcity not set yet (Enhancers tab, 5.2)",ScarcityLine) -> Only 12 places each round.
B39: =IF(UrgencyLine="","Urgency not set yet (Enhancers tab, 5.3)",UrgencyLine) -> The next group starts on November 2, 2026.
B40: THE VALUE EQUATION
B41: =IF(ValueNow="","Not rated yet (Value tab, 3.1)",IF(ValueNew="","Value score "&TEXT(ValueNow,"0.0")&" before. Rate it again after the Offer and Enhancers tabs (Value 3.7).","The value score went from "&TEXT(ValueNow,"0.0")&" to "&TEXT(ValueNew,"0.0")&", "&TEXT(ValueChange,"0.0")&"x what it was.")) -> The value score went from 0.6 to 7.1, 12.4x what it was.
