Workbook

Sheet Start Here
A1: Money Models: a workbook for $100M Money Models
A2: Get paid back before the bill is due. A money model is the order in which you ask a customer to say yes; this workbook walks you through building one.
A4: How to use it
A5: 1. Six planet sheets, one per part of the model. Each has fifteen levels in five bands: Learn (read, answer one question), Numbers (type your figures), Build (the exercises), Prove (what happened when you ran it), Optimize (sharpen it).
A6: 2. Type only in the yellow cells. Blue text is yours; black text is a formula; leave formulas alone.
A7: 3. Every figure on the Dashboard is live. It reads "not yet" until every number it needs is in, so nothing is ever a fake zero.
A8: 4. Plays says which of the nineteen plays your numbers support. Your Model reads the four offers back to you in order.
A9: 5. Do the planets in order, or start where the constraint points: Foundations level 8 tells you.
A11: Use the example numbers? | B11: Yes | C11: Yes: every sheet runs on a made-up six-week fitness challenge, so you can see the whole thing working. No: your own answers, and nothing else.
A13: Legend
A14: Type here | B14: A yellow cell with blue text is yours to fill. Blank means "not known yet"; a typed 0 is a real zero.
A15: Computed | B15: Black text is a formula. Green text is a figure read from another sheet.
A16: not yet | B16: A figure that is still missing an input. The Dashboard says which; the planet sheet says where to type it.
A17: Example | B17: The grey column on every planet sheet: invented numbers for a made-up business, never real ones.
A19: Where you are: levels done, by planet and band (3 of 3 clears a band)
A20: Planet | B20: 1 Learn | C20: 2 Numbers | D20: 3 Build | E20: 4 Prove | F20: 5 Optimize | G20: Done | H20: Sheet
A21: Foundations | B21: =COUNTIFS('1 Foundations'!$H:$H,"Done",'1 Foundations'!$B:$B,"Learn") -> 3 | C21: =COUNTIFS('1 Foundations'!$H:$H,"Done",'1 Foundations'!$B:$B,"Numbers") -> 3 | D21: =COUNTIFS('1 Foundations'!$H:$H,"Done",'1 Foundations'!$B:$B,"Build") -> 3 | E21: =COUNTIFS('1 Foundations'!$H:$H,"Done",'1 Foundations'!$B:$B,"Prove") -> 3 | F21: =COUNTIFS('1 Foundations'!$H:$H,"Done",'1 Foundations'!$B:$B,"Optimize") -> 3 | G21: =COUNTIF('1 Foundations'!$H:$H,"Done")&" of 15" -> 15 of 15 | H21: =HYPERLINK("#'1 Foundations'!A1","Open 1 Foundations") -> Open 1 Foundations
A22: Attraction | B22: =COUNTIFS('2 Attraction'!$H:$H,"Done",'2 Attraction'!$B:$B,"Learn") -> 3 | C22: =COUNTIFS('2 Attraction'!$H:$H,"Done",'2 Attraction'!$B:$B,"Numbers") -> 3 | D22: =COUNTIFS('2 Attraction'!$H:$H,"Done",'2 Attraction'!$B:$B,"Build") -> 3 | E22: =COUNTIFS('2 Attraction'!$H:$H,"Done",'2 Attraction'!$B:$B,"Prove") -> 3 | F22: =COUNTIFS('2 Attraction'!$H:$H,"Done",'2 Attraction'!$B:$B,"Optimize") -> 3 | G22: =COUNTIF('2 Attraction'!$H:$H,"Done")&" of 15" -> 15 of 15 | H22: =HYPERLINK("#'2 Attraction'!A1","Open 2 Attraction") -> Open 2 Attraction
A23: Upsell | B23: =COUNTIFS('3 Upsell'!$H:$H,"Done",'3 Upsell'!$B:$B,"Learn") -> 3 | C23: =COUNTIFS('3 Upsell'!$H:$H,"Done",'3 Upsell'!$B:$B,"Numbers") -> 3 | D23: =COUNTIFS('3 Upsell'!$H:$H,"Done",'3 Upsell'!$B:$B,"Build") -> 3 | E23: =COUNTIFS('3 Upsell'!$H:$H,"Done",'3 Upsell'!$B:$B,"Prove") -> 3 | F23: =COUNTIFS('3 Upsell'!$H:$H,"Done",'3 Upsell'!$B:$B,"Optimize") -> 3 | G23: =COUNTIF('3 Upsell'!$H:$H,"Done")&" of 15" -> 15 of 15 | H23: =HYPERLINK("#'3 Upsell'!A1","Open 3 Upsell") -> Open 3 Upsell
A24: Downsell | B24: =COUNTIFS('4 Downsell'!$H:$H,"Done",'4 Downsell'!$B:$B,"Learn") -> 3 | C24: =COUNTIFS('4 Downsell'!$H:$H,"Done",'4 Downsell'!$B:$B,"Numbers") -> 3 | D24: =COUNTIFS('4 Downsell'!$H:$H,"Done",'4 Downsell'!$B:$B,"Build") -> 3 | E24: =COUNTIFS('4 Downsell'!$H:$H,"Done",'4 Downsell'!$B:$B,"Prove") -> 3 | F24: =COUNTIFS('4 Downsell'!$H:$H,"Done",'4 Downsell'!$B:$B,"Optimize") -> 3 | G24: =COUNTIF('4 Downsell'!$H:$H,"Done")&" of 15" -> 15 of 15 | H24: =HYPERLINK("#'4 Downsell'!A1","Open 4 Downsell") -> Open 4 Downsell
A25: Continuity | B25: =COUNTIFS('5 Continuity'!$H:$H,"Done",'5 Continuity'!$B:$B,"Learn") -> 3 | C25: =COUNTIFS('5 Continuity'!$H:$H,"Done",'5 Continuity'!$B:$B,"Numbers") -> 3 | D25: =COUNTIFS('5 Continuity'!$H:$H,"Done",'5 Continuity'!$B:$B,"Build") -> 3 | E25: =COUNTIFS('5 Continuity'!$H:$H,"Done",'5 Continuity'!$B:$B,"Prove") -> 3 | F25: =COUNTIFS('5 Continuity'!$H:$H,"Done",'5 Continuity'!$B:$B,"Optimize") -> 3 | G25: =COUNTIF('5 Continuity'!$H:$H,"Done")&" of 15" -> 15 of 15 | H25: =HYPERLINK("#'5 Continuity'!A1","Open 5 Continuity") -> Open 5 Continuity
A26: KPIs and Scale | B26: =COUNTIFS('6 KPIs and Scale'!$H:$H,"Done",'6 KPIs and Scale'!$B:$B,"Learn") -> 3 | C26: =COUNTIFS('6 KPIs and Scale'!$H:$H,"Done",'6 KPIs and Scale'!$B:$B,"Numbers") -> 3 | D26: =COUNTIFS('6 KPIs and Scale'!$H:$H,"Done",'6 KPIs and Scale'!$B:$B,"Build") -> 3 | E26: =COUNTIFS('6 KPIs and Scale'!$H:$H,"Done",'6 KPIs and Scale'!$B:$B,"Prove") -> 3 | F26: =COUNTIFS('6 KPIs and Scale'!$H:$H,"Done",'6 KPIs and Scale'!$B:$B,"Optimize") -> 3 | G26: =COUNTIF('6 KPIs and Scale'!$H:$H,"Done")&" of 15" -> 15 of 15 | H26: =HYPERLINK("#'6 KPIs and Scale'!A1","Open 6 KPIs and Scale") -> Open 6 KPIs and Scale
A28: The sun: 30-day ratio | B28: =IF(ISNUMBER(ratio30),ratio30,"not yet") -> 4.7693333 | C28: =IF(ISNUMBER(ratio30),IF(ratio30>=2,"Every customer pays for the next one.",IF(ratio30>=1,"Break even inside the month. Twice the cost is the self-funding line.","Not yet paying back inside 30 days.")),"Needs the Numbers band on Foundations, Attraction, Upsell, Downsell and Continuity.") -> Every customer pays for the next one.
A29: LTGP to CAC | B29: =IF(ISNUMBER(ltgpCac),ltgpCac,"not yet") -> 9.7833333 | C29: How many times over a customer pays for themselves. The book wants at least 3.
A31: About this workbook
A32: Every lesson is a paraphrase in this workbook's own words, never the book's text; the play names are plain-word labels for the book's offer types. Read the book for the reasoning and the stories.
A33: Thresholds (pay a customer back inside 30 days, twice over to self-fund, lifetime gross profit at least three times the cost of a customer) are the book's rules of thumb, not measured findings. Your own numbers decide.
A34: Not financial or business advice. The example numbers are invented. Built from the same tables as the Money Models app in the Personalfinance repository (moneymodels/).

Sheet 1 Foundations
A1: Planet 1 of 6: Foundations
A2: What a money model is, what it costs you to get a customer today, and the one rule the whole book rests on.
A3: Type in the yellow cells (column D). Column F shows the number in use: yours, or the example while the switch on Start Here says Yes.
A4: Level | B4: Band | C4: Title, lesson, questions and boxes | D4: Your answer | E4: Example | F4: In use | G4: Help | H4: Done?
A5: 1 | B5: Learn | C5: What a money model is | G5: About 2 minutes. Read the idea, then answer one check question. | H5: =IF(F7="","",IF(F7="A sequence of offers: the first yes; a bigger yes; a smaller yes after a no; and a repeating yes","Done","Not yet")) -> Done
C6: A money model is a deliberate sequence of offers. Not one product with a price on it: the order in which you ask a customer to say yes, what you ask for each time, and what you do when they say no. The point of the sequence is cash timing. A business that makes plenty of profit over two years can still die in month two, because the money to get the next customer is not back in the bank yet. So the question the whole book asks is: how do you get a customer to pay you more, sooner, than it costs you to get and serve them?
C7: Which of these is a money model? | E7: A sequence of offers: the first yes; a bigger yes; a smaller yes after a no; and a repeating yes | F7: =IF(useExample="Yes",E7,D7) -> A sequence of offers: the first yes; a bigger yes; a smaller yes after a no; and a repeating yes | G7: =IF(F7="","",IF(F7="A sequence of offers: the first yes; a bigger yes; a smaller yes after a no; and a repeating yes","Right. One price is one offer. A money model is the order of offers around it and what each one is for.","Not quite. One price is one offer. A money model is the order of offers around it and what each one is for.")) -> Right. One price is one offer. A money model is the order of offers around it and what each one is for.
C8: Choices: A product with a good price / A sequence of offers: the first yes, a bigger yes, a smaller yes after a no, and a repeating yes / A marketing budget
A10: 2 | B10: Learn | C10: The cash constraint and the 30-day rule | G10: About 2 minutes. Read the idea, then answer one check question. | H10: =IF(F12="","",IF(F12="At least $150; and ideally $300 or more","Done","Not yet")) -> Done
C11: Every customer costs money to get (ads, time, commissions) and money to serve. If that cash comes back in a year, you can only afford as many customers as your savings allow. Growth is capped by your bank balance, not by demand. The rule of thumb the book builds on: get back at least what a customer cost you within 30 days. Get back twice that and every customer pays for the next one. Then growth is funded by customers, not by you or a lender. Thirty days is not magic. It is roughly how long a card bill or an ad invoice gives you before the money is due.
C12: A customer costs $150 to get. What does the model want back from them inside 30 days? | E12: At least $150; and ideally $300 or more | F12: =IF(useExample="Yes",E12,D12) -> At least $150; and ideally $300 or more | G12: =IF(F12="","",IF(F12="At least $150; and ideally $300 or more","Right. Break-even inside 30 days keeps you alive. Twice the cost lets the next customer be bought with this one's money.","Not quite. Break-even inside 30 days keeps you alive. Twice the cost lets the next customer be bought with this one's money.")) -> Right. Break-even inside 30 days keeps you alive. Twice the cost lets the next customer be bought with this one's money.
C13: Choices: At least $150, and ideally $300 or more / Whatever they pay over their lifetime / Nothing, as long as the business is profitable by year end
A15: 3 | B15: Learn | C15: The four kinds of offer | G15: About 2 minutes. Read the idea, then answer one check question. | H15: =IF(F17="","",IF(F17="A downsell: the same promise in a lighter or easier form","Done","Not yet")) -> Done
C16: Attraction offers get the first yes from a stranger. Their job is to bring people in cheaply, not to make the money. Upsell offers ask for a bigger yes right after the first one, when trust is highest. This is where the model earns. Downsell offers turn a no into a smaller yes: same promise, lighter package or easier terms. Continuity offers get the customer to keep paying: a membership, a subscription, a retainer. This is what makes the lifetime value large. Each of the next four planets takes one of these. Do them in order: a great upsell with no one to offer it to is worth nothing.
C17: A customer says no to the bigger package. Which offer comes next? | E17: A downsell: the same promise in a lighter or easier form | F17: =IF(useExample="Yes",E17,D17) -> A downsell: the same promise in a lighter or easier form | G17: =IF(F17="","",IF(F17="A downsell: the same promise in a lighter or easier form","Right. A no to the price or the size is not a no to the result. The downsell keeps the customer and some of the cash.","Not quite. A no to the price or the size is not a no to the result. The downsell keeps the customer and some of the cash.")) -> Right. A no to the price or the size is not a no to the result. The downsell keeps the customer and some of the cash.
C18: Choices: Another attraction offer / A downsell: the same promise in a lighter or easier form / Nothing, the sale is over
A20: 4 | B20: Numbers | C20: What your main offer sells for today | G20: About 1 minute. Type your figures for this part of the model. | H20: =IF(F22<>"","Done","") -> Done
C21: Start with the business as it is. One product or service, the one most customers buy first. Its price, before any discount.
C22: Price of your main offer today | E22: 199 | F22: =IF(useExample="Yes",E22,IF(D22="","",D22)) -> 199 | G22: Dollars. What one customer pays for it. If it is monthly, use one month here; the model will handle the repeat part on the Continuity planet.
A24: 5 | B24: Numbers | C24: What it costs you to deliver one | G24: About 3 minutes. Type your figures for this part of the model. | H24: =IF(F26<>"","Done","") -> Done
C25: Everything you spend to serve one customer for that offer: materials, shipping, contractor hours, software seats, the hours you pay someone for. Not rent, not ads. If you deliver it yourself, count your hours at what you would pay someone else.
C26: Cost to deliver one sale | E26: 60 | F26: =IF(useExample="Yes",E26,IF(D26="","",D26)) -> 60 | G26: Dollars. Only the costs that happen because this one customer bought. Type 0 if there truly are none (a digital file, say).
A28: 6 | B28: Numbers | C28: What a customer costs you to get | G28: About 4 minutes. Type your figures for this part of the model. | H28: =IF(AND(F30<>"",F31<>""),"Done",IF(OR(F30<>"",F31<>""),"Part","")) -> Done
C29: The cost of a customer is everything you spent to get customers in a month, divided by the customers you got. Ads, the person who runs them, referral fees, the free sessions you gave away. Last month is fine. A rough month is better than nothing; you will replace it on the Prove band.
C30: Spent on getting customers last month | E30: 6000 | F30: =IF(useExample="Yes",E30,IF(D30="","",D30)) -> 6000 | G30: Dollars. Ads, agency, commissions, giveaways, the salary of whoever does the marketing.
C31: New customers last month | E31: 40 | F31: =IF(useExample="Yes",E31,IF(D31="","",D31)) -> 40 | G31: People who paid for the first time. Not leads, not sign-ups.
A33: 7 | B33: Build | C33: Exercise: the promise in one line | G33: About 6 minutes. The exercises: pick a play, write the offer, tick the design list. | H33: =IF(AND(F35<>"",F36<>""),"Done",IF(OR(F35<>"",F36<>""),"Part","")) -> Done
C34: Every offer in the model points at the same result. Write it the way the customer would say it, not the way your industry does. 'Lose the first ten pounds in six weeks' beats 'a holistic fitness programme'. This line is reused on every planet: the attraction offer promises it, the upsell gets it faster, the downsell gets it lighter, continuity keeps it.
C35: Who the customer is, in a few words | E35: Busy parents who stopped exercising | F35: =IF(useExample="Yes",E35,IF(D35="","",D35)) -> Busy parents who stopped exercising | G35: One kind of person. 'Busy parents who stopped exercising' is a customer; 'anyone' is not.
C36: The result they want, in their words | E36: Lose the first ten pounds in six weeks | F36: =IF(useExample="Yes",E36,IF(D36="","",D36)) -> Lose the first ten pounds in six weeks | G36: A result with a size and a time if you can: what, how much, by when.
A38: 8 | B38: Build | C38: Exercise: name the constraint | G38: About 2 minutes. The exercises: pick a play, write the offer, tick the design list. | H38: =IF(F40<>"","Done","") -> Done
C39: A business is held back by one thing at a time. Pick the one that is true right now. The model's planets map onto it: not enough customers is an attraction problem; not enough per customer is upsell and downsell; they do not stay is continuity; it costs too much to serve is a margin problem to fix before any of them.
C40: What is holding the business back right now? | E40: Each customer does not pay enough | F40: =IF(useExample="Yes",E40,IF(D40="","",D40)) -> Each customer does not pay enough | G40: Pick one: Not enough customers / Each customer does not pay enough / They do not stay or come back / It costs too much to serve them
A42: 9 | B42: Build | C42: Exercise: map today's sequence | G42: About 5 minutes. The exercises: pick a play, write the offer, tick the design list. | H42: =IF(AND(F44<>"",F45<>"",F46<>"",F47<>""),"Done",IF(OR(F44<>"",F45<>"",F46<>"",F47<>""),"Part","")) -> Done
C43: Write down what a customer is actually offered today, in the order it happens. Most businesses find they have one offer and then silence. That silence is the money model you are about to build.
C44: The first thing a stranger is offered | E44: A $199 six-week class pass | F44: =IF(useExample="Yes",E44,IF(D44="","",D44)) -> A $199 six-week class pass | G44: The ad, the free consult, the intro price. Whatever comes first.
C45: What they are offered after buying | E45: Nothing | F45: =IF(useExample="Yes",E45,IF(D45="","",D45)) -> Nothing | G45: Type 'nothing' if nothing. That is an honest and common answer.
C46: What happens when they say no | E46: Nothing | F46: =IF(useExample="Yes",E46,IF(D46="","",D46)) -> Nothing | G46: A follow-up? A cheaper option? Nothing?
C47: What they pay for on an ongoing basis | E47: Nothing | F47: =IF(useExample="Yes",E47,IF(D47="","",D47)) -> Nothing | G47: A membership, a retainer, refills, or 'nothing'.
A49: 10 | B49: Prove | C49: How long cash takes to come back today | G49: About 3 minutes. Run it for real and type what happened. | H49: =IF(F51<>"","Done","") -> Done
...

Sheet 2 Attraction
A1: Planet 2 of 6: Attraction
A2: The first yes: the offer that turns a stranger into a customer without draining your cash.
A3: Type in the yellow cells (column D). Column F shows the number in use: yours, or the example while the switch on Start Here says Yes.
A4: Level | B4: Band | C4: Title, lesson, questions and boxes | D4: Your answer | E4: Example | F4: In use | G4: Help | H4: Done?
A5: 1 | B5: Learn | C5: What an attraction offer is for | G5: About 2 minutes. Read the idea, then answer one check question. | H5: =IF(F7="","",IF(F7="Good: the customer cost nothing net; and the upsell and continuity are still to come","Done","Not yet")) -> Done
C6: The attraction offer's job is to turn a stranger into a customer. It is the door, not the room. If it makes a profit on its own, wonderful; if it only covers the cost of getting the customer, that is still a win, because the upsell and continuity are waiting behind it. The mistake is to make the attraction offer the whole business: then every customer must be profitable on day one, and the price has to be high, and fewer people walk through the door. A good attraction offer is easy to say yes to, makes the promise from Foundations level 7 in a small, fast form, and naturally leads to the next offer.
C7: The attraction offer breaks even after covering the cost of the customer. Good or bad? | E7: Good: the customer cost nothing net; and the upsell and continuity are still to come | F7: =IF(useExample="Yes",E7,D7) -> Good: the customer cost nothing net; and the upsell and continuity are still to come | G7: =IF(F7="","",IF(F7="Good: the customer cost nothing net; and the upsell and continuity are still to come","Right. A free customer who then sees an upsell and a continuity offer is the whole idea.","Not quite. A free customer who then sees an upsell and a continuity offer is the whole idea.")) -> Right. A free customer who then sees an upsell and a continuity offer is the whole idea.
C8: Choices: Bad: every offer should make a profit / Good: the customer cost nothing net, and the upsell and continuity are still to come / Neither, it depends on the industry
A10: 2 | B10: Learn | C10: The attraction plays | G10: About 3 minutes. Read the idea, then answer one check question. | H10: =IF(F12="","",IF(F12="The few who hit the stated result and followed every rule","Done","Not yet")) -> Done
C11: Win your money back: the customer pays, and gets it back (or as credit) if they hit a defined result and follow the rules. Most will not hit it; the ones who do are the ones you want to keep. Giveaway: one big prize, many entrants, and everyone who did not win gets an offer. Cheap leads at volume. Decoy: a free or very cheap option beside the real one, so the real one looks like the sensible choice, and the free option filters out people who would never pay. Buy some, get some free: bundle volume up front. The free part is margin you would have spent on getting them back anyway. Pay less now or pay more later: two prices for the same thing, a smaller one paid today and a larger one paid on results or over time. Both close; one brings cash forward. Free with strings: free only when the string (a deposit, a booked call, an upsell moment) makes the free customer pay off.
C12: In 'win your money back', who ends up refunded? | E12: The few who hit the stated result and followed every rule | F12: =IF(useExample="Yes",E12,D12) -> The few who hit the stated result and followed every rule | G12: =IF(F12="","",IF(F12="The few who hit the stated result and followed every rule","Right. The condition is real and reachable. The people who reach it are your best customers, and the refund is cheaper than the ad that would have found them.","Not quite. The condition is real and reachable. The people who reach it are your best customers, and the refund is cheaper than the ad that would have found them.")) -> Right. The condition is real and reachable. The people who reach it are your best customers, and the refund is cheaper than the ad that would have found them.
C13: Choices: Everyone who asks / The few who hit the stated result and followed every rule / Nobody, it is a trick
A15: 3 | B15: Learn | C15: The three parts every attraction offer needs | G15: About 2 minutes. Read the idea, then answer one check question. | H15: =IF(F17="","",IF(F17="'50% off everything this month'","Done","Not yet")) -> Done
C16: A clear result with a time on it. Not 'a great experience'; 'ten pounds in six weeks'. A reason it is cheap or free that the customer believes: a challenge, a first-time price, a limited batch, a prize. Cheap with no reason reads as low quality. A string that leads to the next offer: the results call, the check-in, the thing they have to come in for. That is where the upsell lives.
C17: Which attraction offer is missing something? | E17: '50% off everything this month' | F17: =IF(useExample="Yes",E17,D17) -> '50% off everything this month' | G17: =IF(F17="","",IF(F17="'50% off everything this month'","Right. A discount has no result, no reason and no string. The other two have all three.","Not quite. A discount has no result, no reason and no string. The other two have all three.")) -> Right. A discount has no result, no reason and no string. The other two have all three.
C18: Choices: 'Six-week challenge, $500, win it back if you finish all 18 sessions' / '50% off everything this month' / 'Free strategy session, then we build your plan together'
A20: 4 | B20: Numbers | C20: The attraction offer's price | G20: About 1 minute. Type your figures for this part of the model. | H20: =IF(F22<>"","Done","") -> Done
C21: What the stranger pays for the first yes. Type 0 if the plan is free with strings; that is a real answer and the model will treat it as one.
C22: Price of the attraction offer | E22: 500 | F22: =IF(useExample="Yes",E22,IF(D22="","",D22)) -> 500 | G22: Dollars. The cash collected up front, before any refund or credit.
A24: 5 | B24: Numbers | C24: What the attraction offer costs to deliver | G24: About 3 minutes. Type your figures for this part of the model. | H24: =IF(F26<>"","Done","") -> Done
C25: Same idea as Foundations level 5, for this offer. Include the prize if it is a giveaway (prize cost divided by expected entrants) and the expected refunds if it is win-your-money-back (Prove level 11 sharpens that).
C26: Cost to deliver the attraction offer to one customer | E26: 120 | F26: =IF(useExample="Yes",E26,IF(D26="","",D26)) -> 120 | G26: Dollars. Per customer, all in. 0 is allowed.
A28: 6 | B28: Numbers | C28: Leads, and how many of them buy | G28: About 3 minutes. Type your figures for this part of the model. | H28: =IF(AND(F30<>"",F31<>""),"Done",IF(OR(F30<>"",F31<>""),"Part","")) -> Done
C29: A lead is someone who raised a hand: a form, a call, a walk-in. The share who take the attraction offer is the conversion rate. Together with what you spend (Foundations 6) this gives the cost of a lead.
C30: Leads per month | E30: 400 | F30: =IF(useExample="Yes",E30,IF(D30="","",D30)) -> 400 | G30: People who asked, booked or messaged. Last month is fine.
C31: Share of leads who take the attraction offer | E31: 0.1 | F31: =IF(useExample="Yes",E31,IF(D31="","",D31)) -> 0.1 | G31: Type a percent, e.g. 25%. Buyers divided by leads, as a percent.
A33: 7 | B33: Build | C33: Exercise: pick your attraction play | G33: About 2 minutes. The exercises: pick a play, write the offer, tick the design list. | H33: =IF(F35<>"","Done","") -> Done
C34: The Plays page says which of these the numbers already support for you. Pick one. A second one comes on the Optimize band.
C35: Your attraction play | E35: Win your money back | F35: =IF(useExample="Yes",E35,IF(D35="","",D35)) -> Win your money back | G35: Pick one: Win your money back / Giveaway / Decoy / Buy some; get some free / Pay less now or pay more later / Free with strings
A37: 8 | B37: Build | C37: Exercise: write the offer in one sentence | G37: About 8 minutes. The exercises: pick a play, write the offer, tick the design list. | H37: =IF(AND(F39<>"",F40<>""),"Done",IF(OR(F39<>"",F40<>""),"Part","")) -> Done
C38: Use the frame: 'Get [the result] in [the time] for [the price], and [the reason it is cheap or the condition of the reward].' Then add the string: what happens next that leads to the upsell. Say it out loud. If it takes two breaths, it is too long.
C39: The attraction offer, one sentence | E39: Lose ten pounds in six weeks for $500, and win it all back if you finish every session. | F39: =IF(useExample="Yes",E39,IF(D39="","",D39)) -> Lose ten pounds in six weeks for $500, and win it all back if you finish every session. | G39: Result, time, price, reason.
C40: The string: what leads to the next offer | E40: The week-two results check-in with a coach | F40: =IF(useExample="Yes",E40,IF(D40="","",D40)) -> The week-two results check-in with a coach | G40: The results call, the week-two check-in, the pickup, the delivery.
A42: 9 | B42: Build | C42: Checklist: attraction offer design | G42: About 5 minutes. The exercises: pick a play, write the offer, tick the design list. | H42: =IF(COUNTIF(F44:F50,"Yes")=7,"Done",IF(COUNTIF(F44:F50,"Yes")>0,"Part","")) -> Done
C43: Tick what the offer as written has. Anything unticked is the next thing to fix before it goes out.
C44: Names one result with a size and a time | E44: Yes | F44: =IF(useExample="Yes",E44,D44) -> Yes | G44: Yes when it is true
C45: Gives a believable reason it is cheap or free | E45: Yes | F45: =IF(useExample="Yes",E45,D45) -> Yes | G45: Yes when it is true
C46: Has a deadline or a limited number | E46: Yes | F46: =IF(useExample="Yes",E46,D46) -> Yes | G46: Yes when it is true
C47: Has a string that puts the customer in front of the upsell | E47: Yes | F47: =IF(useExample="Yes",E47,D47) -> Yes | G47: Yes when it is true
C48: Any money-back or reward has a measurable, written condition | E48: Yes | F48: =IF(useExample="Yes",E48,D48) -> Yes | G48: Yes when it is true
...

Sheet 3 Upsell
A1: Planet 3 of 6: Upsell
A2: The bigger yes, asked at the moment it is easiest to say. Where the model makes its money.
A3: Type in the yellow cells (column D). Column F shows the number in use: yours, or the example while the switch on Start Here says Yes.
A4: Level | B4: Band | C4: Title, lesson, questions and boxes | D4: Your answer | E4: Example | F4: In use | G4: Help | H4: Done?
A5: 1 | B5: Learn | C5: Why the moment after a yes is worth the most | G5: About 2 minutes. Read the idea, then answer one check question. | H5: =IF(F7="","",IF(F7="Right after the first yes; or right after their first win","Done","Not yet")) -> Done
C6: Someone who just paid you trusts you more than they will at any other point. They have decided you are worth money. Asking for a bigger yes in that window is far cheaper than finding a new customer. The upsell is where the money model makes its money. The attraction offer pays for the customer; the upsell pays for the business. The rule: the upsell must be a faster, bigger or easier way to get the same result they just bought. Not a different product. 'You want this; this gets you there sooner.'
C7: When is the upsell cheapest to make? | E7: Right after the first yes; or right after their first win | F7: =IF(useExample="Yes",E7,D7) -> Right after the first yes; or right after their first win | G7: =IF(F7="","",IF(F7="Right after the first yes; or right after their first win","Right. Trust peaks at the yes and at the first result. Both are upsell moments; the first is the one most businesses skip.","Not quite. Trust peaks at the yes and at the first result. Both are upsell moments; the first is the one most businesses skip.")) -> Right. Trust peaks at the yes and at the first result. Both are upsell moments; the first is the one most businesses skip.
C8: Choices: A month after the first purchase, once they have seen results / Right after the first yes, or right after their first win / Before they buy anything, to anchor high
A10: 2 | B10: Learn | C10: The upsell plays | G10: About 2 minutes. Read the idea, then answer one check question. | H10: =IF(F12="","",IF(F12="Counts it toward the bigger offer; so the first purchase becomes a deposit","Done","Not yet")) -> Done
C11: Classic: the next thing they need to get the result faster or keep it. The membership after the challenge, the installation after the product. Menu: several add-ons, they pick. People say yes to something more often than to one thing. Anchor: show the biggest option first. The one you actually want to sell looks reasonable next to it. Rollover: credit what they just paid toward the bigger thing. 'The $500 you paid comes off the $2,000 programme.' The first purchase becomes a deposit.
C12: What does a rollover upsell do with the money the customer already paid? | E12: Counts it toward the bigger offer; so the first purchase becomes a deposit | F12: =IF(useExample="Yes",E12,D12) -> Counts it toward the bigger offer; so the first purchase becomes a deposit | G12: =IF(F12="","",IF(F12="Counts it toward the bigger offer; so the first purchase becomes a deposit","Right. A customer who has already paid part of the bigger thing is halfway to yes.","Not quite. A customer who has already paid part of the bigger thing is halfway to yes.")) -> Right. A customer who has already paid part of the bigger thing is halfway to yes.
C13: Choices: Refunds it / Counts it toward the bigger offer, so the first purchase becomes a deposit / Ignores it
A15: 3 | B15: Learn | C15: The ask | G15: About 2 minutes. Read the idea, then answer one check question. | H15: =IF(F17="","",IF(F17="Whether every customer was actually offered it","Done","Not yet")) -> Done
C16: An upsell that is never offered has a take rate of zero. Most upsell problems are not the offer; it is that nobody asked. Ask in one sentence, as a service: 'Since you want [result], the people who get there fastest also [next step]. Want me to add it?' Then stop talking. Every customer is asked. Not the ones who look rich. Every one.
C17: The upsell take rate is 5%. What is the first thing to check? | E17: Whether every customer was actually offered it | F17: =IF(useExample="Yes",E17,D17) -> Whether every customer was actually offered it | G17: =IF(F17="","",IF(F17="Whether every customer was actually offered it","Right. Offered-to share times take-rate-when-offered is the real number. Fix the asking before the offer.","Not quite. Offered-to share times take-rate-when-offered is the real number. Fix the asking before the offer.")) -> Right. Offered-to share times take-rate-when-offered is the real number. Fix the asking before the offer.
C18: Choices: The price / Whether every customer was actually offered it / The product
A20: 4 | B20: Numbers | C20: The upsell's price | G20: About 1 minute. Type your figures for this part of the model. | H20: =IF(F22<>"","Done","") -> Done
C21: The bigger yes. If it is a payment plan, type the total here; the Downsell planet handles split terms.
C22: Price of the upsell | E22: 1200 | F22: =IF(useExample="Yes",E22,IF(D22="","",D22)) -> 1200 | G22: Dollars. Total price, before any rollover credit.
A24: 5 | B24: Numbers | C24: What the upsell costs to deliver | G24: About 2 minutes. Type your figures for this part of the model. | H24: =IF(F26<>"","Done","") -> Done
C25: Per customer, all in, for the whole thing you are selling.
C26: Cost to deliver the upsell to one customer | E26: 300 | F26: =IF(useExample="Yes",E26,IF(D26="","",D26)) -> 300 | G26: Dollars. Materials, hours, seats. 0 is allowed.
A28: 6 | B28: Numbers | C28: How many take it | G28: About 2 minutes. Type your figures for this part of the model. | H28: =IF(F30<>"","Done","") -> Done
C29: Of the customers offered the upsell, the share who say yes. If you have not run it yet, use a modest guess (one in five is a common starting point for a well-matched upsell) and mark it to revisit on Prove.
C30: Share of customers offered the upsell who take it | E30: 0.25 | F30: =IF(useExample="Yes",E30,IF(D30="","",D30)) -> 0.25 | G30: Type a percent, e.g. 25%. Takers divided by those asked, as a percent.
A32: 7 | B32: Build | C32: Exercise: pick your upsell play | G32: About 2 minutes. The exercises: pick a play, write the offer, tick the design list. | H32: =IF(F34<>"","Done","") -> Done
C33: Classic if there is an obvious next step. Menu if you have several. Anchor if you have a premium tier. Rollover if the attraction offer's price is a meaningful part of the upsell's.
C34: Your upsell play | E34: Rollover: first payment becomes a deposit | F34: =IF(useExample="Yes",E34,IF(D34="","",D34)) -> Rollover: first payment becomes a deposit | G34: Pick one: Classic: the next step / Menu: they pick from add-ons / Anchor: biggest option first / Rollover: first payment becomes a deposit
A36: 8 | B36: Build | C36: Exercise: write the upsell script | G36: About 8 minutes. The exercises: pick a play, write the offer, tick the design list. | H36: =IF(AND(F38<>"",F39<>""),"Done",IF(OR(F38<>"",F39<>""),"Part","")) -> Done
C37: One sentence to ask, one sentence for the most common no. The frame: 'Since you want [result], most people who get it fastest also [next step]. Want me to add that?'
C38: The ask, in one sentence | E38: Since you want the ten pounds gone for good, the people who keep it off go straight onto the year programme, and the $500 you paid comes off it. Want me to set that up? | F38: =IF(useExample="Yes",E38,IF(D38="","",D38)) -> Since you want the ten pounds gone for good, the people who keep it off go straight onto the year programme, and the $500 you paid comes off it. Want me to set that up? | G38: Say it as a service, not a sale.
C39: What you say to the most common no | E39: Totally fair. Would three payments make it work? | F39: =IF(useExample="Yes",E39,IF(D39="","",D39)) -> Totally fair. Would three payments make it work? | G39: Usually it leads to the downsell.
A41: 9 | B41: Build | C41: Checklist: upsell design | G41: About 5 minutes. The exercises: pick a play, write the offer, tick the design list. | H41: =IF(COUNTIF(F43:F49,"Yes")=7,"Done",IF(COUNTIF(F43:F49,"Yes")>0,"Part","")) -> Done
C42: Tick what is true of the upsell as written.
C43: Offered within minutes of the first yes, or at the first win | E43: Yes | F43: =IF(useExample="Yes",E43,D43) -> Yes | G43: Yes when it is true
C44: Gets the same result faster, bigger or easier | E44: Yes | F44: =IF(useExample="Yes",E44,D44) -> Yes | G44: Yes when it is true
C45: Priced above the attraction offer | E45: Yes | F45: =IF(useExample="Yes",E45,D45) -> Yes | G45: Yes when it is true
C46: Cost to deliver is known | E46: Yes | F46: =IF(useExample="Yes",E46,D46) -> Yes | G46: Yes when it is true
C47: The ask fits in one sentence | E47: Yes | F47: =IF(useExample="Yes",E47,D47) -> Yes | G47: Yes when it is true
C48: A no does not undo the first sale | E48: Yes | F48: =IF(useExample="Yes",E48,D48) -> Yes | G48: Yes when it is true
...

Sheet 4 Downsell
A1: Planet 4 of 6: Downsell
A2: The smaller yes after a no. Keeps the customer and recovers cash you would have lost.
A3: Type in the yellow cells (column D). Column F shows the number in use: yours, or the example while the switch on Start Here says Yes.
A4: Level | B4: Band | C4: Title, lesson, questions and boxes | D4: Your answer | E4: Example | F4: In use | G4: Help | H4: Done?
A5: 1 | B5: Learn | C5: A no is not the end | G5: About 2 minutes. Read the idea, then answer one check question. | H5: =IF(F7="","",IF(F7="The same programme at $2;000 in four payments","Done","Not yet")) -> Done
C6: When a customer says no to the upsell, most businesses stop. The customer wanted the result a minute ago; what they said no to was the size or the terms. A downsell offers a smaller yes: the same promise with less in the box, or the same box with easier terms. It recovers cash that was walking out, and it keeps the customer in the sequence for continuity. Order matters: first change the terms (a payment plan), then the package (a lighter version), then the price. Cutting the price first teaches customers to say no.
C7: The customer says no to a $2,000 programme. What is the first downsell to try? | E7: The same programme at $2;000 in four payments | F7: =IF(useExample="Yes",E7,D7) -> The same programme at $2;000 in four payments | G7: =IF(F7="","",IF(F7="The same programme at $2;000 in four payments","Right. Same value, easier terms. Price cuts come last and cost the most.","Not quite. Same value, easier terms. Price cuts come last and cost the most.")) -> Right. Same value, easier terms. Price cuts come last and cost the most.
C8: Choices: $1,000 for the same programme / The same programme at $2,000 in four payments / A different product
A10: 2 | B10: Learn | C10: The downsell plays | G10: About 2 minutes. Read the idea, then answer one check question. | H10: =IF(F12="","",IF(F12="There is a string: a payment if they keep it or do not do the work","Done","Not yet")) -> Done
C11: Payment plan: the same offer split over time. Usually the first thing to try, and often the only one needed. Trial with a string: try it, and pay if you keep it, or pay a penalty if you do not do the work. The string keeps the free part from being free forever. Lighter version: fewer parts, less access, less support, same result more slowly. Keep the promise, shrink the package. Deposit and decide: a small payment to hold the price or the spot, decided later. Cash today, and a reason to come back.
C12: What makes a trial a downsell rather than a giveaway? | E12: There is a string: a payment if they keep it or do not do the work | F12: =IF(useExample="Yes",E12,D12) -> There is a string: a payment if they keep it or do not do the work | G12: =IF(F12="","",IF(F12="There is a string: a payment if they keep it or do not do the work","Right. A trial with no string is a free customer with no path to paying. The string is the point.","Not quite. A trial with no string is a free customer with no path to paying. The string is the point.")) -> Right. A trial with no string is a free customer with no path to paying. The string is the point.
C13: Choices: It is shorter / There is a string: a payment if they keep it or do not do the work / It is only for some people
A15: 3 | B15: Learn | C15: Where the downsell sits | G15: About 2 minutes. Read the idea, then answer one check question. | H15: =IF(F17="","",IF(F17="The one for customers who said no to the upsell","Done","Not yet")) -> Done
C16: There are two nos in the model. The no to the attraction offer (a stranger who did not buy) and the no to the upsell (a customer who did not go bigger). Each can have a downsell. Start with the second. Those people already paid you once, showed up, and heard the upsell. A smaller yes from them is the easiest cash in the business. The downsell after the attraction offer comes on the Optimize band, once the rest works.
C17: Which downsell should be built first? | E17: The one for customers who said no to the upsell | F17: =IF(useExample="Yes",E17,D17) -> The one for customers who said no to the upsell | G17: =IF(F17="","",IF(F17="The one for customers who said no to the upsell","Right. They are warm, present and have already paid. Build where the yes is easiest.","Not quite. They are warm, present and have already paid. Build where the yes is easiest.")) -> Right. They are warm, present and have already paid. Build where the yes is easiest.
C18: Choices: The one for strangers who did not buy the attraction offer / The one for customers who said no to the upsell / Both at once
A20: 4 | B20: Numbers | C20: The downsell's price | G20: About 1 minute. Type your figures for this part of the model. | H20: =IF(F22<>"","Done","") -> Done
C21: What the smaller yes costs the customer in total. For a payment plan on the same upsell, that may equal the upsell price; the terms are what changed.
C22: Price of the downsell | E22: 450 | F22: =IF(useExample="Yes",E22,IF(D22="","",D22)) -> 450 | G22: Dollars. Total over all payments.
A24: 5 | B24: Numbers | C24: What the downsell costs to deliver | G24: About 2 minutes. Type your figures for this part of the model. | H24: =IF(F26<>"","Done","") -> Done
C25: Per customer. A lighter version should cost less to deliver; a payment plan costs the same as the upsell.
C26: Cost to deliver the downsell to one customer | E26: 300 | F26: =IF(useExample="Yes",E26,IF(D26="","",D26)) -> 300 | G26: Dollars. All in. 0 is allowed.
A28: 6 | B28: Numbers | C28: How many take it | G28: About 2 minutes. Type your figures for this part of the model. | H28: =IF(F30<>"","Done","") -> Done
C29: Of the customers who said no to the upsell and were offered the downsell, the share who take it.
C30: Share of upsell nos who take the downsell | E30: 0.4 | F30: =IF(useExample="Yes",E30,IF(D30="","",D30)) -> 0.4 | G30: Type a percent, e.g. 25%. Takers divided by those offered, as a percent.
A32: 7 | B32: Build | C32: Exercise: pick your downsell play | G32: About 2 minutes. The exercises: pick a play, write the offer, tick the design list. | H32: =IF(F34<>"","Done","") -> Done
C33: Payment plan unless there is a clear reason not to. The Plays page says which ones the numbers support.
C34: Your downsell play | E34: Payment plan | F34: =IF(useExample="Yes",E34,IF(D34="","",D34)) -> Payment plan | G34: Pick one: Payment plan / Trial with a string / Lighter version / Deposit and decide
A36: 8 | B36: Build | C36: Exercise: write the downsell script | G36: About 6 minutes. The exercises: pick a play, write the offer, tick the design list. | H36: =IF(AND(F38<>"",F39<>""),"Done",IF(OR(F38<>"",F39<>""),"Part","")) -> Done
C37: It follows the no directly. 'Totally fair. Would it help if we did [terms or lighter version] instead? You would still get [result], just [the change].'
C38: The downsell, in one sentence | E38: No problem. We can do the same programme as three payments of $150; you still get the full year. | F38: =IF(useExample="Yes",E38,IF(D38="","",D38)) -> No problem. We can do the same programme as three payments of $150; you still get the full year. | G38: Acknowledge the no, offer the smaller yes, keep the result.
C39: What exactly is smaller | E39: Nothing is cut; the terms are longer | F39: =IF(useExample="Yes",E39,IF(D39="","",D39)) -> Nothing is cut; the terms are longer | G39: Fewer sessions, longer terms, less support, no guarantee. Name it.
A41: 9 | B41: Build | C41: Checklist: downsell design | G41: About 4 minutes. The exercises: pick a play, write the offer, tick the design list. | H41: =IF(COUNTIF(F43:F48,"Yes")=6,"Done",IF(COUNTIF(F43:F48,"Yes")>0,"Part","")) -> Done
C42: Tick what is true of the downsell as written.
C43: Keeps the same result, only the package or terms shrink | E43: Yes | F43: =IF(useExample="Yes",E43,D43) -> Yes | G43: Yes when it is true
C44: Terms were tried before price | E44: Yes | F44: =IF(useExample="Yes",E44,D44) -> Yes | G44: Yes when it is true
C45: Still covers its cost to deliver | E45: Yes | F45: =IF(useExample="Yes",E45,D45) -> Yes | G45: Yes when it is true
C46: Still puts the customer in front of the continuity offer | E46: Yes | F46: =IF(useExample="Yes",E46,D46) -> Yes | G46: Yes when it is true
C47: Is never advertised, only offered after a no | E47: Yes | F47: =IF(useExample="Yes",E47,D47) -> Yes | G47: Yes when it is true
C48: The offer fits in one sentence | E48: Yes | F48: =IF(useExample="Yes",E48,D48) -> Yes | G48: Yes when it is true
...

Sheet 5 Continuity
A1: Planet 5 of 6: Continuity
A2: The yes that repeats: getting customers to keep paying, which is what makes lifetime profit large.
A3: Type in the yellow cells (column D). Column F shows the number in use: yours, or the example while the switch on Start Here says Yes.
A4: Level | B4: Band | C4: Title, lesson, questions and boxes | D4: Your answer | E4: Example | F4: In use | G4: Help | H4: Done?
A5: 1 | B5: Learn | C5: One sale into many | G5: About 2 minutes. Read the idea, then answer one check question. | H5: =IF(F7="","",IF(F7="About 10","Done","Not yet")) -> Done
C6: A customer who pays once is a transaction. A customer who pays every month is an asset. Continuity is what turns the model from a series of launches into a business that grows while you sleep. The lifetime gross profit of a customer is mostly continuity. A $150 a month membership with 8% monthly churn is worth about twelve and a half months, over $1,800 of revenue, from one yes. Every earlier offer should end by placing the customer in front of the continuity offer.
C7: Monthly churn is 10%. On average how many months does a member stay? | E7: About 10 | F7: =IF(useExample="Yes",E7,D7) -> About 10 | G7: =IF(F7="","",IF(F7="About 10","Right. Expected months is one divided by the monthly churn: 1 / 0.10 = 10.","Not quite. Expected months is one divided by the monthly churn: 1 / 0.10 = 10.")) -> Right. Expected months is one divided by the monthly churn: 1 / 0.10 = 10.
C8: Choices: About 10 / About 5 / About 20
A10: 2 | B10: Learn | C10: The continuity plays | G10: About 2 minutes. Read the idea, then answer one check question. | H10: =IF(F12="","",IF(F12="Getting people to stay; by giving them something to wait for","Done","Not yet")) -> Done
C11: Bonus for committing: a gift, worth a lot to them and little to you, for joining the ongoing plan today. Discount for a longer term: pay for a year, get it cheaper. Cash forward, churn removed. Waived fee: the setup or first month is free if they join now. The fee exists so that waiving it means something. Bonuses over time: something new arrives in month two, month three, month six. Reasons to stay, not just reasons to join. The default: the ongoing plan is the normal thing to buy; the one-off is the exception you have to ask for.
C12: What is 'bonuses over time' for? | E12: Getting people to stay; by giving them something to wait for | F12: =IF(useExample="Yes",E12,D12) -> Getting people to stay; by giving them something to wait for | G12: =IF(F12="","",IF(F12="Getting people to stay; by giving them something to wait for","Right. Joining bonuses fight the first no. Bonuses over time fight churn.","Not quite. Joining bonuses fight the first no. Bonuses over time fight churn.")) -> Right. Joining bonuses fight the first no. Bonuses over time fight churn.
C13: Choices: Getting people to join / Getting people to stay, by giving them something to wait for / Raising the price
A15: 3 | B15: Learn | C15: Churn is the tax | G15: About 2 minutes. Read the idea, then answer one check question. | H15: =IF(F17="","",IF(F17="It roughly doubles","Done","Not yet")) -> Done
C16: Churn is the share of members who leave each month. Halving it doubles the value of every customer you already have, without a single new lead. Measure it monthly, by cohort (people who joined the same month). A single average hides a leak in month two. Most churn happens early, before the customer has had a win. The continuity offer's first job is to get them a win fast.
C17: Churn drops from 10% to 5% a month. What happens to the average member's lifetime value? | E17: It roughly doubles | F17: =IF(useExample="Yes",E17,D17) -> It roughly doubles | G17: =IF(F17="","",IF(F17="It roughly doubles","Right. Expected months goes from 10 to 20. Same price, twice the months.","Not quite. Expected months goes from 10 to 20. Same price, twice the months.")) -> Right. Expected months goes from 10 to 20. Same price, twice the months.
C18: Choices: It goes up a little / It roughly doubles / Nothing until you raise prices
A20: 4 | B20: Numbers | C20: The monthly price | G20: About 1 minute. Type your figures for this part of the model. | H20: =IF(F22<>"","Done","") -> Done
C21: What a member pays each month. If it is yearly, divide by twelve here; the yearly option comes on Optimize.
C22: Continuity price per month | E22: 149 | F22: =IF(useExample="Yes",E22,IF(D22="","",D22)) -> 149 | G22: Dollars. Per member, per month.
A24: 5 | B24: Numbers | C24: What a member costs to serve each month | G24: About 2 minutes. Type your figures for this part of the model. | H24: =IF(F26<>"","Done","") -> Done
C25: Per member, per month: the classes they attend, the software seat, the check-in call, the shipment.
C26: Cost to serve one member for a month | E26: 40 | F26: =IF(useExample="Yes",E26,IF(D26="","",D26)) -> 40 | G26: Dollars. All in. 0 is allowed.
A28: 6 | B28: Numbers | C28: Who joins, and who leaves | G28: About 3 minutes. Type your figures for this part of the model. | H28: =IF(AND(F30<>"",F31<>""),"Done",IF(OR(F30<>"",F31<>""),"Part","")) -> Done
C29: The share of customers who join continuity by the end of the sequence, and the share of members who leave each month. If you have no history, guess and revisit on Prove.
C30: Share of customers who join continuity | E30: 0.6 | F30: =IF(useExample="Yes",E30,IF(D30="","",D30)) -> 0.6 | G30: Type a percent, e.g. 25%. Joiners divided by customers who finished the earlier offers.
C31: Monthly churn | E31: 0.08 | F31: =IF(useExample="Yes",E31,IF(D31="","",D31)) -> 0.08 | G31: Type a percent, e.g. 25%. Members who left this month divided by members at the start of it.
A33: 7 | B33: Build | C33: Exercise: pick your continuity play | G33: About 2 minutes. The exercises: pick a play, write the offer, tick the design list. | H33: =IF(F35<>"","Done","") -> Done
C34: The default first: make the ongoing plan the normal purchase. Then one of the others to remove the first no.
C35: Your continuity play | E35: The default | F35: =IF(useExample="Yes",E35,IF(D35="","",D35)) -> The default | G35: Pick one: Bonus for committing / Discount for a longer term / Waived fee / Bonuses over time / The default
A37: 8 | B37: Build | C37: Exercise: write the continuity pitch | G37: About 8 minutes. The exercises: pick a play, write the offer, tick the design list. | H37: =IF(AND(F39<>"",F40<>""),"Done",IF(OR(F39<>"",F40<>""),"Part","")) -> Done
C38: Frame: 'To keep [result] going, most people stay on for [the ongoing plan]. It is [price] a month, and if you start today you also get [bonus].' Then the reason to stay: what arrives later.
C39: The pitch, one or two sentences | E39: To keep the weight off, most people stay on as members: $149 a month, and if you start today the first month's meal plans are included. | F39: =IF(useExample="Yes",E39,IF(D39="","",D39)) -> To keep the weight off, most people stay on as members: $149 a month, and if you start today the first month's meal plans are included. | G39: Result, plan, price, the joining bonus.
C40: The reason to stay past month one | E40: A new eight-week block every two months, and a tracked weigh-in chart | F40: =IF(useExample="Yes",E40,IF(D40="","",D40)) -> A new eight-week block every two months, and a tracked weigh-in chart | G40: What arrives in month two, three, six. A tracked result counts.
A42: 9 | B42: Build | C42: Checklist: continuity design | G42: About 4 minutes. The exercises: pick a play, write the offer, tick the design list. | H42: =IF(COUNTIF(F44:F49,"Yes")=6,"Done",IF(COUNTIF(F44:F49,"Yes")>0,"Part","")) -> Done
C43: Tick what is true of the continuity offer as written.
C44: The ongoing plan is the default purchase | E44: Yes | F44: =IF(useExample="Yes",E44,D44) -> Yes | G44: Yes when it is true
C45: There is a reason to join today | E45: Yes | F45: =IF(useExample="Yes",E45,D45) -> Yes | G45: Yes when it is true
C46: There is a reason to stay past month one | E46: Yes | F46: =IF(useExample="Yes",E46,D46) -> Yes | G46: Yes when it is true
C47: The first month is built to deliver a visible win | E47: Yes | F47: =IF(useExample="Yes",E47,D47) -> Yes | G47: Yes when it is true
C48: Billing is automatic | E48: Yes | F48: =IF(useExample="Yes",E48,D48) -> Yes | G48: Yes when it is true
...

Sheet 6 KPIs and Scale
A1: Planet 6 of 6: KPIs and Scale
A2: The six numbers to watch, the two thresholds, and how fast customer money can fund the next customer.
A3: Type in the yellow cells (column D). Column F shows the number in use: yours, or the example while the switch on Start Here says Yes.
A4: Level | B4: Band | C4: Title, lesson, questions and boxes | D4: Your answer | E4: Example | F4: In use | G4: Help | H4: Done?
A5: 1 | B5: Learn | C5: The six numbers | G5: About 3 minutes. Read the idea, then answer one check question. | H5: =IF(F7="","",IF(F7="$380","Done","Not yet")) -> Done
C6: Cost of a customer (CAC): what you spend to get one. Gross profit per sale: price minus the cost to deliver. 30-day cash: gross profit collected from a customer in their first 30 days, across the whole sequence. Lifetime gross profit (LTGP): everything a customer earns you, less delivery, over their whole stay. LTGP to CAC: how many times over a customer pays for themselves. Payback days: how long until a customer has paid back their cost.
C7: Price $500, cost to deliver $120, cost of the customer $150. What is the gross profit per sale? | E7: $380 | F7: =IF(useExample="Yes",E7,D7) -> $380 | G7: =IF(F7="","",IF(F7="$380","Right. Gross profit is price minus delivery cost: 500 minus 120. The cost of the customer is compared against it, not subtracted from it.","Not quite. Gross profit is price minus delivery cost: 500 minus 120. The cost of the customer is compared against it, not subtracted from it.")) -> Right. Gross profit is price minus delivery cost: 500 minus 120. The cost of the customer is compared against it, not subtracted from it.
C8: Choices: $380 / $230 / $350
A10: 2 | B10: Learn | C10: The two thresholds | G10: About 2 minutes. Read the idea, then answer one check question. | H10: =IF(F12="","",IF(F12="Self-funding: each customer pays for the next","Done","Not yet")) -> Done
C11: 30-day cash at least equal to CAC: you break even on each customer before the bills for getting them are due. You are alive. 30-day cash at least twice CAC: each customer funds the next one. You can grow as fast as you can deliver, with no outside money. LTGP at least three times CAC: the business is worth running. Below that, the customers are barely paying for the marketing.
C12: 30-day cash is $300 and CAC is $150. Which is true? | E12: Self-funding: each customer pays for the next | F12: =IF(useExample="Yes",E12,D12) -> Self-funding: each customer pays for the next | G12: =IF(F12="","",IF(F12="Self-funding: each customer pays for the next","Right. Twice the cost inside 30 days is the self-funding line.","Not quite. Twice the cost inside 30 days is the self-funding line.")) -> Right. Twice the cost inside 30 days is the self-funding line.
C13: Choices: Break even only / Self-funding: each customer pays for the next / Losing money
A15: 3 | B15: Learn | C15: The four ways to grow | G15: About 2 minutes. Read the idea, then answer one check question. | H15: =IF(F17="","",IF(F17="A bigger office","Done","Not yet")) -> Done
C16: More customers (attraction). More per customer (upsell, downsell, price). More often (continuity). Less to deliver (margin). Every business grows through those four, and only those four. When you are stuck, the constraint from Foundations level 8 names which one. The model's charts move when you move any of them; try it on the Model page once your numbers are in.
C17: Which of these is not one of the four ways to grow? | E17: A bigger office | F17: =IF(useExample="Yes",E17,D17) -> A bigger office | G17: =IF(F17="","",IF(F17="A bigger office","Right. An office is a cost. Growth comes from customers, price, frequency and margin.","Not quite. An office is a cost. Growth comes from customers, price, frequency and margin.")) -> Right. An office is a cost. Growth comes from customers, price, frequency and margin.
C18: Choices: Customers buy more often / A bigger office / Each sale costs less to deliver
A20: 4 | B20: Numbers | C20: How many you can serve | G20: About 2 minutes. Type your figures for this part of the model. | H20: =IF(F22<>"","Done","") -> Done
C21: The ceiling on the other side: customers you can take on in a month before quality drops. The growth chart flattens here.
C22: Most new customers you can serve in a month | E22: 80 | F22: =IF(useExample="Yes",E22,IF(D22="","",D22)) -> 80 | G22: Honest, at current staff and hours.
A24: 5 | B24: Numbers | C24: What the business costs to keep open | G24: About 3 minutes. Type your figures for this part of the model. | H24: =IF(F26<>"","Done","") -> Done
C25: Rent, salaries, software, insurance: the monthly costs that do not change with one more customer. Gross profit has to cover this before there is any profit.
C26: Fixed costs per month | E26: 9000 | F26: =IF(useExample="Yes",E26,IF(D26="","",D26)) -> 9000 | G26: Dollars. Everything that is due whether or not a customer buys.
A28: 6 | B28: Numbers | C28: The loop: cash in, share back in | G28: About 3 minutes. Type your figures for this part of the model. | H28: =IF(AND(F30<>"",F31<>""),"Done",IF(OR(F30<>"",F31<>""),"Part","")) -> Done
C29: Two figures that decide how fast the model can spin. The cash you can put toward getting customers each month is the ceiling before the model self-funds. The share of each month's 30-day cash you put back into ads is what makes the ceiling rise. 100 is all of it.
C30: Cash available for getting customers each month | E30: 8000 | F30: =IF(useExample="Yes",E30,IF(D30="","",D30)) -> 8000 | G30: Dollars. What you could spend on ads and sales this month without missing payroll or rent.
C31: Share of 30-day cash reinvested in getting customers | E31: 0.5 | F31: =IF(useExample="Yes",E31,IF(D31="","",D31)) -> 0.5 | G31: Type a percent, e.g. 25%. As a percent. 50 is half.
A33: 7 | B33: Build | C33: Exercise: the one number on the wall | G33: About 1 minute. The exercises: pick a play, write the offer, tick the design list. | H33: =IF(F35<>"","Done","") -> Done
C34: Pick the one KPI the whole team sees every week. The constraint says which: customers means CAC or leads; per customer means 30-day cash; stay means churn.
C35: The number you watch weekly | E35: 30-day cash per customer | F35: =IF(useExample="Yes",E35,IF(D35="","",D35)) -> 30-day cash per customer | G35: Pick one: Cost of a customer / 30-day cash per customer / 30-day ratio / Monthly churn / LTGP to CAC / Leads per week
A37: 8 | B37: Build | C37: Exercise: the scoreboard | G37: About 3 minutes. The exercises: pick a play, write the offer, tick the design list. | H37: =IF(AND(F39<>"",F40<>""),"Done",IF(OR(F39<>"",F40<>""),"Part","")) -> Done
C38: Where the numbers live, who updates them, and when. A number nobody owns is a number nobody has.
